Workbook
Name Gewicht_bedOK: Einstellungen!$B$5
Name Ampel_gruen: Einstellungen!$B$6
Name Ampel_gelb: Einstellungen!$B$7
Name Ziel_Verfuegbarkeit: Einstellungen!$B$8
Name Kapitel_Liste: Einstellungen!$B$11:$B$19
Name Auditart_Liste: Einstellungen!$B$34:$B$36

Sheet Dashboard
B1: Audit Instandhaltung allgemein – Bewertung
B2: Rechnet automatisch aus dem Blatt „Checkliste“. Grenzwerte und Gewichte auf „Einstellungen“.
B4: Firma / Werk | D4: Bereich / Abteilung | F4: Auditdatum | H4: Auditor | J4: Auditart | L4: Teilnehmer
B5: =IF(Checkliste!$C$4="","–",Checkliste!$C$4) | D5: =IF(Checkliste!$C$5="","–",Checkliste!$C$5) | F5: =IF(Checkliste!$C$6="","–",Checkliste!$C$6) | H5: =IF(Checkliste!$C$7="","–",Checkliste!$C$7) | J5: =IF(Checkliste!$C$9="","–",Checkliste!$C$9) | L5: =IF(Checkliste!$C$8="","–",Checkliste!$C$8)
B7: Erfüllungsgrad | D7: Gesamtbewertung | F7: Veränderung zum letzten Audit | H7: Bewertungsfortschritt | J7: Maßnahmen gesamt | L7: Maßnahmen überfällig
B8: =IFERROR(SUM(Checkliste!$O$13:$O$85)/SUM(Checkliste!$P$13:$P$85),"") | D8: =IF(B8="","nicht bewertet",IF(B8>=Ampel_gruen,"gut",IF(B8>=Ampel_gelb,"mittel","kritisch"))) | F8: =IF(OR(Checkliste!$C$10="",B8=""),"–",(B8-Checkliste!$C$10)*100) | H8: =IFERROR((COUNTIF(Checkliste!$G$13:$G$85,"N.I.O")+COUNTIF(Checkliste!$G$13:$G$85,"bed. OK")+COUNTIF(Checkliste!$G$13:$G$85,"OK")+COUNTIF(Checkliste!$G$13:$G$85,"n. b."))/COUNTIF(Checkliste!$C$13:$C$85,"?*"),"") | J8: =COUNTIF(Checkliste!$L$13:$L$85,"offen")+COUNTIF(Checkliste!$L$13:$L$85,"überfällig")+COUNTIF(Checkliste!$L$13:$L$85,"erledigt") | L8: =COUNTIF(Checkliste!$L$13:$L$85,"überfällig")
B10: ="Ziel „gut“ ≥ "&TEXT(Ampel_gruen,"0%") | D10: ="gelb ab "&TEXT(Ampel_gelb,"0%")&" · grün ab "&TEXT(Ampel_gruen,"0%") | F10: ="letztes Audit: "&IF(Checkliste!$C$10="","–",TEXT(Checkliste!$C$10,"0%")) | H10: =(COUNTIF(Checkliste!$G$13:$G$85,"N.I.O")+COUNTIF(Checkliste!$G$13:$G$85,"bed. OK")+COUNTIF(Checkliste!$G$13:$G$85,"OK")+COUNTIF(Checkliste!$G$13:$G$85,"n. b."))&" von "&COUNTIF(Checkliste!$C$13:$C$85,"?*")&" Punkten bewertet" | J10: ="davon erledigt: "&COUNTIF(Checkliste!$L$13:$L$85,"erledigt") | L10: ="offen (im Termin / ohne Termin): "&COUNTIF(Checkliste!$L$13:$L$85,"offen")
B12: Ergebnis je Kapitel
B13: Kapitel | E13: Punkte | F13: N.I.O | G13: bed. OK | H13: OK | I13: n. b. | J13: offen | K13: Erfüllungsgrad | L13: Bewertung
B14: =IF(Einstellungen!$B$11="","",Einstellungen!$B$11) | E14: =IF($B14="","",COUNTIFS(Checkliste!$B$13:$B$85,$B14,Checkliste!$C$13:$C$85,"?*")) | F14: =IF($B14="","",COUNTIFS(Checkliste!$B$13:$B$85,$B14,Checkliste!$G$13:$G$85,"N.I.O")) | G14: =IF($B14="","",COUNTIFS(Checkliste!$B$13:$B$85,$B14,Checkliste!$G$13:$G$85,"bed. OK")) | H14: =IF($B14="","",COUNTIFS(Checkliste!$B$13:$B$85,$B14,Checkliste!$G$13:$G$85,"OK")) | I14: =IF($B14="","",COUNTIFS(Checkliste!$B$13:$B$85,$B14,Checkliste!$G$13:$G$85,"n. b.")) | J14: =IF($B14="","",E14-SUM(F14:I14)) | K14: =IF($B14="","",IFERROR(SUMIFS(Checkliste!$O$13:$O$85,Checkliste!$B$13:$B$85,$B14)/SUMIFS(Checkliste!$P$13:$P$85,Checkliste!$B$13:$B$85,$B14),"")) | L14: =IF($B14="","",IF(K14="","nicht bewertet",IF(K14>=Ampel_gruen,"gut",IF(K14>=Ampel_gelb,"mittel","kritisch"))))
B15: =IF(Einstellungen!$B$12="","",Einstellungen!$B$12) | E15: =IF($B15="","",COUNTIFS(Checkliste!$B$13:$B$85,$B15,Checkliste!$C$13:$C$85,"?*")) | F15: =IF($B15="","",COUNTIFS(Checkliste!$B$13:$B$85,$B15,Checkliste!$G$13:$G$85,"N.I.O")) | G15: =IF($B15="","",COUNTIFS(Checkliste!$B$13:$B$85,$B15,Checkliste!$G$13:$G$85,"bed. OK")) | H15: =IF($B15="","",COUNTIFS(Checkliste!$B$13:$B$85,$B15,Checkliste!$G$13:$G$85,"OK")) | I15: =IF($B15="","",COUNTIFS(Checkliste!$B$13:$B$85,$B15,Checkliste!$G$13:$G$85,"n. b.")) | J15: =IF($B15="","",E15-SUM(F15:I15)) | K15: =IF($B15="","",IFERROR(SUMIFS(Checkliste!$O$13:$O$85,Checkliste!$B$13:$B$85,$B15)/SUMIFS(Checkliste!$P$13:$P$85,Checkliste!$B$13:$B$85,$B15),"")) | L15: =IF($B15="","",IF(K15="","nicht bewertet",IF(K15>=Ampel_gruen,"gut",IF(K15>=Ampel_gelb,"mittel","kritisch"))))
B16: =IF(Einstellungen!$B$13="","",Einstellungen!$B$13) | E16: =IF($B16="","",COUNTIFS(Checkliste!$B$13:$B$85,$B16,Checkliste!$C$13:$C$85,"?*")) | F16: =IF($B16="","",COUNTIFS(Checkliste!$B$13:$B$85,$B16,Checkliste!$G$13:$G$85,"N.I.O")) | G16: =IF($B16="","",COUNTIFS(Checkliste!$B$13:$B$85,$B16,Checkliste!$G$13:$G$85,"bed. OK")) | H16: =IF($B16="","",COUNTIFS(Checkliste!$B$13:$B$85,$B16,Checkliste!$G$13:$G$85,"OK")) | I16: =IF($B16="","",COUNTIFS(Checkliste!$B$13:$B$85,$B16,Checkliste!$G$13:$G$85,"n. b.")) | J16: =IF($B16="","",E16-SUM(F16:I16)) | K16: =IF($B16="","",IFERROR(SUMIFS(Checkliste!$O$13:$O$85,Checkliste!$B$13:$B$85,$B16)/SUMIFS(Checkliste!$P$13:$P$85,Checkliste!$B$13:$B$85,$B16),"")) | L16: =IF($B16="","",IF(K16="","nicht bewertet",IF(K16>=Ampel_gruen,"gut",IF(K16>=Ampel_gelb,"mittel","kritisch"))))
B17: =IF(Einstellungen!$B$14="","",Einstellungen!$B$14) | E17: =IF($B17="","",COUNTIFS(Checkliste!$B$13:$B$85,$B17,Checkliste!$C$13:$C$85,"?*")) | F17: =IF($B17="","",COUNTIFS(Checkliste!$B$13:$B$85,$B17,Checkliste!$G$13:$G$85,"N.I.O")) | G17: =IF($B17="","",COUNTIFS(Checkliste!$B$13:$B$85,$B17,Checkliste!$G$13:$G$85,"bed. OK")) | H17: =IF($B17="","",COUNTIFS(Checkliste!$B$13:$B$85,$B17,Checkliste!$G$13:$G$85,"OK")) | I17: =IF($B17="","",COUNTIFS(Checkliste!$B$13:$B$85,$B17,Checkliste!$G$13:$G$85,"n. b.")) | J17: =IF($B17="","",E17-SUM(F17:I17)) | K17: =IF($B17="","",IFERROR(SUMIFS(Checkliste!$O$13:$O$85,Checkliste!$B$13:$B$85,$B17)/SUMIFS(Checkliste!$P$13:$P$85,Checkliste!$B$13:$B$85,$B17),"")) | L17: =IF($B17="","",IF(K17="","nicht bewertet",IF(K17>=Ampel_gruen,"gut",IF(K17>=Ampel_gelb,"mittel","kritisch"))))
B18: =IF(Einstellungen!$B$15="","",Einstellungen!$B$15) | E18: =IF($B18="","",COUNTIFS(Checkliste!$B$13:$B$85,$B18,Checkliste!$C$13:$C$85,"?*")) | F18: =IF($B18="","",COUNTIFS(Checkliste!$B$13:$B$85,$B18,Checkliste!$G$13:$G$85,"N.I.O")) | G18: =IF($B18="","",COUNTIFS(Checkliste!$B$13:$B$85,$B18,Checkliste!$G$13:$G$85,"bed. OK")) | H18: =IF($B18="","",COUNTIFS(Checkliste!$B$13:$B$85,$B18,Checkliste!$G$13:$G$85,"OK")) | I18: =IF($B18="","",COUNTIFS(Checkliste!$B$13:$B$85,$B18,Checkliste!$G$13:$G$85,"n. b.")) | J18: =IF($B18="","",E18-SUM(F18:I18)) | K18: =IF($B18="","",IFERROR(SUMIFS(Checkliste!$O$13:$O$85,Checkliste!$B$13:$B$85,$B18)/SUMIFS(Checkliste!$P$13:$P$85,Checkliste!$B$13:$B$85,$B18),"")) | L18: =IF($B18="","",IF(K18="","nicht bewertet",IF(K18>=Ampel_gruen,"gut",IF(K18>=Ampel_gelb,"mittel","kritisch"))))
B19: =IF(Einstellungen!$B$16="","",Einstellungen!$B$16) | E19: =IF($B19="","",COUNTIFS(Checkliste!$B$13:$B$85,$B19,Checkliste!$C$13:$C$85,"?*")) | F19: =IF($B19="","",COUNTIFS(Checkliste!$B$13:$B$85,$B19,Checkliste!$G$13:$G$85,"N.I.O")) | G19: =IF($B19="","",COUNTIFS(Checkliste!$B$13:$B$85,$B19,Checkliste!$G$13:$G$85,"bed. OK")) | H19: =IF($B19="","",COUNTIFS(Checkliste!$B$13:$B$85,$B19,Checkliste!$G$13:$G$85,"OK")) | I19: =IF($B19="","",COUNTIFS(Checkliste!$B$13:$B$85,$B19,Checkliste!$G$13:$G$85,"n. b.")) | J19: =IF($B19="","",E19-SUM(F19:I19)) | K19: =IF($B19="","",IFERROR(SUMIFS(Checkliste!$O$13:$O$85,Checkliste!$B$13:$B$85,$B19)/SUMIFS(Checkliste!$P$13:$P$85,Checkliste!$B$13:$B$85,$B19),"")) | L19: =IF($B19="","",IF(K19="","nicht bewertet",IF(K19>=Ampel_gruen,"gut",IF(K19>=Ampel_gelb,"mittel","kritisch"))))
B20: =IF(Einstellungen!$B$17="","",Einstellungen!$B$17) | E20: =IF($B20="","",COUNTIFS(Checkliste!$B$13:$B$85,$B20,Checkliste!$C$13:$C$85,"?*")) | F20: =IF($B20="","",COUNTIFS(Checkliste!$B$13:$B$85,$B20,Checkliste!$G$13:$G$85,"N.I.O")) | G20: =IF($B20="","",COUNTIFS(Checkliste!$B$13:$B$85,$B20,Checkliste!$G$13:$G$85,"bed. OK")) | H20: =IF($B20="","",COUNTIFS(Checkliste!$B$13:$B$85,$B20,Checkliste!$G$13:$G$85,"OK")) | I20: =IF($B20="","",COUNTIFS(Checkliste!$B$13:$B$85,$B20,Checkliste!$G$13:$G$85,"n. b.")) | J20: =IF($B20="","",E20-SUM(F20:I20)) | K20: =IF($B20="","",IFERROR(SUMIFS(Checkliste!$O$13:$O$85,Checkliste!$B$13:$B$85,$B20)/SUMIFS(Checkliste!$P$13:$P$85,Checkliste!$B$13:$B$85,$B20),"")) | L20: =IF($B20="","",IF(K20="","nicht bewertet",IF(K20>=Ampel_gruen,"gut",IF(K20>=Ampel_gelb,"mittel","kritisch"))))
B21: =IF(Einstellungen!$B$18="","",Einstellungen!$B$18) | E21: =IF($B21="","",COUNTIFS(Checkliste!$B$13:$B$85,$B21,Checkliste!$C$13:$C$85,"?*")) | F21: =IF($B21="","",COUNTIFS(Checkliste!$B$13:$B$85,$B21,Checkliste!$G$13:$G$85,"N.I.O")) | G21: =IF($B21="","",COUNTIFS(Checkliste!$B$13:$B$85,$B21,Checkliste!$G$13:$G$85,"bed. OK")) | H21: =IF($B21="","",COUNTIFS(Checkliste!$B$13:$B$85,$B21,Checkliste!$G$13:$G$85,"OK")) | I21: =IF($B21="","",COUNTIFS(Checkliste!$B$13:$B$85,$B21,Checkliste!$G$13:$G$85,"n. b.")) | J21: =IF($B21="","",E21-SUM(F21:I21)) | K21: =IF($B21="","",IFERROR(SUMIFS(Checkliste!$O$13:$O$85,Checkliste!$B$13:$B$85,$B21)/SUMIFS(Checkliste!$P$13:$P$85,Checkliste!$B$13:$B$85,$B21),"")) | L21: =IF($B21="","",IF(K21="","nicht bewertet",IF(K21>=Ampel_gruen,"gut",IF(K21>=Ampel_gelb,"mittel","kritisch"))))
B22: =IF(Einstellungen!$B$19="","",Einstellungen!$B$19) | E22: =IF($B22="","",COUNTIFS(Checkliste!$B$13:$B$85,$B22,Checkliste!$C$13:$C$85,"?*")) | F22: =IF($B22="","",COUNTIFS(Checkliste!$B$13:$B$85,$B22,Checkliste!$G$13:$G$85,"N.I.O")) | G22: =IF($B22="","",COUNTIFS(Checkliste!$B$13:$B$85,$B22,Checkliste!$G$13:$G$85,"bed. OK")) | H22: =IF($B22="","",COUNTIFS(Checkliste!$B$13:$B$85,$B22,Checkliste!$G$13:$G$85,"OK")) | I22: =IF($B22="","",COUNTIFS(Checkliste!$B$13:$B$85,$B22,Checkliste!$G$13:$G$85,"n. b.")) | J22: =IF($B22="","",E22-SUM(F22:I22)) | K22: =IF($B22="","",IFERROR(SUMIFS(Checkliste!$O$13:$O$85,Checkliste!$B$13:$B$85,$B22)/SUMIFS(Checkliste!$P$13:$P$85,Checkliste!$B$13:$B$85,$B22),"")) | L22: =IF($B22="","",IF(K22="","nicht bewertet",IF(K22>=Ampel_gruen,"gut",IF(K22>=Ampel_gelb,"mittel","kritisch"))))
B23: Gesamt | E23: =SUM(E14:E22) | F23: =SUM(F14:F22) | G23: =SUM(G14:G22) | H23: =SUM(H14:H22) | I23: =SUM(I14:I22) | J23: =SUM(J14:J22) | K23: =B8 | L23: =D8
B25: Diagramme
B45: Kritische Befunde (N.I.O) – vorrangig bearbeiten
B46: Nr. | C46: Check-Punkt | H46: Befund / Maßnahme | K46: Verantwortlich | L46: Termin | M46: Status
B47: =IFERROR(INDEX(Checkliste!$A$13:$A$85,MATCH(1,Checkliste!$N$13:$N$85,0)),"") | C47: =IFERROR(INDEX(Checkliste!$C$13:$C$85,MATCH(1,Checkliste!$N$13:$N$85,0)),"") | H47: =IFERROR(INDEX(Checkliste!$H$13:$H$85,MATCH(1,Checkliste!$N$13:$N$85,0))&"","") | K47: =IFERROR(INDEX(Checkliste!$I$13:$I$85,MATCH(1,Checkliste!$N$13:$N$85,0))&"","") | L47: =IFERROR(IF(INDEX(Checkliste!$J$13:$J$85,MATCH(1,Checkliste!$N$13:$N$85,0))="","",INDEX(Checkliste!$J$13:$J$85,MATCH(1,Checkliste!$N$13:$N$85,0))),"") | M47: =IFERROR(INDEX(Checkliste!$L$13:$L$85,MATCH(1,Checkliste!$N$13:$N$85,0)),"")
B48: =IFERROR(INDEX(Checkliste!$A$13:$A$85,MATCH(2,Checkliste!$N$13:$N$85,0)),"") | C48: =IFERROR(INDEX(Checkliste!$C$13:$C$85,MATCH(2,Checkliste!$N$13:$N$85,0)),"") | H48: =IFERROR(INDEX(Checkliste!$H$13:$H$85,MATCH(2,Checkliste!$N$13:$N$85,0))&"","") | K48: =IFERROR(INDEX(Checkliste!$I$13:$I$85,MATCH(2,Checkliste!$N$13:$N$85,0))&"","") | L48: =IFERROR(IF(INDEX(Checkliste!$J$13:$J$85,MATCH(2,Checkliste!$N$13:$N$85,0))="","",INDEX(Checkliste!$J$13:$J$85,MATCH(2,Checkliste!$N$13:$N$85,0))),"") | M48: =IFERROR(INDEX(Checkliste!$L$13:$L$85,MATCH(2,Checkliste!$N$13:$N$85,0)),"")
B49: =IFERROR(INDEX(Checkliste!$A$13:$A$85,MATCH(3,Checkliste!$N$13:$N$85,0)),"") | C49: =IFERROR(INDEX(Checkliste!$C$13:$C$85,MATCH(3,Checkliste!$N$13:$N$85,0)),"") | H49: =IFERROR(INDEX(Checkliste!$H$13:$H$85,MATCH(3,Checkliste!$N$13:$N$85,0))&"","") | K49: =IFERROR(INDEX(Checkliste!$I$13:$I$85,MATCH(3,Checkliste!$N$13:$N$85,0))&"","") | L49: =IFERROR(IF(INDEX(Checkliste!$J$13:$J$85,MATCH(3,Checkliste!$N$13:$N$85,0))="","",INDEX(Checkliste!$J$13:$J$85,MATCH(3,Checkliste!$N$13:$N$85,0))),"") | M49: =IFERROR(INDEX(Checkliste!$L$13:$L$85,MATCH(3,Checkliste!$N$13:$N$85,0)),"")
B50: =IFERROR(INDEX(Checkliste!$A$13:$A$85,MATCH(4,Checkliste!$N$13:$N$85,0)),"") | C50: =IFERROR(INDEX(Checkliste!$C$13:$C$85,MATCH(4,Checkliste!$N$13:$N$85,0)),"") | H50: =IFERROR(INDEX(Checkliste!$H$13:$H$85,MATCH(4,Checkliste!$N$13:$N$85,0))&"","") | K50: =IFERROR(INDEX(Checkliste!$I$13:$I$85,MATCH(4,Checkliste!$N$13:$N$85,0))&"","") | L50: =IFERROR(IF(INDEX(Checkliste!$J$13:$J$85,MATCH(4,Checkliste!$N$13:$N$85,0))="","",INDEX(Checkliste!$J$13:$J$85,MATCH(4,Checkliste!$N$13:$N$85,0))),"") | M50: =IFERROR(INDEX(Checkliste!$L$13:$L$85,MATCH(4,Checkliste!$N$13:$N$85,0)),"")
B51: =IFERROR(INDEX(Checkliste!$A$13:$A$85,MATCH(5,Checkliste!$N$13:$N$85,0)),"") | C51: =IFERROR(INDEX(Checkliste!$C$13:$C$85,MATCH(5,Checkliste!$N$13:$N$85,0)),"") | H51: =IFERROR(INDEX(Checkliste!$H$13:$H$85,MATCH(5,Checkliste!$N$13:$N$85,0))&"","") | K51: =IFERROR(INDEX(Checkliste!$I$13:$I$85,MATCH(5,Checkliste!$N$13:$N$85,0))&"","") | L51: =IFERROR(IF(INDEX(Checkliste!$J$13:$J$85,MATCH(5,Checkliste!$N$13:$N$85,0))="","",INDEX(Checkliste!$J$13:$J$85,MATCH(5,Checkliste!$N$13:$N$85,0))),"") | M51: =IFERROR(INDEX(Checkliste!$L$13:$L$85,MATCH(5,Checkliste!$N$13:$N$85,0)),"")
B52: =IFERROR(INDEX(Checkliste!$A$13:$A$85,MATCH(6,Checkliste!$N$13:$N$85,0)),"") | C52: =IFERROR(INDEX(Checkliste!$C$13:$C$85,MATCH(6,Checkliste!$N$13:$N$85,0)),"") | H52: =IFERROR(INDEX(Checkliste!$H$13:$H$85,MATCH(6,Checkliste!$N$13:$N$85,0))&"","") | K52: =IFERROR(INDEX(Checkliste!$I$13:$I$85,MATCH(6,Checkliste!$N$13:$N$85,0))&"","") | L52: =IFERROR(IF(INDEX(Checkliste!$J$13:$J$85,MATCH(6,Checkliste!$N$13:$N$85,0))="","",INDEX(Checkliste!$J$13:$J$85,MATCH(6,Checkliste!$N$13:$N$85,0))),"") | M52: =IFERROR(INDEX(Checkliste!$L$13:$L$85,MATCH(6,Checkliste!$N$13:$N$85,0)),"")
B53: =IFERROR(INDEX(Checkliste!$A$13:$A$85,MATCH(7,Checkliste!$N$13:$N$85,0)),"") | C53: =IFERROR(INDEX(Checkliste!$C$13:$C$85,MATCH(7,Checkliste!$N$13:$N$85,0)),"") | H53: =IFERROR(INDEX(Checkliste!$H$13:$H$85,MATCH(7,Checkliste!$N$13:$N$85,0))&"","") | K53: =IFERROR(INDEX(Checkliste!$I$13:$I$85,MATCH(7,Checkliste!$N$13:$N$85,0))&"","") | L53: =IFERROR(IF(INDEX(Checkliste!$J$13:$J$85,MATCH(7,Checkliste!$N$13:$N$85,0))="","",INDEX(Checkliste!$J$13:$J$85,MATCH(7,Checkliste!$N$13:$N$85,0))),"") | M53: =IFERROR(INDEX(Checkliste!$L$13:$L$85,MATCH(7,Checkliste!$N$13:$N$85,0)),"")
B54: =IFERROR(INDEX(Checkliste!$A$13:$A$85,MATCH(8,Checkliste!$N$13:$N$85,0)),"") | C54: =IFERROR(INDEX(Checkliste!$C$13:$C$85,MATCH(8,Checkliste!$N$13:$N$85,0)),"") | H54: =IFERROR(INDEX(Checkliste!$H$13:$H$85,MATCH(8,Checkliste!$N$13:$N$85,0))&"","") | K54: =IFERROR(INDEX(Checkliste!$I$13:$I$85,MATCH(8,Checkliste!$N$13:$N$85,0))&"","") | L54: =IFERROR(IF(INDEX(Checkliste!$J$13:$J$85,MATCH(8,Checkliste!$N$13:$N$85,0))="","",INDEX(Checkliste!$J$13:$J$85,MATCH(8,Checkliste!$N$13:$N$85,0))),"") | M54: =IFERROR(INDEX(Checkliste!$L$13:$L$85,MATCH(8,Checkliste!$N$13:$N$85,0)),"")
B55: =IFERROR(INDEX(Checkliste!$A$13:$A$85,MATCH(9,Checkliste!$N$13:$N$85,0)),"") | C55: =IFERROR(INDEX(Checkliste!$C$13:$C$85,MATCH(9,Checkliste!$N$13:$N$85,0)),"") | H55: =IFERROR(INDEX(Checkliste!$H$13:$H$85,MATCH(9,Checkliste!$N$13:$N$85,0))&"","") | K55: =IFERROR(INDEX(Checkliste!$I$13:$I$85,MATCH(9,Checkliste!$N$13:$N$85,0))&"","") | L55: =IFERROR(IF(INDEX(Checkliste!$J$13:$J$85,MATCH(9,Checkliste!$N$13:$N$85,0))="","",INDEX(Checkliste!$J$13:$J$85,MATCH(9,Checkliste!$N$13:$N$85,0))),"") | M55: =IFERROR(INDEX(Checkliste!$L$13:$L$85,MATCH(9,Checkliste!$N$13:$N$85,0)),"")
B56: =IFERROR(INDEX(Checkliste!$A$13:$A$85,MATCH(10,Checkliste!$N$13:$N$85,0)),"") | C56: =IFERROR(INDEX(Checkliste!$C$13:$C$85,MATCH(10,Checkliste!$N$13:$N$85,0)),"") | H56: =IFERROR(INDEX(Checkliste!$H$13:$H$85,MATCH(10,Checkliste!$N$13:$N$85,0))&"","") | K56: =IFERROR(INDEX(Checkliste!$I$13:$I$85,MATCH(10,Checkliste!$N$13:$N$85,0))&"","") | L56: =IFERROR(IF(INDEX(Checkliste!$J$13:$J$85,MATCH(10,Checkliste!$N$13:$N$85,0))="","",INDEX(Checkliste!$J$13:$J$85,MATCH(10,Checkliste!$N$13:$N$85,0))),"") | M56: =IFERROR(INDEX(Checkliste!$L$13:$L$85,MATCH(10,Checkliste!$N$13:$N$85,0)),"")
B57: =IFERROR(INDEX(Checkliste!$A$13:$A$85,MATCH(11,Checkliste!$N$13:$N$85,0)),"") | C57: =IFERROR(INDEX(Checkliste!$C$13:$C$85,MATCH(11,Checkliste!$N$13:$N$85,0)),"") | H57: =IFERROR(INDEX(Checkliste!$H$13:$H$85,MATCH(11,Checkliste!$N$13:$N$85,0))&"","") | K57: =IFERROR(INDEX(Checkliste!$I$13:$I$85,MATCH(11,Checkliste!$N$13:$N$85,0))&"","") | L57: =IFERROR(IF(INDEX(Checkliste!$J$13:$J$85,MATCH(11,Checkliste!$N$13:$N$85,0))="","",INDEX(Checkliste!$J$13:$J$85,MATCH(11,Checkliste!$N$13:$N$85,0))),"") | M57: =IFERROR(INDEX(Checkliste!$L$13:$L$85,MATCH(11,Checkliste!$N$13:$N$85,0)),"")
B58: =IFERROR(INDEX(Checkliste!$A$13:$A$85,MATCH(12,Checkliste!$N$13:$N$85,0)),"") | C58: =IFERROR(INDEX(Checkliste!$C$13:$C$85,MATCH(12,Checkliste!$N$13:$N$85,0)),"") | H58: =IFERROR(INDEX(Checkliste!$H$13:$H$85,MATCH(12,Checkliste!$N$13:$N$85,0))&"","") | K58: =IFERROR(INDEX(Checkliste!$I$13:$I$85,MATCH(12,Checkliste!$N$13:$N$85,0))&"","") | L58: =IFERROR(IF(INDEX(Checkliste!$J$13:$J$85,MATCH(12,Checkliste!$N$13:$N$85,0))="","",INDEX(Checkliste!$J$13:$J$85,MATCH(12,Checkliste!$N$13:$N$85,0))),"") | M58: =IFERROR(INDEX(Checkliste!$L$13:$L$85,MATCH(12,Checkliste!$N$13:$N$85,0)),"")
B59: =IFERROR(INDEX(Checkliste!$A$13:$A$85,MATCH(13,Checkliste!$N$13:$N$85,0)),"") | C59: =IFERROR(INDEX(Checkliste!$C$13:$C$85,MATCH(13,Checkliste!$N$13:$N$85,0)),"") | H59: =IFERROR(INDEX(Checkliste!$H$13:$H$85,MATCH(13,Checkliste!$N$13:$N$85,0))&"","") | K59: =IFERROR(INDEX(Checkliste!$I$13:$I$85,MATCH(13,Checkliste!$N$13:$N$85,0))&"","") | L59: =IFERROR(IF(INDEX(Checkliste!$J$13:$J$85,MATCH(13,Checkliste!$N$13:$N$85,0))="","",INDEX(Checkliste!$J$13:$J$85,MATCH(13,Checkliste!$N$13:$N$85,0))),"") | M59: =IFERROR(INDEX(Checkliste!$L$13:$L$85,MATCH(13,Checkliste!$N$13:$N$85,0)),"")
B60: =IFERROR(INDEX(Checkliste!$A$13:$A$85,MATCH(14,Checkliste!$N$13:$N$85,0)),"") | C60: =IFERROR(INDEX(Checkliste!$C$13:$C$85,MATCH(14,Checkliste!$N$13:$N$85,0)),"") | H60: =IFERROR(INDEX(Checkliste!$H$13:$H$85,MATCH(14,Checkliste!$N$13:$N$85,0))&"","") | K60: =IFERROR(INDEX(Checkliste!$I$13:$I$85,MATCH(14,Checkliste!$N$13:$N$85,0))&"","") | L60: =IFERROR(IF(INDEX(Checkliste!$J$13:$J$85,MATCH(14,Checkliste!$N$13:$N$85,0))="","",INDEX(Checkliste!$J$13:$J$85,MATCH(14,Checkliste!$N$13:$N$85,0))),"") | M60: =IFERROR(INDEX(Checkliste!$L$13:$L$85,MATCH(14,Checkliste!$N$13:$N$85,0)),"")
B61: =IFERROR(INDEX(Checkliste!$A$13:$A$85,MATCH(15,Checkliste!$N$13:$N$85,0)),"") | C61: =IFERROR(INDEX(Checkliste!$C$13:$C$85,MATCH(15,Checkliste!$N$13:$N$85,0)),"") | H61: =IFERROR(INDEX(Checkliste!$H$13:$H$85,MATCH(15,Checkliste!$N$13:$N$85,0))&"","") | K61: =IFERROR(INDEX(Checkliste!$I$13:$I$85,MATCH(15,Checkliste!$N$13:$N$85,0))&"","") | L61: =IFERROR(IF(INDEX(Checkliste!$J$13:$J$85,MATCH(15,Checkliste!$N$13:$N$85,0))="","",INDEX(Checkliste!$J$13:$J$85,MATCH(15,Checkliste!$N$13:$N$85,0))),"") | M61: =IFERROR(INDEX(Checkliste!$L$13:$L$85,MATCH(15,Checkliste!$N$13:$N$85,0)),"")
B62: =IF(COUNTIF(Checkliste!$G$13:$G$85,"N.I.O")=0,"Keine N.I.O-Befunde.",IF(COUNTIF(Checkliste!$G$13:$G$85,"N.I.O")>15,"+ "&(COUNTIF(Checkliste!$G$13:$G$85,"N.I.O")-15)&" weitere N.I.O-Befunde – siehe Blatt „Maßnahmenplan“.","Alle Maßnahmen (auch bed. OK) im Blatt „Maßnahmenplan“."))
B64: Fazit des Auditors
B73: Datum, Unterschrift Auditor | H73: Datum, Unterschrift Bereichsleitung

Sheet Checkliste
A1: Audit Instandhaltung allgemein – Checkliste
A2: Gelbe Felder ausfüllen. Bewertung je Prüfpunkt aus der Liste wählen; bei N.I.O / bed. OK Befund bzw. Maßnahme, Verantwortlich und Termin eintragen. Blau hinterlegte Nummern = neue Prüfpunkte (NEU).
A3: Kopfdaten | G3: Ergebnis (live)
A4: Firma / Werk | G4: =Dashboard!B8
A5: Bereich / Abteilung
A6: Auditdatum
A7: Auditor | G7: =Dashboard!D8
A8: Teilnehmer / Auditteam | G8: =Dashboard!H10
A9: Auditart
A10: Ergebnis letztes Audit | D10: Erfüllungsgrad des Vorgänger-Audits (für die Veränderung im Dashboard), leer lassen beim Erstaudit.
N11: Hilfswerte (nicht ändern)
A12: Nr. | B12: Kapitel | C12: Check-Punkt | D12: Prüfhinweis / Nachweise | E12: Quelle | F12: Gewich- tung | G12: Bewertung | H12: Befund / Maßnahme | I12: Verantwortlich | J12: Termin | K12: Erledigt | L12: Status | M12: Maßn.-Nr. | N12: N.I.O-Rang | O12: Punkte erreicht | P12: Punkte möglich | Q12: Check-Punkt (EN)
A13: =IF(C13="","",COUNTIF($C$13:C13,"?*")) | B13: Organisation & Personal | C13: Existiert eine Verfahrensanweisung für das Instandhaltungssystem (aktuell / wird sie gelebt)? | D13: VA vorlegen lassen: Freigabe, Revisionsstand, letzte Überprüfung. Stichprobe, ob das Vorgehen in der Praxis eingehalten wird. | E13: Vorlage 1 | F13: 1 | L13: =IF(OR(G13="N.I.O",G13="bed. OK"),IF(K13="ja","erledigt",IF(AND(J13<>"",J13<TODAY()),"überfällig","offen")),"") | M13: =IF(OR(G13="N.I.O",G13="bed. OK"),COUNTIF($G$13:G13,"N.I.O")+COUNTIF($G$13:G13,"bed. OK"),"") | N13: =IF(G13="N.I.O",COUNTIF($G$13:G13,"N.I.O"),"") | O13: =IF(G13="OK",IF(F13="",1,F13),IF(G13="bed. OK",IF(F13="",1,F13)*Gewicht_bedOK,IF(G13="N.I.O",0,""))) | P13: =IF(OR(G13="OK",G13="bed. OK",G13="N.I.O"),IF(F13="",1,F13),"") | Q13: Is there a procedure for the maintenance system? (Is it currently being followed/implemented?)
A14: =IF(C14="","",COUNTIF($C$13:C14,"?*")) | B14: Organisation & Personal | C14: Existiert eine Arbeitsanweisung für die vorbeugende Instandhaltung (aktuell / wird sie gelebt)? | D14: AA einsehen; an 1–2 Anlagen nachfragen, ob die Mitarbeiter sie kennen und anwenden. | E14: Vorlage 2 | F14: 1 | L14: =IF(OR(G14="N.I.O",G14="bed. OK"),IF(K14="ja","erledigt",IF(AND(J14<>"",J14<TODAY()),"überfällig","offen")),"") | M14: =IF(OR(G14="N.I.O",G14="bed. OK"),COUNTIF($G$13:G14,"N.I.O")+COUNTIF($G$13:G14,"bed. OK"),"") | N14: =IF(G14="N.I.O",COUNTIF($G$13:G14,"N.I.O"),"") | O14: =IF(G14="OK",IF(F14="",1,F14),IF(G14="bed. OK",IF(F14="",1,F14)*Gewicht_bedOK,IF(G14="N.I.O",0,""))) | P14: =IF(OR(G14="OK",G14="bed. OK",G14="N.I.O"),IF(F14="",1,F14),"") | Q14: Is there a work instruction for preventive maintenance? (Is it currently being implemented/is it being followed?)
A15: =IF(C15="","",COUNTIF($C$13:C15,"?*")) | B15: Organisation & Personal | C15: Existiert eine Qualifikationsmatrix / Vertretungsregelung / Struktur der IH? | D15: Organigramm, Qualifikationsmatrix (Stand?), Vertretung für Schlüsselfunktionen geregelt. | E15: Vorlage 3 | F15: 1 | L15: =IF(OR(G15="N.I.O",G15="bed. OK"),IF(K15="ja","erledigt",IF(AND(J15<>"",J15<TODAY()),"überfällig","offen")),"") | M15: =IF(OR(G15="N.I.O",G15="bed. OK"),COUNTIF($G$13:G15,"N.I.O")+COUNTIF($G$13:G15,"bed. OK"),"") | N15: =IF(G15="N.I.O",COUNTIF($G$13:G15,"N.I.O"),"") | O15: =IF(G15="OK",IF(F15="",1,F15),IF(G15="bed. OK",IF(F15="",1,F15)*Gewicht_bedOK,IF(G15="N.I.O",0,""))) | P15: =IF(OR(G15="OK",G15="bed. OK",G15="N.I.O"),IF(F15="",1,F15),"") | Q15: Does a qualification matrix / substitution arrangement / structure of the maintenance department exist?
A16: =IF(C16="","",COUNTIF($C$13:C16,"?*")) | B16: Organisation & Personal | C16: Existiert eine Schichtregelung? Ist die technische Betreuung der Anlage gewährleistet? | D16: Schichtplan, IH-Besetzung je Schicht, Erreichbarkeit in allen Schichten. | E16: Vorlage 4 | F16: 1 | L16: =IF(OR(G16="N.I.O",G16="bed. OK"),IF(K16="ja","erledigt",IF(AND(J16<>"",J16<TODAY()),"überfällig","offen")),"") | M16: =IF(OR(G16="N.I.O",G16="bed. OK"),COUNTIF($G$13:G16,"N.I.O")+COUNTIF($G$13:G16,"bed. OK"),"") | N16: =IF(G16="N.I.O",COUNTIF($G$13:G16,"N.I.O"),"") | O16: =IF(G16="OK",IF(F16="",1,F16),IF(G16="bed. OK",IF(F16="",1,F16)*Gewicht_bedOK,IF(G16="N.I.O",0,""))) | P16: =IF(OR(G16="OK",G16="bed. OK",G16="N.I.O"),IF(F16="",1,F16),"") | Q16: Is there a shift system in place? Is technical support for the plant guaranteed?
A17: =IF(C17="","",COUNTIF($C$13:C17,"?*")) | B17: Organisation & Personal | C17: Führungskräfteanzahl in der IH | D17: Führungsspanne (Mitarbeiter je Führungskraft), Stellvertretung, Organigramm. | E17: Vorlage 5 | F17: 1 | L17: =IF(OR(G17="N.I.O",G17="bed. OK"),IF(K17="ja","erledigt",IF(AND(J17<>"",J17<TODAY()),"überfällig","offen")),"") | M17: =IF(OR(G17="N.I.O",G17="bed. OK"),COUNTIF($G$13:G17,"N.I.O")+COUNTIF($G$13:G17,"bed. OK"),"") | N17: =IF(G17="N.I.O",COUNTIF($G$13:G17,"N.I.O"),"") | O17: =IF(G17="OK",IF(F17="",1,F17),IF(G17="bed. OK",IF(F17="",1,F17)*Gewicht_bedOK,IF(G17="N.I.O",0,""))) | P17: =IF(OR(G17="OK",G17="bed. OK",G17="N.I.O"),IF(F17="",1,F17),"") | Q17: Number of managers in maintenance
A18: =IF(C18="","",COUNTIF($C$13:C18,"?*")) | B18: Organisation & Personal | C18: Existiert eine Kapazitäts- und Terminplanung der MA (T/W/M/J)? | D18: Tages-/Wochen-/Monatsplanung, Auslastung, Urlaubs- und Abwesenheitsplanung. | E18: Vorlage 6 | F18: 1 | L18: =IF(OR(G18="N.I.O",G18="bed. OK"),IF(K18="ja","erledigt",IF(AND(J18<>"",J18<TODAY()),"überfällig","offen")),"") | M18: =IF(OR(G18="N.I.O",G18="bed. OK"),COUNTIF($G$13:G18,"N.I.O")+COUNTIF($G$13:G18,"bed. OK"),"") | N18: =IF(G18="N.I.O",COUNTIF($G$13:G18,"N.I.O"),"") | O18: =IF(G18="OK",IF(F18="",1,F18),IF(G18="bed. OK",IF(F18="",1,F18)*Gewicht_bedOK,IF(G18="N.I.O",0,""))) | P18: =IF(OR(G18="OK",G18="bed. OK",G18="N.I.O"),IF(F18="",1,F18),"") | Q18: Is there capacity and scheduling planning for employees (daily/weekly/monthly/yearly)?
A19: =IF(C19="","",COUNTIF($C$13:C19,"?*")) | B19: Organisation & Personal | C19: Flexibilität und Qualifikation der MA innerhalb der Fertigungsbereiche | D19: Einsatz in mehreren Bereichen möglich? Mehrfachqualifikation laut Matrix. | E19: Vorlage 7 | F19: 1 | L19: =IF(OR(G19="N.I.O",G19="bed. OK"),IF(K19="ja","erledigt",IF(AND(J19<>"",J19<TODAY()),"überfällig","offen")),"") | M19: =IF(OR(G19="N.I.O",G19="bed. OK"),COUNTIF($G$13:G19,"N.I.O")+COUNTIF($G$13:G19,"bed. OK"),"") | N19: =IF(G19="N.I.O",COUNTIF($G$13:G19,"N.I.O"),"") | O19: =IF(G19="OK",IF(F19="",1,F19),IF(G19="bed. OK",IF(F19="",1,F19)*Gewicht_bedOK,IF(G19="N.I.O",0,""))) | P19: =IF(OR(G19="OK",G19="bed. OK",G19="N.I.O"),IF(F19="",1,F19),"") | Q19: Flexibility and qualification of employees within the production areas
A20: =IF(C20="","",COUNTIF($C$13:C20,"?*")) | B20: Organisation & Personal | C20: Gibt es eine Rufbereitschaft und einen Eskalationsweg bei Störungen außerhalb der Regelarbeitszeit? | D20: Rufbereitschaftsplan, Eskalationsstufen, vereinbarte Reaktionszeiten, Erreichbarkeit nachts / am Wochenende. | E20: NEU | F20: 1 | L20: =IF(OR(G20="N.I.O",G20="bed. OK"),IF(K20="ja","erledigt",IF(AND(J20<>"",J20<TODAY()),"überfällig","offen")),"") | M20: =IF(OR(G20="N.I.O",G20="bed. OK"),COUNTIF($G$13:G20,"N.I.O")+COUNTIF($G$13:G20,"bed. OK"),"") | N20: =IF(G20="N.I.O",COUNTIF($G$13:G20,"N.I.O"),"") | O20: =IF(G20="OK",IF(F20="",1,F20),IF(G20="bed. OK",IF(F20="",1,F20)*Gewicht_bedOK,IF(G20="N.I.O",0,""))) | P20: =IF(OR(G20="OK",G20="bed. OK",G20="N.I.O"),IF(F20="",1,F20),"") | Q20: Is there an on-call service and escalation path for breakdowns outside regular hours?
A21: =IF(C21="","",COUNTIF($C$13:C21,"?*")) | B21: Organisation & Personal | C21: Ist das Erfahrungswissen gesichert (Know-how-Träger, Nachfolge, Einarbeitung)? | D21: Altersstruktur, Know-how-Träger benannt, Einarbeitungspläne, dokumentiertes Erfahrungswissen. | E21: NEU | F21: 1 | L21: =IF(OR(G21="N.I.O",G21="bed. OK"),IF(K21="ja","erledigt",IF(AND(J21<>"",J21<TODAY()),"überfällig","offen")),"") | M21: =IF(OR(G21="N.I.O",G21="bed. OK"),COUNTIF($G$13:G21,"N.I.O")+COUNTIF($G$13:G21,"bed. OK"),"") | N21: =IF(G21="N.I.O",COUNTIF($G$13:G21,"N.I.O"),"") | O21: =IF(G21="OK",IF(F21="",1,F21),IF(G21="bed. OK",IF(F21="",1,F21)*Gewicht_bedOK,IF(G21="N.I.O",0,""))) | P21: =IF(OR(G21="OK",G21="bed. OK",G21="N.I.O"),IF(F21="",1,F21),"") | Q21: Is expert knowledge secured (key persons, succession, onboarding)?
A22: =IF(C22="","",COUNTIF($C$13:C22,"?*")) | B22: Organisation & Personal | C22: Sind Elektrofachkräfte und zur Prüfung befähigte Personen schriftlich bestellt? | D22: Bestellung EFK / EuP, befähigte Personen nach BetrSichV § 2, Verantwortliche Elektrofachkraft benannt. | E22: NEU | F22: 1 | L22: =IF(OR(G22="N.I.O",G22="bed. OK"),IF(K22="ja","erledigt",IF(AND(J22<>"",J22<TODAY()),"überfällig","offen")),"") | M22: =IF(OR(G22="N.I.O",G22="bed. OK"),COUNTIF($G$13:G22,"N.I.O")+COUNTIF($G$13:G22,"bed. OK"),"") | N22: =IF(G22="N.I.O",COUNTIF($G$13:G22,"N.I.O"),"") | O22: =IF(G22="OK",IF(F22="",1,F22),IF(G22="bed. OK",IF(F22="",1,F22)*Gewicht_bedOK,IF(G22="N.I.O",0,""))) | P22: =IF(OR(G22="OK",G22="bed. OK",G22="N.I.O"),IF(F22="",1,F22),"") | Q22: Are qualified electricians and competent persons for inspections formally appointed?
A23: =IF(C23="","",COUNTIF($C$13:C23,"?*")) | B23: Strategie & IH-System | C23: Anwendung von Instandhaltungsstrategien (welche Instandhaltungsstrategie?) | D23: Strategie je Anlagenklasse (korrektiv, präventiv, zustandsorientiert, TPM) und Begründung. | E23: Vorlage 8 | F23: 1 | L23: =IF(OR(G23="N.I.O",G23="bed. OK"),IF(K23="ja","erledigt",IF(AND(J23<>"",J23<TODAY()),"überfällig","offen")),"") | M23: =IF(OR(G23="N.I.O",G23="bed. OK"),COUNTIF($G$13:G23,"N.I.O")+COUNTIF($G$13:G23,"bed. OK"),"") | N23: =IF(G23="N.I.O",COUNTIF($G$13:G23,"N.I.O"),"") | O23: =IF(G23="OK",IF(F23="",1,F23),IF(G23="bed. OK",IF(F23="",1,F23)*Gewicht_bedOK,IF(G23="N.I.O",0,""))) | P23: =IF(OR(G23="OK",G23="bed. OK",G23="N.I.O"),IF(F23="",1,F23),"") | Q23: Application of maintenance strategies (which maintenance strategy)
A24: =IF(C24="","",COUNTIF($C$13:C24,"?*")) | B24: Strategie & IH-System | C24: Sind die Anlagen nach Kritikalität (A/B/C) eingestuft und ist die Strategie daraus abgeleitet? | D24: Anlagenliste mit A/B/C-Einstufung und Kriterien; Schlüsselanlagen nach IATF 16949, 8.5.1.5. | E24: NEU | F24: 1 | L24: =IF(OR(G24="N.I.O",G24="bed. OK"),IF(K24="ja","erledigt",IF(AND(J24<>"",J24<TODAY()),"überfällig","offen")),"") | M24: =IF(OR(G24="N.I.O",G24="bed. OK"),COUNTIF($G$13:G24,"N.I.O")+COUNTIF($G$13:G24,"bed. OK"),"") | N24: =IF(G24="N.I.O",COUNTIF($G$13:G24,"N.I.O"),"") | O24: =IF(G24="OK",IF(F24="",1,F24),IF(G24="bed. OK",IF(F24="",1,F24)*Gewicht_bedOK,IF(G24="N.I.O",0,""))) | P24: =IF(OR(G24="OK",G24="bed. OK",G24="N.I.O"),IF(F24="",1,F24),"") | Q24: Are machines classified by criticality (A/B/C) and is the strategy derived from it?
... A44: =IF(C44="","",COUNTIF($C$13:C44,"?*")) | B44: Auswertung & Verbesserung | C44: Schadensanalysen und Durchführung | D44: Ursachenanalysen (5-Why, Ishikawa, 8D) bei wiederkehrenden Störungen; Top-Störer-Liste. | E44: Vorlage 23 | F44: 1 | L44: =IF(OR(G44="N.I.O",G44="bed. OK"),IF(K44="ja","erledigt",IF(AND(J44<>"",J44<TODAY()),"überfällig","offen")),"") | M44: =IF(OR(G44="N.I.O",G44="bed. OK"),COUNTIF($G$13:G44,"N.I.O")+COUNTIF($G$13:G44,"bed. OK"),"") | N44: =IF(G44="N.I.O",COUNTIF($G$13:G44,"N.I.O"),"") | O44: =IF(G44="OK",IF(F44="",1,F44),IF(G44="bed. OK",IF(F44="",1,F44)*Gewicht_bedOK,IF(G44="N.I.O",0,""))) | P44: =IF(OR(G44="OK",G44="bed. OK",G44="N.I.O"),IF(F44="",1,F44),"") | Q44: Damage analysis and implementation
A45: =IF(C45="","",COUNTIF($C$13:C45,"?*")) | B45: Auswertung & Verbesserung | C45: ="Technische Verfügbarkeit der Maschinen als Maß für die IH ≥ "&TEXT(Ziel_Verfuegbarkeit,"0%")&" (Zielwert, siehe Einstellungen)" | D45: Berechnung: MTBF ÷ (MTBF + MTTR). Datenquelle prüfen. Zielwert auf Blatt „Einstellungen“ (Vorlage nannte DE 90 %, EN 80 %). | E45: Vorlage 24 | F45: 1 | L45: =IF(OR(G45="N.I.O",G45="bed. OK"),IF(K45="ja","erledigt",IF(AND(J45<>"",J45<TODAY()),"überfällig","offen")),"") | M45: =IF(OR(G45="N.I.O",G45="bed. OK"),COUNTIF($G$13:G45,"N.I.O")+COUNTIF($G$13:G45,"bed. OK"),"") | N45: =IF(G45="N.I.O",COUNTIF($G$13:G45,"N.I.O"),"") | O45: =IF(G45="OK",IF(F45="",1,F45),IF(G45="bed. OK",IF(F45="",1,F45)*Gewicht_bedOK,IF(G45="N.I.O",0,""))) | P45: =IF(OR(G45="OK",G45="bed. OK",G45="N.I.O"),IF(F45="",1,F45),"") | Q45: Technical availability of machines as a measure of maintenance (target see settings)
A46: =IF(C46="","",COUNTIF($C$13:C46,"?*")) | B46: Auswertung & Verbesserung | C46: Gibt es regelmäßige Besprechungen IH / Produktion mit Störungs- und Maßnahmenverfolgung (Shopfloor)? | D46: Termin und Teilnehmer, Störungs- und Maßnahmenliste mit Verantwortlichen und Terminen. | E46: NEU | F46: 1 | L46: =IF(OR(G46="N.I.O",G46="bed. OK"),IF(K46="ja","erledigt",IF(AND(J46<>"",J46<TODAY()),"überfällig","offen")),"") | M46: =IF(OR(G46="N.I.O",G46="bed. OK"),COUNTIF($G$13:G46,"N.I.O")+COUNTIF($G$13:G46,"bed. OK"),"") | N46: =IF(G46="N.I.O",COUNTIF($G$13:G46,"N.I.O"),"") | O46: =IF(G46="OK",IF(F46="",1,F46),IF(G46="bed. OK",IF(F46="",1,F46)*Gewicht_bedOK,IF(G46="N.I.O",0,""))) | P46: =IF(OR(G46="OK",G46="bed. OK",G46="N.I.O"),IF(F46="",1,F46),"") | Q46: Are there regular maintenance/production meetings tracking breakdowns and actions (shopfloor)?
A47: =IF(C47="","",COUNTIF($C$13:C47,"?*")) | B47: Auswertung & Verbesserung | C47: Wird die IH bei der Beschaffung neuer Anlagen beteiligt (Lastenheft, Abnahme)? | D47: IH-Anforderungen im Lastenheft (Doku, Ersatzteile, Zugänglichkeit), Beteiligung an Abnahme. | E47: NEU | F47: 1 | L47: =IF(OR(G47="N.I.O",G47="bed. OK"),IF(K47="ja","erledigt",IF(AND(J47<>"",J47<TODAY()),"überfällig","offen")),"") | M47: =IF(OR(G47="N.I.O",G47="bed. OK"),COUNTIF($G$13:G47,"N.I.O")+COUNTIF($G$13:G47,"bed. OK"),"") | N47: =IF(G47="N.I.O",COUNTIF($G$13:G47,"N.I.O"),"") | O47: =IF(G47="OK",IF(F47="",1,F47),IF(G47="bed. OK",IF(F47="",1,F47)*Gewicht_bedOK,IF(G47="N.I.O",0,""))) | P47: =IF(OR(G47="OK",G47="bed. OK",G47="N.I.O"),IF(F47="",1,F47),"") | Q47: Is maintenance involved in purchasing new equipment (specification, acceptance)?
A48: =IF(C48="","",COUNTIF($C$13:C48,"?*")) | B48: Dokumentation & Kommunikation | C48: Verwaltung der technischen Dokumentation (Stücklisten, Maschinenbeschreibung, technische Zeichnungen) | D48: Ablage aktuell und zugänglich (digital / Papier): Stücklisten, Schaltpläne, Zeichnungen, Betriebsanleitungen. | E48: Vorlage 25 | F48: 1 | L48: =IF(OR(G48="N.I.O",G48="bed. OK"),IF(K48="ja","erledigt",IF(AND(J48<>"",J48<TODAY()),"überfällig","offen")),"") | M48: =IF(OR(G48="N.I.O",G48="bed. OK"),COUNTIF($G$13:G48,"N.I.O")+COUNTIF($G$13:G48,"bed. OK"),"") | N48: =IF(G48="N.I.O",COUNTIF($G$13:G48,"N.I.O"),"") | O48: =IF(G48="OK",IF(F48="",1,F48),IF(G48="bed. OK",IF(F48="",1,F48)*Gewicht_bedOK,IF(G48="N.I.O",0,""))) | P48: =IF(OR(G48="OK",G48="bed. OK",G48="N.I.O"),IF(F48="",1,F48),"") | Q48: Management of technical documentation (parts lists; machine descriptions; technical drawings)
A49: =IF(C49="","",COUNTIF($C$13:C49,"?*")) | B49: Dokumentation & Kommunikation | C49: Wird je Anlage eine Maschinenhistorie (Lebenslaufakte) geführt? | D49: Störungen, Reparaturen, Änderungen und Prüfungen je Anlage nachvollziehbar. | E49: NEU | F49: 1 | L49: =IF(OR(G49="N.I.O",G49="bed. OK"),IF(K49="ja","erledigt",IF(AND(J49<>"",J49<TODAY()),"überfällig","offen")),"") | M49: =IF(OR(G49="N.I.O",G49="bed. OK"),COUNTIF($G$13:G49,"N.I.O")+COUNTIF($G$13:G49,"bed. OK"),"") | N49: =IF(G49="N.I.O",COUNTIF($G$13:G49,"N.I.O"),"") | O49: =IF(G49="OK",IF(F49="",1,F49),IF(G49="bed. OK",IF(F49="",1,F49)*Gewicht_bedOK,IF(G49="N.I.O",0,""))) | P49: =IF(OR(G49="OK",G49="bed. OK",G49="N.I.O"),IF(F49="",1,F49),"") | Q49: Is a machine history (log book) kept for each machine?
A50: =IF(C50="","",COUNTIF($C$13:C50,"?*")) | B50: Dokumentation & Kommunikation | C50: Werden technische Änderungen an Anlagen dokumentiert (inkl. Steuerungs-/Software-Stände, Datensicherung)? | D50: Änderungsantrag und -freigabe, Unterlagen nachgeführt, aktuelle Sicherung der SPS-/Roboterprogramme. | E50: NEU | F50: 1 | L50: =IF(OR(G50="N.I.O",G50="bed. OK"),IF(K50="ja","erledigt",IF(AND(J50<>"",J50<TODAY()),"überfällig","offen")),"") | M50: =IF(OR(G50="N.I.O",G50="bed. OK"),COUNTIF($G$13:G50,"N.I.O")+COUNTIF($G$13:G50,"bed. OK"),"") | N50: =IF(G50="N.I.O",COUNTIF($G$13:G50,"N.I.O"),"") | O50: =IF(G50="OK",IF(F50="",1,F50),IF(G50="bed. OK",IF(F50="",1,F50)*Gewicht_bedOK,IF(G50="N.I.O",0,""))) | P50: =IF(OR(G50="OK",G50="bed. OK",G50="N.I.O"),IF(F50="",1,F50),"") | Q50: Are technical changes documented (incl. control/software versions, backups)?
A51: =IF(C51="","",COUNTIF($C$13:C51,"?*")) | B51: Dokumentation & Kommunikation | C51: Findet eine Absprache zwischen Instandhaltung und Produktion statt? | D51: Abstimmung von Stillständen und Wartungsfenstern; Protokolle. | E51: Vorlage 26 | F51: 1 | L51: =IF(OR(G51="N.I.O",G51="bed. OK"),IF(K51="ja","erledigt",IF(AND(J51<>"",J51<TODAY()),"überfällig","offen")),"") | M51: =IF(OR(G51="N.I.O",G51="bed. OK"),COUNTIF($G$13:G51,"N.I.O")+COUNTIF($G$13:G51,"bed. OK"),"") | N51: =IF(G51="N.I.O",COUNTIF($G$13:G51,"N.I.O"),"") | O51: =IF(G51="OK",IF(F51="",1,F51),IF(G51="bed. OK",IF(F51="",1,F51)*Gewicht_bedOK,IF(G51="N.I.O",0,""))) | P51: =IF(OR(G51="OK",G51="bed. OK",G51="N.I.O"),IF(F51="",1,F51),"") | Q51: Is there coordination between maintenance and production?
A52: =IF(C52="","",COUNTIF($C$13:C52,"?*")) | B52: Dokumentation & Kommunikation | C52: Wie gelangen Informationen an die Instandhalter / Anlagenführer? | D52: Schichtübergabe, Schichtbuch, Infotafel, digitale Meldungen. | E52: Vorlage 27 | F52: 1 | L52: =IF(OR(G52="N.I.O",G52="bed. OK"),IF(K52="ja","erledigt",IF(AND(J52<>"",J52<TODAY()),"überfällig","offen")),"") | M52: =IF(OR(G52="N.I.O",G52="bed. OK"),COUNTIF($G$13:G52,"N.I.O")+COUNTIF($G$13:G52,"bed. OK"),"") | N52: =IF(G52="N.I.O",COUNTIF($G$13:G52,"N.I.O"),"") | O52: =IF(G52="OK",IF(F52="",1,F52),IF(G52="bed. OK",IF(F52="",1,F52)*Gewicht_bedOK,IF(G52="N.I.O",0,""))) | P52: =IF(OR(G52="OK",G52="bed. OK",G52="N.I.O"),IF(F52="",1,F52),"") | Q52: How does information reach maintenance staff / machine operators?
A53: =IF(C53="","",COUNTIF($C$13:C53,"?*")) | B53: Dokumentation & Kommunikation | C53: Wie ist die Bereitschaft der Instandhalter zu Weiterbildungsmaßnahmen? | D53: Weiterbildungsplan, Teilnahmequote, Mitarbeitergespräche. | E53: Vorlage 28 | F53: 1 | L53: =IF(OR(G53="N.I.O",G53="bed. OK"),IF(K53="ja","erledigt",IF(AND(J53<>"",J53<TODAY()),"überfällig","offen")),"") | M53: =IF(OR(G53="N.I.O",G53="bed. OK"),COUNTIF($G$13:G53,"N.I.O")+COUNTIF($G$13:G53,"bed. OK"),"") | N53: =IF(G53="N.I.O",COUNTIF($G$13:G53,"N.I.O"),"") | O53: =IF(G53="OK",IF(F53="",1,F53),IF(G53="bed. OK",IF(F53="",1,F53)*Gewicht_bedOK,IF(G53="N.I.O",0,""))) | P53: =IF(OR(G53="OK",G53="bed. OK",G53="N.I.O"),IF(F53="",1,F53),"") | Q53: How willing are maintenance staff to take part in further training?
A54: =IF(C54="","",COUNTIF($C$13:C54,"?*")) | B54: Werkstatt & Betriebsmittel | C54: Wie sieht die Werkstattausstattung aus und wie ist deren Qualität? | D54: Begehung: Maschinen, Arbeitsplätze, Hebezeuge, Zustand. | E54: Vorlage 29 | F54: 1 | L54: =IF(OR(G54="N.I.O",G54="bed. OK"),IF(K54="ja","erledigt",IF(AND(J54<>"",J54<TODAY()),"überfällig","offen")),"") | M54: =IF(OR(G54="N.I.O",G54="bed. OK"),COUNTIF($G$13:G54,"N.I.O")+COUNTIF($G$13:G54,"bed. OK"),"") | N54: =IF(G54="N.I.O",COUNTIF($G$13:G54,"N.I.O"),"") | O54: =IF(G54="OK",IF(F54="",1,F54),IF(G54="bed. OK",IF(F54="",1,F54)*Gewicht_bedOK,IF(G54="N.I.O",0,""))) | P54: =IF(OR(G54="OK",G54="bed. OK",G54="N.I.O"),IF(F54="",1,F54),"") | Q54: What does the workshop equipment look like and what is its quality?
A55: =IF(C55="","",COUNTIF($C$13:C55,"?*")) | B55: Werkstatt & Betriebsmittel | C55: Gibt es Betriebsmittel für Instandsetzung, PM und Generalüberholung? | D55: Vorrichtungen, Spezialwerkzeug, Prüfstände vorhanden und einsatzbereit. | E55: Vorlage 30 | F55: 1 | L55: =IF(OR(G55="N.I.O",G55="bed. OK"),IF(K55="ja","erledigt",IF(AND(J55<>"",J55<TODAY()),"überfällig","offen")),"") | M55: =IF(OR(G55="N.I.O",G55="bed. OK"),COUNTIF($G$13:G55,"N.I.O")+COUNTIF($G$13:G55,"bed. OK"),"") | N55: =IF(G55="N.I.O",COUNTIF($G$13:G55,"N.I.O"),"") | O55: =IF(G55="OK",IF(F55="",1,F55),IF(G55="bed. OK",IF(F55="",1,F55)*Gewicht_bedOK,IF(G55="N.I.O",0,""))) | P55: =IF(OR(G55="OK",G55="bed. OK",G55="N.I.O"),IF(F55="",1,F55),"") | Q55: Are there resources available for repair, preventive maintenance (PM), and major overhauls?
A56: =IF(C56="","",COUNTIF($C$13:C56,"?*")) | B56: Werkstatt & Betriebsmittel | C56: Ordnung und Sauberkeit in der IH-Werkstatt (5S)? | D56: Kennzeichnung, feste Plätze (Schattenbretter), Sauberkeit; Ergebnis letztes 5S-Audit. | E56: NEU | F56: 1 | L56: =IF(OR(G56="N.I.O",G56="bed. OK"),IF(K56="ja","erledigt",IF(AND(J56<>"",J56<TODAY()),"überfällig","offen")),"") | M56: =IF(OR(G56="N.I.O",G56="bed. OK"),COUNTIF($G$13:G56,"N.I.O")+COUNTIF($G$13:G56,"bed. OK"),"") | N56: =IF(G56="N.I.O",COUNTIF($G$13:G56,"N.I.O"),"") | O56: =IF(G56="OK",IF(F56="",1,F56),IF(G56="bed. OK",IF(F56="",1,F56)*Gewicht_bedOK,IF(G56="N.I.O",0,""))) | P56: =IF(OR(G56="OK",G56="bed. OK",G56="N.I.O"),IF(F56="",1,F56),"") | Q56: Order and cleanliness in the maintenance workshop (5S)?
A57: =IF(C57="","",COUNTIF($C$13:C57,"?*")) | B57: Werkstatt & Betriebsmittel | C57: Sind die Prüf- und Messmittel der IH erfasst und kalibriert? | D57: Messmittelliste (Multimeter, Drehmomentschlüssel, Messschieber …), Prüfplakette gültig. | E57: NEU | F57: 1 | L57: =IF(OR(G57="N.I.O",G57="bed. OK"),IF(K57="ja","erledigt",IF(AND(J57<>"",J57<TODAY()),"überfällig","offen")),"") | M57: =IF(OR(G57="N.I.O",G57="bed. OK"),COUNTIF($G$13:G57,"N.I.O")+COUNTIF($G$13:G57,"bed. OK"),"") | N57: =IF(G57="N.I.O",COUNTIF($G$13:G57,"N.I.O"),"") | O57: =IF(G57="OK",IF(F57="",1,F57),IF(G57="bed. OK",IF(F57="",1,F57)*Gewicht_bedOK,IF(G57="N.I.O",0,""))) | P57: =IF(OR(G57="OK",G57="bed. OK",G57="N.I.O"),IF(F57="",1,F57),"") | Q57: Are maintenance test and measuring devices registered and calibrated?
... A75: =IF(C75="","",COUNTIF($C$13:C75,"?*")) | B75: Arbeits- & Umweltschutz | C75: Werden Druckluft-Leckagen und Energieverluste regelmäßig gesucht und beseitigt? | D75: Leckage-Ortung (Intervall), gekennzeichnete Leckagen, Behebungsquote. | E75: NEU | F75: 1 | L75: =IF(OR(G75="N.I.O",G75="bed. OK"),IF(K75="ja","erledigt",IF(AND(J75<>"",J75<TODAY()),"überfällig","offen")),"") | M75: =IF(OR(G75="N.I.O",G75="bed. OK"),COUNTIF($G$13:G75,"N.I.O")+COUNTIF($G$13:G75,"bed. OK"),"") | N75: =IF(G75="N.I.O",COUNTIF($G$13:G75,"N.I.O"),"") | O75: =IF(G75="OK",IF(F75="",1,F75),IF(G75="bed. OK",IF(F75="",1,F75)*Gewicht_bedOK,IF(G75="N.I.O",0,""))) | P75: =IF(OR(G75="OK",G75="bed. OK",G75="N.I.O"),IF(F75="",1,F75),"") | Q75: Are compressed-air leaks and energy losses regularly detected and fixed?
A76: =IF(C76="","",COUNTIF($C$13:C76,"?*")) | L76: =IF(OR(G76="N.I.O",G76="bed. OK"),IF(K76="ja","erledigt",IF(AND(J76<>"",J76<TODAY()),"überfällig","offen")),"") | M76: =IF(OR(G76="N.I.O",G76="bed. OK"),COUNTIF($G$13:G76,"N.I.O")+COUNTIF($G$13:G76,"bed. OK"),"") | N76: =IF(G76="N.I.O",COUNTIF($G$13:G76,"N.I.O"),"") | O76: =IF(G76="OK",IF(F76="",1,F76),IF(G76="bed. OK",IF(F76="",1,F76)*Gewicht_bedOK,IF(G76="N.I.O",0,""))) | P76: =IF(OR(G76="OK",G76="bed. OK",G76="N.I.O"),IF(F76="",1,F76),"")
...

Sheet Maßnahmenplan
A1: Maßnahmenplan – Audit Instandhaltung allgemein
A2: Wird automatisch aus der Checkliste erzeugt (alle N.I.O und bed. OK). Änderungen bitte in der Checkliste eintragen.
A4: Maßn.-Nr. | B4: Nr. | C4: Kapitel | D4: Check-Punkt | E4: Bewertung | F4: Befund / Maßnahme | G4: Verantwortlich | H4: Termin | I4: Status | J4: Zeile
A5: =IF($J5="","",1) | B5: =IF($J5="","",INDEX(Checkliste!$A$13:$A$85,$J5)) | C5: =IF($J5="","",INDEX(Checkliste!$B$13:$B$85,$J5)&"") | D5: =IF($J5="","",INDEX(Checkliste!$C$13:$C$85,$J5)&"") | E5: =IF($J5="","",INDEX(Checkliste!$G$13:$G$85,$J5)&"") | F5: =IF($J5="","",INDEX(Checkliste!$H$13:$H$85,$J5)&"") | G5: =IF($J5="","",INDEX(Checkliste!$I$13:$I$85,$J5)&"") | H5: =IF($J5="","",IF(INDEX(Checkliste!$J$13:$J$85,$J5)="","",INDEX(Checkliste!$J$13:$J$85,$J5))) | I5: =IF($J5="","",INDEX(Checkliste!$L$13:$L$85,$J5)&"") | J5: =IFERROR(MATCH(1,Checkliste!$M$13:$M$85,0),"")
A6: =IF($J6="","",2) | B6: =IF($J6="","",INDEX(Checkliste!$A$13:$A$85,$J6)) | C6: =IF($J6="","",INDEX(Checkliste!$B$13:$B$85,$J6)&"") | D6: =IF($J6="","",INDEX(Checkliste!$C$13:$C$85,$J6)&"") | E6: =IF($J6="","",INDEX(Checkliste!$G$13:$G$85,$J6)&"") | F6: =IF($J6="","",INDEX(Checkliste!$H$13:$H$85,$J6)&"") | G6: =IF($J6="","",INDEX(Checkliste!$I$13:$I$85,$J6)&"") | H6: =IF($J6="","",IF(INDEX(Checkliste!$J$13:$J$85,$J6)="","",INDEX(Checkliste!$J$13:$J$85,$J6))) | I6: =IF($J6="","",INDEX(Checkliste!$L$13:$L$85,$J6)&"") | J6: =IFERROR(MATCH(2,Checkliste!$M$13:$M$85,0),"")
A7: =IF($J7="","",3) | B7: =IF($J7="","",INDEX(Checkliste!$A$13:$A$85,$J7)) | C7: =IF($J7="","",INDEX(Checkliste!$B$13:$B$85,$J7)&"") | D7: =IF($J7="","",INDEX(Checkliste!$C$13:$C$85,$J7)&"") | E7: =IF($J7="","",INDEX(Checkliste!$G$13:$G$85,$J7)&"") | F7: =IF($J7="","",INDEX(Checkliste!$H$13:$H$85,$J7)&"") | G7: =IF($J7="","",INDEX(Checkliste!$I$13:$I$85,$J7)&"") | H7: =IF($J7="","",IF(INDEX(Checkliste!$J$13:$J$85,$J7)="","",INDEX(Checkliste!$J$13:$J$85,$J7))) | I7: =IF($J7="","",INDEX(Checkliste!$L$13:$L$85,$J7)&"") | J7: =IFERROR(MATCH(3,Checkliste!$M$13:$M$85,0),"")
A8: =IF($J8="","",4) | B8: =IF($J8="","",INDEX(Checkliste!$A$13:$A$85,$J8)) | C8: =IF($J8="","",INDEX(Checkliste!$B$13:$B$85,$J8)&"") | D8: =IF($J8="","",INDEX(Checkliste!$C$13:$C$85,$J8)&"") | E8: =IF($J8="","",INDEX(Checkliste!$G$13:$G$85,$J8)&"") | F8: =IF($J8="","",INDEX(Checkliste!$H$13:$H$85,$J8)&"") | G8: =IF($J8="","",INDEX(Checkliste!$I$13:$I$85,$J8)&"") | H8: =IF($J8="","",IF(INDEX(Checkliste!$J$13:$J$85,$J8)="","",INDEX(Checkliste!$J$13:$J$85,$J8))) | I8: =IF($J8="","",INDEX(Checkliste!$L$13:$L$85,$J8)&"") | J8: =IFERROR(MATCH(4,Checkliste!$M$13:$M$85,0),"")
A9: =IF($J9="","",5) | B9: =IF($J9="","",INDEX(Checkliste!$A$13:$A$85,$J9)) | C9: =IF($J9="","",INDEX(Checkliste!$B$13:$B$85,$J9)&"") | D9: =IF($J9="","",INDEX(Checkliste!$C$13:$C$85,$J9)&"") | E9: =IF($J9="","",INDEX(Checkliste!$G$13:$G$85,$J9)&"") | F9: =IF($J9="","",INDEX(Checkliste!$H$13:$H$85,$J9)&"") | G9: =IF($J9="","",INDEX(Checkliste!$I$13:$I$85,$J9)&"") | H9: =IF($J9="","",IF(INDEX(Checkliste!$J$13:$J$85,$J9)="","",INDEX(Checkliste!$J$13:$J$85,$J9))) | I9: =IF($J9="","",INDEX(Checkliste!$L$13:$L$85,$J9)&"") | J9: =IFERROR(MATCH(5,Checkliste!$M$13:$M$85,0),"")
A10: =IF($J10="","",6) | B10: =IF($J10="","",INDEX(Checkliste!$A$13:$A$85,$J10)) | C10: =IF($J10="","",INDEX(Checkliste!$B$13:$B$85,$J10)&"") | D10: =IF($J10="","",INDEX(Checkliste!$C$13:$C$85,$J10)&"") | E10: =IF($J10="","",INDEX(Checkliste!$G$13:$G$85,$J10)&"") | F10: =IF($J10="","",INDEX(Checkliste!$H$13:$H$85,$J10)&"") | G10: =IF($J10="","",INDEX(Checkliste!$I$13:$I$85,$J10)&"") | H10: =IF($J10="","",IF(INDEX(Checkliste!$J$13:$J$85,$J10)="","",INDEX(Checkliste!$J$13:$J$85,$J10))) | I10: =IF($J10="","",INDEX(Checkliste!$L$13:$L$85,$J10)&"") | J10: =IFERROR(MATCH(6,Checkliste!$M$13:$M$85,0),"")
A11: =IF($J11="","",7) | B11: =IF($J11="","",INDEX(Checkliste!$A$13:$A$85,$J11)) | C11: =IF($J11="","",INDEX(Checkliste!$B$13:$B$85,$J11)&"") | D11: =IF($J11="","",INDEX(Checkliste!$C$13:$C$85,$J11)&"") | E11: =IF($J11="","",INDEX(Checkliste!$G$13:$G$85,$J11)&"") | F11: =IF($J11="","",INDEX(Checkliste!$H$13:$H$85,$J11)&"") | G11: =IF($J11="","",INDEX(Checkliste!$I$13:$I$85,$J11)&"") | H11: =IF($J11="","",IF(INDEX(Checkliste!$J$13:$J$85,$J11)="","",INDEX(Checkliste!$J$13:$J$85,$J11))) | I11: =IF($J11="","",INDEX(Checkliste!$L$13:$L$85,$J11)&"") | J11: =IFERROR(MATCH(7,Checkliste!$M$13:$M$85,0),"")
A12: =IF($J12="","",8) | B12: =IF($J12="","",INDEX(Checkliste!$A$13:$A$85,$J12)) | C12: =IF($J12="","",INDEX(Checkliste!$B$13:$B$85,$J12)&"") | D12: =IF($J12="","",INDEX(Checkliste!$C$13:$C$85,$J12)&"") | E12: =IF($J12="","",INDEX(Checkliste!$G$13:$G$85,$J12)&"") | F12: =IF($J12="","",INDEX(Checkliste!$H$13:$H$85,$J12)&"") | G12: =IF($J12="","",INDEX(Checkliste!$I$13:$I$85,$J12)&"") | H12: =IF($J12="","",IF(INDEX(Checkliste!$J$13:$J$85,$J12)="","",INDEX(Checkliste!$J$13:$J$85,$J12))) | I12: =IF($J12="","",INDEX(Checkliste!$L$13:$L$85,$J12)&"") | J12: =IFERROR(MATCH(8,Checkliste!$M$13:$M$85,0),"")
A13: =IF($J13="","",9) | B13: =IF($J13="","",INDEX(Checkliste!$A$13:$A$85,$J13)) | C13: =IF($J13="","",INDEX(Checkliste!$B$13:$B$85,$J13)&"") | D13: =IF($J13="","",INDEX(Checkliste!$C$13:$C$85,$J13)&"") | E13: =IF($J13="","",INDEX(Checkliste!$G$13:$G$85,$J13)&"") | F13: =IF($J13="","",INDEX(Checkliste!$H$13:$H$85,$J13)&"") | G13: =IF($J13="","",INDEX(Checkliste!$I$13:$I$85,$J13)&"") | H13: =IF($J13="","",IF(INDEX(Checkliste!$J$13:$J$85,$J13)="","",INDEX(Checkliste!$J$13:$J$85,$J13))) | I13: =IF($J13="","",INDEX(Checkliste!$L$13:$L$85,$J13)&"") | J13: =IFERROR(MATCH(9,Checkliste!$M$13:$M$85,0),"")
A14: =IF($J14="","",10) | B14: =IF($J14="","",INDEX(Checkliste!$A$13:$A$85,$J14)) | C14: =IF($J14="","",INDEX(Checkliste!$B$13:$B$85,$J14)&"") | D14: =IF($J14="","",INDEX(Checkliste!$C$13:$C$85,$J14)&"") | E14: =IF($J14="","",INDEX(Checkliste!$G$13:$G$85,$J14)&"") | F14: =IF($J14="","",INDEX(Checkliste!$H$13:$H$85,$J14)&"") | G14: =IF($J14="","",INDEX(Checkliste!$I$13:$I$85,$J14)&"") | H14: =IF($J14="","",IF(INDEX(Checkliste!$J$13:$J$85,$J14)="","",INDEX(Checkliste!$J$13:$J$85,$J14))) | I14: =IF($J14="","",INDEX(Checkliste!$L$13:$L$85,$J14)&"") | J14: =IFERROR(MATCH(10,Checkliste!$M$13:$M$85,0),"")
A15: =IF($J15="","",11) | B15: =IF($J15="","",INDEX(Checkliste!$A$13:$A$85,$J15)) | C15: =IF($J15="","",INDEX(Checkliste!$B$13:$B$85,$J15)&"") | D15: =IF($J15="","",INDEX(Checkliste!$C$13:$C$85,$J15)&"") | E15: =IF($J15="","",INDEX(Checkliste!$G$13:$G$85,$J15)&"") | F15: =IF($J15="","",INDEX(Checkliste!$H$13:$H$85,$J15)&"") | G15: =IF($J15="","",INDEX(Checkliste!$I$13:$I$85,$J15)&"") | H15: =IF($J15="","",IF(INDEX(Checkliste!$J$13:$J$85,$J15)="","",INDEX(Checkliste!$J$13:$J$85,$J15))) | I15: =IF($J15="","",INDEX(Checkliste!$L$13:$L$85,$J15)&"") | J15: =IFERROR(MATCH(11,Checkliste!$M$13:$M$85,0),"")
A16: =IF($J16="","",12) | B16: =IF($J16="","",INDEX(Checkliste!$A$13:$A$85,$J16)) | C16: =IF($J16="","",INDEX(Checkliste!$B$13:$B$85,$J16)&"") | D16: =IF($J16="","",INDEX(Checkliste!$C$13:$C$85,$J16)&"") | E16: =IF($J16="","",INDEX(Checkliste!$G$13:$G$85,$J16)&"") | F16: =IF($J16="","",INDEX(Checkliste!$H$13:$H$85,$J16)&"") | G16: =IF($J16="","",INDEX(Checkliste!$I$13:$I$85,$J16)&"") | H16: =IF($J16="","",IF(INDEX(Checkliste!$J$13:$J$85,$J16)="","",INDEX(Checkliste!$J$13:$J$85,$J16))) | I16: =IF($J16="","",INDEX(Checkliste!$L$13:$L$85,$J16)&"") | J16: =IFERROR(MATCH(12,Checkliste!$M$13:$M$85,0),"")
A17: =IF($J17="","",13) | B17: =IF($J17="","",INDEX(Checkliste!$A$13:$A$85,$J17)) | C17: =IF($J17="","",INDEX(Checkliste!$B$13:$B$85,$J17)&"") | D17: =IF($J17="","",INDEX(Checkliste!$C$13:$C$85,$J17)&"") | E17: =IF($J17="","",INDEX(Checkliste!$G$13:$G$85,$J17)&"") | F17: =IF($J17="","",INDEX(Checkliste!$H$13:$H$85,$J17)&"") | G17: =IF($J17="","",INDEX(Checkliste!$I$13:$I$85,$J17)&"") | H17: =IF($J17="","",IF(INDEX(Checkliste!$J$13:$J$85,$J17)="","",INDEX(Checkliste!$J$13:$J$85,$J17))) | I17: =IF($J17="","",INDEX(Checkliste!$L$13:$L$85,$J17)&"") | J17: =IFERROR(MATCH(13,Checkliste!$M$13:$M$85,0),"")
A18: =IF($J18="","",14) | B18: =IF($J18="","",INDEX(Checkliste!$A$13:$A$85,$J18)) | C18: =IF($J18="","",INDEX(Checkliste!$B$13:$B$85,$J18)&"") | D18: =IF($J18="","",INDEX(Checkliste!$C$13:$C$85,$J18)&"") | E18: =IF($J18="","",INDEX(Checkliste!$G$13:$G$85,$J18)&"") | F18: =IF($J18="","",INDEX(Checkliste!$H$13:$H$85,$J18)&"") | G18: =IF($J18="","",INDEX(Checkliste!$I$13:$I$85,$J18)&"") | H18: =IF($J18="","",IF(INDEX(Checkliste!$J$13:$J$85,$J18)="","",INDEX(Checkliste!$J$13:$J$85,$J18))) | I18: =IF($J18="","",INDEX(Checkliste!$L$13:$L$85,$J18)&"") | J18: =IFERROR(MATCH(14,Checkliste!$M$13:$M$85,0),"")
A19: =IF($J19="","",15) | B19: =IF($J19="","",INDEX(Checkliste!$A$13:$A$85,$J19)) | C19: =IF($J19="","",INDEX(Checkliste!$B$13:$B$85,$J19)&"") | D19: =IF($J19="","",INDEX(Checkliste!$C$13:$C$85,$J19)&"") | E19: =IF($J19="","",INDEX(Checkliste!$G$13:$G$85,$J19)&"") | F19: =IF($J19="","",INDEX(Checkliste!$H$13:$H$85,$J19)&"") | G19: =IF($J19="","",INDEX(Checkliste!$I$13:$I$85,$J19)&"") | H19: =IF($J19="","",IF(INDEX(Checkliste!$J$13:$J$85,$J19)="","",INDEX(Checkliste!$J$13:$J$85,$J19))) | I19: =IF($J19="","",INDEX(Checkliste!$L$13:$L$85,$J19)&"") | J19: =IFERROR(MATCH(15,Checkliste!$M$13:$M$85,0),"")
A20: =IF($J20="","",16) | B20: =IF($J20="","",INDEX(Checkliste!$A$13:$A$85,$J20)) | C20: =IF($J20="","",INDEX(Checkliste!$B$13:$B$85,$J20)&"") | D20: =IF($J20="","",INDEX(Checkliste!$C$13:$C$85,$J20)&"") | E20: =IF($J20="","",INDEX(Checkliste!$G$13:$G$85,$J20)&"") | F20: =IF($J20="","",INDEX(Checkliste!$H$13:$H$85,$J20)&"") | G20: =IF($J20="","",INDEX(Checkliste!$I$13:$I$85,$J20)&"") | H20: =IF($J20="","",IF(INDEX(Checkliste!$J$13:$J$85,$J20)="","",INDEX(Checkliste!$J$13:$J$85,$J20))) | I20: =IF($J20="","",INDEX(Checkliste!$L$13:$L$85,$J20)&"") | J20: =IFERROR(MATCH(16,Checkliste!$M$13:$M$85,0),"")
A21: =IF($J21="","",17) | B21: =IF($J21="","",INDEX(Checkliste!$A$13:$A$85,$J21)) | C21: =IF($J21="","",INDEX(Checkliste!$B$13:$B$85,$J21)&"") | D21: =IF($J21="","",INDEX(Checkliste!$C$13:$C$85,$J21)&"") | E21: =IF($J21="","",INDEX(Checkliste!$G$13:$G$85,$J21)&"") | F21: =IF($J21="","",INDEX(Checkliste!$H$13:$H$85,$J21)&"") | G21: =IF($J21="","",INDEX(Checkliste!$I$13:$I$85,$J21)&"") | H21: =IF($J21="","",IF(INDEX(Checkliste!$J$13:$J$85,$J21)="","",INDEX(Checkliste!$J$13:$J$85,$J21))) | I21: =IF($J21="","",INDEX(Checkliste!$L$13:$L$85,$J21)&"") | J21: =IFERROR(MATCH(17,Checkliste!$M$13:$M$85,0),"")
A22: =IF($J22="","",18) | B22: =IF($J22="","",INDEX(Checkliste!$A$13:$A$85,$J22)) | C22: =IF($J22="","",INDEX(Checkliste!$B$13:$B$85,$J22)&"") | D22: =IF($J22="","",INDEX(Checkliste!$C$13:$C$85,$J22)&"") | E22: =IF($J22="","",INDEX(Checkliste!$G$13:$G$85,$J22)&"") | F22: =IF($J22="","",INDEX(Checkliste!$H$13:$H$85,$J22)&"") | G22: =IF($J22="","",INDEX(Checkliste!$I$13:$I$85,$J22)&"") | H22: =IF($J22="","",IF(INDEX(Checkliste!$J$13:$J$85,$J22)="","",INDEX(Checkliste!$J$13:$J$85,$J22))) | I22: =IF($J22="","",INDEX(Checkliste!$L$13:$L$85,$J22)&"") | J22: =IFERROR(MATCH(18,Checkliste!$M$13:$M$85,0),"")
A23: =IF($J23="","",19) | B23: =IF($J23="","",INDEX(Checkliste!$A$13:$A$85,$J23)) | C23: =IF($J23="","",INDEX(Checkliste!$B$13:$B$85,$J23)&"") | D23: =IF($J23="","",INDEX(Checkliste!$C$13:$C$85,$J23)&"") | E23: =IF($J23="","",INDEX(Checkliste!$G$13:$G$85,$J23)&"") | F23: =IF($J23="","",INDEX(Checkliste!$H$13:$H$85,$J23)&"") | G23: =IF($J23="","",INDEX(Checkliste!$I$13:$I$85,$J23)&"") | H23: =IF($J23="","",IF(INDEX(Checkliste!$J$13:$J$85,$J23)="","",INDEX(Checkliste!$J$13:$J$85,$J23))) | I23: =IF($J23="","",INDEX(Checkliste!$L$13:$L$85,$J23)&"") | J23: =IFERROR(MATCH(19,Checkliste!$M$13:$M$85,0),"")
A24: =IF($J24="","",20) | B24: =IF($J24="","",INDEX(Checkliste!$A$13:$A$85,$J24)) | C24: =IF($J24="","",INDEX(Checkliste!$B$13:$B$85,$J24)&"") | D24: =IF($J24="","",INDEX(Checkliste!$C$13:$C$85,$J24)&"") | E24: =IF($J24="","",INDEX(Checkliste!$G$13:$G$85,$J24)&"") | F24: =IF($J24="","",INDEX(Checkliste!$H$13:$H$85,$J24)&"") | G24: =IF($J24="","",INDEX(Checkliste!$I$13:$I$85,$J24)&"") | H24: =IF($J24="","",IF(INDEX(Checkliste!$J$13:$J$85,$J24)="","",INDEX(Checkliste!$J$13:$J$85,$J24))) | I24: =IF($J24="","",INDEX(Checkliste!$L$13:$L$85,$J24)&"") | J24: =IFERROR(MATCH(20,Checkliste!$M$13:$M$85,0),"")
A25: =IF($J25="","",21) | B25: =IF($J25="","",INDEX(Checkliste!$A$13:$A$85,$J25)) | C25: =IF($J25="","",INDEX(Checkliste!$B$13:$B$85,$J25)&"") | D25: =IF($J25="","",INDEX(Checkliste!$C$13:$C$85,$J25)&"") | E25: =IF($J25="","",INDEX(Checkliste!$G$13:$G$85,$J25)&"") | F25: =IF($J25="","",INDEX(Checkliste!$H$13:$H$85,$J25)&"") | G25: =IF($J25="","",INDEX(Checkliste!$I$13:$I$85,$J25)&"") | H25: =IF($J25="","",IF(INDEX(Checkliste!$J$13:$J$85,$J25)="","",INDEX(Checkliste!$J$13:$J$85,$J25))) | I25: =IF($J25="","",INDEX(Checkliste!$L$13:$L$85,$J25)&"") | J25: =IFERROR(MATCH(21,Checkliste!$M$13:$M$85,0),"")
A26: =IF($J26="","",22) | B26: =IF($J26="","",INDEX(Checkliste!$A$13:$A$85,$J26)) | C26: =IF($J26="","",INDEX(Checkliste!$B$13:$B$85,$J26)&"") | D26: =IF($J26="","",INDEX(Checkliste!$C$13:$C$85,$J26)&"") | E26: =IF($J26="","",INDEX(Checkliste!$G$13:$G$85,$J26)&"") | F26: =IF($J26="","",INDEX(Checkliste!$H$13:$H$85,$J26)&"") | G26: =IF($J26="","",INDEX(Checkliste!$I$13:$I$85,$J26)&"") | H26: =IF($J26="","",IF(INDEX(Checkliste!$J$13:$J$85,$J26)="","",INDEX(Checkliste!$J$13:$J$85,$J26))) | I26: =IF($J26="","",INDEX(Checkliste!$L$13:$L$85,$J26)&"") | J26: =IFERROR(MATCH(22,Checkliste!$M$13:$M$85,0),"")
A27: =IF($J27="","",23) | B27: =IF($J27="","",INDEX(Checkliste!$A$13:$A$85,$J27)) | C27: =IF($J27="","",INDEX(Checkliste!$B$13:$B$85,$J27)&"") | D27: =IF($J27="","",INDEX(Checkliste!$C$13:$C$85,$J27)&"") | E27: =IF($J27="","",INDEX(Checkliste!$G$13:$G$85,$J27)&"") | F27: =IF($J27="","",INDEX(Checkliste!$H$13:$H$85,$J27)&"") | G27: =IF($J27="","",INDEX(Checkliste!$I$13:$I$85,$J27)&"") | H27: =IF($J27="","",IF(INDEX(Checkliste!$J$13:$J$85,$J27)="","",INDEX(Checkliste!$J$13:$J$85,$J27))) | I27: =IF($J27="","",INDEX(Checkliste!$L$13:$L$85,$J27)&"") | J27: =IFERROR(MATCH(23,Checkliste!$M$13:$M$85,0),"")
A28: =IF($J28="","",24) | B28: =IF($J28="","",INDEX(Checkliste!$A$13:$A$85,$J28)) | C28: =IF($J28="","",INDEX(Checkliste!$B$13:$B$85,$J28)&"") | D28: =IF($J28="","",INDEX(Checkliste!$C$13:$C$85,$J28)&"") | E28: =IF($J28="","",INDEX(Checkliste!$G$13:$G$85,$J28)&"") | F28: =IF($J28="","",INDEX(Checkliste!$H$13:$H$85,$J28)&"") | G28: =IF($J28="","",INDEX(Checkliste!$I$13:$I$85,$J28)&"") | H28: =IF($J28="","",IF(INDEX(Checkliste!$J$13:$J$85,$J28)="","",INDEX(Checkliste!$J$13:$J$85,$J28))) | I28: =IF($J28="","",INDEX(Checkliste!$L$13:$L$85,$J28)&"") | J28: =IFERROR(MATCH(24,Checkliste!$M$13:$M$85,0),"")
A29: =IF($J29="","",25) | B29: =IF($J29="","",INDEX(Checkliste!$A$13:$A$85,$J29)) | C29: =IF($J29="","",INDEX(Checkliste!$B$13:$B$85,$J29)&"") | D29: =IF($J29="","",INDEX(Checkliste!$C$13:$C$85,$J29)&"") | E29: =IF($J29="","",INDEX(Checkliste!$G$13:$G$85,$J29)&"") | F29: =IF($J29="","",INDEX(Checkliste!$H$13:$H$85,$J29)&"") | G29: =IF($J29="","",INDEX(Checkliste!$I$13:$I$85,$J29)&"") | H29: =IF($J29="","",IF(INDEX(Checkliste!$J$13:$J$85,$J29)="","",INDEX(Checkliste!$J$13:$J$85,$J29))) | I29: =IF($J29="","",INDEX(Checkliste!$L$13:$L$85,$J29)&"") | J29: =IFERROR(MATCH(25,Checkliste!$M$13:$M$85,0),"")
A30: =IF($J30="","",26) | B30: =IF($J30="","",INDEX(Checkliste!$A$13:$A$85,$J30)) | C30: =IF($J30="","",INDEX(Checkliste!$B$13:$B$85,$J30)&"") | D30: =IF($J30="","",INDEX(Checkliste!$C$13:$C$85,$J30)&"") | E30: =IF($J30="","",INDEX(Checkliste!$G$13:$G$85,$J30)&"") | F30: =IF($J30="","",INDEX(Checkliste!$H$13:$H$85,$J30)&"") | G30: =IF($J30="","",INDEX(Checkliste!$I$13:$I$85,$J30)&"") | H30: =IF($J30="","",IF(INDEX(Checkliste!$J$13:$J$85,$J30)="","",INDEX(Checkliste!$J$13:$J$85,$J30))) | I30: =IF($J30="","",INDEX(Checkliste!$L$13:$L$85,$J30)&"") | J30: =IFERROR(MATCH(26,Checkliste!$M$13:$M$85,0),"")
A31: =IF($J31="","",27) | B31: =IF($J31="","",INDEX(Checkliste!$A$13:$A$85,$J31)) | C31: =IF($J31="","",INDEX(Checkliste!$B$13:$B$85,$J31)&"") | D31: =IF($J31="","",INDEX(Checkliste!$C$13:$C$85,$J31)&"") | E31: =IF($J31="","",INDEX(Checkliste!$G$13:$G$85,$J31)&"") | F31: =IF($J31="","",INDEX(Checkliste!$H$13:$H$85,$J31)&"") | G31: =IF($J31="","",INDEX(Checkliste!$I$13:$I$85,$J31)&"") | H31: =IF($J31="","",IF(INDEX(Checkliste!$J$13:$J$85,$J31)="","",INDEX(Checkliste!$J$13:$J$85,$J31))) | I31: =IF($J31="","",INDEX(Checkliste!$L$13:$L$85,$J31)&"") | J31: =IFERROR(MATCH(27,Checkliste!$M$13:$M$85,0),"")
A32: =IF($J32="","",28) | B32: =IF($J32="","",INDEX(Checkliste!$A$13:$A$85,$J32)) | C32: =IF($J32="","",INDEX(Checkliste!$B$13:$B$85,$J32)&"") | D32: =IF($J32="","",INDEX(Checkliste!$C$13:$C$85,$J32)&"") | E32: =IF($J32="","",INDEX(Checkliste!$G$13:$G$85,$J32)&"") | F32: =IF($J32="","",INDEX(Checkliste!$H$13:$H$85,$J32)&"") | G32: =IF($J32="","",INDEX(Checkliste!$I$13:$I$85,$J32)&"") | H32: =IF($J32="","",IF(INDEX(Checkliste!$J$13:$J$85,$J32)="","",INDEX(Checkliste!$J$13:$J$85,$J32))) | I32: =IF($J32="","",INDEX(Checkliste!$L$13:$L$85,$J32)&"") | J32: =IFERROR(MATCH(28,Checkliste!$M$13:$M$85,0),"")
