Workbook
Name Gewicht_bedOK: Einstellungen!$C$5
Name Ampel_gruen: Einstellungen!$C$6
Name Ampel_gelb: Einstellungen!$C$7
Name KO_aktiv: Einstellungen!$C$8
Name Ziel_Verfuegbarkeit: Einstellungen!$C$11
Name Grenz_IHKQ: Einstellungen!$C$12
Name Risiko_hoch: Einstellungen!$C$13
Name Risiko_mittel: Einstellungen!$C$14
Name Kapitel_Liste: Einstellungen!$B$18:$B$31
Name L_Geltung: Einstellungen!$A$65:$A$66
Name L_JaNein: Einstellungen!$B$65:$B$66
Name L_Krit: Einstellungen!$C$65:$C$67
Name L_Obs: Einstellungen!$D$65:$D$68
Name L_Support: Einstellungen!$E$65:$E$68
Name L_Ausweich: Einstellungen!$F$65:$F$67
Name L_Option: Einstellungen!$G$65:$G$69
Name Aud_Nr: Audit!$A$9:$A$106
Name Aud_Kapitel: Audit!$B$9:$B$106
Name Aud_Punkt: Audit!$C$9:$C$106
Name Aud_Gew: Audit!$F$9:$F$106
Name Aud_KO: Audit!$G$9:$G$106
Name Aud_Bew: Audit!$H$9:$H$106
Name Aud_Massn: Audit!$J$9:$J$106
Name Aud_Verantw: Audit!$K$9:$K$106
Name Aud_Termin: Audit!$L$9:$L$106
Name Aud_Status: Audit!$N$9:$N$106
Name Aud_MNr: Audit!$O$9:$O$106
Name Aud_NIO: Audit!$Q$9:$Q$106
Name Anl_Eq: 'Anlagenübersicht'!$B$5:$B$34
Name Anl_Name: 'Anlagenübersicht'!$C$5:$C$34
Name Anl_Krit: 'Anlagenübersicht'!$H$5:$H$34
Name Anl_Engpass: 'Anlagenübersicht'!$I$5:$I$34
Name Anl_Verf: 'Anlagenübersicht'!$J$5:$J$34
Name Anl_Obs: 'Anlagenübersicht'!$M$5:$M$34
Name Anl_Support: 'Anlagenübersicht'!$N$5:$N$34
Name Anl_Ausweich: 'Anlagenübersicht'!$O$5:$O$34
Name Anl_Notfall: 'Anlagenübersicht'!$P$5:$P$34
Name Anl_W: 'Anlagenübersicht'!$Q$5:$Q$34
Name Anl_A: 'Anlagenübersicht'!$R$5:$R$34
Name Anl_RZ: 'Anlagenübersicht'!$S$5:$S$34
Name Anl_RK: 'Anlagenübersicht'!$T$5:$T$34
Name Anl_Option: 'Anlagenübersicht'!$U$5:$U$34
Name Anl_Invest: 'Anlagenübersicht'!$V$5:$V$34
Name Anl_Key: 'Anlagenübersicht'!$Z$5:$Z$34
Name ET_Teil: 'Kritische Ersatzteile'!$C$5:$C$44
Name ET_Allein: 'Kritische Ersatzteile'!$F$5:$F$44
Name ET_Status: 'Kritische Ersatzteile'!$M$5:$M$44

Sheet Dashboard
B1: Anlagenzustandsanalyse | R1: Dashboard · Bewertung
B2: Auswertung der Blätter „Audit“, „Anlagenübersicht“ und „Kritische Ersatzteile“. Alle Werte berechnen sich automatisch – Eingaben nur in diesen Blättern.
B3: Werk / Standort | H3: Anlage / Maschinengruppe | N3: Datum | Q3: Auditor | U3: Geltungsbereich
B4: =IF(Audit!$C$3="","–",Audit!$C$3) | H4: =IF(Audit!$C$4="","–",Audit!$C$4) | N4: =IF(Audit!$E$3="","–",Audit!$E$3) | Q4: =IF(Audit!$E$4="","–",Audit!$E$4) | U4: =IF(Audit!$E$5="","–",Audit!$E$5)
B6: Gesamtergebnis
B7: Erfüllungsgrad | E7: Gesamtbewertung | H7: Prüfpunkte bewertet | K7: N.I.O | N7: bed. OK | Q7: K.O.-Verstöße | T7: Maßnahmen offen | W7: Maßnahmen erledigt
B8: =Audit!$P$4 | E8: =Audit!$P$5 | H8: =(COUNTA(Aud_Punkt)-Audit!$N$4)&" / "&COUNTA(Aud_Punkt) | K8: =Audit!$J$4 | N8: =Audit!$K$4 | Q8: =Audit!$O$4 | T8: =COUNTIF(Aud_Status,"offen")+COUNTIF(Aud_Status,"überfällig") | W8: =COUNTIF(Aud_Status,"erledigt")&" / "&COUNT(Aud_MNr)
B9: ="Ziel: ≥ "&TEXT(Ampel_gruen,"0%") | E9: ="grün ab "&TEXT(Ampel_gruen,"0%")&" · gelb ab "&TEXT(Ampel_gelb,"0%") | H9: =IFERROR(TEXT((COUNTA(Aud_Punkt)-Audit!$N$4)/COUNTA(Aud_Punkt),"0%")&" bewertet","") | K9: ="nicht erfüllt" | N9: ="teilweise erfüllt" | Q9: ="K.O.-Punkte mit N.I.O" | T9: ="davon überfällig: "&COUNTIF(Aud_Status,"überfällig") | W9: =IFERROR(TEXT(COUNTIF(Aud_Status,"erledigt")/COUNT(Aud_MNr),"0%")&" umgesetzt","keine Maßnahmen")
B11: Ergebnis je Kapitel | S11: Verteilung der Bewertungen | AA11: Hilfswerte (nicht ändern)
B12: Kapitel | H12: Punkte | I12: N.I.O | J12: bed. OK | K12: OK | L12: n. b. | M12: offen | N12: Erfüllungsgrad | P12: Ampel | AB12: gut | AC12: mittel | AD12: kritisch | AE12: Rang-Schlüssel | AG12: Bewertung | AH12: Anzahl
B13: =Einstellungen!$B$18 | H13: =COUNTIFS(Aud_Kapitel,$B13,Aud_Punkt,"?*") | I13: =COUNTIFS(Aud_Kapitel,$B13,Aud_Bew,"N.I.O") | J13: =COUNTIFS(Aud_Kapitel,$B13,Aud_Bew,"bed. OK") | K13: =COUNTIFS(Aud_Kapitel,$B13,Aud_Bew,"OK") | L13: =COUNTIFS(Aud_Kapitel,$B13,Aud_Bew,"n. b.") | M13: =H13-SUM(I13:L13) | N13: =IFERROR((SUMIFS(Aud_Gew,Aud_Kapitel,$B13,Aud_Bew,"OK")+Gewicht_bedOK*SUMIFS(Aud_Gew,Aud_Kapitel,$B13,Aud_Bew,"bed. OK"))/(SUMIFS(Aud_Gew,Aud_Kapitel,$B13,Aud_Bew,"N.I.O")+SUMIFS(Aud_Gew,Aud_Kapitel,$B13,Aud_Bew,"bed. OK")+SUMIFS(Aud_Gew,Aud_Kapitel,$B13,Aud_Bew,"OK")),"") | P13: =IF($N13="","nicht bewertet",IF(AND(KO_aktiv="ja",COUNTIFS(Aud_Kapitel,$B13,Aud_KO,"K.O.",Aud_Bew,"N.I.O")>0),"kritisch (K.O.)",IF($N13>=Ampel_gruen,"gut",IF($N13>=Ampel_gelb,"mittel","kritisch")))) | AB13: =IF($N13="","",IF($N13>=Ampel_gruen,$N13,"")) | AC13: =IF($N13="","",IF(AND($N13>=Ampel_gelb,$N13<Ampel_gruen),$N13,"")) | AD13: =IF($N13="","",IF($N13<Ampel_gelb,$N13,"")) | AE13: =IF($N13="","",$N13+ROW()/100000) | AG13: N.I.O | AH13: =I27
B14: =Einstellungen!$B$19 | H14: =COUNTIFS(Aud_Kapitel,$B14,Aud_Punkt,"?*") | I14: =COUNTIFS(Aud_Kapitel,$B14,Aud_Bew,"N.I.O") | J14: =COUNTIFS(Aud_Kapitel,$B14,Aud_Bew,"bed. OK") | K14: =COUNTIFS(Aud_Kapitel,$B14,Aud_Bew,"OK") | L14: =COUNTIFS(Aud_Kapitel,$B14,Aud_Bew,"n. b.") | M14: =H14-SUM(I14:L14) | N14: =IFERROR((SUMIFS(Aud_Gew,Aud_Kapitel,$B14,Aud_Bew,"OK")+Gewicht_bedOK*SUMIFS(Aud_Gew,Aud_Kapitel,$B14,Aud_Bew,"bed. OK"))/(SUMIFS(Aud_Gew,Aud_Kapitel,$B14,Aud_Bew,"N.I.O")+SUMIFS(Aud_Gew,Aud_Kapitel,$B14,Aud_Bew,"bed. OK")+SUMIFS(Aud_Gew,Aud_Kapitel,$B14,Aud_Bew,"OK")),"") | P14: =IF($N14="","nicht bewertet",IF(AND(KO_aktiv="ja",COUNTIFS(Aud_Kapitel,$B14,Aud_KO,"K.O.",Aud_Bew,"N.I.O")>0),"kritisch (K.O.)",IF($N14>=Ampel_gruen,"gut",IF($N14>=Ampel_gelb,"mittel","kritisch")))) | AB14: =IF($N14="","",IF($N14>=Ampel_gruen,$N14,"")) | AC14: =IF($N14="","",IF(AND($N14>=Ampel_gelb,$N14<Ampel_gruen),$N14,"")) | AD14: =IF($N14="","",IF($N14<Ampel_gelb,$N14,"")) | AE14: =IF($N14="","",$N14+ROW()/100000) | AG14: bed. OK | AH14: =J27
B15: =Einstellungen!$B$20 | H15: =COUNTIFS(Aud_Kapitel,$B15,Aud_Punkt,"?*") | I15: =COUNTIFS(Aud_Kapitel,$B15,Aud_Bew,"N.I.O") | J15: =COUNTIFS(Aud_Kapitel,$B15,Aud_Bew,"bed. OK") | K15: =COUNTIFS(Aud_Kapitel,$B15,Aud_Bew,"OK") | L15: =COUNTIFS(Aud_Kapitel,$B15,Aud_Bew,"n. b.") | M15: =H15-SUM(I15:L15) | N15: =IFERROR((SUMIFS(Aud_Gew,Aud_Kapitel,$B15,Aud_Bew,"OK")+Gewicht_bedOK*SUMIFS(Aud_Gew,Aud_Kapitel,$B15,Aud_Bew,"bed. OK"))/(SUMIFS(Aud_Gew,Aud_Kapitel,$B15,Aud_Bew,"N.I.O")+SUMIFS(Aud_Gew,Aud_Kapitel,$B15,Aud_Bew,"bed. OK")+SUMIFS(Aud_Gew,Aud_Kapitel,$B15,Aud_Bew,"OK")),"") | P15: =IF($N15="","nicht bewertet",IF(AND(KO_aktiv="ja",COUNTIFS(Aud_Kapitel,$B15,Aud_KO,"K.O.",Aud_Bew,"N.I.O")>0),"kritisch (K.O.)",IF($N15>=Ampel_gruen,"gut",IF($N15>=Ampel_gelb,"mittel","kritisch")))) | AB15: =IF($N15="","",IF($N15>=Ampel_gruen,$N15,"")) | AC15: =IF($N15="","",IF(AND($N15>=Ampel_gelb,$N15<Ampel_gruen),$N15,"")) | AD15: =IF($N15="","",IF($N15<Ampel_gelb,$N15,"")) | AE15: =IF($N15="","",$N15+ROW()/100000) | AG15: OK | AH15: =K27
B16: =Einstellungen!$B$21 | H16: =COUNTIFS(Aud_Kapitel,$B16,Aud_Punkt,"?*") | I16: =COUNTIFS(Aud_Kapitel,$B16,Aud_Bew,"N.I.O") | J16: =COUNTIFS(Aud_Kapitel,$B16,Aud_Bew,"bed. OK") | K16: =COUNTIFS(Aud_Kapitel,$B16,Aud_Bew,"OK") | L16: =COUNTIFS(Aud_Kapitel,$B16,Aud_Bew,"n. b.") | M16: =H16-SUM(I16:L16) | N16: =IFERROR((SUMIFS(Aud_Gew,Aud_Kapitel,$B16,Aud_Bew,"OK")+Gewicht_bedOK*SUMIFS(Aud_Gew,Aud_Kapitel,$B16,Aud_Bew,"bed. OK"))/(SUMIFS(Aud_Gew,Aud_Kapitel,$B16,Aud_Bew,"N.I.O")+SUMIFS(Aud_Gew,Aud_Kapitel,$B16,Aud_Bew,"bed. OK")+SUMIFS(Aud_Gew,Aud_Kapitel,$B16,Aud_Bew,"OK")),"") | P16: =IF($N16="","nicht bewertet",IF(AND(KO_aktiv="ja",COUNTIFS(Aud_Kapitel,$B16,Aud_KO,"K.O.",Aud_Bew,"N.I.O")>0),"kritisch (K.O.)",IF($N16>=Ampel_gruen,"gut",IF($N16>=Ampel_gelb,"mittel","kritisch")))) | AB16: =IF($N16="","",IF($N16>=Ampel_gruen,$N16,"")) | AC16: =IF($N16="","",IF(AND($N16>=Ampel_gelb,$N16<Ampel_gruen),$N16,"")) | AD16: =IF($N16="","",IF($N16<Ampel_gelb,$N16,"")) | AE16: =IF($N16="","",$N16+ROW()/100000) | AG16: n. b. | AH16: =L27
B17: =Einstellungen!$B$22 | H17: =COUNTIFS(Aud_Kapitel,$B17,Aud_Punkt,"?*") | I17: =COUNTIFS(Aud_Kapitel,$B17,Aud_Bew,"N.I.O") | J17: =COUNTIFS(Aud_Kapitel,$B17,Aud_Bew,"bed. OK") | K17: =COUNTIFS(Aud_Kapitel,$B17,Aud_Bew,"OK") | L17: =COUNTIFS(Aud_Kapitel,$B17,Aud_Bew,"n. b.") | M17: =H17-SUM(I17:L17) | N17: =IFERROR((SUMIFS(Aud_Gew,Aud_Kapitel,$B17,Aud_Bew,"OK")+Gewicht_bedOK*SUMIFS(Aud_Gew,Aud_Kapitel,$B17,Aud_Bew,"bed. OK"))/(SUMIFS(Aud_Gew,Aud_Kapitel,$B17,Aud_Bew,"N.I.O")+SUMIFS(Aud_Gew,Aud_Kapitel,$B17,Aud_Bew,"bed. OK")+SUMIFS(Aud_Gew,Aud_Kapitel,$B17,Aud_Bew,"OK")),"") | P17: =IF($N17="","nicht bewertet",IF(AND(KO_aktiv="ja",COUNTIFS(Aud_Kapitel,$B17,Aud_KO,"K.O.",Aud_Bew,"N.I.O")>0),"kritisch (K.O.)",IF($N17>=Ampel_gruen,"gut",IF($N17>=Ampel_gelb,"mittel","kritisch")))) | AB17: =IF($N17="","",IF($N17>=Ampel_gruen,$N17,"")) | AC17: =IF($N17="","",IF(AND($N17>=Ampel_gelb,$N17<Ampel_gruen),$N17,"")) | AD17: =IF($N17="","",IF($N17<Ampel_gelb,$N17,"")) | AE17: =IF($N17="","",$N17+ROW()/100000) | AG17: offen | AH17: =M27
B18: =Einstellungen!$B$23 | H18: =COUNTIFS(Aud_Kapitel,$B18,Aud_Punkt,"?*") | I18: =COUNTIFS(Aud_Kapitel,$B18,Aud_Bew,"N.I.O") | J18: =COUNTIFS(Aud_Kapitel,$B18,Aud_Bew,"bed. OK") | K18: =COUNTIFS(Aud_Kapitel,$B18,Aud_Bew,"OK") | L18: =COUNTIFS(Aud_Kapitel,$B18,Aud_Bew,"n. b.") | M18: =H18-SUM(I18:L18) | N18: =IFERROR((SUMIFS(Aud_Gew,Aud_Kapitel,$B18,Aud_Bew,"OK")+Gewicht_bedOK*SUMIFS(Aud_Gew,Aud_Kapitel,$B18,Aud_Bew,"bed. OK"))/(SUMIFS(Aud_Gew,Aud_Kapitel,$B18,Aud_Bew,"N.I.O")+SUMIFS(Aud_Gew,Aud_Kapitel,$B18,Aud_Bew,"bed. OK")+SUMIFS(Aud_Gew,Aud_Kapitel,$B18,Aud_Bew,"OK")),"") | P18: =IF($N18="","nicht bewertet",IF(AND(KO_aktiv="ja",COUNTIFS(Aud_Kapitel,$B18,Aud_KO,"K.O.",Aud_Bew,"N.I.O")>0),"kritisch (K.O.)",IF($N18>=Ampel_gruen,"gut",IF($N18>=Ampel_gelb,"mittel","kritisch")))) | AB18: =IF($N18="","",IF($N18>=Ampel_gruen,$N18,"")) | AC18: =IF($N18="","",IF(AND($N18>=Ampel_gelb,$N18<Ampel_gruen),$N18,"")) | AD18: =IF($N18="","",IF($N18<Ampel_gelb,$N18,"")) | AE18: =IF($N18="","",$N18+ROW()/100000)
B19: =Einstellungen!$B$24 | H19: =COUNTIFS(Aud_Kapitel,$B19,Aud_Punkt,"?*") | I19: =COUNTIFS(Aud_Kapitel,$B19,Aud_Bew,"N.I.O") | J19: =COUNTIFS(Aud_Kapitel,$B19,Aud_Bew,"bed. OK") | K19: =COUNTIFS(Aud_Kapitel,$B19,Aud_Bew,"OK") | L19: =COUNTIFS(Aud_Kapitel,$B19,Aud_Bew,"n. b.") | M19: =H19-SUM(I19:L19) | N19: =IFERROR((SUMIFS(Aud_Gew,Aud_Kapitel,$B19,Aud_Bew,"OK")+Gewicht_bedOK*SUMIFS(Aud_Gew,Aud_Kapitel,$B19,Aud_Bew,"bed. OK"))/(SUMIFS(Aud_Gew,Aud_Kapitel,$B19,Aud_Bew,"N.I.O")+SUMIFS(Aud_Gew,Aud_Kapitel,$B19,Aud_Bew,"bed. OK")+SUMIFS(Aud_Gew,Aud_Kapitel,$B19,Aud_Bew,"OK")),"") | P19: =IF($N19="","nicht bewertet",IF(AND(KO_aktiv="ja",COUNTIFS(Aud_Kapitel,$B19,Aud_KO,"K.O.",Aud_Bew,"N.I.O")>0),"kritisch (K.O.)",IF($N19>=Ampel_gruen,"gut",IF($N19>=Ampel_gelb,"mittel","kritisch")))) | AB19: =IF($N19="","",IF($N19>=Ampel_gruen,$N19,"")) | AC19: =IF($N19="","",IF(AND($N19>=Ampel_gelb,$N19<Ampel_gruen),$N19,"")) | AD19: =IF($N19="","",IF($N19<Ampel_gelb,$N19,"")) | AE19: =IF($N19="","",$N19+ROW()/100000)
B20: =Einstellungen!$B$25 | H20: =COUNTIFS(Aud_Kapitel,$B20,Aud_Punkt,"?*") | I20: =COUNTIFS(Aud_Kapitel,$B20,Aud_Bew,"N.I.O") | J20: =COUNTIFS(Aud_Kapitel,$B20,Aud_Bew,"bed. OK") | K20: =COUNTIFS(Aud_Kapitel,$B20,Aud_Bew,"OK") | L20: =COUNTIFS(Aud_Kapitel,$B20,Aud_Bew,"n. b.") | M20: =H20-SUM(I20:L20) | N20: =IFERROR((SUMIFS(Aud_Gew,Aud_Kapitel,$B20,Aud_Bew,"OK")+Gewicht_bedOK*SUMIFS(Aud_Gew,Aud_Kapitel,$B20,Aud_Bew,"bed. OK"))/(SUMIFS(Aud_Gew,Aud_Kapitel,$B20,Aud_Bew,"N.I.O")+SUMIFS(Aud_Gew,Aud_Kapitel,$B20,Aud_Bew,"bed. OK")+SUMIFS(Aud_Gew,Aud_Kapitel,$B20,Aud_Bew,"OK")),"") | P20: =IF($N20="","nicht bewertet",IF(AND(KO_aktiv="ja",COUNTIFS(Aud_Kapitel,$B20,Aud_KO,"K.O.",Aud_Bew,"N.I.O")>0),"kritisch (K.O.)",IF($N20>=Ampel_gruen,"gut",IF($N20>=Ampel_gelb,"mittel","kritisch")))) | AB20: =IF($N20="","",IF($N20>=Ampel_gruen,$N20,"")) | AC20: =IF($N20="","",IF(AND($N20>=Ampel_gelb,$N20<Ampel_gruen),$N20,"")) | AD20: =IF($N20="","",IF($N20<Ampel_gelb,$N20,"")) | AE20: =IF($N20="","",$N20+ROW()/100000)
B21: =Einstellungen!$B$26 | H21: =COUNTIFS(Aud_Kapitel,$B21,Aud_Punkt,"?*") | I21: =COUNTIFS(Aud_Kapitel,$B21,Aud_Bew,"N.I.O") | J21: =COUNTIFS(Aud_Kapitel,$B21,Aud_Bew,"bed. OK") | K21: =COUNTIFS(Aud_Kapitel,$B21,Aud_Bew,"OK") | L21: =COUNTIFS(Aud_Kapitel,$B21,Aud_Bew,"n. b.") | M21: =H21-SUM(I21:L21) | N21: =IFERROR((SUMIFS(Aud_Gew,Aud_Kapitel,$B21,Aud_Bew,"OK")+Gewicht_bedOK*SUMIFS(Aud_Gew,Aud_Kapitel,$B21,Aud_Bew,"bed. OK"))/(SUMIFS(Aud_Gew,Aud_Kapitel,$B21,Aud_Bew,"N.I.O")+SUMIFS(Aud_Gew,Aud_Kapitel,$B21,Aud_Bew,"bed. OK")+SUMIFS(Aud_Gew,Aud_Kapitel,$B21,Aud_Bew,"OK")),"") | P21: =IF($N21="","nicht bewertet",IF(AND(KO_aktiv="ja",COUNTIFS(Aud_Kapitel,$B21,Aud_KO,"K.O.",Aud_Bew,"N.I.O")>0),"kritisch (K.O.)",IF($N21>=Ampel_gruen,"gut",IF($N21>=Ampel_gelb,"mittel","kritisch")))) | AB21: =IF($N21="","",IF($N21>=Ampel_gruen,$N21,"")) | AC21: =IF($N21="","",IF(AND($N21>=Ampel_gelb,$N21<Ampel_gruen),$N21,"")) | AD21: =IF($N21="","",IF($N21<Ampel_gelb,$N21,"")) | AE21: =IF($N21="","",$N21+ROW()/100000)
B22: =Einstellungen!$B$27 | H22: =COUNTIFS(Aud_Kapitel,$B22,Aud_Punkt,"?*") | I22: =COUNTIFS(Aud_Kapitel,$B22,Aud_Bew,"N.I.O") | J22: =COUNTIFS(Aud_Kapitel,$B22,Aud_Bew,"bed. OK") | K22: =COUNTIFS(Aud_Kapitel,$B22,Aud_Bew,"OK") | L22: =COUNTIFS(Aud_Kapitel,$B22,Aud_Bew,"n. b.") | M22: =H22-SUM(I22:L22) | N22: =IFERROR((SUMIFS(Aud_Gew,Aud_Kapitel,$B22,Aud_Bew,"OK")+Gewicht_bedOK*SUMIFS(Aud_Gew,Aud_Kapitel,$B22,Aud_Bew,"bed. OK"))/(SUMIFS(Aud_Gew,Aud_Kapitel,$B22,Aud_Bew,"N.I.O")+SUMIFS(Aud_Gew,Aud_Kapitel,$B22,Aud_Bew,"bed. OK")+SUMIFS(Aud_Gew,Aud_Kapitel,$B22,Aud_Bew,"OK")),"") | P22: =IF($N22="","nicht bewertet",IF(AND(KO_aktiv="ja",COUNTIFS(Aud_Kapitel,$B22,Aud_KO,"K.O.",Aud_Bew,"N.I.O")>0),"kritisch (K.O.)",IF($N22>=Ampel_gruen,"gut",IF($N22>=Ampel_gelb,"mittel","kritisch")))) | AB22: =IF($N22="","",IF($N22>=Ampel_gruen,$N22,"")) | AC22: =IF($N22="","",IF(AND($N22>=Ampel_gelb,$N22<Ampel_gruen),$N22,"")) | AD22: =IF($N22="","",IF($N22<Ampel_gelb,$N22,"")) | AE22: =IF($N22="","",$N22+ROW()/100000)
B23: =Einstellungen!$B$28 | H23: =COUNTIFS(Aud_Kapitel,$B23,Aud_Punkt,"?*") | I23: =COUNTIFS(Aud_Kapitel,$B23,Aud_Bew,"N.I.O") | J23: =COUNTIFS(Aud_Kapitel,$B23,Aud_Bew,"bed. OK") | K23: =COUNTIFS(Aud_Kapitel,$B23,Aud_Bew,"OK") | L23: =COUNTIFS(Aud_Kapitel,$B23,Aud_Bew,"n. b.") | M23: =H23-SUM(I23:L23) | N23: =IFERROR((SUMIFS(Aud_Gew,Aud_Kapitel,$B23,Aud_Bew,"OK")+Gewicht_bedOK*SUMIFS(Aud_Gew,Aud_Kapitel,$B23,Aud_Bew,"bed. OK"))/(SUMIFS(Aud_Gew,Aud_Kapitel,$B23,Aud_Bew,"N.I.O")+SUMIFS(Aud_Gew,Aud_Kapitel,$B23,Aud_Bew,"bed. OK")+SUMIFS(Aud_Gew,Aud_Kapitel,$B23,Aud_Bew,"OK")),"") | P23: =IF($N23="","nicht bewertet",IF(AND(KO_aktiv="ja",COUNTIFS(Aud_Kapitel,$B23,Aud_KO,"K.O.",Aud_Bew,"N.I.O")>0),"kritisch (K.O.)",IF($N23>=Ampel_gruen,"gut",IF($N23>=Ampel_gelb,"mittel","kritisch")))) | AB23: =IF($N23="","",IF($N23>=Ampel_gruen,$N23,"")) | AC23: =IF($N23="","",IF(AND($N23>=Ampel_gelb,$N23<Ampel_gruen),$N23,"")) | AD23: =IF($N23="","",IF($N23<Ampel_gelb,$N23,"")) | AE23: =IF($N23="","",$N23+ROW()/100000)
B24: =Einstellungen!$B$29 | H24: =COUNTIFS(Aud_Kapitel,$B24,Aud_Punkt,"?*") | I24: =COUNTIFS(Aud_Kapitel,$B24,Aud_Bew,"N.I.O") | J24: =COUNTIFS(Aud_Kapitel,$B24,Aud_Bew,"bed. OK") | K24: =COUNTIFS(Aud_Kapitel,$B24,Aud_Bew,"OK") | L24: =COUNTIFS(Aud_Kapitel,$B24,Aud_Bew,"n. b.") | M24: =H24-SUM(I24:L24) | N24: =IFERROR((SUMIFS(Aud_Gew,Aud_Kapitel,$B24,Aud_Bew,"OK")+Gewicht_bedOK*SUMIFS(Aud_Gew,Aud_Kapitel,$B24,Aud_Bew,"bed. OK"))/(SUMIFS(Aud_Gew,Aud_Kapitel,$B24,Aud_Bew,"N.I.O")+SUMIFS(Aud_Gew,Aud_Kapitel,$B24,Aud_Bew,"bed. OK")+SUMIFS(Aud_Gew,Aud_Kapitel,$B24,Aud_Bew,"OK")),"") | P24: =IF($N24="","nicht bewertet",IF(AND(KO_aktiv="ja",COUNTIFS(Aud_Kapitel,$B24,Aud_KO,"K.O.",Aud_Bew,"N.I.O")>0),"kritisch (K.O.)",IF($N24>=Ampel_gruen,"gut",IF($N24>=Ampel_gelb,"mittel","kritisch")))) | AB24: =IF($N24="","",IF($N24>=Ampel_gruen,$N24,"")) | AC24: =IF($N24="","",IF(AND($N24>=Ampel_gelb,$N24<Ampel_gruen),$N24,"")) | AD24: =IF($N24="","",IF($N24<Ampel_gelb,$N24,"")) | AE24: =IF($N24="","",$N24+ROW()/100000)
B25: =Einstellungen!$B$30 | H25: =COUNTIFS(Aud_Kapitel,$B25,Aud_Punkt,"?*") | I25: =COUNTIFS(Aud_Kapitel,$B25,Aud_Bew,"N.I.O") | J25: =COUNTIFS(Aud_Kapitel,$B25,Aud_Bew,"bed. OK") | K25: =COUNTIFS(Aud_Kapitel,$B25,Aud_Bew,"OK") | L25: =COUNTIFS(Aud_Kapitel,$B25,Aud_Bew,"n. b.") | M25: =H25-SUM(I25:L25) | N25: =IFERROR((SUMIFS(Aud_Gew,Aud_Kapitel,$B25,Aud_Bew,"OK")+Gewicht_bedOK*SUMIFS(Aud_Gew,Aud_Kapitel,$B25,Aud_Bew,"bed. OK"))/(SUMIFS(Aud_Gew,Aud_Kapitel,$B25,Aud_Bew,"N.I.O")+SUMIFS(Aud_Gew,Aud_Kapitel,$B25,Aud_Bew,"bed. OK")+SUMIFS(Aud_Gew,Aud_Kapitel,$B25,Aud_Bew,"OK")),"") | P25: =IF($N25="","nicht bewertet",IF(AND(KO_aktiv="ja",COUNTIFS(Aud_Kapitel,$B25,Aud_KO,"K.O.",Aud_Bew,"N.I.O")>0),"kritisch (K.O.)",IF($N25>=Ampel_gruen,"gut",IF($N25>=Ampel_gelb,"mittel","kritisch")))) | AB25: =IF($N25="","",IF($N25>=Ampel_gruen,$N25,"")) | AC25: =IF($N25="","",IF(AND($N25>=Ampel_gelb,$N25<Ampel_gruen),$N25,"")) | AD25: =IF($N25="","",IF($N25<Ampel_gelb,$N25,"")) | AE25: =IF($N25="","",$N25+ROW()/100000)
B26: =Einstellungen!$B$31 | H26: =COUNTIFS(Aud_Kapitel,$B26,Aud_Punkt,"?*") | I26: =COUNTIFS(Aud_Kapitel,$B26,Aud_Bew,"N.I.O") | J26: =COUNTIFS(Aud_Kapitel,$B26,Aud_Bew,"bed. OK") | K26: =COUNTIFS(Aud_Kapitel,$B26,Aud_Bew,"OK") | L26: =COUNTIFS(Aud_Kapitel,$B26,Aud_Bew,"n. b.") | M26: =H26-SUM(I26:L26) | N26: =IFERROR((SUMIFS(Aud_Gew,Aud_Kapitel,$B26,Aud_Bew,"OK")+Gewicht_bedOK*SUMIFS(Aud_Gew,Aud_Kapitel,$B26,Aud_Bew,"bed. OK"))/(SUMIFS(Aud_Gew,Aud_Kapitel,$B26,Aud_Bew,"N.I.O")+SUMIFS(Aud_Gew,Aud_Kapitel,$B26,Aud_Bew,"bed. OK")+SUMIFS(Aud_Gew,Aud_Kapitel,$B26,Aud_Bew,"OK")),"") | P26: =IF($N26="","nicht bewertet",IF(AND(KO_aktiv="ja",COUNTIFS(Aud_Kapitel,$B26,Aud_KO,"K.O.",Aud_Bew,"N.I.O")>0),"kritisch (K.O.)",IF($N26>=Ampel_gruen,"gut",IF($N26>=Ampel_gelb,"mittel","kritisch")))) | AB26: =IF($N26="","",IF($N26>=Ampel_gruen,$N26,"")) | AC26: =IF($N26="","",IF(AND($N26>=Ampel_gelb,$N26<Ampel_gruen),$N26,"")) | AD26: =IF($N26="","",IF($N26<Ampel_gelb,$N26,"")) | AE26: =IF($N26="","",$N26+ROW()/100000)
B27: Gesamt | H27: =SUM(H13:H26) | I27: =SUM(I13:I26) | J27: =SUM(J13:J26) | K27: =SUM(K13:K26) | L27: =SUM(L13:L26) | M27: =SUM(M13:M26) | N27: =Audit!$P$4 | P27: =Audit!$P$5
B29: Erfüllungsgrad je Kapitel | O29: Bewertungen je Kapitel (Anzahl Prüfpunkte)
B49: Erfüllungsgrad = Σ(Gewicht × Wertung) ÷ Σ(Gewicht) der bewerteten Punkte. Gewicht „bed. OK“, Ampelgrenzen und K.O.-Regel: Blatt „Einstellungen“.
B51: Größter Handlungsbedarf (5 Kapitel mit dem niedrigsten Erfüllungsgrad) | O51: Umsetzungsstand der Maßnahmen
B52: Rang | C52: Kapitel | I52: Erfüllungsgrad | K52: N.I.O | L52: bed. OK | O52: Status | S52: Anzahl | U52: Anteil | AF52: k-kleinster | AG52: Position
B53: =IF($AG53="","",1) | C53: =IF($AG53="","",INDEX($B$13:$B$26,$AG53)) | I53: =IF($AG53="","",INDEX($N$13:$N$26,$AG53)) | K53: =IF($AG53="","",INDEX($I$13:$I$26,$AG53)) | L53: =IF($AG53="","",INDEX($J$13:$J$26,$AG53)) | O53: überfällig | S53: =COUNTIF(Aud_Status,"überfällig") | U53: =IFERROR(S53/$S$56,0) | AF53: =IFERROR(SMALL($AE$13:$AE$26,1),"") | AG53: =IF($AF53="","",MATCH($AF53,$AE$13:$AE$26,0))
B54: =IF($AG54="","",2) | C54: =IF($AG54="","",INDEX($B$13:$B$26,$AG54)) | I54: =IF($AG54="","",INDEX($N$13:$N$26,$AG54)) | K54: =IF($AG54="","",INDEX($I$13:$I$26,$AG54)) | L54: =IF($AG54="","",INDEX($J$13:$J$26,$AG54)) | O54: offen | S54: =COUNTIF(Aud_Status,"offen") | U54: =IFERROR(S54/$S$56,0) | AF54: =IFERROR(SMALL($AE$13:$AE$26,2),"") | AG54: =IF($AF54="","",MATCH($AF54,$AE$13:$AE$26,0))
B55: =IF($AG55="","",3) | C55: =IF($AG55="","",INDEX($B$13:$B$26,$AG55)) | I55: =IF($AG55="","",INDEX($N$13:$N$26,$AG55)) | K55: =IF($AG55="","",INDEX($I$13:$I$26,$AG55)) | L55: =IF($AG55="","",INDEX($J$13:$J$26,$AG55)) | O55: erledigt | S55: =COUNTIF(Aud_Status,"erledigt") | U55: =IFERROR(S55/$S$56,0) | AF55: =IFERROR(SMALL($AE$13:$AE$26,3),"") | AG55: =IF($AF55="","",MATCH($AF55,$AE$13:$AE$26,0))
B56: =IF($AG56="","",4) | C56: =IF($AG56="","",INDEX($B$13:$B$26,$AG56)) | I56: =IF($AG56="","",INDEX($N$13:$N$26,$AG56)) | K56: =IF($AG56="","",INDEX($I$13:$I$26,$AG56)) | L56: =IF($AG56="","",INDEX($J$13:$J$26,$AG56)) | O56: Gesamt | S56: =SUM(S53:S55) | U56: =IF(S56=0,"keine Maßnahmen","Maßnahmen aus N.I.O und bed. OK") | AF56: =IFERROR(SMALL($AE$13:$AE$26,4),"") | AG56: =IF($AF56="","",MATCH($AF56,$AE$13:$AE$26,0))
B57: =IF($AG57="","",5) | C57: =IF($AG57="","",INDEX($B$13:$B$26,$AG57)) | I57: =IF($AG57="","",INDEX($N$13:$N$26,$AG57)) | K57: =IF($AG57="","",INDEX($I$13:$I$26,$AG57)) | L57: =IF($AG57="","",INDEX($J$13:$J$26,$AG57)) | AF57: =IFERROR(SMALL($AE$13:$AE$26,5),"") | AG57: =IF($AF57="","",MATCH($AF57,$AE$13:$AE$26,0))
B58: Reihenfolge nach Erfüllungsgrad; bei Gleichstand zählt die Kapitelreihenfolge.
B60: Kritische Abweichungen – Prüfpunkte mit N.I.O
B61: Nr. | C61: Kapitel | G61: Check-Punkt | O61: Maßnahme / Bemerkung | T61: Verantwortlich | V61: Termin | X61: Status | AF61: Position
B62: =IF($AF62="","",INDEX(Aud_Nr,$AF62)) | C62: =IF($AF62="","",INDEX(Aud_Kapitel,$AF62)) | G62: =IF($AF62="","",INDEX(Aud_Punkt,$AF62)) | O62: =IF($AF62="","",IF(INDEX(Aud_Massn,$AF62)="","– fehlt –",INDEX(Aud_Massn,$AF62))) | T62: =IF($AF62="","",IF(INDEX(Aud_Verantw,$AF62)="","– fehlt –",INDEX(Aud_Verantw,$AF62))) | V62: =IF($AF62="","",IF(INDEX(Aud_Termin,$AF62)="","– fehlt –",INDEX(Aud_Termin,$AF62))) | X62: =IF($AF62="","",INDEX(Aud_Status,$AF62)) | AF62: =IFERROR(MATCH(1,Aud_NIO,0),"")
B63: =IF($AF63="","",INDEX(Aud_Nr,$AF63)) | C63: =IF($AF63="","",INDEX(Aud_Kapitel,$AF63)) | G63: =IF($AF63="","",INDEX(Aud_Punkt,$AF63)) | O63: =IF($AF63="","",IF(INDEX(Aud_Massn,$AF63)="","– fehlt –",INDEX(Aud_Massn,$AF63))) | T63: =IF($AF63="","",IF(INDEX(Aud_Verantw,$AF63)="","– fehlt –",INDEX(Aud_Verantw,$AF63))) | V63: =IF($AF63="","",IF(INDEX(Aud_Termin,$AF63)="","– fehlt –",INDEX(Aud_Termin,$AF63))) | X63: =IF($AF63="","",INDEX(Aud_Status,$AF63)) | AF63: =IFERROR(MATCH(2,Aud_NIO,0),"")
B64: =IF($AF64="","",INDEX(Aud_Nr,$AF64)) | C64: =IF($AF64="","",INDEX(Aud_Kapitel,$AF64)) | G64: =IF($AF64="","",INDEX(Aud_Punkt,$AF64)) | O64: =IF($AF64="","",IF(INDEX(Aud_Massn,$AF64)="","– fehlt –",INDEX(Aud_Massn,$AF64))) | T64: =IF($AF64="","",IF(INDEX(Aud_Verantw,$AF64)="","– fehlt –",INDEX(Aud_Verantw,$AF64))) | V64: =IF($AF64="","",IF(INDEX(Aud_Termin,$AF64)="","– fehlt –",INDEX(Aud_Termin,$AF64))) | X64: =IF($AF64="","",INDEX(Aud_Status,$AF64)) | AF64: =IFERROR(MATCH(3,Aud_NIO,0),"")
...

Sheet Audit
A1: Anlagenzustandsanalyse – Checkliste
A2: Gelbe Felder ausfüllen. Bewertung je Prüfpunkt: N.I.O · bed. OK · OK · n. b. – die Auswertung steht im Blatt „Dashboard“. | J2: Ergebnis
A3: Werk / Standort | D3: Datum | J3: N.I.O | K3: bed. OK | L3: OK | M3: n. b. | N3: offen | O3: K.O. | P3: Erfüllungsgrad
A4: Anlage / Maschinengruppe | D4: Auditor | J4: =COUNTIF(Aud_Bew,"N.I.O") | K4: =COUNTIF(Aud_Bew,"bed. OK") | L4: =COUNTIF(Aud_Bew,"OK") | M4: =COUNTIF(Aud_Bew,"n. b.") | N4: =COUNTA(Aud_Punkt)-SUM(J4:M4) | O4: =COUNTIFS(Aud_KO,"K.O.",Aud_Bew,"N.I.O") | P4: =IFERROR((SUMIFS(Aud_Gew,Aud_Bew,"OK")+Gewicht_bedOK*SUMIFS(Aud_Gew,Aud_Bew,"bed. OK"))/(SUMIFS(Aud_Gew,Aud_Bew,"N.I.O")+SUMIFS(Aud_Gew,Aud_Bew,"bed. OK")+SUMIFS(Aud_Gew,Aud_Bew,"OK")),"")
A5: Equipment-Nr. (bei Gruppe: alle) | D5: Geltungsbereich | J5: Erfüllungsgrad = Σ(Gewicht × Wertung) ÷ Σ(Gewicht) der mit N.I.O, bed. OK oder OK bewerteten Punkte (OK = 100 %, bed. OK = Gewicht aus „Einstellungen“, N.I.O = 0 %). „n. b.“ und offene Punkte zählen nicht. K.O.-Punkt mit N.I.O ⇒ „kritisch (K.O.)“. | P5: =IF(P4="","nicht bewertet",IF(AND(KO_aktiv="ja",O4>0),"kritisch (K.O.)",IF(P4>=Ampel_gruen,"gut",IF(P4>=Ampel_gelb,"mittel","kritisch"))))
A6: Teilnehmer | D6: Kostenstelle / Bereich
A8: Nr. | B8: Kapitel | C8: Check-Punkt | D8: Check-Punkt (EN) | E8: Normbezug | F8: Gewicht | G8: K.O. | H8: Bewertung | I8: Nachweis / Evidenz | J8: Maßnahmen / Bemerkung | K8: Verantwortlich | L8: Termin | M8: Erledigt | N8: Status | O8: Maßn.-Nr. | P8: Herkunft | Q8: N.I.O-Nr.
A9: =IF(C9="","",COUNTA($C$9:C9)) | B9: Technischer Zustand | C9: Ist der allgemeine Zustand der Maschine in Ordnung (Sauberkeit, Umgebung, Kennzeichnung mit Anlagenbezeichnung / Equipment-Nr.)? | D9: Is the general condition of the machine in order (cleanliness, surroundings, labelling with machine name / equipment no.)? | E9: IATF 7.1.4.1 | F9: 1 | N9: =IF(OR(H9="N.I.O",H9="bed. OK"),IF(M9="ja","erledigt",IF(AND(L9<>"",L9<TODAY()),"überfällig","offen")),"") | O9: =IF(OR(H9="N.I.O",H9="bed. OK"),COUNTIF($H$9:H9,"N.I.O")+COUNTIF($H$9:H9,"bed. OK"),"") | P9: Vorlage M 1 / A1 B6 | Q9: =IF(H9="N.I.O",COUNTIF($H$9:H9,"N.I.O"),"")
A10: =IF(C10="","",COUNTA($C$9:C10)) | B10: Technischer Zustand | C10: Wird das Umfeld der Anlage in einem ordentlichen, sauberen und instand gehaltenen Zustand gehalten (5S, feste Plätze)? | D10: Is the area around the machine kept in an orderly, clean and well-maintained condition (5S, fixed locations)? | E10: IATF 7.1.4.1 | F10: 1 | N10: =IF(OR(H10="N.I.O",H10="bed. OK"),IF(M10="ja","erledigt",IF(AND(L10<>"",L10<TODAY()),"überfällig","offen")),"") | O10: =IF(OR(H10="N.I.O",H10="bed. OK"),COUNTIF($H$9:H10,"N.I.O")+COUNTIF($H$9:H10,"bed. OK"),"") | P10: Vorlage A1 B15 | Q10: =IF(H10="N.I.O",COUNTIF($H$9:H10,"N.I.O"),"")
A11: =IF(C11="","",COUNTA($C$9:C11)) | B11: Technischer Zustand | C11: Sind Funktion und Zustand der Mechanik in Ordnung (Führungen, Lager, Spindeln, Spiel) – bezogen auf die letzte Inspektion? | D11: Are function and condition of the mechanics in order (guides, bearings, spindles, backlash) – based on the last inspection? | E11: DIN 31051 | F11: 2 | N11: =IF(OR(H11="N.I.O",H11="bed. OK"),IF(M11="ja","erledigt",IF(AND(L11<>"",L11<TODAY()),"überfällig","offen")),"") | O11: =IF(OR(H11="N.I.O",H11="bed. OK"),COUNTIF($H$9:H11,"N.I.O")+COUNTIF($H$9:H11,"bed. OK"),"") | P11: Vorlage M 2.5 | Q11: =IF(H11="N.I.O",COUNTIF($H$9:H11,"N.I.O"),"")
A12: =IF(C12="","",COUNTA($C$9:C12)) | B12: Technischer Zustand | C12: Sind Funktion und Zustand der Hydraulik in Ordnung (Dichtheit, Ölzustand, Drücke, Filter)? | D12: Are function and condition of the hydraulics in order (tightness, oil condition, pressures, filters)? | E12: DIN 31051 | F12: 2 | N12: =IF(OR(H12="N.I.O",H12="bed. OK"),IF(M12="ja","erledigt",IF(AND(L12<>"",L12<TODAY()),"überfällig","offen")),"") | O12: =IF(OR(H12="N.I.O",H12="bed. OK"),COUNTIF($H$9:H12,"N.I.O")+COUNTIF($H$9:H12,"bed. OK"),"") | P12: Vorlage M 2.6 | Q12: =IF(H12="N.I.O",COUNTIF($H$9:H12,"N.I.O"),"")
A13: =IF(C13="","",COUNTA($C$9:C13)) | B13: Technischer Zustand | C13: Sind Funktion und Zustand der Pneumatik in Ordnung (Dichtheit, Wartungseinheit, Ventile)? | D13: Are function and condition of the pneumatics in order (tightness, service unit, valves)? | E13: DIN 31051 | F13: 2 | N13: =IF(OR(H13="N.I.O",H13="bed. OK"),IF(M13="ja","erledigt",IF(AND(L13<>"",L13<TODAY()),"überfällig","offen")),"") | O13: =IF(OR(H13="N.I.O",H13="bed. OK"),COUNTIF($H$9:H13,"N.I.O")+COUNTIF($H$9:H13,"bed. OK"),"") | P13: Vorlage M 2.7 | Q13: =IF(H13="N.I.O",COUNTIF($H$9:H13,"N.I.O"),"")
A14: =IF(C14="","",COUNTA($C$9:C14)) | B14: Technischer Zustand | C14: Sind Funktion und Zustand der Elektrik in Ordnung (Schaltschrank, Verkabelung, Klimatisierung, Sensorik)? | D14: Are function and condition of the electrics in order (control cabinet, wiring, air conditioning, sensors)? | E14: DIN 31051 | F14: 2 | N14: =IF(OR(H14="N.I.O",H14="bed. OK"),IF(M14="ja","erledigt",IF(AND(L14<>"",L14<TODAY()),"überfällig","offen")),"") | O14: =IF(OR(H14="N.I.O",H14="bed. OK"),COUNTIF($H$9:H14,"N.I.O")+COUNTIF($H$9:H14,"bed. OK"),"") | P14: Vorlage M 2.8 | Q14: =IF(H14="N.I.O",COUNTIF($H$9:H14,"N.I.O"),"")
A15: =IF(C15="","",COUNTA($C$9:C15)) | B15: Technischer Zustand | C15: Arbeiten Steuerung, Antriebe und Bedienpanel (HMI) zuverlässig, ohne wiederkehrende Fehlermeldungen? | D15: Do the control system, drives and operator panel (HMI) work reliably without recurring error messages? | E15: DIN 31051 | F15: 2 | N15: =IF(OR(H15="N.I.O",H15="bed. OK"),IF(M15="ja","erledigt",IF(AND(L15<>"",L15<TODAY()),"überfällig","offen")),"") | O15: =IF(OR(H15="N.I.O",H15="bed. OK"),COUNTIF($H$9:H15,"N.I.O")+COUNTIF($H$9:H15,"bed. OK"),"") | P15: NEU | Q15: =IF(H15="N.I.O",COUNTIF($H$9:H15,"N.I.O"),"")
A16: =IF(C16="","",COUNTA($C$9:C16)) | B16: Technischer Zustand | C16: Ist die Anlage frei von Auffälligkeiten wie Leckagen, ungewöhnlichen Geräuschen, Vibrationen oder Temperaturen (ggf. aus Zustandsüberwachung)? | D16: Is the machine free of abnormalities such as leaks, unusual noise, vibration or temperatures (from condition monitoring, if available)? | E16: DIN EN 13306 | F16: 2 | N16: =IF(OR(H16="N.I.O",H16="bed. OK"),IF(M16="ja","erledigt",IF(AND(L16<>"",L16<TODAY()),"überfällig","offen")),"") | O16: =IF(OR(H16="N.I.O",H16="bed. OK"),COUNTIF($H$9:H16,"N.I.O")+COUNTIF($H$9:H16,"bed. OK"),"") | P16: NEU | Q16: =IF(H16="N.I.O",COUNTIF($H$9:H16,"N.I.O"),"")
A17: =IF(C17="","",COUNTA($C$9:C17)) | B17: Technischer Zustand | C17: Sind Baujahr, Betriebsstunden und letzte Generalüberholung bekannt und dokumentiert? | D17: Are year of construction, operating hours and the last general overhaul known and documented? | E17: DIN EN 13306 | F17: 1 | N17: =IF(OR(H17="N.I.O",H17="bed. OK"),IF(M17="ja","erledigt",IF(AND(L17<>"",L17<TODAY()),"überfällig","offen")),"") | O17: =IF(OR(H17="N.I.O",H17="bed. OK"),COUNTIF($H$9:H17,"N.I.O")+COUNTIF($H$9:H17,"bed. OK"),"") | P17: NEU | Q17: =IF(H17="N.I.O",COUNTIF($H$9:H17,"N.I.O"),"")
A18: =IF(C18="","",COUNTA($C$9:C18)) | B18: Technischer Zustand | C18: Ist die Maschinen- bzw. Prozessfähigkeit (Cmk / Cpk) für die relevanten Merkmale nachgewiesen und stabil? | D18: Is machine / process capability (Cmk / Cpk) for the relevant characteristics proven and stable? | E18: IATF 9.1.1.1 | F18: 2 | N18: =IF(OR(H18="N.I.O",H18="bed. OK"),IF(M18="ja","erledigt",IF(AND(L18<>"",L18<TODAY()),"überfällig","offen")),"") | O18: =IF(OR(H18="N.I.O",H18="bed. OK"),COUNTIF($H$9:H18,"N.I.O")+COUNTIF($H$9:H18,"bed. OK"),"") | P18: NEU | Q18: =IF(H18="N.I.O",COUNTIF($H$9:H18,"N.I.O"),"")
A19: =IF(C19="","",COUNTA($C$9:C19)) | B19: Betriebsbereitschaft | C19: Ist die Anlage betriebsbereit und für die Produktion freigegeben – ohne Provisorien oder Überbrückungen? | D19: Is the machine ready for operation and released for production – without temporary fixes or bypasses? | E19: IATF 8.5.1.5 | F19: 2 | N19: =IF(OR(H19="N.I.O",H19="bed. OK"),IF(M19="ja","erledigt",IF(AND(L19<>"",L19<TODAY()),"überfällig","offen")),"") | O19: =IF(OR(H19="N.I.O",H19="bed. OK"),COUNTIF($H$9:H19,"N.I.O")+COUNTIF($H$9:H19,"bed. OK"),"") | P19: Vorlage A1 B18 (präzisiert) | Q19: =IF(H19="N.I.O",COUNTIF($H$9:H19,"N.I.O"),"")
A20: =IF(C20="","",COUNTA($C$9:C20)) | B20: Betriebsbereitschaft | C20: Gibt es eine festgelegte Vorgehensweise beim Rüsten (Rüstanweisung, Qualifikationsmatrix)? | D20: Is there a defined set-up procedure (set-up instruction, qualification matrix)? | E20: IATF 8.5.1.3 | F20: 1 | N20: =IF(OR(H20="N.I.O",H20="bed. OK"),IF(M20="ja","erledigt",IF(AND(L20<>"",L20<TODAY()),"überfällig","offen")),"") | O20: =IF(OR(H20="N.I.O",H20="bed. OK"),COUNTIF($H$9:H20,"N.I.O")+COUNTIF($H$9:H20,"bed. OK"),"") | P20: Vorlage M 3 | Q20: =IF(H20="N.I.O",COUNTIF($H$9:H20,"N.I.O"),"")
... A64: =IF(C64="","",COUNTA($C$9:C64)) | B64: Obsoleszenz & Herstellersupport | C64: Ist Fernwartung möglich bzw. sind alternative Dienstleister für die Anlage bekannt? | D64: Is remote service possible or are alternative service providers known for the machine? | E64: IATF 6.1.2.3 | F64: 1 | N64: =IF(OR(H64="N.I.O",H64="bed. OK"),IF(M64="ja","erledigt",IF(AND(L64<>"",L64<TODAY()),"überfällig","offen")),"") | O64: =IF(OR(H64="N.I.O",H64="bed. OK"),COUNTIF($H$9:H64,"N.I.O")+COUNTIF($H$9:H64,"bed. OK"),"") | P64: NEU | Q64: =IF(H64="N.I.O",COUNTIF($H$9:H64,"N.I.O"),"")
A65: =IF(C65="","",COUNTA($C$9:C65)) | B65: Sicherheit & Umwelt | C65: Sind die Sicherheitseinrichtungen an der Anlage vorhanden und wirksam (Schutzhauben, Schutztüren, Lichtgitter)? | D65: Are the safety devices on the machine present and effective (guards, safety doors, light curtains)? | E65: BetrSichV § 4 / § 6 | F65: 3 | G65: K.O. | N65: =IF(OR(H65="N.I.O",H65="bed. OK"),IF(M65="ja","erledigt",IF(AND(L65<>"",L65<TODAY()),"überfällig","offen")),"") | O65: =IF(OR(H65="N.I.O",H65="bed. OK"),COUNTIF($H$9:H65,"N.I.O")+COUNTIF($H$9:H65,"bed. OK"),"") | P65: Vorlage A1 B12 | Q65: =IF(H65="N.I.O",COUNTIF($H$9:H65,"N.I.O"),"")
A66: =IF(C66="","",COUNTA($C$9:C66)) | B66: Sicherheit & Umwelt | C66: Sind Not-Halt und Schutzeinrichtungen nachweislich in festgelegten Intervallen funktionsgeprüft? | D66: Are emergency stop and safety devices demonstrably function-tested at defined intervals? | E66: BetrSichV § 14 | F66: 3 | G66: K.O. | N66: =IF(OR(H66="N.I.O",H66="bed. OK"),IF(M66="ja","erledigt",IF(AND(L66<>"",L66<TODAY()),"überfällig","offen")),"") | O66: =IF(OR(H66="N.I.O",H66="bed. OK"),COUNTIF($H$9:H66,"N.I.O")+COUNTIF($H$9:H66,"bed. OK"),"") | P66: NEU | Q66: =IF(H66="N.I.O",COUNTIF($H$9:H66,"N.I.O"),"")
A67: =IF(C67="","",COUNTA($C$9:C67)) | B67: Sicherheit & Umwelt | C67: Liegen Gefährdungsbeurteilung und Betriebsanweisung aktuell vor; wurde die CE-Konformität nach wesentlichen Veränderungen bewertet? | D67: Are risk assessment and operating instructions up to date; was CE conformity assessed after substantial modifications? | E67: ArbSchG § 5 / BetrSichV § 3 | F67: 3 | G67: K.O. | N67: =IF(OR(H67="N.I.O",H67="bed. OK"),IF(M67="ja","erledigt",IF(AND(L67<>"",L67<TODAY()),"überfällig","offen")),"") | O67: =IF(OR(H67="N.I.O",H67="bed. OK"),COUNTIF($H$9:H67,"N.I.O")+COUNTIF($H$9:H67,"bed. OK"),"") | P67: NEU | Q67: =IF(H67="N.I.O",COUNTIF($H$9:H67,"N.I.O"),"")
A68: =IF(C68="","",COUNTA($C$9:C68)) | B68: Sicherheit & Umwelt | C68: Werden wiederkehrende Prüfungen fristgerecht durchgeführt (z. B. DGUV V3, Druckgeräte, Hebezeuge)? | D68: Are recurring inspections carried out on time (e.g. DGUV V3, pressure equipment, lifting gear)? | E68: BetrSichV § 14 / DGUV V3 | F68: 3 | G68: K.O. | N68: =IF(OR(H68="N.I.O",H68="bed. OK"),IF(M68="ja","erledigt",IF(AND(L68<>"",L68<TODAY()),"überfällig","offen")),"") | O68: =IF(OR(H68="N.I.O",H68="bed. OK"),COUNTIF($H$9:H68,"N.I.O")+COUNTIF($H$9:H68,"bed. OK"),"") | P68: NEU | Q68: =IF(H68="N.I.O",COUNTIF($H$9:H68,"N.I.O"),"")
A69: =IF(C69="","",COUNTA($C$9:C69)) | B69: Sicherheit & Umwelt | C69: Ist das Freischalten und Sichern gegen Wiedereinschalten anlagenspezifisch beschrieben (LOTO, Restenergien)? | D69: Is isolation and securing against restart described for this machine (LOTO, residual energies)? | E69: BetrSichV § 10 | F69: 2 | N69: =IF(OR(H69="N.I.O",H69="bed. OK"),IF(M69="ja","erledigt",IF(AND(L69<>"",L69<TODAY()),"überfällig","offen")),"") | O69: =IF(OR(H69="N.I.O",H69="bed. OK"),COUNTIF($H$9:H69,"N.I.O")+COUNTIF($H$9:H69,"bed. OK"),"") | P69: NEU | Q69: =IF(H69="N.I.O",COUNTIF($H$9:H69,"N.I.O"),"")
A70: =IF(C70="","",COUNTA($C$9:C70)) | B70: Sicherheit & Umwelt | C70: Sind Umweltaspekte beherrscht (keine Leckagen, Auffangwannen, Umgang mit wassergefährdenden Stoffen)? | D70: Are environmental aspects under control (no leaks, drip trays, handling of water-polluting substances)? | E70: AwSV / ISO 14001 | F70: 2 | N70: =IF(OR(H70="N.I.O",H70="bed. OK"),IF(M70="ja","erledigt",IF(AND(L70<>"",L70<TODAY()),"überfällig","offen")),"") | O70: =IF(OR(H70="N.I.O",H70="bed. OK"),COUNTIF($H$9:H70,"N.I.O")+COUNTIF($H$9:H70,"bed. OK"),"") | P70: NEU | Q70: =IF(H70="N.I.O",COUNTIF($H$9:H70,"N.I.O"),"")
A71: =IF(C71="","",COUNTA($C$9:C71)) | B71: Sicherheit & Umwelt | C71: Ist der Brandschutz an der Anlage gewährleistet (Löscheinrichtung, Absaugung, Filterreinigung)? | D71: Is fire protection at the machine ensured (extinguishing system, extraction, filter cleaning)? | E71: ASR A2.2 | F71: 1 | N71: =IF(OR(H71="N.I.O",H71="bed. OK"),IF(M71="ja","erledigt",IF(AND(L71<>"",L71<TODAY()),"überfällig","offen")),"") | O71: =IF(OR(H71="N.I.O",H71="bed. OK"),COUNTIF($H$9:H71,"N.I.O")+COUNTIF($H$9:H71,"bed. OK"),"") | P71: NEU | Q71: =IF(H71="N.I.O",COUNTIF($H$9:H71,"N.I.O"),"")
A72: =IF(C72="","",COUNTA($C$9:C72)) | B72: Produktionsrelevanz & Engpass | C72: Hat die Organisation ermittelt, ob die Anlage für Schlüsselprozesse notwendig ist (Schlüssel- / Engpassanlage)? | D72: Has the organisation determined whether the machine is necessary for key processes (key / bottleneck machine)? | E72: IATF 8.5.1.5 | F72: 2 | N72: =IF(OR(H72="N.I.O",H72="bed. OK"),IF(M72="ja","erledigt",IF(AND(L72<>"",L72<TODAY()),"überfällig","offen")),"") | O72: =IF(OR(H72="N.I.O",H72="bed. OK"),COUNTIF($H$9:H72,"N.I.O")+COUNTIF($H$9:H72,"bed. OK"),"") | P72: Vorlage A1 B13 (Teil) | Q72: =IF(H72="N.I.O",COUNTIF($H$9:H72,"N.I.O"),"")
A73: =IF(C73="","",COUNTA($C$9:C73)) | B73: Produktionsrelevanz & Engpass | C73: Ist die Anlage einer Kritikalitätsklasse (A / B / C) zugeordnet und ist die IH-Strategie daraus abgeleitet? | D73: Is the machine assigned to a criticality class (A / B / C) and is the maintenance strategy derived from it? | E73: DIN EN 13306 | F73: 2 | N73: =IF(OR(H73="N.I.O",H73="bed. OK"),IF(M73="ja","erledigt",IF(AND(L73<>"",L73<TODAY()),"überfällig","offen")),"") | O73: =IF(OR(H73="N.I.O",H73="bed. OK"),COUNTIF($H$9:H73,"N.I.O")+COUNTIF($H$9:H73,"bed. OK"),"") | P73: NEU | Q73: =IF(H73="N.I.O",COUNTIF($H$9:H73,"N.I.O"),"")
A74: =IF(C74="","",COUNTA($C$9:C74)) | B74: Produktionsrelevanz & Engpass | C74: Ist die Produktionsrelevanz dokumentiert (Kunden, Teilenummern, Umsatz- bzw. Stückzahlanteil)? | D74: Is the production relevance documented (customers, part numbers, share of sales / volume)? | E74: IATF 6.1.2.3 | F74: 1 | N74: =IF(OR(H74="N.I.O",H74="bed. OK"),IF(M74="ja","erledigt",IF(AND(L74<>"",L74<TODAY()),"überfällig","offen")),"") | O74: =IF(OR(H74="N.I.O",H74="bed. OK"),COUNTIF($H$9:H74,"N.I.O")+COUNTIF($H$9:H74,"bed. OK"),"") | P74: NEU | Q74: =IF(H74="N.I.O",COUNTIF($H$9:H74,"N.I.O"),"")
A75: =IF(C75="","",COUNTA($C$9:C75)) | B75: Produktionsrelevanz & Engpass | C75: Sind besondere Merkmale bzw. Sonderprozesse auf der Anlage bekannt und ist der IH-Umfang darauf abgestimmt? | D75: Are special characteristics / special processes on the machine known and is maintenance scope aligned with them? | E75: IATF 8.3.3.3 | F75: 1 | N75: =IF(OR(H75="N.I.O",H75="bed. OK"),IF(M75="ja","erledigt",IF(AND(L75<>"",L75<TODAY()),"überfällig","offen")),"") | O75: =IF(OR(H75="N.I.O",H75="bed. OK"),COUNTIF($H$9:H75,"N.I.O")+COUNTIF($H$9:H75,"bed. OK"),"") | P75: NEU | Q75: =IF(H75="N.I.O",COUNTIF($H$9:H75,"N.I.O"),"")
A76: =IF(C76="","",COUNTA($C$9:C76)) | B76: Produktionsrelevanz & Engpass | C76: Ist die Kapazitätsauslastung bekannt und gibt es Reserve, um Ausfälle nachzuholen? | D76: Is the capacity utilisation known and is there reserve capacity to recover from breakdowns? | E76: IATF 6.1.2.3 | F76: 1 | N76: =IF(OR(H76="N.I.O",H76="bed. OK"),IF(M76="ja","erledigt",IF(AND(L76<>"",L76<TODAY()),"überfällig","offen")),"") | O76: =IF(OR(H76="N.I.O",H76="bed. OK"),COUNTIF($H$9:H76,"N.I.O")+COUNTIF($H$9:H76,"bed. OK"),"") | P76: NEU | Q76: =IF(H76="N.I.O",COUNTIF($H$9:H76,"N.I.O"),"")
A77: =IF(C77="","",COUNTA($C$9:C77)) | B77: Ausweichfertigung & Notfall | C77: Gibt es eine Ausweichmöglichkeit (intern / extern) mit ausreichender Kapazität? | D77: Is there an alternative production option (internal / external) with sufficient capacity? | E77: IATF 6.1.2.3 | F77: 2 | N77: =IF(OR(H77="N.I.O",H77="bed. OK"),IF(M77="ja","erledigt",IF(AND(L77<>"",L77<TODAY()),"überfällig","offen")),"") | O77: =IF(OR(H77="N.I.O",H77="bed. OK"),COUNTIF($H$9:H77,"N.I.O")+COUNTIF($H$9:H77,"bed. OK"),"") | P77: NEU | Q77: =IF(H77="N.I.O",COUNTIF($H$9:H77,"N.I.O"),"")
A78: =IF(C78="","",COUNTA($C$9:C78)) | B78: Ausweichfertigung & Notfall | C78: Ist die Ausweichfertigung vom Kunden freigegeben (PPAP / PPF) und ist die Umstellzeit bekannt? | D78: Is the alternative production approved by the customer (PPAP / PPF) and is the changeover time known? | E78: IATF 8.5.6.1.1 | F78: 2 | N78: =IF(OR(H78="N.I.O",H78="bed. OK"),IF(M78="ja","erledigt",IF(AND(L78<>"",L78<TODAY()),"überfällig","offen")),"") | O78: =IF(OR(H78="N.I.O",H78="bed. OK"),COUNTIF($H$9:H78,"N.I.O")+COUNTIF($H$9:H78,"bed. OK"),"") | P78: NEU | Q78: =IF(H78="N.I.O",COUNTIF($H$9:H78,"N.I.O"),"")
A79: =IF(C79="","",COUNTA($C$9:C79)) | B79: Ausweichfertigung & Notfall | C79: Gibt es einen Notfallplan für den Ausfall dieser Anlage? | D79: Is there a contingency plan for a breakdown of this machine? | E79: IATF 6.1.2.3 | F79: 3 | G79: K.O. | N79: =IF(OR(H79="N.I.O",H79="bed. OK"),IF(M79="ja","erledigt",IF(AND(L79<>"",L79<TODAY()),"überfällig","offen")),"") | O79: =IF(OR(H79="N.I.O",H79="bed. OK"),COUNTIF($H$9:H79,"N.I.O")+COUNTIF($H$9:H79,"bed. OK"),"") | P79: NEU | Q79: =IF(H79="N.I.O",COUNTIF($H$9:H79,"N.I.O"),"")
A80: =IF(C80="","",COUNTA($C$9:C80)) | B80: Ausweichfertigung & Notfall | C80: Gibt es einen Wiederanlaufplan mit Zielzeit, Zuständigkeiten und Notfallkontakten (Hersteller, Dienstleister)? | D80: Is there a restart plan with target time, responsibilities and emergency contacts (manufacturer, service providers)? | E80: IATF 6.1.2.3 | F80: 2 | N80: =IF(OR(H80="N.I.O",H80="bed. OK"),IF(M80="ja","erledigt",IF(AND(L80<>"",L80<TODAY()),"überfällig","offen")),"") | O80: =IF(OR(H80="N.I.O",H80="bed. OK"),COUNTIF($H$9:H80,"N.I.O")+COUNTIF($H$9:H80,"bed. OK"),"") | P80: NEU | Q80: =IF(H80="N.I.O",COUNTIF($H$9:H80,"N.I.O"),"")
A81: =IF(C81="","",COUNTA($C$9:C81)) | B81: Ausweichfertigung & Notfall | C81: Wird der Notfallplan regelmäßig (mind. jährlich) getestet bzw. bewertet und aktualisiert? | D81: Is the contingency plan tested / reviewed and updated regularly (at least annually)? | E81: IATF 6.1.2.3 | F81: 1 | N81: =IF(OR(H81="N.I.O",H81="bed. OK"),IF(M81="ja","erledigt",IF(AND(L81<>"",L81<TODAY()),"überfällig","offen")),"") | O81: =IF(OR(H81="N.I.O",H81="bed. OK"),COUNTIF($H$9:H81,"N.I.O")+COUNTIF($H$9:H81,"bed. OK"),"") | P81: NEU | Q81: =IF(H81="N.I.O",COUNTIF($H$9:H81,"N.I.O"),"")
A82: =IF(C82="","",COUNTA($C$9:C82)) | B82: Ausweichfertigung & Notfall | C82: Ist ein Sicherheitsbestand an Fertigteilen bzw. ein Puffer für die erwartete Ausfallzeit festgelegt? | D82: Is a safety stock of finished parts or a buffer for the expected downtime defined? | E82: IATF 6.1.2.3 | F82: 1 | N82: =IF(OR(H82="N.I.O",H82="bed. OK"),IF(M82="ja","erledigt",IF(AND(L82<>"",L82<TODAY()),"überfällig","offen")),"") | O82: =IF(OR(H82="N.I.O",H82="bed. OK"),COUNTIF($H$9:H82,"N.I.O")+COUNTIF($H$9:H82,"bed. OK"),"") | P82: NEU | Q82: =IF(H82="N.I.O",COUNTIF($H$9:H82,"N.I.O"),"")
A83: =IF(C83="","",COUNTA($C$9:C83)) | B83: Ausweichfertigung & Notfall | C83: Sind IT- und Cyberrisiken berücksichtigt (Netzwerkanbindung, Virenschutz, Wiederherstellung)? | D83: Are IT and cyber risks considered (network connection, virus protection, recovery)? | E83: IATF 6.1.2.3 | F83: 1 | N83: =IF(OR(H83="N.I.O",H83="bed. OK"),IF(M83="ja","erledigt",IF(AND(L83<>"",L83<TODAY()),"überfällig","offen")),"") | O83: =IF(OR(H83="N.I.O",H83="bed. OK"),COUNTIF($H$9:H83,"N.I.O")+COUNTIF($H$9:H83,"bed. OK"),"") | P83: NEU | Q83: =IF(H83="N.I.O",COUNTIF($H$9:H83,"N.I.O"),"")
A84: =IF(C84="","",COUNTA($C$9:C84)) | B84: Dokumentation & Software | C84: Wird die technische Dokumentation verwaltet (Stücklisten, Maschinenbeschreibung, technische Zeichnungen)? | D84: Is the technical documentation managed (parts lists, machine description, technical drawings)? | E84: IATF 7.5 | F84: 2 | N84: =IF(OR(H84="N.I.O",H84="bed. OK"),IF(M84="ja","erledigt",IF(AND(L84<>"",L84<TODAY()),"überfällig","offen")),"") | O84: =IF(OR(H84="N.I.O",H84="bed. OK"),COUNTIF($H$9:H84,"N.I.O")+COUNTIF($H$9:H84,"bed. OK"),"") | P84: Vorlage M 2.4 / A1 B17 | Q84: =IF(H84="N.I.O",COUNTIF($H$9:H84,"N.I.O"),"")
...

Sheet Maßnahmen
A1: Maßnahmenplan – Anlagenzustandsanalyse
A2: Füllt sich automatisch aus allen Prüfpunkten mit N.I.O oder bed. OK. Eingaben bitte im Blatt „Audit“ machen.
A4: Nr. | B4: Punkt | C4: Kapitel | D4: Check-Punkt | E4: Bewertung | F4: Befund / Maßnahme | G4: Verantwortlich | H4: Termin | I4: Status
A5: =IF(1<=COUNT(Aud_MNr),1,"") | B5: =IFERROR(IF($A5="","",INDEX(Aud_Nr,MATCH($A5,Aud_MNr,0))),"") | C5: =IFERROR(IF($A5="","",INDEX(Aud_Kapitel,MATCH($A5,Aud_MNr,0))),"") | D5: =IFERROR(IF($A5="","",INDEX(Aud_Punkt,MATCH($A5,Aud_MNr,0))),"") | E5: =IFERROR(IF($A5="","",INDEX(Aud_Bew,MATCH($A5,Aud_MNr,0))),"") | F5: =IFERROR(IF($A5="","",IF(INDEX(Aud_Massn,MATCH($A5,Aud_MNr,0))="","",INDEX(Aud_Massn,MATCH($A5,Aud_MNr,0)))),"") | G5: =IFERROR(IF($A5="","",IF(INDEX(Aud_Verantw,MATCH($A5,Aud_MNr,0))="","",INDEX(Aud_Verantw,MATCH($A5,Aud_MNr,0)))),"") | H5: =IFERROR(IF($A5="","",IF(INDEX(Aud_Termin,MATCH($A5,Aud_MNr,0))="","",INDEX(Aud_Termin,MATCH($A5,Aud_MNr,0)))),"") | I5: =IFERROR(IF($A5="","",INDEX(Aud_Status,MATCH($A5,Aud_MNr,0))),"")
A6: =IF(2<=COUNT(Aud_MNr),2,"") | B6: =IFERROR(IF($A6="","",INDEX(Aud_Nr,MATCH($A6,Aud_MNr,0))),"") | C6: =IFERROR(IF($A6="","",INDEX(Aud_Kapitel,MATCH($A6,Aud_MNr,0))),"") | D6: =IFERROR(IF($A6="","",INDEX(Aud_Punkt,MATCH($A6,Aud_MNr,0))),"") | E6: =IFERROR(IF($A6="","",INDEX(Aud_Bew,MATCH($A6,Aud_MNr,0))),"") | F6: =IFERROR(IF($A6="","",IF(INDEX(Aud_Massn,MATCH($A6,Aud_MNr,0))="","",INDEX(Aud_Massn,MATCH($A6,Aud_MNr,0)))),"") | G6: =IFERROR(IF($A6="","",IF(INDEX(Aud_Verantw,MATCH($A6,Aud_MNr,0))="","",INDEX(Aud_Verantw,MATCH($A6,Aud_MNr,0)))),"") | H6: =IFERROR(IF($A6="","",IF(INDEX(Aud_Termin,MATCH($A6,Aud_MNr,0))="","",INDEX(Aud_Termin,MATCH($A6,Aud_MNr,0)))),"") | I6: =IFERROR(IF($A6="","",INDEX(Aud_Status,MATCH($A6,Aud_MNr,0))),"")
A7: =IF(3<=COUNT(Aud_MNr),3,"") | B7: =IFERROR(IF($A7="","",INDEX(Aud_Nr,MATCH($A7,Aud_MNr,0))),"") | C7: =IFERROR(IF($A7="","",INDEX(Aud_Kapitel,MATCH($A7,Aud_MNr,0))),"") | D7: =IFERROR(IF($A7="","",INDEX(Aud_Punkt,MATCH($A7,Aud_MNr,0))),"") | E7: =IFERROR(IF($A7="","",INDEX(Aud_Bew,MATCH($A7,Aud_MNr,0))),"") | F7: =IFERROR(IF($A7="","",IF(INDEX(Aud_Massn,MATCH($A7,Aud_MNr,0))="","",INDEX(Aud_Massn,MATCH($A7,Aud_MNr,0)))),"") | G7: =IFERROR(IF($A7="","",IF(INDEX(Aud_Verantw,MATCH($A7,Aud_MNr,0))="","",INDEX(Aud_Verantw,MATCH($A7,Aud_MNr,0)))),"") | H7: =IFERROR(IF($A7="","",IF(INDEX(Aud_Termin,MATCH($A7,Aud_MNr,0))="","",INDEX(Aud_Termin,MATCH($A7,Aud_MNr,0)))),"") | I7: =IFERROR(IF($A7="","",INDEX(Aud_Status,MATCH($A7,Aud_MNr,0))),"")
A8: =IF(4<=COUNT(Aud_MNr),4,"") | B8: =IFERROR(IF($A8="","",INDEX(Aud_Nr,MATCH($A8,Aud_MNr,0))),"") | C8: =IFERROR(IF($A8="","",INDEX(Aud_Kapitel,MATCH($A8,Aud_MNr,0))),"") | D8: =IFERROR(IF($A8="","",INDEX(Aud_Punkt,MATCH($A8,Aud_MNr,0))),"") | E8: =IFERROR(IF($A8="","",INDEX(Aud_Bew,MATCH($A8,Aud_MNr,0))),"") | F8: =IFERROR(IF($A8="","",IF(INDEX(Aud_Massn,MATCH($A8,Aud_MNr,0))="","",INDEX(Aud_Massn,MATCH($A8,Aud_MNr,0)))),"") | G8: =IFERROR(IF($A8="","",IF(INDEX(Aud_Verantw,MATCH($A8,Aud_MNr,0))="","",INDEX(Aud_Verantw,MATCH($A8,Aud_MNr,0)))),"") | H8: =IFERROR(IF($A8="","",IF(INDEX(Aud_Termin,MATCH($A8,Aud_MNr,0))="","",INDEX(Aud_Termin,MATCH($A8,Aud_MNr,0)))),"") | I8: =IFERROR(IF($A8="","",INDEX(Aud_Status,MATCH($A8,Aud_MNr,0))),"")
A9: =IF(5<=COUNT(Aud_MNr),5,"") | B9: =IFERROR(IF($A9="","",INDEX(Aud_Nr,MATCH($A9,Aud_MNr,0))),"") | C9: =IFERROR(IF($A9="","",INDEX(Aud_Kapitel,MATCH($A9,Aud_MNr,0))),"") | D9: =IFERROR(IF($A9="","",INDEX(Aud_Punkt,MATCH($A9,Aud_MNr,0))),"") | E9: =IFERROR(IF($A9="","",INDEX(Aud_Bew,MATCH($A9,Aud_MNr,0))),"") | F9: =IFERROR(IF($A9="","",IF(INDEX(Aud_Massn,MATCH($A9,Aud_MNr,0))="","",INDEX(Aud_Massn,MATCH($A9,Aud_MNr,0)))),"") | G9: =IFERROR(IF($A9="","",IF(INDEX(Aud_Verantw,MATCH($A9,Aud_MNr,0))="","",INDEX(Aud_Verantw,MATCH($A9,Aud_MNr,0)))),"") | H9: =IFERROR(IF($A9="","",IF(INDEX(Aud_Termin,MATCH($A9,Aud_MNr,0))="","",INDEX(Aud_Termin,MATCH($A9,Aud_MNr,0)))),"") | I9: =IFERROR(IF($A9="","",INDEX(Aud_Status,MATCH($A9,Aud_MNr,0))),"")
A10: =IF(6<=COUNT(Aud_MNr),6,"") | B10: =IFERROR(IF($A10="","",INDEX(Aud_Nr,MATCH($A10,Aud_MNr,0))),"") | C10: =IFERROR(IF($A10="","",INDEX(Aud_Kapitel,MATCH($A10,Aud_MNr,0))),"") | D10: =IFERROR(IF($A10="","",INDEX(Aud_Punkt,MATCH($A10,Aud_MNr,0))),"") | E10: =IFERROR(IF($A10="","",INDEX(Aud_Bew,MATCH($A10,Aud_MNr,0))),"") | F10: =IFERROR(IF($A10="","",IF(INDEX(Aud_Massn,MATCH($A10,Aud_MNr,0))="","",INDEX(Aud_Massn,MATCH($A10,Aud_MNr,0)))),"") | G10: =IFERROR(IF($A10="","",IF(INDEX(Aud_Verantw,MATCH($A10,Aud_MNr,0))="","",INDEX(Aud_Verantw,MATCH($A10,Aud_MNr,0)))),"") | H10: =IFERROR(IF($A10="","",IF(INDEX(Aud_Termin,MATCH($A10,Aud_MNr,0))="","",INDEX(Aud_Termin,MATCH($A10,Aud_MNr,0)))),"") | I10: =IFERROR(IF($A10="","",INDEX(Aud_Status,MATCH($A10,Aud_MNr,0))),"")
A11: =IF(7<=COUNT(Aud_MNr),7,"") | B11: =IFERROR(IF($A11="","",INDEX(Aud_Nr,MATCH($A11,Aud_MNr,0))),"") | C11: =IFERROR(IF($A11="","",INDEX(Aud_Kapitel,MATCH($A11,Aud_MNr,0))),"") | D11: =IFERROR(IF($A11="","",INDEX(Aud_Punkt,MATCH($A11,Aud_MNr,0))),"") | E11: =IFERROR(IF($A11="","",INDEX(Aud_Bew,MATCH($A11,Aud_MNr,0))),"") | F11: =IFERROR(IF($A11="","",IF(INDEX(Aud_Massn,MATCH($A11,Aud_MNr,0))="","",INDEX(Aud_Massn,MATCH($A11,Aud_MNr,0)))),"") | G11: =IFERROR(IF($A11="","",IF(INDEX(Aud_Verantw,MATCH($A11,Aud_MNr,0))="","",INDEX(Aud_Verantw,MATCH($A11,Aud_MNr,0)))),"") | H11: =IFERROR(IF($A11="","",IF(INDEX(Aud_Termin,MATCH($A11,Aud_MNr,0))="","",INDEX(Aud_Termin,MATCH($A11,Aud_MNr,0)))),"") | I11: =IFERROR(IF($A11="","",INDEX(Aud_Status,MATCH($A11,Aud_MNr,0))),"")
A12: =IF(8<=COUNT(Aud_MNr),8,"") | B12: =IFERROR(IF($A12="","",INDEX(Aud_Nr,MATCH($A12,Aud_MNr,0))),"") | C12: =IFERROR(IF($A12="","",INDEX(Aud_Kapitel,MATCH($A12,Aud_MNr,0))),"") | D12: =IFERROR(IF($A12="","",INDEX(Aud_Punkt,MATCH($A12,Aud_MNr,0))),"") | E12: =IFERROR(IF($A12="","",INDEX(Aud_Bew,MATCH($A12,Aud_MNr,0))),"") | F12: =IFERROR(IF($A12="","",IF(INDEX(Aud_Massn,MATCH($A12,Aud_MNr,0))="","",INDEX(Aud_Massn,MATCH($A12,Aud_MNr,0)))),"") | G12: =IFERROR(IF($A12="","",IF(INDEX(Aud_Verantw,MATCH($A12,Aud_MNr,0))="","",INDEX(Aud_Verantw,MATCH($A12,Aud_MNr,0)))),"") | H12: =IFERROR(IF($A12="","",IF(INDEX(Aud_Termin,MATCH($A12,Aud_MNr,0))="","",INDEX(Aud_Termin,MATCH($A12,Aud_MNr,0)))),"") | I12: =IFERROR(IF($A12="","",INDEX(Aud_Status,MATCH($A12,Aud_MNr,0))),"")
A13: =IF(9<=COUNT(Aud_MNr),9,"") | B13: =IFERROR(IF($A13="","",INDEX(Aud_Nr,MATCH($A13,Aud_MNr,0))),"") | C13: =IFERROR(IF($A13="","",INDEX(Aud_Kapitel,MATCH($A13,Aud_MNr,0))),"") | D13: =IFERROR(IF($A13="","",INDEX(Aud_Punkt,MATCH($A13,Aud_MNr,0))),"") | E13: =IFERROR(IF($A13="","",INDEX(Aud_Bew,MATCH($A13,Aud_MNr,0))),"") | F13: =IFERROR(IF($A13="","",IF(INDEX(Aud_Massn,MATCH($A13,Aud_MNr,0))="","",INDEX(Aud_Massn,MATCH($A13,Aud_MNr,0)))),"") | G13: =IFERROR(IF($A13="","",IF(INDEX(Aud_Verantw,MATCH($A13,Aud_MNr,0))="","",INDEX(Aud_Verantw,MATCH($A13,Aud_MNr,0)))),"") | H13: =IFERROR(IF($A13="","",IF(INDEX(Aud_Termin,MATCH($A13,Aud_MNr,0))="","",INDEX(Aud_Termin,MATCH($A13,Aud_MNr,0)))),"") | I13: =IFERROR(IF($A13="","",INDEX(Aud_Status,MATCH($A13,Aud_MNr,0))),"")
A14: =IF(10<=COUNT(Aud_MNr),10,"") | B14: =IFERROR(IF($A14="","",INDEX(Aud_Nr,MATCH($A14,Aud_MNr,0))),"") | C14: =IFERROR(IF($A14="","",INDEX(Aud_Kapitel,MATCH($A14,Aud_MNr,0))),"") | D14: =IFERROR(IF($A14="","",INDEX(Aud_Punkt,MATCH($A14,Aud_MNr,0))),"") | E14: =IFERROR(IF($A14="","",INDEX(Aud_Bew,MATCH($A14,Aud_MNr,0))),"") | F14: =IFERROR(IF($A14="","",IF(INDEX(Aud_Massn,MATCH($A14,Aud_MNr,0))="","",INDEX(Aud_Massn,MATCH($A14,Aud_MNr,0)))),"") | G14: =IFERROR(IF($A14="","",IF(INDEX(Aud_Verantw,MATCH($A14,Aud_MNr,0))="","",INDEX(Aud_Verantw,MATCH($A14,Aud_MNr,0)))),"") | H14: =IFERROR(IF($A14="","",IF(INDEX(Aud_Termin,MATCH($A14,Aud_MNr,0))="","",INDEX(Aud_Termin,MATCH($A14,Aud_MNr,0)))),"") | I14: =IFERROR(IF($A14="","",INDEX(Aud_Status,MATCH($A14,Aud_MNr,0))),"")
A15: =IF(11<=COUNT(Aud_MNr),11,"") | B15: =IFERROR(IF($A15="","",INDEX(Aud_Nr,MATCH($A15,Aud_MNr,0))),"") | C15: =IFERROR(IF($A15="","",INDEX(Aud_Kapitel,MATCH($A15,Aud_MNr,0))),"") | D15: =IFERROR(IF($A15="","",INDEX(Aud_Punkt,MATCH($A15,Aud_MNr,0))),"") | E15: =IFERROR(IF($A15="","",INDEX(Aud_Bew,MATCH($A15,Aud_MNr,0))),"") | F15: =IFERROR(IF($A15="","",IF(INDEX(Aud_Massn,MATCH($A15,Aud_MNr,0))="","",INDEX(Aud_Massn,MATCH($A15,Aud_MNr,0)))),"") | G15: =IFERROR(IF($A15="","",IF(INDEX(Aud_Verantw,MATCH($A15,Aud_MNr,0))="","",INDEX(Aud_Verantw,MATCH($A15,Aud_MNr,0)))),"") | H15: =IFERROR(IF($A15="","",IF(INDEX(Aud_Termin,MATCH($A15,Aud_MNr,0))="","",INDEX(Aud_Termin,MATCH($A15,Aud_MNr,0)))),"") | I15: =IFERROR(IF($A15="","",INDEX(Aud_Status,MATCH($A15,Aud_MNr,0))),"")
A16: =IF(12<=COUNT(Aud_MNr),12,"") | B16: =IFERROR(IF($A16="","",INDEX(Aud_Nr,MATCH($A16,Aud_MNr,0))),"") | C16: =IFERROR(IF($A16="","",INDEX(Aud_Kapitel,MATCH($A16,Aud_MNr,0))),"") | D16: =IFERROR(IF($A16="","",INDEX(Aud_Punkt,MATCH($A16,Aud_MNr,0))),"") | E16: =IFERROR(IF($A16="","",INDEX(Aud_Bew,MATCH($A16,Aud_MNr,0))),"") | F16: =IFERROR(IF($A16="","",IF(INDEX(Aud_Massn,MATCH($A16,Aud_MNr,0))="","",INDEX(Aud_Massn,MATCH($A16,Aud_MNr,0)))),"") | G16: =IFERROR(IF($A16="","",IF(INDEX(Aud_Verantw,MATCH($A16,Aud_MNr,0))="","",INDEX(Aud_Verantw,MATCH($A16,Aud_MNr,0)))),"") | H16: =IFERROR(IF($A16="","",IF(INDEX(Aud_Termin,MATCH($A16,Aud_MNr,0))="","",INDEX(Aud_Termin,MATCH($A16,Aud_MNr,0)))),"") | I16: =IFERROR(IF($A16="","",INDEX(Aud_Status,MATCH($A16,Aud_MNr,0))),"")
A17: =IF(13<=COUNT(Aud_MNr),13,"") | B17: =IFERROR(IF($A17="","",INDEX(Aud_Nr,MATCH($A17,Aud_MNr,0))),"") | C17: =IFERROR(IF($A17="","",INDEX(Aud_Kapitel,MATCH($A17,Aud_MNr,0))),"") | D17: =IFERROR(IF($A17="","",INDEX(Aud_Punkt,MATCH($A17,Aud_MNr,0))),"") | E17: =IFERROR(IF($A17="","",INDEX(Aud_Bew,MATCH($A17,Aud_MNr,0))),"") | F17: =IFERROR(IF($A17="","",IF(INDEX(Aud_Massn,MATCH($A17,Aud_MNr,0))="","",INDEX(Aud_Massn,MATCH($A17,Aud_MNr,0)))),"") | G17: =IFERROR(IF($A17="","",IF(INDEX(Aud_Verantw,MATCH($A17,Aud_MNr,0))="","",INDEX(Aud_Verantw,MATCH($A17,Aud_MNr,0)))),"") | H17: =IFERROR(IF($A17="","",IF(INDEX(Aud_Termin,MATCH($A17,Aud_MNr,0))="","",INDEX(Aud_Termin,MATCH($A17,Aud_MNr,0)))),"") | I17: =IFERROR(IF($A17="","",INDEX(Aud_Status,MATCH($A17,Aud_MNr,0))),"")
A18: =IF(14<=COUNT(Aud_MNr),14,"") | B18: =IFERROR(IF($A18="","",INDEX(Aud_Nr,MATCH($A18,Aud_MNr,0))),"") | C18: =IFERROR(IF($A18="","",INDEX(Aud_Kapitel,MATCH($A18,Aud_MNr,0))),"") | D18: =IFERROR(IF($A18="","",INDEX(Aud_Punkt,MATCH($A18,Aud_MNr,0))),"") | E18: =IFERROR(IF($A18="","",INDEX(Aud_Bew,MATCH($A18,Aud_MNr,0))),"") | F18: =IFERROR(IF($A18="","",IF(INDEX(Aud_Massn,MATCH($A18,Aud_MNr,0))="","",INDEX(Aud_Massn,MATCH($A18,Aud_MNr,0)))),"") | G18: =IFERROR(IF($A18="","",IF(INDEX(Aud_Verantw,MATCH($A18,Aud_MNr,0))="","",INDEX(Aud_Verantw,MATCH($A18,Aud_MNr,0)))),"") | H18: =IFERROR(IF($A18="","",IF(INDEX(Aud_Termin,MATCH($A18,Aud_MNr,0))="","",INDEX(Aud_Termin,MATCH($A18,Aud_MNr,0)))),"") | I18: =IFERROR(IF($A18="","",INDEX(Aud_Status,MATCH($A18,Aud_MNr,0))),"")
A19: =IF(15<=COUNT(Aud_MNr),15,"") | B19: =IFERROR(IF($A19="","",INDEX(Aud_Nr,MATCH($A19,Aud_MNr,0))),"") | C19: =IFERROR(IF($A19="","",INDEX(Aud_Kapitel,MATCH($A19,Aud_MNr,0))),"") | D19: =IFERROR(IF($A19="","",INDEX(Aud_Punkt,MATCH($A19,Aud_MNr,0))),"") | E19: =IFERROR(IF($A19="","",INDEX(Aud_Bew,MATCH($A19,Aud_MNr,0))),"") | F19: =IFERROR(IF($A19="","",IF(INDEX(Aud_Massn,MATCH($A19,Aud_MNr,0))="","",INDEX(Aud_Massn,MATCH($A19,Aud_MNr,0)))),"") | G19: =IFERROR(IF($A19="","",IF(INDEX(Aud_Verantw,MATCH($A19,Aud_MNr,0))="","",INDEX(Aud_Verantw,MATCH($A19,Aud_MNr,0)))),"") | H19: =IFERROR(IF($A19="","",IF(INDEX(Aud_Termin,MATCH($A19,Aud_MNr,0))="","",INDEX(Aud_Termin,MATCH($A19,Aud_MNr,0)))),"") | I19: =IFERROR(IF($A19="","",INDEX(Aud_Status,MATCH($A19,Aud_MNr,0))),"")
A20: =IF(16<=COUNT(Aud_MNr),16,"") | B20: =IFERROR(IF($A20="","",INDEX(Aud_Nr,MATCH($A20,Aud_MNr,0))),"") | C20: =IFERROR(IF($A20="","",INDEX(Aud_Kapitel,MATCH($A20,Aud_MNr,0))),"") | D20: =IFERROR(IF($A20="","",INDEX(Aud_Punkt,MATCH($A20,Aud_MNr,0))),"") | E20: =IFERROR(IF($A20="","",INDEX(Aud_Bew,MATCH($A20,Aud_MNr,0))),"") | F20: =IFERROR(IF($A20="","",IF(INDEX(Aud_Massn,MATCH($A20,Aud_MNr,0))="","",INDEX(Aud_Massn,MATCH($A20,Aud_MNr,0)))),"") | G20: =IFERROR(IF($A20="","",IF(INDEX(Aud_Verantw,MATCH($A20,Aud_MNr,0))="","",INDEX(Aud_Verantw,MATCH($A20,Aud_MNr,0)))),"") | H20: =IFERROR(IF($A20="","",IF(INDEX(Aud_Termin,MATCH($A20,Aud_MNr,0))="","",INDEX(Aud_Termin,MATCH($A20,Aud_MNr,0)))),"") | I20: =IFERROR(IF($A20="","",INDEX(Aud_Status,MATCH($A20,Aud_MNr,0))),"")
A21: =IF(17<=COUNT(Aud_MNr),17,"") | B21: =IFERROR(IF($A21="","",INDEX(Aud_Nr,MATCH($A21,Aud_MNr,0))),"") | C21: =IFERROR(IF($A21="","",INDEX(Aud_Kapitel,MATCH($A21,Aud_MNr,0))),"") | D21: =IFERROR(IF($A21="","",INDEX(Aud_Punkt,MATCH($A21,Aud_MNr,0))),"") | E21: =IFERROR(IF($A21="","",INDEX(Aud_Bew,MATCH($A21,Aud_MNr,0))),"") | F21: =IFERROR(IF($A21="","",IF(INDEX(Aud_Massn,MATCH($A21,Aud_MNr,0))="","",INDEX(Aud_Massn,MATCH($A21,Aud_MNr,0)))),"") | G21: =IFERROR(IF($A21="","",IF(INDEX(Aud_Verantw,MATCH($A21,Aud_MNr,0))="","",INDEX(Aud_Verantw,MATCH($A21,Aud_MNr,0)))),"") | H21: =IFERROR(IF($A21="","",IF(INDEX(Aud_Termin,MATCH($A21,Aud_MNr,0))="","",INDEX(Aud_Termin,MATCH($A21,Aud_MNr,0)))),"") | I21: =IFERROR(IF($A21="","",INDEX(Aud_Status,MATCH($A21,Aud_MNr,0))),"")
A22: =IF(18<=COUNT(Aud_MNr),18,"") | B22: =IFERROR(IF($A22="","",INDEX(Aud_Nr,MATCH($A22,Aud_MNr,0))),"") | C22: =IFERROR(IF($A22="","",INDEX(Aud_Kapitel,MATCH($A22,Aud_MNr,0))),"") | D22: =IFERROR(IF($A22="","",INDEX(Aud_Punkt,MATCH($A22,Aud_MNr,0))),"") | E22: =IFERROR(IF($A22="","",INDEX(Aud_Bew,MATCH($A22,Aud_MNr,0))),"") | F22: =IFERROR(IF($A22="","",IF(INDEX(Aud_Massn,MATCH($A22,Aud_MNr,0))="","",INDEX(Aud_Massn,MATCH($A22,Aud_MNr,0)))),"") | G22: =IFERROR(IF($A22="","",IF(INDEX(Aud_Verantw,MATCH($A22,Aud_MNr,0))="","",INDEX(Aud_Verantw,MATCH($A22,Aud_MNr,0)))),"") | H22: =IFERROR(IF($A22="","",IF(INDEX(Aud_Termin,MATCH($A22,Aud_MNr,0))="","",INDEX(Aud_Termin,MATCH($A22,Aud_MNr,0)))),"") | I22: =IFERROR(IF($A22="","",INDEX(Aud_Status,MATCH($A22,Aud_MNr,0))),"")
A23: =IF(19<=COUNT(Aud_MNr),19,"") | B23: =IFERROR(IF($A23="","",INDEX(Aud_Nr,MATCH($A23,Aud_MNr,0))),"") | C23: =IFERROR(IF($A23="","",INDEX(Aud_Kapitel,MATCH($A23,Aud_MNr,0))),"") | D23: =IFERROR(IF($A23="","",INDEX(Aud_Punkt,MATCH($A23,Aud_MNr,0))),"") | E23: =IFERROR(IF($A23="","",INDEX(Aud_Bew,MATCH($A23,Aud_MNr,0))),"") | F23: =IFERROR(IF($A23="","",IF(INDEX(Aud_Massn,MATCH($A23,Aud_MNr,0))="","",INDEX(Aud_Massn,MATCH($A23,Aud_MNr,0)))),"") | G23: =IFERROR(IF($A23="","",IF(INDEX(Aud_Verantw,MATCH($A23,Aud_MNr,0))="","",INDEX(Aud_Verantw,MATCH($A23,Aud_MNr,0)))),"") | H23: =IFERROR(IF($A23="","",IF(INDEX(Aud_Termin,MATCH($A23,Aud_MNr,0))="","",INDEX(Aud_Termin,MATCH($A23,Aud_MNr,0)))),"") | I23: =IFERROR(IF($A23="","",INDEX(Aud_Status,MATCH($A23,Aud_MNr,0))),"")
A24: =IF(20<=COUNT(Aud_MNr),20,"") | B24: =IFERROR(IF($A24="","",INDEX(Aud_Nr,MATCH($A24,Aud_MNr,0))),"") | C24: =IFERROR(IF($A24="","",INDEX(Aud_Kapitel,MATCH($A24,Aud_MNr,0))),"") | D24: =IFERROR(IF($A24="","",INDEX(Aud_Punkt,MATCH($A24,Aud_MNr,0))),"") | E24: =IFERROR(IF($A24="","",INDEX(Aud_Bew,MATCH($A24,Aud_MNr,0))),"") | F24: =IFERROR(IF($A24="","",IF(INDEX(Aud_Massn,MATCH($A24,Aud_MNr,0))="","",INDEX(Aud_Massn,MATCH($A24,Aud_MNr,0)))),"") | G24: =IFERROR(IF($A24="","",IF(INDEX(Aud_Verantw,MATCH($A24,Aud_MNr,0))="","",INDEX(Aud_Verantw,MATCH($A24,Aud_MNr,0)))),"") | H24: =IFERROR(IF($A24="","",IF(INDEX(Aud_Termin,MATCH($A24,Aud_MNr,0))="","",INDEX(Aud_Termin,MATCH($A24,Aud_MNr,0)))),"") | I24: =IFERROR(IF($A24="","",INDEX(Aud_Status,MATCH($A24,Aud_MNr,0))),"")
