Workbook
Name ListeProjekte: Projekte!$A$5:$A$34
Name ListeKategorie: Projekte!$F$5:$F$19
Name ListeStatus: Projekte!$H$5:$H$19
Name ListePrio: Projekte!$J$5:$J$19

Sheet Dashboard
B1: Dashboard – Zeitplanung
B3: Stichtag | C3: =TODAY() | D3: ← heute (überschreibbar, z. B. für Rückblick)
B4: Wochenziel (Std.) | C4: 40 | D4: ← Ihre Annahme, anpassen
B5: Arbeitstage / Woche | C5: 5 | E5: Wochenbeginn: | F5: =C3-WEEKDAY(C3,2)+1 | G5: ="KW "&_xlfn.ISOWEEKNUM(C3)
B7: Heute | D7: Diese Woche | F7: Wochenziel erreicht
B8: =SUMIFS(Eingabe!$K$5:$K$2004,Eingabe!$A$5:$A$2004,$C$3) | D8: =SUMIFS(Eingabe!$K$5:$K$2004,Eingabe!$A$5:$A$2004,">="&$F$5,Eingabe!$A$5:$A$2004,"<="&$F$5+6) | F8: =IF($C$4=0,0,D8/$C$4)
B10: Dieser Monat | D10: Ø pro Arbeitstag (Woche) | F10: Offene Aufgaben
B11: =SUMIFS(Eingabe!$K$5:$K$2004,Eingabe!$A$5:$A$2004,">="&DATE(YEAR($C$3),MONTH($C$3),1),Eingabe!$A$5:$A$2004,"<="&EOMONTH($C$3,0)) | D11: =IFERROR(D8/SUMPRODUCT(--(COUNTIFS(Eingabe!$A$5:$A$2004,$F$5+ROW($1:$7)-1,Eingabe!$K$5:$K$2004,">0")>0)),0) | F11: =COUNTIFS(Eingabe!$H$5:$H$2004,"Offen")+COUNTIFS(Eingabe!$H$5:$H$2004,"In Arbeit")+COUNTIFS(Eingabe!$H$5:$H$2004,"Wartet")
B14: Projekte | I14: Deadlines
B15: Projekt | C15: Woche (h) | D15: Monat (h) | E15: Gesamt (h) | F15: Budget (h) | G15: Verbraucht | I15: Projekt | J15: Deadline | K15: Tage noch | L15: Rest (h)
B16: =IF(Projekte!$A$5="","",Projekte!$A$5) | C16: =IF($B16="","",SUMIFS(Eingabe!$K$5:$K$2004,Eingabe!$B$5:$B$2004,$B16,Eingabe!$A$5:$A$2004,">="&$F$5,Eingabe!$A$5:$A$2004,"<="&$F$5+6)) | D16: =IF($B16="","",SUMIFS(Eingabe!$K$5:$K$2004,Eingabe!$B$5:$B$2004,$B16,Eingabe!$A$5:$A$2004,">="&DATE(YEAR($C$3),MONTH($C$3),1),Eingabe!$A$5:$A$2004,"<="&EOMONTH($C$3,0))) | E16: =IF($B16="","",SUMIFS(Eingabe!$K$5:$K$2004,Eingabe!$B$5:$B$2004,$B16)) | F16: =IF(OR($B16="",Projekte!$B$5=""),"",Projekte!$B$5) | G16: =IF(OR($B16="",F16=""),"",E16/F16) | I16: =IF(Projekte!$C$5="","",Projekte!$A$5) | J16: =IF(I16="","",Projekte!$C$5) | K16: =IF(I16="","",J16-$C$3) | L16: =IF(OR(I16="",Projekte!$B$5=""),"",Projekte!$B$5-SUMIFS(Eingabe!$K$5:$K$2004,Eingabe!$B$5:$B$2004,Projekte!$A$5))
B17: =IF(Projekte!$A$6="","",Projekte!$A$6) | C17: =IF($B17="","",SUMIFS(Eingabe!$K$5:$K$2004,Eingabe!$B$5:$B$2004,$B17,Eingabe!$A$5:$A$2004,">="&$F$5,Eingabe!$A$5:$A$2004,"<="&$F$5+6)) | D17: =IF($B17="","",SUMIFS(Eingabe!$K$5:$K$2004,Eingabe!$B$5:$B$2004,$B17,Eingabe!$A$5:$A$2004,">="&DATE(YEAR($C$3),MONTH($C$3),1),Eingabe!$A$5:$A$2004,"<="&EOMONTH($C$3,0))) | E17: =IF($B17="","",SUMIFS(Eingabe!$K$5:$K$2004,Eingabe!$B$5:$B$2004,$B17)) | F17: =IF(OR($B17="",Projekte!$B$6=""),"",Projekte!$B$6) | G17: =IF(OR($B17="",F17=""),"",E17/F17) | I17: =IF(Projekte!$C$6="","",Projekte!$A$6) | J17: =IF(I17="","",Projekte!$C$6) | K17: =IF(I17="","",J17-$C$3) | L17: =IF(OR(I17="",Projekte!$B$6=""),"",Projekte!$B$6-SUMIFS(Eingabe!$K$5:$K$2004,Eingabe!$B$5:$B$2004,Projekte!$A$6))
B18: =IF(Projekte!$A$7="","",Projekte!$A$7) | C18: =IF($B18="","",SUMIFS(Eingabe!$K$5:$K$2004,Eingabe!$B$5:$B$2004,$B18,Eingabe!$A$5:$A$2004,">="&$F$5,Eingabe!$A$5:$A$2004,"<="&$F$5+6)) | D18: =IF($B18="","",SUMIFS(Eingabe!$K$5:$K$2004,Eingabe!$B$5:$B$2004,$B18,Eingabe!$A$5:$A$2004,">="&DATE(YEAR($C$3),MONTH($C$3),1),Eingabe!$A$5:$A$2004,"<="&EOMONTH($C$3,0))) | E18: =IF($B18="","",SUMIFS(Eingabe!$K$5:$K$2004,Eingabe!$B$5:$B$2004,$B18)) | F18: =IF(OR($B18="",Projekte!$B$7=""),"",Projekte!$B$7) | G18: =IF(OR($B18="",F18=""),"",E18/F18) | I18: =IF(Projekte!$C$7="","",Projekte!$A$7) | J18: =IF(I18="","",Projekte!$C$7) | K18: =IF(I18="","",J18-$C$3) | L18: =IF(OR(I18="",Projekte!$B$7=""),"",Projekte!$B$7-SUMIFS(Eingabe!$K$5:$K$2004,Eingabe!$B$5:$B$2004,Projekte!$A$7))
B19: =IF(Projekte!$A$8="","",Projekte!$A$8) | C19: =IF($B19="","",SUMIFS(Eingabe!$K$5:$K$2004,Eingabe!$B$5:$B$2004,$B19,Eingabe!$A$5:$A$2004,">="&$F$5,Eingabe!$A$5:$A$2004,"<="&$F$5+6)) | D19: =IF($B19="","",SUMIFS(Eingabe!$K$5:$K$2004,Eingabe!$B$5:$B$2004,$B19,Eingabe!$A$5:$A$2004,">="&DATE(YEAR($C$3),MONTH($C$3),1),Eingabe!$A$5:$A$2004,"<="&EOMONTH($C$3,0))) | E19: =IF($B19="","",SUMIFS(Eingabe!$K$5:$K$2004,Eingabe!$B$5:$B$2004,$B19)) | F19: =IF(OR($B19="",Projekte!$B$8=""),"",Projekte!$B$8) | G19: =IF(OR($B19="",F19=""),"",E19/F19) | I19: =IF(Projekte!$C$8="","",Projekte!$A$8) | J19: =IF(I19="","",Projekte!$C$8) | K19: =IF(I19="","",J19-$C$3) | L19: =IF(OR(I19="",Projekte!$B$8=""),"",Projekte!$B$8-SUMIFS(Eingabe!$K$5:$K$2004,Eingabe!$B$5:$B$2004,Projekte!$A$8))
B20: =IF(Projekte!$A$9="","",Projekte!$A$9) | C20: =IF($B20="","",SUMIFS(Eingabe!$K$5:$K$2004,Eingabe!$B$5:$B$2004,$B20,Eingabe!$A$5:$A$2004,">="&$F$5,Eingabe!$A$5:$A$2004,"<="&$F$5+6)) | D20: =IF($B20="","",SUMIFS(Eingabe!$K$5:$K$2004,Eingabe!$B$5:$B$2004,$B20,Eingabe!$A$5:$A$2004,">="&DATE(YEAR($C$3),MONTH($C$3),1),Eingabe!$A$5:$A$2004,"<="&EOMONTH($C$3,0))) | E20: =IF($B20="","",SUMIFS(Eingabe!$K$5:$K$2004,Eingabe!$B$5:$B$2004,$B20)) | F20: =IF(OR($B20="",Projekte!$B$9=""),"",Projekte!$B$9) | G20: =IF(OR($B20="",F20=""),"",E20/F20) | I20: =IF(Projekte!$C$9="","",Projekte!$A$9) | J20: =IF(I20="","",Projekte!$C$9) | K20: =IF(I20="","",J20-$C$3) | L20: =IF(OR(I20="",Projekte!$B$9=""),"",Projekte!$B$9-SUMIFS(Eingabe!$K$5:$K$2004,Eingabe!$B$5:$B$2004,Projekte!$A$9))
B21: =IF(Projekte!$A$10="","",Projekte!$A$10) | C21: =IF($B21="","",SUMIFS(Eingabe!$K$5:$K$2004,Eingabe!$B$5:$B$2004,$B21,Eingabe!$A$5:$A$2004,">="&$F$5,Eingabe!$A$5:$A$2004,"<="&$F$5+6)) | D21: =IF($B21="","",SUMIFS(Eingabe!$K$5:$K$2004,Eingabe!$B$5:$B$2004,$B21,Eingabe!$A$5:$A$2004,">="&DATE(YEAR($C$3),MONTH($C$3),1),Eingabe!$A$5:$A$2004,"<="&EOMONTH($C$3,0))) | E21: =IF($B21="","",SUMIFS(Eingabe!$K$5:$K$2004,Eingabe!$B$5:$B$2004,$B21)) | F21: =IF(OR($B21="",Projekte!$B$10=""),"",Projekte!$B$10) | G21: =IF(OR($B21="",F21=""),"",E21/F21) | I21: =IF(Projekte!$C$10="","",Projekte!$A$10) | J21: =IF(I21="","",Projekte!$C$10) | K21: =IF(I21="","",J21-$C$3) | L21: =IF(OR(I21="",Projekte!$B$10=""),"",Projekte!$B$10-SUMIFS(Eingabe!$K$5:$K$2004,Eingabe!$B$5:$B$2004,Projekte!$A$10))
B22: =IF(Projekte!$A$11="","",Projekte!$A$11) | C22: =IF($B22="","",SUMIFS(Eingabe!$K$5:$K$2004,Eingabe!$B$5:$B$2004,$B22,Eingabe!$A$5:$A$2004,">="&$F$5,Eingabe!$A$5:$A$2004,"<="&$F$5+6)) | D22: =IF($B22="","",SUMIFS(Eingabe!$K$5:$K$2004,Eingabe!$B$5:$B$2004,$B22,Eingabe!$A$5:$A$2004,">="&DATE(YEAR($C$3),MONTH($C$3),1),Eingabe!$A$5:$A$2004,"<="&EOMONTH($C$3,0))) | E22: =IF($B22="","",SUMIFS(Eingabe!$K$5:$K$2004,Eingabe!$B$5:$B$2004,$B22)) | F22: =IF(OR($B22="",Projekte!$B$11=""),"",Projekte!$B$11) | G22: =IF(OR($B22="",F22=""),"",E22/F22) | I22: =IF(Projekte!$C$11="","",Projekte!$A$11) | J22: =IF(I22="","",Projekte!$C$11) | K22: =IF(I22="","",J22-$C$3) | L22: =IF(OR(I22="",Projekte!$B$11=""),"",Projekte!$B$11-SUMIFS(Eingabe!$K$5:$K$2004,Eingabe!$B$5:$B$2004,Projekte!$A$11))
B23: =IF(Projekte!$A$12="","",Projekte!$A$12) | C23: =IF($B23="","",SUMIFS(Eingabe!$K$5:$K$2004,Eingabe!$B$5:$B$2004,$B23,Eingabe!$A$5:$A$2004,">="&$F$5,Eingabe!$A$5:$A$2004,"<="&$F$5+6)) | D23: =IF($B23="","",SUMIFS(Eingabe!$K$5:$K$2004,Eingabe!$B$5:$B$2004,$B23,Eingabe!$A$5:$A$2004,">="&DATE(YEAR($C$3),MONTH($C$3),1),Eingabe!$A$5:$A$2004,"<="&EOMONTH($C$3,0))) | E23: =IF($B23="","",SUMIFS(Eingabe!$K$5:$K$2004,Eingabe!$B$5:$B$2004,$B23)) | F23: =IF(OR($B23="",Projekte!$B$12=""),"",Projekte!$B$12) | G23: =IF(OR($B23="",F23=""),"",E23/F23) | I23: =IF(Projekte!$C$12="","",Projekte!$A$12) | J23: =IF(I23="","",Projekte!$C$12) | K23: =IF(I23="","",J23-$C$3) | L23: =IF(OR(I23="",Projekte!$B$12=""),"",Projekte!$B$12-SUMIFS(Eingabe!$K$5:$K$2004,Eingabe!$B$5:$B$2004,Projekte!$A$12))
B24: =IF(Projekte!$A$13="","",Projekte!$A$13) | C24: =IF($B24="","",SUMIFS(Eingabe!$K$5:$K$2004,Eingabe!$B$5:$B$2004,$B24,Eingabe!$A$5:$A$2004,">="&$F$5,Eingabe!$A$5:$A$2004,"<="&$F$5+6)) | D24: =IF($B24="","",SUMIFS(Eingabe!$K$5:$K$2004,Eingabe!$B$5:$B$2004,$B24,Eingabe!$A$5:$A$2004,">="&DATE(YEAR($C$3),MONTH($C$3),1),Eingabe!$A$5:$A$2004,"<="&EOMONTH($C$3,0))) | E24: =IF($B24="","",SUMIFS(Eingabe!$K$5:$K$2004,Eingabe!$B$5:$B$2004,$B24)) | F24: =IF(OR($B24="",Projekte!$B$13=""),"",Projekte!$B$13) | G24: =IF(OR($B24="",F24=""),"",E24/F24) | I24: =IF(Projekte!$C$13="","",Projekte!$A$13) | J24: =IF(I24="","",Projekte!$C$13) | K24: =IF(I24="","",J24-$C$3) | L24: =IF(OR(I24="",Projekte!$B$13=""),"",Projekte!$B$13-SUMIFS(Eingabe!$K$5:$K$2004,Eingabe!$B$5:$B$2004,Projekte!$A$13))
B25: =IF(Projekte!$A$14="","",Projekte!$A$14) | C25: =IF($B25="","",SUMIFS(Eingabe!$K$5:$K$2004,Eingabe!$B$5:$B$2004,$B25,Eingabe!$A$5:$A$2004,">="&$F$5,Eingabe!$A$5:$A$2004,"<="&$F$5+6)) | D25: =IF($B25="","",SUMIFS(Eingabe!$K$5:$K$2004,Eingabe!$B$5:$B$2004,$B25,Eingabe!$A$5:$A$2004,">="&DATE(YEAR($C$3),MONTH($C$3),1),Eingabe!$A$5:$A$2004,"<="&EOMONTH($C$3,0))) | E25: =IF($B25="","",SUMIFS(Eingabe!$K$5:$K$2004,Eingabe!$B$5:$B$2004,$B25)) | F25: =IF(OR($B25="",Projekte!$B$14=""),"",Projekte!$B$14) | G25: =IF(OR($B25="",F25=""),"",E25/F25) | I25: =IF(Projekte!$C$14="","",Projekte!$A$14) | J25: =IF(I25="","",Projekte!$C$14) | K25: =IF(I25="","",J25-$C$3) | L25: =IF(OR(I25="",Projekte!$B$14=""),"",Projekte!$B$14-SUMIFS(Eingabe!$K$5:$K$2004,Eingabe!$B$5:$B$2004,Projekte!$A$14))
B26: =IF(Projekte!$A$15="","",Projekte!$A$15) | C26: =IF($B26="","",SUMIFS(Eingabe!$K$5:$K$2004,Eingabe!$B$5:$B$2004,$B26,Eingabe!$A$5:$A$2004,">="&$F$5,Eingabe!$A$5:$A$2004,"<="&$F$5+6)) | D26: =IF($B26="","",SUMIFS(Eingabe!$K$5:$K$2004,Eingabe!$B$5:$B$2004,$B26,Eingabe!$A$5:$A$2004,">="&DATE(YEAR($C$3),MONTH($C$3),1),Eingabe!$A$5:$A$2004,"<="&EOMONTH($C$3,0))) | E26: =IF($B26="","",SUMIFS(Eingabe!$K$5:$K$2004,Eingabe!$B$5:$B$2004,$B26)) | F26: =IF(OR($B26="",Projekte!$B$15=""),"",Projekte!$B$15) | G26: =IF(OR($B26="",F26=""),"",E26/F26) | I26: =IF(Projekte!$C$15="","",Projekte!$A$15) | J26: =IF(I26="","",Projekte!$C$15) | K26: =IF(I26="","",J26-$C$3) | L26: =IF(OR(I26="",Projekte!$B$15=""),"",Projekte!$B$15-SUMIFS(Eingabe!$K$5:$K$2004,Eingabe!$B$5:$B$2004,Projekte!$A$15))
B27: =IF(Projekte!$A$16="","",Projekte!$A$16) | C27: =IF($B27="","",SUMIFS(Eingabe!$K$5:$K$2004,Eingabe!$B$5:$B$2004,$B27,Eingabe!$A$5:$A$2004,">="&$F$5,Eingabe!$A$5:$A$2004,"<="&$F$5+6)) | D27: =IF($B27="","",SUMIFS(Eingabe!$K$5:$K$2004,Eingabe!$B$5:$B$2004,$B27,Eingabe!$A$5:$A$2004,">="&DATE(YEAR($C$3),MONTH($C$3),1),Eingabe!$A$5:$A$2004,"<="&EOMONTH($C$3,0))) | E27: =IF($B27="","",SUMIFS(Eingabe!$K$5:$K$2004,Eingabe!$B$5:$B$2004,$B27)) | F27: =IF(OR($B27="",Projekte!$B$16=""),"",Projekte!$B$16) | G27: =IF(OR($B27="",F27=""),"",E27/F27) | I27: =IF(Projekte!$C$16="","",Projekte!$A$16) | J27: =IF(I27="","",Projekte!$C$16) | K27: =IF(I27="","",J27-$C$3) | L27: =IF(OR(I27="",Projekte!$B$16=""),"",Projekte!$B$16-SUMIFS(Eingabe!$K$5:$K$2004,Eingabe!$B$5:$B$2004,Projekte!$A$16))
B28: =IF(Projekte!$A$17="","",Projekte!$A$17) | C28: =IF($B28="","",SUMIFS(Eingabe!$K$5:$K$2004,Eingabe!$B$5:$B$2004,$B28,Eingabe!$A$5:$A$2004,">="&$F$5,Eingabe!$A$5:$A$2004,"<="&$F$5+6)) | D28: =IF($B28="","",SUMIFS(Eingabe!$K$5:$K$2004,Eingabe!$B$5:$B$2004,$B28,Eingabe!$A$5:$A$2004,">="&DATE(YEAR($C$3),MONTH($C$3),1),Eingabe!$A$5:$A$2004,"<="&EOMONTH($C$3,0))) | E28: =IF($B28="","",SUMIFS(Eingabe!$K$5:$K$2004,Eingabe!$B$5:$B$2004,$B28)) | F28: =IF(OR($B28="",Projekte!$B$17=""),"",Projekte!$B$17) | G28: =IF(OR($B28="",F28=""),"",E28/F28) | I28: =IF(Projekte!$C$17="","",Projekte!$A$17) | J28: =IF(I28="","",Projekte!$C$17) | K28: =IF(I28="","",J28-$C$3) | L28: =IF(OR(I28="",Projekte!$B$17=""),"",Projekte!$B$17-SUMIFS(Eingabe!$K$5:$K$2004,Eingabe!$B$5:$B$2004,Projekte!$A$17))
B29: =IF(Projekte!$A$18="","",Projekte!$A$18) | C29: =IF($B29="","",SUMIFS(Eingabe!$K$5:$K$2004,Eingabe!$B$5:$B$2004,$B29,Eingabe!$A$5:$A$2004,">="&$F$5,Eingabe!$A$5:$A$2004,"<="&$F$5+6)) | D29: =IF($B29="","",SUMIFS(Eingabe!$K$5:$K$2004,Eingabe!$B$5:$B$2004,$B29,Eingabe!$A$5:$A$2004,">="&DATE(YEAR($C$3),MONTH($C$3),1),Eingabe!$A$5:$A$2004,"<="&EOMONTH($C$3,0))) | E29: =IF($B29="","",SUMIFS(Eingabe!$K$5:$K$2004,Eingabe!$B$5:$B$2004,$B29)) | F29: =IF(OR($B29="",Projekte!$B$18=""),"",Projekte!$B$18) | G29: =IF(OR($B29="",F29=""),"",E29/F29) | I29: =IF(Projekte!$C$18="","",Projekte!$A$18) | J29: =IF(I29="","",Projekte!$C$18) | K29: =IF(I29="","",J29-$C$3) | L29: =IF(OR(I29="",Projekte!$B$18=""),"",Projekte!$B$18-SUMIFS(Eingabe!$K$5:$K$2004,Eingabe!$B$5:$B$2004,Projekte!$A$18))
B30: =IF(Projekte!$A$19="","",Projekte!$A$19) | C30: =IF($B30="","",SUMIFS(Eingabe!$K$5:$K$2004,Eingabe!$B$5:$B$2004,$B30,Eingabe!$A$5:$A$2004,">="&$F$5,Eingabe!$A$5:$A$2004,"<="&$F$5+6)) | D30: =IF($B30="","",SUMIFS(Eingabe!$K$5:$K$2004,Eingabe!$B$5:$B$2004,$B30,Eingabe!$A$5:$A$2004,">="&DATE(YEAR($C$3),MONTH($C$3),1),Eingabe!$A$5:$A$2004,"<="&EOMONTH($C$3,0))) | E30: =IF($B30="","",SUMIFS(Eingabe!$K$5:$K$2004,Eingabe!$B$5:$B$2004,$B30)) | F30: =IF(OR($B30="",Projekte!$B$19=""),"",Projekte!$B$19) | G30: =IF(OR($B30="",F30=""),"",E30/F30) | I30: =IF(Projekte!$C$19="","",Projekte!$A$19) | J30: =IF(I30="","",Projekte!$C$19) | K30: =IF(I30="","",J30-$C$3) | L30: =IF(OR(I30="",Projekte!$B$19=""),"",Projekte!$B$19-SUMIFS(Eingabe!$K$5:$K$2004,Eingabe!$B$5:$B$2004,Projekte!$A$19))
B31: =IF(Projekte!$A$20="","",Projekte!$A$20) | C31: =IF($B31="","",SUMIFS(Eingabe!$K$5:$K$2004,Eingabe!$B$5:$B$2004,$B31,Eingabe!$A$5:$A$2004,">="&$F$5,Eingabe!$A$5:$A$2004,"<="&$F$5+6)) | D31: =IF($B31="","",SUMIFS(Eingabe!$K$5:$K$2004,Eingabe!$B$5:$B$2004,$B31,Eingabe!$A$5:$A$2004,">="&DATE(YEAR($C$3),MONTH($C$3),1),Eingabe!$A$5:$A$2004,"<="&EOMONTH($C$3,0))) | E31: =IF($B31="","",SUMIFS(Eingabe!$K$5:$K$2004,Eingabe!$B$5:$B$2004,$B31)) | F31: =IF(OR($B31="",Projekte!$B$20=""),"",Projekte!$B$20) | G31: =IF(OR($B31="",F31=""),"",E31/F31) | I31: =IF(Projekte!$C$20="","",Projekte!$A$20) | J31: =IF(I31="","",Projekte!$C$20) | K31: =IF(I31="","",J31-$C$3) | L31: =IF(OR(I31="",Projekte!$B$20=""),"",Projekte!$B$20-SUMIFS(Eingabe!$K$5:$K$2004,Eingabe!$B$5:$B$2004,Projekte!$A$20))
B32: =IF(Projekte!$A$21="","",Projekte!$A$21) | C32: =IF($B32="","",SUMIFS(Eingabe!$K$5:$K$2004,Eingabe!$B$5:$B$2004,$B32,Eingabe!$A$5:$A$2004,">="&$F$5,Eingabe!$A$5:$A$2004,"<="&$F$5+6)) | D32: =IF($B32="","",SUMIFS(Eingabe!$K$5:$K$2004,Eingabe!$B$5:$B$2004,$B32,Eingabe!$A$5:$A$2004,">="&DATE(YEAR($C$3),MONTH($C$3),1),Eingabe!$A$5:$A$2004,"<="&EOMONTH($C$3,0))) | E32: =IF($B32="","",SUMIFS(Eingabe!$K$5:$K$2004,Eingabe!$B$5:$B$2004,$B32)) | F32: =IF(OR($B32="",Projekte!$B$21=""),"",Projekte!$B$21) | G32: =IF(OR($B32="",F32=""),"",E32/F32) | I32: =IF(Projekte!$C$21="","",Projekte!$A$21) | J32: =IF(I32="","",Projekte!$C$21) | K32: =IF(I32="","",J32-$C$3) | L32: =IF(OR(I32="",Projekte!$B$21=""),"",Projekte!$B$21-SUMIFS(Eingabe!$K$5:$K$2004,Eingabe!$B$5:$B$2004,Projekte!$A$21))
B33: =IF(Projekte!$A$22="","",Projekte!$A$22) | C33: =IF($B33="","",SUMIFS(Eingabe!$K$5:$K$2004,Eingabe!$B$5:$B$2004,$B33,Eingabe!$A$5:$A$2004,">="&$F$5,Eingabe!$A$5:$A$2004,"<="&$F$5+6)) | D33: =IF($B33="","",SUMIFS(Eingabe!$K$5:$K$2004,Eingabe!$B$5:$B$2004,$B33,Eingabe!$A$5:$A$2004,">="&DATE(YEAR($C$3),MONTH($C$3),1),Eingabe!$A$5:$A$2004,"<="&EOMONTH($C$3,0))) | E33: =IF($B33="","",SUMIFS(Eingabe!$K$5:$K$2004,Eingabe!$B$5:$B$2004,$B33)) | F33: =IF(OR($B33="",Projekte!$B$22=""),"",Projekte!$B$22) | G33: =IF(OR($B33="",F33=""),"",E33/F33) | I33: =IF(Projekte!$C$22="","",Projekte!$A$22) | J33: =IF(I33="","",Projekte!$C$22) | K33: =IF(I33="","",J33-$C$3) | L33: =IF(OR(I33="",Projekte!$B$22=""),"",Projekte!$B$22-SUMIFS(Eingabe!$K$5:$K$2004,Eingabe!$B$5:$B$2004,Projekte!$A$22))
B34: =IF(Projekte!$A$23="","",Projekte!$A$23) | C34: =IF($B34="","",SUMIFS(Eingabe!$K$5:$K$2004,Eingabe!$B$5:$B$2004,$B34,Eingabe!$A$5:$A$2004,">="&$F$5,Eingabe!$A$5:$A$2004,"<="&$F$5+6)) | D34: =IF($B34="","",SUMIFS(Eingabe!$K$5:$K$2004,Eingabe!$B$5:$B$2004,$B34,Eingabe!$A$5:$A$2004,">="&DATE(YEAR($C$3),MONTH($C$3),1),Eingabe!$A$5:$A$2004,"<="&EOMONTH($C$3,0))) | E34: =IF($B34="","",SUMIFS(Eingabe!$K$5:$K$2004,Eingabe!$B$5:$B$2004,$B34)) | F34: =IF(OR($B34="",Projekte!$B$23=""),"",Projekte!$B$23) | G34: =IF(OR($B34="",F34=""),"",E34/F34) | I34: =IF(Projekte!$C$23="","",Projekte!$A$23) | J34: =IF(I34="","",Projekte!$C$23) | K34: =IF(I34="","",J34-$C$3) | L34: =IF(OR(I34="",Projekte!$B$23=""),"",Projekte!$B$23-SUMIFS(Eingabe!$K$5:$K$2004,Eingabe!$B$5:$B$2004,Projekte!$A$23))
B35: =IF(Projekte!$A$24="","",Projekte!$A$24) | C35: =IF($B35="","",SUMIFS(Eingabe!$K$5:$K$2004,Eingabe!$B$5:$B$2004,$B35,Eingabe!$A$5:$A$2004,">="&$F$5,Eingabe!$A$5:$A$2004,"<="&$F$5+6)) | D35: =IF($B35="","",SUMIFS(Eingabe!$K$5:$K$2004,Eingabe!$B$5:$B$2004,$B35,Eingabe!$A$5:$A$2004,">="&DATE(YEAR($C$3),MONTH($C$3),1),Eingabe!$A$5:$A$2004,"<="&EOMONTH($C$3,0))) | E35: =IF($B35="","",SUMIFS(Eingabe!$K$5:$K$2004,Eingabe!$B$5:$B$2004,$B35)) | F35: =IF(OR($B35="",Projekte!$B$24=""),"",Projekte!$B$24) | G35: =IF(OR($B35="",F35=""),"",E35/F35) | I35: =IF(Projekte!$C$24="","",Projekte!$A$24) | J35: =IF(I35="","",Projekte!$C$24) | K35: =IF(I35="","",J35-$C$3) | L35: =IF(OR(I35="",Projekte!$B$24=""),"",Projekte!$B$24-SUMIFS(Eingabe!$K$5:$K$2004,Eingabe!$B$5:$B$2004,Projekte!$A$24))
B36: =IF(Projekte!$A$25="","",Projekte!$A$25) | C36: =IF($B36="","",SUMIFS(Eingabe!$K$5:$K$2004,Eingabe!$B$5:$B$2004,$B36,Eingabe!$A$5:$A$2004,">="&$F$5,Eingabe!$A$5:$A$2004,"<="&$F$5+6)) | D36: =IF($B36="","",SUMIFS(Eingabe!$K$5:$K$2004,Eingabe!$B$5:$B$2004,$B36,Eingabe!$A$5:$A$2004,">="&DATE(YEAR($C$3),MONTH($C$3),1),Eingabe!$A$5:$A$2004,"<="&EOMONTH($C$3,0))) | E36: =IF($B36="","",SUMIFS(Eingabe!$K$5:$K$2004,Eingabe!$B$5:$B$2004,$B36)) | F36: =IF(OR($B36="",Projekte!$B$25=""),"",Projekte!$B$25) | G36: =IF(OR($B36="",F36=""),"",E36/F36) | I36: =IF(Projekte!$C$25="","",Projekte!$A$25) | J36: =IF(I36="","",Projekte!$C$25) | K36: =IF(I36="","",J36-$C$3) | L36: =IF(OR(I36="",Projekte!$B$25=""),"",Projekte!$B$25-SUMIFS(Eingabe!$K$5:$K$2004,Eingabe!$B$5:$B$2004,Projekte!$A$25))
B37: =IF(Projekte!$A$26="","",Projekte!$A$26) | C37: =IF($B37="","",SUMIFS(Eingabe!$K$5:$K$2004,Eingabe!$B$5:$B$2004,$B37,Eingabe!$A$5:$A$2004,">="&$F$5,Eingabe!$A$5:$A$2004,"<="&$F$5+6)) | D37: =IF($B37="","",SUMIFS(Eingabe!$K$5:$K$2004,Eingabe!$B$5:$B$2004,$B37,Eingabe!$A$5:$A$2004,">="&DATE(YEAR($C$3),MONTH($C$3),1),Eingabe!$A$5:$A$2004,"<="&EOMONTH($C$3,0))) | E37: =IF($B37="","",SUMIFS(Eingabe!$K$5:$K$2004,Eingabe!$B$5:$B$2004,$B37)) | F37: =IF(OR($B37="",Projekte!$B$26=""),"",Projekte!$B$26) | G37: =IF(OR($B37="",F37=""),"",E37/F37) | I37: =IF(Projekte!$C$26="","",Projekte!$A$26) | J37: =IF(I37="","",Projekte!$C$26) | K37: =IF(I37="","",J37-$C$3) | L37: =IF(OR(I37="",Projekte!$B$26=""),"",Projekte!$B$26-SUMIFS(Eingabe!$K$5:$K$2004,Eingabe!$B$5:$B$2004,Projekte!$A$26))
B38: =IF(Projekte!$A$27="","",Projekte!$A$27) | C38: =IF($B38="","",SUMIFS(Eingabe!$K$5:$K$2004,Eingabe!$B$5:$B$2004,$B38,Eingabe!$A$5:$A$2004,">="&$F$5,Eingabe!$A$5:$A$2004,"<="&$F$5+6)) | D38: =IF($B38="","",SUMIFS(Eingabe!$K$5:$K$2004,Eingabe!$B$5:$B$2004,$B38,Eingabe!$A$5:$A$2004,">="&DATE(YEAR($C$3),MONTH($C$3),1),Eingabe!$A$5:$A$2004,"<="&EOMONTH($C$3,0))) | E38: =IF($B38="","",SUMIFS(Eingabe!$K$5:$K$2004,Eingabe!$B$5:$B$2004,$B38)) | F38: =IF(OR($B38="",Projekte!$B$27=""),"",Projekte!$B$27) | G38: =IF(OR($B38="",F38=""),"",E38/F38) | I38: =IF(Projekte!$C$27="","",Projekte!$A$27) | J38: =IF(I38="","",Projekte!$C$27) | K38: =IF(I38="","",J38-$C$3) | L38: =IF(OR(I38="",Projekte!$B$27=""),"",Projekte!$B$27-SUMIFS(Eingabe!$K$5:$K$2004,Eingabe!$B$5:$B$2004,Projekte!$A$27))
B39: =IF(Projekte!$A$28="","",Projekte!$A$28) | C39: =IF($B39="","",SUMIFS(Eingabe!$K$5:$K$2004,Eingabe!$B$5:$B$2004,$B39,Eingabe!$A$5:$A$2004,">="&$F$5,Eingabe!$A$5:$A$2004,"<="&$F$5+6)) | D39: =IF($B39="","",SUMIFS(Eingabe!$K$5:$K$2004,Eingabe!$B$5:$B$2004,$B39,Eingabe!$A$5:$A$2004,">="&DATE(YEAR($C$3),MONTH($C$3),1),Eingabe!$A$5:$A$2004,"<="&EOMONTH($C$3,0))) | E39: =IF($B39="","",SUMIFS(Eingabe!$K$5:$K$2004,Eingabe!$B$5:$B$2004,$B39)) | F39: =IF(OR($B39="",Projekte!$B$28=""),"",Projekte!$B$28) | G39: =IF(OR($B39="",F39=""),"",E39/F39) | I39: =IF(Projekte!$C$28="","",Projekte!$A$28) | J39: =IF(I39="","",Projekte!$C$28) | K39: =IF(I39="","",J39-$C$3) | L39: =IF(OR(I39="",Projekte!$B$28=""),"",Projekte!$B$28-SUMIFS(Eingabe!$K$5:$K$2004,Eingabe!$B$5:$B$2004,Projekte!$A$28))
B40: =IF(Projekte!$A$29="","",Projekte!$A$29) | C40: =IF($B40="","",SUMIFS(Eingabe!$K$5:$K$2004,Eingabe!$B$5:$B$2004,$B40,Eingabe!$A$5:$A$2004,">="&$F$5,Eingabe!$A$5:$A$2004,"<="&$F$5+6)) | D40: =IF($B40="","",SUMIFS(Eingabe!$K$5:$K$2004,Eingabe!$B$5:$B$2004,$B40,Eingabe!$A$5:$A$2004,">="&DATE(YEAR($C$3),MONTH($C$3),1),Eingabe!$A$5:$A$2004,"<="&EOMONTH($C$3,0))) | E40: =IF($B40="","",SUMIFS(Eingabe!$K$5:$K$2004,Eingabe!$B$5:$B$2004,$B40)) | F40: =IF(OR($B40="",Projekte!$B$29=""),"",Projekte!$B$29) | G40: =IF(OR($B40="",F40=""),"",E40/F40) | I40: =IF(Projekte!$C$29="","",Projekte!$A$29) | J40: =IF(I40="","",Projekte!$C$29) | K40: =IF(I40="","",J40-$C$3) | L40: =IF(OR(I40="",Projekte!$B$29=""),"",Projekte!$B$29-SUMIFS(Eingabe!$K$5:$K$2004,Eingabe!$B$5:$B$2004,Projekte!$A$29))
B41: =IF(Projekte!$A$30="","",Projekte!$A$30) | C41: =IF($B41="","",SUMIFS(Eingabe!$K$5:$K$2004,Eingabe!$B$5:$B$2004,$B41,Eingabe!$A$5:$A$2004,">="&$F$5,Eingabe!$A$5:$A$2004,"<="&$F$5+6)) | D41: =IF($B41="","",SUMIFS(Eingabe!$K$5:$K$2004,Eingabe!$B$5:$B$2004,$B41,Eingabe!$A$5:$A$2004,">="&DATE(YEAR($C$3),MONTH($C$3),1),Eingabe!$A$5:$A$2004,"<="&EOMONTH($C$3,0))) | E41: =IF($B41="","",SUMIFS(Eingabe!$K$5:$K$2004,Eingabe!$B$5:$B$2004,$B41)) | F41: =IF(OR($B41="",Projekte!$B$30=""),"",Projekte!$B$30) | G41: =IF(OR($B41="",F41=""),"",E41/F41) | I41: =IF(Projekte!$C$30="","",Projekte!$A$30) | J41: =IF(I41="","",Projekte!$C$30) | K41: =IF(I41="","",J41-$C$3) | L41: =IF(OR(I41="",Projekte!$B$30=""),"",Projekte!$B$30-SUMIFS(Eingabe!$K$5:$K$2004,Eingabe!$B$5:$B$2004,Projekte!$A$30))
B42: =IF(Projekte!$A$31="","",Projekte!$A$31) | C42: =IF($B42="","",SUMIFS(Eingabe!$K$5:$K$2004,Eingabe!$B$5:$B$2004,$B42,Eingabe!$A$5:$A$2004,">="&$F$5,Eingabe!$A$5:$A$2004,"<="&$F$5+6)) | D42: =IF($B42="","",SUMIFS(Eingabe!$K$5:$K$2004,Eingabe!$B$5:$B$2004,$B42,Eingabe!$A$5:$A$2004,">="&DATE(YEAR($C$3),MONTH($C$3),1),Eingabe!$A$5:$A$2004,"<="&EOMONTH($C$3,0))) | E42: =IF($B42="","",SUMIFS(Eingabe!$K$5:$K$2004,Eingabe!$B$5:$B$2004,$B42)) | F42: =IF(OR($B42="",Projekte!$B$31=""),"",Projekte!$B$31) | G42: =IF(OR($B42="",F42=""),"",E42/F42) | I42: =IF(Projekte!$C$31="","",Projekte!$A$31) | J42: =IF(I42="","",Projekte!$C$31) | K42: =IF(I42="","",J42-$C$3) | L42: =IF(OR(I42="",Projekte!$B$31=""),"",Projekte!$B$31-SUMIFS(Eingabe!$K$5:$K$2004,Eingabe!$B$5:$B$2004,Projekte!$A$31))
B43: =IF(Projekte!$A$32="","",Projekte!$A$32) | C43: =IF($B43="","",SUMIFS(Eingabe!$K$5:$K$2004,Eingabe!$B$5:$B$2004,$B43,Eingabe!$A$5:$A$2004,">="&$F$5,Eingabe!$A$5:$A$2004,"<="&$F$5+6)) | D43: =IF($B43="","",SUMIFS(Eingabe!$K$5:$K$2004,Eingabe!$B$5:$B$2004,$B43,Eingabe!$A$5:$A$2004,">="&DATE(YEAR($C$3),MONTH($C$3),1),Eingabe!$A$5:$A$2004,"<="&EOMONTH($C$3,0))) | E43: =IF($B43="","",SUMIFS(Eingabe!$K$5:$K$2004,Eingabe!$B$5:$B$2004,$B43)) | F43: =IF(OR($B43="",Projekte!$B$32=""),"",Projekte!$B$32) | G43: =IF(OR($B43="",F43=""),"",E43/F43) | I43: =IF(Projekte!$C$32="","",Projekte!$A$32) | J43: =IF(I43="","",Projekte!$C$32) | K43: =IF(I43="","",J43-$C$3) | L43: =IF(OR(I43="",Projekte!$B$32=""),"",Projekte!$B$32-SUMIFS(Eingabe!$K$5:$K$2004,Eingabe!$B$5:$B$2004,Projekte!$A$32))
B44: =IF(Projekte!$A$33="","",Projekte!$A$33) | C44: =IF($B44="","",SUMIFS(Eingabe!$K$5:$K$2004,Eingabe!$B$5:$B$2004,$B44,Eingabe!$A$5:$A$2004,">="&$F$5,Eingabe!$A$5:$A$2004,"<="&$F$5+6)) | D44: =IF($B44="","",SUMIFS(Eingabe!$K$5:$K$2004,Eingabe!$B$5:$B$2004,$B44,Eingabe!$A$5:$A$2004,">="&DATE(YEAR($C$3),MONTH($C$3),1),Eingabe!$A$5:$A$2004,"<="&EOMONTH($C$3,0))) | E44: =IF($B44="","",SUMIFS(Eingabe!$K$5:$K$2004,Eingabe!$B$5:$B$2004,$B44)) | F44: =IF(OR($B44="",Projekte!$B$33=""),"",Projekte!$B$33) | G44: =IF(OR($B44="",F44=""),"",E44/F44) | I44: =IF(Projekte!$C$33="","",Projekte!$A$33) | J44: =IF(I44="","",Projekte!$C$33) | K44: =IF(I44="","",J44-$C$3) | L44: =IF(OR(I44="",Projekte!$B$33=""),"",Projekte!$B$33-SUMIFS(Eingabe!$K$5:$K$2004,Eingabe!$B$5:$B$2004,Projekte!$A$33))
B45: =IF(Projekte!$A$34="","",Projekte!$A$34) | C45: =IF($B45="","",SUMIFS(Eingabe!$K$5:$K$2004,Eingabe!$B$5:$B$2004,$B45,Eingabe!$A$5:$A$2004,">="&$F$5,Eingabe!$A$5:$A$2004,"<="&$F$5+6)) | D45: =IF($B45="","",SUMIFS(Eingabe!$K$5:$K$2004,Eingabe!$B$5:$B$2004,$B45,Eingabe!$A$5:$A$2004,">="&DATE(YEAR($C$3),MONTH($C$3),1),Eingabe!$A$5:$A$2004,"<="&EOMONTH($C$3,0))) | E45: =IF($B45="","",SUMIFS(Eingabe!$K$5:$K$2004,Eingabe!$B$5:$B$2004,$B45)) | F45: =IF(OR($B45="",Projekte!$B$34=""),"",Projekte!$B$34) | G45: =IF(OR($B45="",F45=""),"",E45/F45) | I45: =IF(Projekte!$C$34="","",Projekte!$A$34) | J45: =IF(I45="","",Projekte!$C$34) | K45: =IF(I45="","",J45-$C$3) | L45: =IF(OR(I45="",Projekte!$B$34=""),"",Projekte!$B$34-SUMIFS(Eingabe!$K$5:$K$2004,Eingabe!$B$5:$B$2004,Projekte!$A$34))
...

Sheet Eingabe
A1: Arbeitstagebuch – tägliche Erfassung
A2: Gelbe Spalten ausfüllen, graue rechnen automatisch. Datum: Strg + . | Uhrzeit: Strg + Umschalt + . | Entweder 'Dauer' eintragen ODER Start + Ende. Beispielzeilen einfach löschen.
A4: Datum | B4: Projekt | C4: Kategorie | D4: Aufgabe / Tätigkeit | E4: Dauer (Std.) | F4: Start | G4: Ende | H4: Status | I4: Priorität | J4: Notiz | K4: Stunden | L4: Wochentag | M4: KW | N4: Monat
A5: 46293 | B5: Projekt Alpha | C5: Planung | D5: Projektplan Q4 erstellen | E5: 2 | H5: Erledigt | I5: Hoch | K5: =IF(E5<>"",E5,IF(AND(F5<>"",G5<>""),MOD(G5-F5,1)*24,"")) | L5: =IF(A5="","",CHOOSE(WEEKDAY(A5,2),"Montag","Dienstag","Mittwoch","Donnerstag","Freitag","Samstag","Sonntag")) | M5: =IF(A5="","",_xlfn.ISOWEEKNUM(A5)) | N5: =IF(A5="","",DATE(YEAR(A5),MONTH(A5),1))
A6: 46293 | B6: Verwaltung | C6: E-Mail / Orga | D6: Posteingang abarbeiten | E6: 1 | H6: Erledigt | I6: Niedrig | K6: =IF(E6<>"",E6,IF(AND(F6<>"",G6<>""),MOD(G6-F6,1)*24,"")) | L6: =IF(A6="","",CHOOSE(WEEKDAY(A6,2),"Montag","Dienstag","Mittwoch","Donnerstag","Freitag","Samstag","Sonntag")) | M6: =IF(A6="","",_xlfn.ISOWEEKNUM(A6)) | N6: =IF(A6="","",DATE(YEAR(A6),MONTH(A6),1))
A7: 46294 | B7: Kunde Müller | C7: Besprechung | D7: Abstimmung Angebot | F7: 0.375 | G7: 0.4375 | H7: Erledigt | I7: Mittel | J7: Rückruf Fr. | K7: =IF(E7<>"",E7,IF(AND(F7<>"",G7<>""),MOD(G7-F7,1)*24,"")) | L7: =IF(A7="","",CHOOSE(WEEKDAY(A7,2),"Montag","Dienstag","Mittwoch","Donnerstag","Freitag","Samstag","Sonntag")) | M7: =IF(A7="","",_xlfn.ISOWEEKNUM(A7)) | N7: =IF(A7="","",DATE(YEAR(A7),MONTH(A7),1))
A8: 46295 | B8: Projekt Alpha | C8: Umsetzung | D8: Konzept Teil 1 | E8: 4.5 | H8: Erledigt | I8: Hoch | K8: =IF(E8<>"",E8,IF(AND(F8<>"",G8<>""),MOD(G8-F8,1)*24,"")) | L8: =IF(A8="","",CHOOSE(WEEKDAY(A8,2),"Montag","Dienstag","Mittwoch","Donnerstag","Freitag","Samstag","Sonntag")) | M8: =IF(A8="","",_xlfn.ISOWEEKNUM(A8)) | N8: =IF(A8="","",DATE(YEAR(A8),MONTH(A8),1))
A9: 46296 | B9: Kunde Müller | C9: Umsetzung | D9: Angebot ausarbeiten | E9: 3 | H9: In Arbeit | I9: Hoch | K9: =IF(E9<>"",E9,IF(AND(F9<>"",G9<>""),MOD(G9-F9,1)*24,"")) | L9: =IF(A9="","",CHOOSE(WEEKDAY(A9,2),"Montag","Dienstag","Mittwoch","Donnerstag","Freitag","Samstag","Sonntag")) | M9: =IF(A9="","",_xlfn.ISOWEEKNUM(A9)) | N9: =IF(A9="","",DATE(YEAR(A9),MONTH(A9),1))
A10: 46297 | B10: Weiterbildung | C10: Lernen | D10: Excel-Kurs Modul 2 | E10: 1.5 | H10: Erledigt | I10: Niedrig | K10: =IF(E10<>"",E10,IF(AND(F10<>"",G10<>""),MOD(G10-F10,1)*24,"")) | L10: =IF(A10="","",CHOOSE(WEEKDAY(A10,2),"Montag","Dienstag","Mittwoch","Donnerstag","Freitag","Samstag","Sonntag")) | M10: =IF(A10="","",_xlfn.ISOWEEKNUM(A10)) | N10: =IF(A10="","",DATE(YEAR(A10),MONTH(A10),1))
A11: 46300 | B11: Projekt Alpha | C11: Umsetzung | D11: Konzept Teil 2 | F11: 0.33333333 | G11: 0.46875 | H11: In Arbeit | I11: Hoch | K11: =IF(E11<>"",E11,IF(AND(F11<>"",G11<>""),MOD(G11-F11,1)*24,"")) | L11: =IF(A11="","",CHOOSE(WEEKDAY(A11,2),"Montag","Dienstag","Mittwoch","Donnerstag","Freitag","Samstag","Sonntag")) | M11: =IF(A11="","",_xlfn.ISOWEEKNUM(A11)) | N11: =IF(A11="","",DATE(YEAR(A11),MONTH(A11),1))
A12: 46300 | B12: Verwaltung | C12: E-Mail / Orga | D12: Wochenplanung | E12: 0.5 | H12: Offen | I12: Mittel | J12: Beispielzeile – löschen | K12: =IF(E12<>"",E12,IF(AND(F12<>"",G12<>""),MOD(G12-F12,1)*24,"")) | L12: =IF(A12="","",CHOOSE(WEEKDAY(A12,2),"Montag","Dienstag","Mittwoch","Donnerstag","Freitag","Samstag","Sonntag")) | M12: =IF(A12="","",_xlfn.ISOWEEKNUM(A12)) | N12: =IF(A12="","",DATE(YEAR(A12),MONTH(A12),1))
K13: =IF(E13<>"",E13,IF(AND(F13<>"",G13<>""),MOD(G13-F13,1)*24,"")) | L13: =IF(A13="","",CHOOSE(WEEKDAY(A13,2),"Montag","Dienstag","Mittwoch","Donnerstag","Freitag","Samstag","Sonntag")) | M13: =IF(A13="","",_xlfn.ISOWEEKNUM(A13)) | N13: =IF(A13="","",DATE(YEAR(A13),MONTH(A13),1))
K14: =IF(E14<>"",E14,IF(AND(F14<>"",G14<>""),MOD(G14-F14,1)*24,"")) | L14: =IF(A14="","",CHOOSE(WEEKDAY(A14,2),"Montag","Dienstag","Mittwoch","Donnerstag","Freitag","Samstag","Sonntag")) | M14: =IF(A14="","",_xlfn.ISOWEEKNUM(A14)) | N14: =IF(A14="","",DATE(YEAR(A14),MONTH(A14),1))
K15: =IF(E15<>"",E15,IF(AND(F15<>"",G15<>""),MOD(G15-F15,1)*24,"")) | L15: =IF(A15="","",CHOOSE(WEEKDAY(A15,2),"Montag","Dienstag","Mittwoch","Donnerstag","Freitag","Samstag","Sonntag")) | M15: =IF(A15="","",_xlfn.ISOWEEKNUM(A15)) | N15: =IF(A15="","",DATE(YEAR(A15),MONTH(A15),1))
K16: =IF(E16<>"",E16,IF(AND(F16<>"",G16<>""),MOD(G16-F16,1)*24,"")) | L16: =IF(A16="","",CHOOSE(WEEKDAY(A16,2),"Montag","Dienstag","Mittwoch","Donnerstag","Freitag","Samstag","Sonntag")) | M16: =IF(A16="","",_xlfn.ISOWEEKNUM(A16)) | N16: =IF(A16="","",DATE(YEAR(A16),MONTH(A16),1))
K17: =IF(E17<>"",E17,IF(AND(F17<>"",G17<>""),MOD(G17-F17,1)*24,"")) | L17: =IF(A17="","",CHOOSE(WEEKDAY(A17,2),"Montag","Dienstag","Mittwoch","Donnerstag","Freitag","Samstag","Sonntag")) | M17: =IF(A17="","",_xlfn.ISOWEEKNUM(A17)) | N17: =IF(A17="","",DATE(YEAR(A17),MONTH(A17),1))
K18: =IF(E18<>"",E18,IF(AND(F18<>"",G18<>""),MOD(G18-F18,1)*24,"")) | L18: =IF(A18="","",CHOOSE(WEEKDAY(A18,2),"Montag","Dienstag","Mittwoch","Donnerstag","Freitag","Samstag","Sonntag")) | M18: =IF(A18="","",_xlfn.ISOWEEKNUM(A18)) | N18: =IF(A18="","",DATE(YEAR(A18),MONTH(A18),1))
K19: =IF(E19<>"",E19,IF(AND(F19<>"",G19<>""),MOD(G19-F19,1)*24,"")) | L19: =IF(A19="","",CHOOSE(WEEKDAY(A19,2),"Montag","Dienstag","Mittwoch","Donnerstag","Freitag","Samstag","Sonntag")) | M19: =IF(A19="","",_xlfn.ISOWEEKNUM(A19)) | N19: =IF(A19="","",DATE(YEAR(A19),MONTH(A19),1))
K20: =IF(E20<>"",E20,IF(AND(F20<>"",G20<>""),MOD(G20-F20,1)*24,"")) | L20: =IF(A20="","",CHOOSE(WEEKDAY(A20,2),"Montag","Dienstag","Mittwoch","Donnerstag","Freitag","Samstag","Sonntag")) | M20: =IF(A20="","",_xlfn.ISOWEEKNUM(A20)) | N20: =IF(A20="","",DATE(YEAR(A20),MONTH(A20),1))
K21: =IF(E21<>"",E21,IF(AND(F21<>"",G21<>""),MOD(G21-F21,1)*24,"")) | L21: =IF(A21="","",CHOOSE(WEEKDAY(A21,2),"Montag","Dienstag","Mittwoch","Donnerstag","Freitag","Samstag","Sonntag")) | M21: =IF(A21="","",_xlfn.ISOWEEKNUM(A21)) | N21: =IF(A21="","",DATE(YEAR(A21),MONTH(A21),1))
K22: =IF(E22<>"",E22,IF(AND(F22<>"",G22<>""),MOD(G22-F22,1)*24,"")) | L22: =IF(A22="","",CHOOSE(WEEKDAY(A22,2),"Montag","Dienstag","Mittwoch","Donnerstag","Freitag","Samstag","Sonntag")) | M22: =IF(A22="","",_xlfn.ISOWEEKNUM(A22)) | N22: =IF(A22="","",DATE(YEAR(A22),MONTH(A22),1))
K23: =IF(E23<>"",E23,IF(AND(F23<>"",G23<>""),MOD(G23-F23,1)*24,"")) | L23: =IF(A23="","",CHOOSE(WEEKDAY(A23,2),"Montag","Dienstag","Mittwoch","Donnerstag","Freitag","Samstag","Sonntag")) | M23: =IF(A23="","",_xlfn.ISOWEEKNUM(A23)) | N23: =IF(A23="","",DATE(YEAR(A23),MONTH(A23),1))
K24: =IF(E24<>"",E24,IF(AND(F24<>"",G24<>""),MOD(G24-F24,1)*24,"")) | L24: =IF(A24="","",CHOOSE(WEEKDAY(A24,2),"Montag","Dienstag","Mittwoch","Donnerstag","Freitag","Samstag","Sonntag")) | M24: =IF(A24="","",_xlfn.ISOWEEKNUM(A24)) | N24: =IF(A24="","",DATE(YEAR(A24),MONTH(A24),1))
... K2004: =IF(E2004<>"",E2004,IF(AND(F2004<>"",G2004<>""),MOD(G2004-F2004,1)*24,"")) | L2004: =IF(A2004="","",CHOOSE(WEEKDAY(A2004,2),"Montag","Dienstag","Mittwoch","Donnerstag","Freitag","Samstag","Sonntag")) | M2004: =IF(A2004="","",_xlfn.ISOWEEKNUM(A2004)) | N2004: =IF(A2004="","",DATE(YEAR(A2004),MONTH(A2004),1))

Sheet Projekte
A1: Projekte & Auswahllisten
A2: Hier eigene Projekte eintragen (gelbe Felder). Sie erscheinen sofort in der Auswahl auf 'Eingabe' und im Dashboard.
A4: Projekt | B4: Budget (Std.) | C4: Deadline | D4: Bemerkung | F4: Kategorie | H4: Status | J4: Priorität
A5: Projekt Alpha | B5: 80 | C5: 46374 | D5: Beispiel | F5: Planung | H5: Offen | J5: Hoch
A6: Kunde Müller | B6: 20 | C6: 46325 | D6: Beispiel | F6: Umsetzung | H6: In Arbeit | J6: Mittel
A7: Verwaltung | D7: laufend | F7: Besprechung | H7: Erledigt | J7: Niedrig
A8: Weiterbildung | B8: 24 | C8: 46387 | F8: Telefon | H8: Wartet
F9: E-Mail / Orga
F10: Recherche
F11: Dokumentation
F12: Fahrt
F13: Lernen
F14: Pause

Sheet Anleitung
B1: Arbeitstagebuch – so geht's
B3: 1. Einmalig: Projekte anlegen
B4: Im Blatt 'Projekte' Ihre Projekte eintragen – optional mit Stunden-Budget und Deadline. Kategorien, Status und Prioritäten sind dort ebenfalls frei änderbar.
B5: 2. Täglich erfassen (ca. 10 Sekunden pro Aufgabe)
B6: Blatt 'Eingabe', nächste leere Zeile: Strg + . (Datum) → Tab → Projekt aus Liste → Tab → Kategorie → Tab → Aufgabe → Tab → Dauer, z. B. 1,5
B7: Alternativ statt Dauer: Start und Ende als Uhrzeit (z. B. 8:00 und 11:15) – die Stunden werden automatisch berechnet (auch über Mitternacht).
B8: Tipp: In der Auswahlliste den Anfangsbuchstaben tippen, oder mit Alt + ↓ die Liste öffnen.
B9: Tipp: Strg + D kopiert die Zelle von oben (z. B. gleiches Datum oder gleiches Projekt).
B10: 3. Dashboard ansehen
B11: Zeigt Stunden heute / Woche / Monat, Wochenziel, Stunden je Projekt inkl. Budget-Verbrauch, Deadlines mit Ampel, Kategorien und die letzten 14 Tage.
B12: Der Stichtag ist automatisch 'heute'. Für einen Rückblick einfach ein anderes Datum in C3 eintragen; mit =HEUTE() wieder zurücksetzen.
B13: Mehr als 15 Projekte? Links neben den Zeilennummern auf [+] klicken, dann werden alle 30 Projektzeilen sichtbar.
... B27: Die Beispielzeilen in 'Eingabe' und die Beispielprojekte können einfach gelöscht werden (Inhalte löschen mit Entf – nicht die Zeilen löschen, damit die grauen Formeln erhalten bleiben).
