Workbook

Sheet Übersicht
A1: Instandhaltungs-Audit – Übersicht
A2: Auswertung aller Checklisten dieser Mappe. Gelbe Felder sind Eingaben.
A4: Einstellungen
A5: Firma / Werk / Abteilung | D5: Erscheint nur hier; frei ausfüllen.
A6: Gewicht „bed. OK“ | C6: 0.5 | D6: Annahme (Vorschlag): bed. OK zählt zur Hälfte. Die Excel-Vorlage enthält keine Formel.
A7: Ampel grün ab | C7: 0.85 | D7: Annahme (Vorschlag), frei änderbar.
A8: Ampel gelb ab | C8: 0.6 | D8: Annahme (Vorschlag), frei änderbar.
A11: Ergebnis je Checkliste | O11: Hilfswerte (nicht ändern)
A12: Checkliste | B12: Objekt | C12: Datum | D12: Auditor | E12: Punkte | F12: N.I.O | G12: bed. OK | H12: OK | I12: n. b. | J12: offen | K12: Erfüllungsgrad | L12: Ampel | M12: Maßnahmen | O12: Offset Allgemein | P12: 0
A13: Allgemein | B13: =IF(Audit_Allgemein!C4="","–",Audit_Allgemein!C4) -> – | C13: =IF(Audit_Allgemein!C6="","–",Audit_Allgemein!C6) -> – | D13: =IF(Audit_Allgemein!C7="","–",Audit_Allgemein!C7) -> – | E13: 39 | F13: =Audit_Allgemein!H4 -> 0 | G13: =Audit_Allgemein!H5 -> 0 | H13: =Audit_Allgemein!H6 -> 0 | I13: =Audit_Allgemein!H7 -> 0 | J13: =Audit_Allgemein!H8 -> 39 | K13: =Audit_Allgemein!I5 | L13: =Audit_Allgemein!I7 -> nicht bewertet | M13: =COUNTIF(Audit_Allgemein!E12:E50,"N.I.O")+COUNTIF(Audit_Allgemein!E12:E50,"bed. OK") -> 0 | O13: Offset Maschine | P13: =P12+M13 -> 0
A14: Maschine | B14: =IF(Audit_Maschine!C4="","–",Audit_Maschine!C4) -> – | C14: =IF(Audit_Maschine!C6="","–",Audit_Maschine!C6) -> – | D14: =IF(Audit_Maschine!C7="","–",Audit_Maschine!C7) -> – | E14: 13 | F14: =Audit_Maschine!H4 -> 0 | G14: =Audit_Maschine!H5 -> 0 | H14: =Audit_Maschine!H6 -> 0 | I14: =Audit_Maschine!H7 -> 0 | J14: =Audit_Maschine!H8 -> 13 | K14: =Audit_Maschine!I5 | L14: =Audit_Maschine!I7 -> nicht bewertet | M14: =COUNTIF(Audit_Maschine!E12:E24,"N.I.O")+COUNTIF(Audit_Maschine!E12:E24,"bed. OK") -> 0 | O14: Offset Werkzeug | P14: =P13+M14 -> 0
A15: Werkzeug | B15: =IF(Audit_Werkzeuge!C4="","–",Audit_Werkzeuge!C4) -> – | C15: =IF(Audit_Werkzeuge!C6="","–",Audit_Werkzeuge!C6) -> – | D15: =IF(Audit_Werkzeuge!C7="","–",Audit_Werkzeuge!C7) -> – | E15: 10 | F15: =Audit_Werkzeuge!H4 -> 0 | G15: =Audit_Werkzeuge!H5 -> 0 | H15: =Audit_Werkzeuge!H6 -> 0 | I15: =Audit_Werkzeuge!H7 -> 0 | J15: =Audit_Werkzeuge!H8 -> 10 | K15: =Audit_Werkzeuge!I5 | L15: =Audit_Werkzeuge!I7 -> nicht bewertet | M15: =COUNTIF(Audit_Werkzeuge!E12:E21,"N.I.O")+COUNTIF(Audit_Werkzeuge!E12:E21,"bed. OK") -> 0 | O15: Offset Kompakt | P15: =P14+M15 -> 0
A16: Kompakt | B16: =IF(Audit_Kompakt!C4="","–",Audit_Kompakt!C4) -> – | C16: =IF(Audit_Kompakt!C6="","–",Audit_Kompakt!C6) -> – | D16: =IF(Audit_Kompakt!C7="","–",Audit_Kompakt!C7) -> – | E16: 24 | F16: =Audit_Kompakt!H4 -> 0 | G16: =Audit_Kompakt!H5 -> 0 | H16: =Audit_Kompakt!H6 -> 0 | I16: =Audit_Kompakt!H7 -> 0 | J16: =Audit_Kompakt!H8 -> 24 | K16: =Audit_Kompakt!I5 | L16: =Audit_Kompakt!I7 -> nicht bewertet | M16: =COUNTIF(Audit_Kompakt!E12:E35,"N.I.O")+COUNTIF(Audit_Kompakt!E12:E35,"bed. OK") -> 0
A17: Gesamt | E17: =SUM(E13:E16) -> 86 | F17: =SUM(F13:F16) -> 0 | G17: =SUM(G13:G16) -> 0 | H17: =SUM(H13:H16) -> 0 | I17: =SUM(I13:I16) -> 0 | J17: =SUM(J13:J16) -> 86 | K17: =IFERROR((H17+Gewicht_bedOK*G17)/(F17+G17+H17),"") | L17: =IF(K17="","nicht bewertet",IF(K17>=Ampel_gruen,"gut",IF(K17>=Ampel_gelb,"mittel","kritisch"))) -> nicht bewertet | M17: =SUM(M13:M16) -> 0
A20: Umsetzungsstand Maßnahmen | D20: Maschinenpark nach Kritikalität
A21: Status | B21: Anzahl | D21: Klasse | E21: Anzahl
A22: überfällig | B22: =COUNTIF(Audit_Allgemein!J12:J50,"überfällig")+COUNTIF(Audit_Maschine!J12:J24,"überfällig")+COUNTIF(Audit_Werkzeuge!J12:J21,"überfällig")+COUNTIF(Audit_Kompakt!J12:J35,"überfällig") -> 0 | D22: A – kritisch | E22: =COUNTIF(Maschinen!$T$5:$T$24,"A*") -> 2
A23: offen | B23: =COUNTIF(Audit_Allgemein!J12:J50,"offen")+COUNTIF(Audit_Maschine!J12:J24,"offen")+COUNTIF(Audit_Werkzeuge!J12:J21,"offen")+COUNTIF(Audit_Kompakt!J12:J35,"offen") -> 0 | D23: B – mittel | E23: =COUNTIF(Maschinen!$T$5:$T$24,"B*") -> 1
A24: erledigt | B24: =COUNTIF(Audit_Allgemein!J12:J50,"erledigt")+COUNTIF(Audit_Maschine!J12:J24,"erledigt")+COUNTIF(Audit_Werkzeuge!J12:J21,"erledigt")+COUNTIF(Audit_Kompakt!J12:J35,"erledigt") -> 0 | D24: C – gering | E24: =COUNTIF(Maschinen!$T$5:$T$24,"C*") -> 0
D25: nicht eingestuft | E25: =COUNTIF(Maschinen!$B$5:$B$24,"?*")-SUM(E22:E24) -> 1

Sheet Audit_Allgemein
A1: Audit-Checkliste für: Instandhaltung allgemein
A2: Vorlage: Blatt „Auditcheckliste_allg“ · Bewertung: Zustand
G3: Ergebnis
A4: Abteilung / Bereich | G4: N.I.O | H4: =COUNTIF($E$12:$E$50,"N.I.O") -> 0 | I4: Erfüllungsgrad
A5: Equipmentnummer | G5: bed. OK | H5: =COUNTIF($E$12:$E$50,"bed. OK") -> 0 | I5: =IFERROR((H6+Gewicht_bedOK*H5)/(H4+H5+H6),"")
A6: Datum | G6: OK | H6: =COUNTIF($E$12:$E$50,"OK") -> 0
A7: Auditor | G7: n. b. | H7: =COUNTIF($E$12:$E$50,"n. b.") -> 0 | I7: =IF(I5="","nicht bewertet",IF(I5>=Ampel_gruen,"gut",IF(I5>=Ampel_gelb,"mittel","kritisch"))) -> nicht bewertet
A8: Abteilung / Bereich | G8: offen | H8: =39-SUM(H4:H7) -> 39
G9: Erfüllungsgrad = (OK + Gewicht × bed. OK) ÷ (N.I.O + bed. OK + OK); Gewicht und Ampelgrenzen auf „Übersicht“.
A11: Nr. | B11: Kapitel | C11: Check-Punkt | D11: Check-Punkt (EN) | E11: Bewertung | F11: Maßnahmen / Bemerkung | G11: Verantwortlich | H11: Termin | I11: Erledigt | J11: Status | K11: Maßn.-Nr.
A12: 1 | B12: Organisation & Personal | C12: Existiert eine Verfahrensanweisung für das Instandhaltungssystem (aktuell / wird sie gelebt)? | D12: Is there a procedure for the maintenance system? (Is it currently being followed/implemented?) | J12: =IF(OR(E12="N.I.O",E12="bed. OK"),IF(I12="ja","erledigt",IF(AND(H12<>"",H12<TODAY()),"überfällig","offen")),"") | K12: =IF(OR(E12="N.I.O",E12="bed. OK"),Offset_allg+COUNTIF($E$12:E12,"N.I.O")+COUNTIF($E$12:E12,"bed. OK"),"")
A13: 2 | B13: Organisation & Personal | C13: Existiert eine Arbeitsanweisung für die vorbeugende Instandhaltung (aktuell / wird sie gelebt)? | D13: Is there a work instruction for preventive maintenance? (Is it currently being implemented/is it being followed?) | J13: =IF(OR(E13="N.I.O",E13="bed. OK"),IF(I13="ja","erledigt",IF(AND(H13<>"",H13<TODAY()),"überfällig","offen")),"") | K13: =IF(OR(E13="N.I.O",E13="bed. OK"),Offset_allg+COUNTIF($E$12:E13,"N.I.O")+COUNTIF($E$12:E13,"bed. OK"),"")
A14: 3 | B14: Organisation & Personal | C14: Existiert eine Qualifikationsmatrix / Vertretungsregelung / Struktur der IH? | D14: Does a qualification matrix / substitution arrangement / structure of the IH exist? | J14: =IF(OR(E14="N.I.O",E14="bed. OK"),IF(I14="ja","erledigt",IF(AND(H14<>"",H14<TODAY()),"überfällig","offen")),"") | K14: =IF(OR(E14="N.I.O",E14="bed. OK"),Offset_allg+COUNTIF($E$12:E14,"N.I.O")+COUNTIF($E$12:E14,"bed. OK"),"")
A15: 4 | B15: Organisation & Personal | C15: Existiert eine Schichtregelung? Ist die technische Betreuung der Anlage gewährleistet? | D15: Is there a shift system in place? Is technical support for the plant guaranteed? | J15: =IF(OR(E15="N.I.O",E15="bed. OK"),IF(I15="ja","erledigt",IF(AND(H15<>"",H15<TODAY()),"überfällig","offen")),"") | K15: =IF(OR(E15="N.I.O",E15="bed. OK"),Offset_allg+COUNTIF($E$12:E15,"N.I.O")+COUNTIF($E$12:E15,"bed. OK"),"")
A16: 5 | B16: Organisation & Personal | C16: Führungskräfteanzahl in der IH | J16: =IF(OR(E16="N.I.O",E16="bed. OK"),IF(I16="ja","erledigt",IF(AND(H16<>"",H16<TODAY()),"überfällig","offen")),"") | K16: =IF(OR(E16="N.I.O",E16="bed. OK"),Offset_allg+COUNTIF($E$12:E16,"N.I.O")+COUNTIF($E$12:E16,"bed. OK"),"")
A17: 6 | B17: Organisation & Personal | C17: Existiert eine Kapazitäts- und Terminplanung der MA (T/W/M/J)? | J17: =IF(OR(E17="N.I.O",E17="bed. OK"),IF(I17="ja","erledigt",IF(AND(H17<>"",H17<TODAY()),"überfällig","offen")),"") | K17: =IF(OR(E17="N.I.O",E17="bed. OK"),Offset_allg+COUNTIF($E$12:E17,"N.I.O")+COUNTIF($E$12:E17,"bed. OK"),"")
A18: 7 | B18: Organisation & Personal | C18: Flexibilität und Qualifikation der MA innerhalb der Fertigungsbereiche | J18: =IF(OR(E18="N.I.O",E18="bed. OK"),IF(I18="ja","erledigt",IF(AND(H18<>"",H18<TODAY()),"überfällig","offen")),"") | K18: =IF(OR(E18="N.I.O",E18="bed. OK"),Offset_allg+COUNTIF($E$12:E18,"N.I.O")+COUNTIF($E$12:E18,"bed. OK"),"")
A19: 8 | B19: Strategie & IH-System | C19: Anwendung von Instandhaltungsstrategien (welche Instandhaltungsstrategie?) | D19: Application of maintenance strategies (which maintenance strategy) | J19: =IF(OR(E19="N.I.O",E19="bed. OK"),IF(I19="ja","erledigt",IF(AND(H19<>"",H19<TODAY()),"überfällig","offen")),"") | K19: =IF(OR(E19="N.I.O",E19="bed. OK"),Offset_allg+COUNTIF($E$12:E19,"N.I.O")+COUNTIF($E$12:E19,"bed. OK"),"")
A20: 9 | B20: Strategie & IH-System | C20: Welches IH-System steht zur Verfügung (Wartung, Inspektion, geplante/ungeplante Reparatur) und wird es genutzt? | D20: Which maintenance system is available (maintenance; inspection; planned/unplanned repairs) and is it being used? | J20: =IF(OR(E20="N.I.O",E20="bed. OK"),IF(I20="ja","erledigt",IF(AND(H20<>"",H20<TODAY()),"überfällig","offen")),"") | K20: =IF(OR(E20="N.I.O",E20="bed. OK"),Offset_allg+COUNTIF($E$12:E20,"N.I.O")+COUNTIF($E$12:E20,"bed. OK"),"")
A21: 10 | B21: Strategie & IH-System | C21: Existiert eine vorbeugende Instandhaltung? | D21: Preventive maintenance exists | J21: =IF(OR(E21="N.I.O",E21="bed. OK"),IF(I21="ja","erledigt",IF(AND(H21<>"",H21<TODAY()),"überfällig","offen")),"") | K21: =IF(OR(E21="N.I.O",E21="bed. OK"),Offset_allg+COUNTIF($E$12:E21,"N.I.O")+COUNTIF($E$12:E21,"bed. OK"),"")
A22: 11 | B22: Strategie & IH-System | C22: Qualität planmäßige Wartung (Intervalle, Arbeitspläne, Arbeitsabläufe) | D22: Quality of scheduled maintenance (intervals; work plans; work processes) | J22: =IF(OR(E22="N.I.O",E22="bed. OK"),IF(I22="ja","erledigt",IF(AND(H22<>"",H22<TODAY()),"überfällig","offen")),"") | K22: =IF(OR(E22="N.I.O",E22="bed. OK"),Offset_allg+COUNTIF($E$12:E22,"N.I.O")+COUNTIF($E$12:E22,"bed. OK"),"")
A23: 12 | B23: Strategie & IH-System | C23: Qualität planmäßige Inspektion (Intervalle, Arbeitspläne, Arbeitsabläufe) | D23: Quality of scheduled inspections (intervals; work plans; work procedures) | J23: =IF(OR(E23="N.I.O",E23="bed. OK"),IF(I23="ja","erledigt",IF(AND(H23<>"",H23<TODAY()),"überfällig","offen")),"") | K23: =IF(OR(E23="N.I.O",E23="bed. OK"),Offset_allg+COUNTIF($E$12:E23,"N.I.O")+COUNTIF($E$12:E23,"bed. OK"),"")
A24: 13 | B24: Strategie & IH-System | C24: Qualität planmäßig vorbeugende Instandsetzung (Intervalle, Arbeitspläne, Arbeitsabläufe) | D24: Quality of scheduled preventive maintenance (intervals; work plans; workflows) | J24: =IF(OR(E24="N.I.O",E24="bed. OK"),IF(I24="ja","erledigt",IF(AND(H24<>"",H24<TODAY()),"überfällig","offen")),"") | K24: =IF(OR(E24="N.I.O",E24="bed. OK"),Offset_allg+COUNTIF($E$12:E24,"N.I.O")+COUNTIF($E$12:E24,"bed. OK"),"")
A25: 14 | B25: Strategie & IH-System | C25: Qualität störungsbedingte, bedarfsweise Instandsetzung / Einsatzbereitschaft (Arbeitspläne, Reaktionsvermögen bei Störungen) | D25: Quality of breakdown-based and demand-based maintenance / operational readiness (work plans; responsiveness to malfunctions) | J25: =IF(OR(E25="N.I.O",E25="bed. OK"),IF(I25="ja","erledigt",IF(AND(H25<>"",H25<TODAY()),"überfällig","offen")),"") | K25: =IF(OR(E25="N.I.O",E25="bed. OK"),Offset_allg+COUNTIF($E$12:E25,"N.I.O")+COUNTIF($E$12:E25,"bed. OK"),"")
A26: 15 | B26: Strategie & IH-System | C26: Wird Outsourcing (Fremdauftragsvergabe) für Wartung, Inspektion und geplante Instandsetzung praktiziert? | D26: Is outsourcing (contracting) practiced for maintenance, inspection, and planned repairs? | J26: =IF(OR(E26="N.I.O",E26="bed. OK"),IF(I26="ja","erledigt",IF(AND(H26<>"",H26<TODAY()),"überfällig","offen")),"") | K26: =IF(OR(E26="N.I.O",E26="bed. OK"),Offset_allg+COUNTIF($E$12:E26,"N.I.O")+COUNTIF($E$12:E26,"bed. OK"),"")
A27: 16 | B27: Durchführung & Schulung | C27: Sind MA für präventive Instandhaltung (PM) geschult worden? | D27: Have employees been trained in preventive maintenance (PM)? | J27: =IF(OR(E27="N.I.O",E27="bed. OK"),IF(I27="ja","erledigt",IF(AND(H27<>"",H27<TODAY()),"überfällig","offen")),"") | K27: =IF(OR(E27="N.I.O",E27="bed. OK"),Offset_allg+COUNTIF($E$12:E27,"N.I.O")+COUNTIF($E$12:E27,"bed. OK"),"")
A28: 17 | B28: Durchführung & Schulung | C28: Werden Betriebsstoffe für PM bereitgestellt? | D28: Are operating materials provided for PM? | J28: =IF(OR(E28="N.I.O",E28="bed. OK"),IF(I28="ja","erledigt",IF(AND(H28<>"",H28<TODAY()),"überfällig","offen")),"") | K28: =IF(OR(E28="N.I.O",E28="bed. OK"),Offset_allg+COUNTIF($E$12:E28,"N.I.O")+COUNTIF($E$12:E28,"bed. OK"),"")
A29: 18 | B29: Durchführung & Schulung | C29: Werden Wartungen sachgemäß durchgeführt? Sichtkontrolle? Erledigte/unerledigte Aufträge? | D29: Is maintenance being carried out properly? Visual inspection? Completed/uncompleted tasks? | J29: =IF(OR(E29="N.I.O",E29="bed. OK"),IF(I29="ja","erledigt",IF(AND(H29<>"",H29<TODAY()),"überfällig","offen")),"") | K29: =IF(OR(E29="N.I.O",E29="bed. OK"),Offset_allg+COUNTIF($E$12:E29,"N.I.O")+COUNTIF($E$12:E29,"bed. OK"),"")
A30: 19 | B30: Durchführung & Schulung | C30: Wie werden Werkzeuge gewartet? In welchem Zustand? | D30: How are tools maintained? In what condition? | J30: =IF(OR(E30="N.I.O",E30="bed. OK"),IF(I30="ja","erledigt",IF(AND(H30<>"",H30<TODAY()),"überfällig","offen")),"") | K30: =IF(OR(E30="N.I.O",E30="bed. OK"),Offset_allg+COUNTIF($E$12:E30,"N.I.O")+COUNTIF($E$12:E30,"bed. OK"),"")
... A32: 21 | B32: Auswertung & Verbesserung | C32: Kontinuierliche Optimierung der Wartungs-/Inspektionspläne? | D32: Continuous optimization of maintenance/inspection plans? | J32: =IF(OR(E32="N.I.O",E32="bed. OK"),IF(I32="ja","erledigt",IF(AND(H32<>"",H32<TODAY()),"überfällig","offen")),"") | K32: =IF(OR(E32="N.I.O",E32="bed. OK"),Offset_allg+COUNTIF($E$12:E32,"N.I.O")+COUNTIF($E$12:E32,"bed. OK"),"")
A33: 22 | B33: Auswertung & Verbesserung | C33: Schadensregistrierung (Änderung durch konstruktives Beseitigen von Störquellen) | J33: =IF(OR(E33="N.I.O",E33="bed. OK"),IF(I33="ja","erledigt",IF(AND(H33<>"",H33<TODAY()),"überfällig","offen")),"") | K33: =IF(OR(E33="N.I.O",E33="bed. OK"),Offset_allg+COUNTIF($E$12:E33,"N.I.O")+COUNTIF($E$12:E33,"bed. OK"),"")
A34: 23 | B34: Auswertung & Verbesserung | C34: Schadensanalysen und Durchführung | D34: Damage analysis and implementation | J34: =IF(OR(E34="N.I.O",E34="bed. OK"),IF(I34="ja","erledigt",IF(AND(H34<>"",H34<TODAY()),"überfällig","offen")),"") | K34: =IF(OR(E34="N.I.O",E34="bed. OK"),Offset_allg+COUNTIF($E$12:E34,"N.I.O")+COUNTIF($E$12:E34,"bed. OK"),"")
A35: 24 | B35: Auswertung & Verbesserung | C35: Technische Verfügbarkeit der Maschinen als Maß für die IH <> 90 % | D35: Technical availability of machines as a measure of IH <> 80 % | J35: =IF(OR(E35="N.I.O",E35="bed. OK"),IF(I35="ja","erledigt",IF(AND(H35<>"",H35<TODAY()),"überfällig","offen")),"") | K35: =IF(OR(E35="N.I.O",E35="bed. OK"),Offset_allg+COUNTIF($E$12:E35,"N.I.O")+COUNTIF($E$12:E35,"bed. OK"),"")
A36: 25 | B36: Dokumentation & Kommunikation | C36: Verwaltung der technischen Dokumentation (Stücklisten, Maschinenbeschreibung, technische Zeichnungen) | D36: Management of technical documentation (parts lists; machine descriptions; technical drawings) | J36: =IF(OR(E36="N.I.O",E36="bed. OK"),IF(I36="ja","erledigt",IF(AND(H36<>"",H36<TODAY()),"überfällig","offen")),"") | K36: =IF(OR(E36="N.I.O",E36="bed. OK"),Offset_allg+COUNTIF($E$12:E36,"N.I.O")+COUNTIF($E$12:E36,"bed. OK"),"")
A37: 26 | B37: Dokumentation & Kommunikation | C37: Findet eine Absprache zwischen Instandhaltung und Produktion statt? | D37: Is there coordination between maintenance and production? | J37: =IF(OR(E37="N.I.O",E37="bed. OK"),IF(I37="ja","erledigt",IF(AND(H37<>"",H37<TODAY()),"überfällig","offen")),"") | K37: =IF(OR(E37="N.I.O",E37="bed. OK"),Offset_allg+COUNTIF($E$12:E37,"N.I.O")+COUNTIF($E$12:E37,"bed. OK"),"")
A38: 27 | B38: Dokumentation & Kommunikation | C38: Wie gelangen Informationen an die Instandhalter / Anlagenführer? | J38: =IF(OR(E38="N.I.O",E38="bed. OK"),IF(I38="ja","erledigt",IF(AND(H38<>"",H38<TODAY()),"überfällig","offen")),"") | K38: =IF(OR(E38="N.I.O",E38="bed. OK"),Offset_allg+COUNTIF($E$12:E38,"N.I.O")+COUNTIF($E$12:E38,"bed. OK"),"")
A39: 28 | B39: Dokumentation & Kommunikation | C39: Wie ist die Bereitschaft der Instandhalter zu Weiterbildungsmaßnahmen? | J39: =IF(OR(E39="N.I.O",E39="bed. OK"),IF(I39="ja","erledigt",IF(AND(H39<>"",H39<TODAY()),"überfällig","offen")),"") | K39: =IF(OR(E39="N.I.O",E39="bed. OK"),Offset_allg+COUNTIF($E$12:E39,"N.I.O")+COUNTIF($E$12:E39,"bed. OK"),"")
A40: 29 | B40: Werkstatt & Betriebsmittel | C40: Wie sieht die Werkstattausstattung aus und wie ist deren Qualität? | D40: What does the workshop equipment look like and what is its quality? | J40: =IF(OR(E40="N.I.O",E40="bed. OK"),IF(I40="ja","erledigt",IF(AND(H40<>"",H40<TODAY()),"überfällig","offen")),"") | K40: =IF(OR(E40="N.I.O",E40="bed. OK"),Offset_allg+COUNTIF($E$12:E40,"N.I.O")+COUNTIF($E$12:E40,"bed. OK"),"")
A41: 30 | B41: Werkstatt & Betriebsmittel | C41: Gibt es Betriebsmittel für Instandsetzung, PM und Generalüberholung? | D41: Are there resources available for repair, preventive maintenance (PM), and major overhauls? | J41: =IF(OR(E41="N.I.O",E41="bed. OK"),IF(I41="ja","erledigt",IF(AND(H41<>"",H41<TODAY()),"überfällig","offen")),"") | K41: =IF(OR(E41="N.I.O",E41="bed. OK"),Offset_allg+COUNTIF($E$12:E41,"N.I.O")+COUNTIF($E$12:E41,"bed. OK"),"")
A42: 31 | B42: Material & Ersatzteile | C42: Wie wird die Materialplanung (Ersatzteile, Betriebs- und Hilfsstoffe) durchgeführt (Stücklisten, Programme, Disposition)? | D42: How is material planning (spare parts, operating and auxiliary materials) carried out (bills of materials; programs; scheduling)? | J42: =IF(OR(E42="N.I.O",E42="bed. OK"),IF(I42="ja","erledigt",IF(AND(H42<>"",H42<TODAY()),"überfällig","offen")),"") | K42: =IF(OR(E42="N.I.O",E42="bed. OK"),Offset_allg+COUNTIF($E$12:E42,"N.I.O")+COUNTIF($E$12:E42,"bed. OK"),"")
...

Sheet Audit_Maschine
A1: Audit-Checkliste für: Maschine
A2: Vorlage: Blatt „Auditcheckliste_Maschine“ · Bewertung: M.Z. (Maschinenzustand)
G3: Ergebnis
A4: Maschinenbezeichnung | G4: N.I.O | H4: =COUNTIF($E$12:$E$24,"N.I.O") -> 0 | I4: Erfüllungsgrad
A5: Equipmentnummer | G5: bed. OK | H5: =COUNTIF($E$12:$E$24,"bed. OK") -> 0 | I5: =IFERROR((H6+Gewicht_bedOK*H5)/(H4+H5+H6),"")
A6: Datum | G6: OK | H6: =COUNTIF($E$12:$E$24,"OK") -> 0
A7: Auditor | G7: n. b. | H7: =COUNTIF($E$12:$E$24,"n. b.") -> 0 | I7: =IF(I5="","nicht bewertet",IF(I5>=Ampel_gruen,"gut",IF(I5>=Ampel_gelb,"mittel","kritisch"))) -> nicht bewertet
A8: Abteilung / Bereich | G8: offen | H8: =13-SUM(H4:H7) -> 13
G9: Erfüllungsgrad = (OK + Gewicht × bed. OK) ÷ (N.I.O + bed. OK + OK); Gewicht und Ampelgrenzen auf „Übersicht“.
A11: Nr. | B11: Kapitel | C11: Check-Punkt | D11: Hinweis | E11: Bewertung | F11: Maßnahmen / Bemerkung | G11: Verantwortlich | H11: Termin | I11: Erledigt | J11: Status | K11: Maßn.-Nr.
A12: 1 | B12: Zustand | C12: Allgemeiner Zustand der Maschine (Sauberkeit, Umgebung, Bezeichnung?) | J12: =IF(OR(E12="N.I.O",E12="bed. OK"),IF(I12="ja","erledigt",IF(AND(H12<>"",H12<TODAY()),"überfällig","offen")),"") | K12: =IF(OR(E12="N.I.O",E12="bed. OK"),Offset_maschine+COUNTIF($E$12:E12,"N.I.O")+COUNTIF($E$12:E12,"bed. OK"),"")
A13: 2 | B13: Vorbeugende Instandhaltung | C13: Existiert eine vorbeugende Instandhaltung (aktuell / wird sie gelebt und optimiert?) | J13: =IF(OR(E13="N.I.O",E13="bed. OK"),IF(I13="ja","erledigt",IF(AND(H13<>"",H13<TODAY()),"überfällig","offen")),"") | K13: =IF(OR(E13="N.I.O",E13="bed. OK"),Offset_maschine+COUNTIF($E$12:E13,"N.I.O")+COUNTIF($E$12:E13,"bed. OK"),"")
A14: 2.1 | B14: Vorbeugende Instandhaltung | C14: Gibt es Schmierpläne für diese Maschine? | J14: =IF(OR(E14="N.I.O",E14="bed. OK"),IF(I14="ja","erledigt",IF(AND(H14<>"",H14<TODAY()),"überfällig","offen")),"") | K14: =IF(OR(E14="N.I.O",E14="bed. OK"),Offset_maschine+COUNTIF($E$12:E14,"N.I.O")+COUNTIF($E$12:E14,"bed. OK"),"")
A15: 2.2 | B15: Vorbeugende Instandhaltung | C15: Sind die Schmierarbeiten gemäß den vorgegebenen Schmierintervallen durchgeführt? | J15: =IF(OR(E15="N.I.O",E15="bed. OK"),IF(I15="ja","erledigt",IF(AND(H15<>"",H15<TODAY()),"überfällig","offen")),"") | K15: =IF(OR(E15="N.I.O",E15="bed. OK"),Offset_maschine+COUNTIF($E$12:E15,"N.I.O")+COUNTIF($E$12:E15,"bed. OK"),"")
A16: 2.3 | B16: Vorbeugende Instandhaltung | C16: Gibt es Nachweise über die wöchentlich, monatlich, … durchgeführten Wartungs- und Inspektionsarbeiten? | J16: =IF(OR(E16="N.I.O",E16="bed. OK"),IF(I16="ja","erledigt",IF(AND(H16<>"",H16<TODAY()),"überfällig","offen")),"") | K16: =IF(OR(E16="N.I.O",E16="bed. OK"),Offset_maschine+COUNTIF($E$12:E16,"N.I.O")+COUNTIF($E$12:E16,"bed. OK"),"")
A17: 2.4 | B17: Vorbeugende Instandhaltung | C17: Verwaltung der technischen Dokumentation (Stücklisten, Maschinenbeschreibung, technische Zeichnungen)? | J17: =IF(OR(E17="N.I.O",E17="bed. OK"),IF(I17="ja","erledigt",IF(AND(H17<>"",H17<TODAY()),"überfällig","offen")),"") | K17: =IF(OR(E17="N.I.O",E17="bed. OK"),Offset_maschine+COUNTIF($E$12:E17,"N.I.O")+COUNTIF($E$12:E17,"bed. OK"),"")
A18: 2.5 | B18: Funktion & Zustand der Technik | C18: Funktion und Zustand der Mechanik (bezogen auf durchgeführte Inspektion, siehe Checkliste) | J18: =IF(OR(E18="N.I.O",E18="bed. OK"),IF(I18="ja","erledigt",IF(AND(H18<>"",H18<TODAY()),"überfällig","offen")),"") | K18: =IF(OR(E18="N.I.O",E18="bed. OK"),Offset_maschine+COUNTIF($E$12:E18,"N.I.O")+COUNTIF($E$12:E18,"bed. OK"),"")
A19: 2.6 | B19: Funktion & Zustand der Technik | C19: Funktion und Zustand der Hydraulik (bezogen auf durchgeführte Inspektion, siehe Checkliste) | J19: =IF(OR(E19="N.I.O",E19="bed. OK"),IF(I19="ja","erledigt",IF(AND(H19<>"",H19<TODAY()),"überfällig","offen")),"") | K19: =IF(OR(E19="N.I.O",E19="bed. OK"),Offset_maschine+COUNTIF($E$12:E19,"N.I.O")+COUNTIF($E$12:E19,"bed. OK"),"")
A20: 2.7 | B20: Funktion & Zustand der Technik | C20: Funktion und Zustand der Pneumatik (bezogen auf durchgeführte Inspektion, siehe Checkliste) | J20: =IF(OR(E20="N.I.O",E20="bed. OK"),IF(I20="ja","erledigt",IF(AND(H20<>"",H20<TODAY()),"überfällig","offen")),"") | K20: =IF(OR(E20="N.I.O",E20="bed. OK"),Offset_maschine+COUNTIF($E$12:E20,"N.I.O")+COUNTIF($E$12:E20,"bed. OK"),"")
A21: 2.8 | B21: Funktion & Zustand der Technik | C21: Funktion und Zustand der Elektrik (bezogen auf durchgeführte Inspektion, siehe Checkliste) | J21: =IF(OR(E21="N.I.O",E21="bed. OK"),IF(I21="ja","erledigt",IF(AND(H21<>"",H21<TODAY()),"überfällig","offen")),"") | K21: =IF(OR(E21="N.I.O",E21="bed. OK"),Offset_maschine+COUNTIF($E$12:E21,"N.I.O")+COUNTIF($E$12:E21,"bed. OK"),"")
A22: 3 | B22: Rüsten & Störungen | C22: Gibt es eine definierte Vorgehensweise beim Rüsten (Qualifikationsmatrix)? | J22: =IF(OR(E22="N.I.O",E22="bed. OK"),IF(I22="ja","erledigt",IF(AND(H22<>"",H22<TODAY()),"überfällig","offen")),"") | K22: =IF(OR(E22="N.I.O",E22="bed. OK"),Offset_maschine+COUNTIF($E$12:E22,"N.I.O")+COUNTIF($E$12:E22,"bed. OK"),"")
A23: 4 | B23: Rüsten & Störungen | C23: Vorgehensweise bei ungeplanten Störungen (Schwachstellenanalyse) | J23: =IF(OR(E23="N.I.O",E23="bed. OK"),IF(I23="ja","erledigt",IF(AND(H23<>"",H23<TODAY()),"überfällig","offen")),"") | K23: =IF(OR(E23="N.I.O",E23="bed. OK"),Offset_maschine+COUNTIF($E$12:E23,"N.I.O")+COUNTIF($E$12:E23,"bed. OK"),"")
A24: 4.1 | B24: Rüsten & Störungen | C24: Ist ein Ablauf / Maßnahmenplan / Qualifikation der Mitarbeiter für schnelle Reparatur beschrieben? | J24: =IF(OR(E24="N.I.O",E24="bed. OK"),IF(I24="ja","erledigt",IF(AND(H24<>"",H24<TODAY()),"überfällig","offen")),"") | K24: =IF(OR(E24="N.I.O",E24="bed. OK"),Offset_maschine+COUNTIF($E$12:E24,"N.I.O")+COUNTIF($E$12:E24,"bed. OK"),"")
A26: Auswertung je Kapitel
B27: Kapitel | C27: Punkte | D27: N.I.O | E27: bed. OK | F27: OK | G27: n. b. | H27: offen | I27: Erfüllungsgrad
B28: Zustand | C28: =COUNTIF($B$12:$B$24,B28) -> 1 | D28: =COUNTIFS($B$12:$B$24,$B28,$E$12:$E$24,"N.I.O") -> 0 | E28: =COUNTIFS($B$12:$B$24,$B28,$E$12:$E$24,"bed. OK") -> 0 | F28: =COUNTIFS($B$12:$B$24,$B28,$E$12:$E$24,"OK") -> 0 | G28: =COUNTIFS($B$12:$B$24,$B28,$E$12:$E$24,"n. b.") -> 0 | H28: =C28-SUM(D28:G28) -> 1 | I28: =IFERROR((F28+Gewicht_bedOK*E28)/(D28+E28+F28),"")
B29: Vorbeugende Instandhaltung | C29: =COUNTIF($B$12:$B$24,B29) -> 5 | D29: =COUNTIFS($B$12:$B$24,$B29,$E$12:$E$24,"N.I.O") -> 0 | E29: =COUNTIFS($B$12:$B$24,$B29,$E$12:$E$24,"bed. OK") -> 0 | F29: =COUNTIFS($B$12:$B$24,$B29,$E$12:$E$24,"OK") -> 0 | G29: =COUNTIFS($B$12:$B$24,$B29,$E$12:$E$24,"n. b.") -> 0 | H29: =C29-SUM(D29:G29) -> 5 | I29: =IFERROR((F29+Gewicht_bedOK*E29)/(D29+E29+F29),"")
B30: Funktion & Zustand der Technik | C30: =COUNTIF($B$12:$B$24,B30) -> 4 | D30: =COUNTIFS($B$12:$B$24,$B30,$E$12:$E$24,"N.I.O") -> 0 | E30: =COUNTIFS($B$12:$B$24,$B30,$E$12:$E$24,"bed. OK") -> 0 | F30: =COUNTIFS($B$12:$B$24,$B30,$E$12:$E$24,"OK") -> 0 | G30: =COUNTIFS($B$12:$B$24,$B30,$E$12:$E$24,"n. b.") -> 0 | H30: =C30-SUM(D30:G30) -> 4 | I30: =IFERROR((F30+Gewicht_bedOK*E30)/(D30+E30+F30),"")
B31: Rüsten & Störungen | C31: =COUNTIF($B$12:$B$24,B31) -> 3 | D31: =COUNTIFS($B$12:$B$24,$B31,$E$12:$E$24,"N.I.O") -> 0 | E31: =COUNTIFS($B$12:$B$24,$B31,$E$12:$E$24,"bed. OK") -> 0 | F31: =COUNTIFS($B$12:$B$24,$B31,$E$12:$E$24,"OK") -> 0 | G31: =COUNTIFS($B$12:$B$24,$B31,$E$12:$E$24,"n. b.") -> 0 | H31: =C31-SUM(D31:G31) -> 3 | I31: =IFERROR((F31+Gewicht_bedOK*E31)/(D31+E31+F31),"")

Sheet Audit_Werkzeuge
A1: Audit-Checkliste für: Werkzeuge
A2: Vorlage: Blatt „Auditcheckliste_Werkzeuge“ · Bewertung: WKZ (Werkzeugzustand)
G3: Ergebnis
A4: Werkzeug | G4: N.I.O | H4: =COUNTIF($E$12:$E$21,"N.I.O") -> 0 | I4: Erfüllungsgrad
A5: Equipmentnummer | G5: bed. OK | H5: =COUNTIF($E$12:$E$21,"bed. OK") -> 0 | I5: =IFERROR((H6+Gewicht_bedOK*H5)/(H4+H5+H6),"")
A6: Datum | G6: OK | H6: =COUNTIF($E$12:$E$21,"OK") -> 0
A7: Auditor | G7: n. b. | H7: =COUNTIF($E$12:$E$21,"n. b.") -> 0 | I7: =IF(I5="","nicht bewertet",IF(I5>=Ampel_gruen,"gut",IF(I5>=Ampel_gelb,"mittel","kritisch"))) -> nicht bewertet
A8: Abteilung / Bereich | G8: offen | H8: =10-SUM(H4:H7) -> 10
G9: Erfüllungsgrad = (OK + Gewicht × bed. OK) ÷ (N.I.O + bed. OK + OK); Gewicht und Ampelgrenzen auf „Übersicht“.
A11: Nr. | B11: Kapitel | C11: Check-Punkt | D11: Hinweis | E11: Bewertung | F11: Maßnahmen / Bemerkung | G11: Verantwortlich | H11: Termin | I11: Erledigt | J11: Status | K11: Maßn.-Nr.
A12: 1 | B12: Zustand | C12: Allgemeiner Zustand der Werkzeuge | J12: =IF(OR(E12="N.I.O",E12="bed. OK"),IF(I12="ja","erledigt",IF(AND(H12<>"",H12<TODAY()),"überfällig","offen")),"") | K12: =IF(OR(E12="N.I.O",E12="bed. OK"),Offset_werkzeug+COUNTIF($E$12:E12,"N.I.O")+COUNTIF($E$12:E12,"bed. OK"),"")
A13: 1.1 | B13: Zustand | C13: Sauberkeit | J13: =IF(OR(E13="N.I.O",E13="bed. OK"),IF(I13="ja","erledigt",IF(AND(H13<>"",H13<TODAY()),"überfällig","offen")),"") | K13: =IF(OR(E13="N.I.O",E13="bed. OK"),Offset_werkzeug+COUNTIF($E$12:E13,"N.I.O")+COUNTIF($E$12:E13,"bed. OK"),"")
A14: 1.2 | B14: Zustand | C14: Lagerung | J14: =IF(OR(E14="N.I.O",E14="bed. OK"),IF(I14="ja","erledigt",IF(AND(H14<>"",H14<TODAY()),"überfällig","offen")),"") | K14: =IF(OR(E14="N.I.O",E14="bed. OK"),Offset_werkzeug+COUNTIF($E$12:E14,"N.I.O")+COUNTIF($E$12:E14,"bed. OK"),"")
A15: 1.3 | B15: Zustand | C15: Schmierung | J15: =IF(OR(E15="N.I.O",E15="bed. OK"),IF(I15="ja","erledigt",IF(AND(H15<>"",H15<TODAY()),"überfällig","offen")),"") | K15: =IF(OR(E15="N.I.O",E15="bed. OK"),Offset_werkzeug+COUNTIF($E$12:E15,"N.I.O")+COUNTIF($E$12:E15,"bed. OK"),"")
A16: 2 | B16: Ersatzteile | C16: Ersatzteile für oben genanntes Werkzeug | J16: =IF(OR(E16="N.I.O",E16="bed. OK"),IF(I16="ja","erledigt",IF(AND(H16<>"",H16<TODAY()),"überfällig","offen")),"") | K16: =IF(OR(E16="N.I.O",E16="bed. OK"),Offset_werkzeug+COUNTIF($E$12:E16,"N.I.O")+COUNTIF($E$12:E16,"bed. OK"),"")
A17: 3 | B17: Inspektion & Wartung | C17: Gibt es Anweisungen für Inspektion und Wartung der Werkzeuge? | J17: =IF(OR(E17="N.I.O",E17="bed. OK"),IF(I17="ja","erledigt",IF(AND(H17<>"",H17<TODAY()),"überfällig","offen")),"") | K17: =IF(OR(E17="N.I.O",E17="bed. OK"),Offset_werkzeug+COUNTIF($E$12:E17,"N.I.O")+COUNTIF($E$12:E17,"bed. OK"),"")
A18: 3.1 | B18: Inspektion & Wartung | C18: Funktion und Zustand der Werkzeuge (bezogen auf durchgeführte Inspektion, siehe Checkliste) | J18: =IF(OR(E18="N.I.O",E18="bed. OK"),IF(I18="ja","erledigt",IF(AND(H18<>"",H18<TODAY()),"überfällig","offen")),"") | K18: =IF(OR(E18="N.I.O",E18="bed. OK"),Offset_werkzeug+COUNTIF($E$12:E18,"N.I.O")+COUNTIF($E$12:E18,"bed. OK"),"")
A19: 4 | B19: Dokumentation | C19: Verwaltung der technischen Dokumentation (Stücklisten, Werkzeugbeschreibung, technische Zeichnungen)? | J19: =IF(OR(E19="N.I.O",E19="bed. OK"),IF(I19="ja","erledigt",IF(AND(H19<>"",H19<TODAY()),"überfällig","offen")),"") | K19: =IF(OR(E19="N.I.O",E19="bed. OK"),Offset_werkzeug+COUNTIF($E$12:E19,"N.I.O")+COUNTIF($E$12:E19,"bed. OK"),"")
A20: 5 | B20: Verschleiß & Instandsetzung | C20: Nach welchen Kriterien entscheidet Instandhalter/Meister, dass ein Werkzeug verschleißbedingt überholt werden muss? Sind diese Kriterien schriftlich festgelegt, und wo? | J20: =IF(OR(E20="N.I.O",E20="bed. OK"),IF(I20="ja","erledigt",IF(AND(H20<>"",H20<TODAY()),"überfällig","offen")),"") | K20: =IF(OR(E20="N.I.O",E20="bed. OK"),Offset_werkzeug+COUNTIF($E$12:E20,"N.I.O")+COUNTIF($E$12:E20,"bed. OK"),"")
A21: 5.1 | B21: Verschleiß & Instandsetzung | C21: Vorgehensweise bei Nacharbeit und Instandsetzung der Werkzeuge | J21: =IF(OR(E21="N.I.O",E21="bed. OK"),IF(I21="ja","erledigt",IF(AND(H21<>"",H21<TODAY()),"überfällig","offen")),"") | K21: =IF(OR(E21="N.I.O",E21="bed. OK"),Offset_werkzeug+COUNTIF($E$12:E21,"N.I.O")+COUNTIF($E$12:E21,"bed. OK"),"")
A23: Auswertung je Kapitel
B24: Kapitel | C24: Punkte | D24: N.I.O | E24: bed. OK | F24: OK | G24: n. b. | H24: offen | I24: Erfüllungsgrad
B25: Zustand | C25: =COUNTIF($B$12:$B$21,B25) -> 4 | D25: =COUNTIFS($B$12:$B$21,$B25,$E$12:$E$21,"N.I.O") -> 0 | E25: =COUNTIFS($B$12:$B$21,$B25,$E$12:$E$21,"bed. OK") -> 0 | F25: =COUNTIFS($B$12:$B$21,$B25,$E$12:$E$21,"OK") -> 0 | G25: =COUNTIFS($B$12:$B$21,$B25,$E$12:$E$21,"n. b.") -> 0 | H25: =C25-SUM(D25:G25) -> 4 | I25: =IFERROR((F25+Gewicht_bedOK*E25)/(D25+E25+F25),"")
B26: Ersatzteile | C26: =COUNTIF($B$12:$B$21,B26) -> 1 | D26: =COUNTIFS($B$12:$B$21,$B26,$E$12:$E$21,"N.I.O") -> 0 | E26: =COUNTIFS($B$12:$B$21,$B26,$E$12:$E$21,"bed. OK") -> 0 | F26: =COUNTIFS($B$12:$B$21,$B26,$E$12:$E$21,"OK") -> 0 | G26: =COUNTIFS($B$12:$B$21,$B26,$E$12:$E$21,"n. b.") -> 0 | H26: =C26-SUM(D26:G26) -> 1 | I26: =IFERROR((F26+Gewicht_bedOK*E26)/(D26+E26+F26),"")
B27: Inspektion & Wartung | C27: =COUNTIF($B$12:$B$21,B27) -> 2 | D27: =COUNTIFS($B$12:$B$21,$B27,$E$12:$E$21,"N.I.O") -> 0 | E27: =COUNTIFS($B$12:$B$21,$B27,$E$12:$E$21,"bed. OK") -> 0 | F27: =COUNTIFS($B$12:$B$21,$B27,$E$12:$E$21,"OK") -> 0 | G27: =COUNTIFS($B$12:$B$21,$B27,$E$12:$E$21,"n. b.") -> 0 | H27: =C27-SUM(D27:G27) -> 2 | I27: =IFERROR((F27+Gewicht_bedOK*E27)/(D27+E27+F27),"")
B28: Dokumentation | C28: =COUNTIF($B$12:$B$21,B28) -> 1 | D28: =COUNTIFS($B$12:$B$21,$B28,$E$12:$E$21,"N.I.O") -> 0 | E28: =COUNTIFS($B$12:$B$21,$B28,$E$12:$E$21,"bed. OK") -> 0 | F28: =COUNTIFS($B$12:$B$21,$B28,$E$12:$E$21,"OK") -> 0 | G28: =COUNTIFS($B$12:$B$21,$B28,$E$12:$E$21,"n. b.") -> 0 | H28: =C28-SUM(D28:G28) -> 1 | I28: =IFERROR((F28+Gewicht_bedOK*E28)/(D28+E28+F28),"")
B29: Verschleiß & Instandsetzung | C29: =COUNTIF($B$12:$B$21,B29) -> 2 | D29: =COUNTIFS($B$12:$B$21,$B29,$E$12:$E$21,"N.I.O") -> 0 | E29: =COUNTIFS($B$12:$B$21,$B29,$E$12:$E$21,"bed. OK") -> 0 | F29: =COUNTIFS($B$12:$B$21,$B29,$E$12:$E$21,"OK") -> 0 | G29: =COUNTIFS($B$12:$B$21,$B29,$E$12:$E$21,"n. b.") -> 0 | H29: =C29-SUM(D29:G29) -> 2 | I29: =IFERROR((F29+Gewicht_bedOK*E29)/(D29+E29+F29),"")

Sheet Audit_Kompakt
A1: Audit-Checkliste für: Kompakt-Audit Anlage · Werkzeuge · Ersatzteile
A2: Vorlage: Blatt „Auditcheckliste_1“ · Bewertung: Zustand
G3: Ergebnis
A4: Maschinenbezeichnung | G4: N.I.O | H4: =COUNTIF($E$12:$E$35,"N.I.O") -> 0 | I4: Erfüllungsgrad
A5: Equipmentnummer | G5: bed. OK | H5: =COUNTIF($E$12:$E$35,"bed. OK") -> 0 | I5: =IFERROR((H6+Gewicht_bedOK*H5)/(H4+H5+H6),"")
A6: Datum | G6: OK | H6: =COUNTIF($E$12:$E$35,"OK") -> 0
A7: Auditor | G7: n. b. | H7: =COUNTIF($E$12:$E$35,"n. b.") -> 0 | I7: =IF(I5="","nicht bewertet",IF(I5>=Ampel_gruen,"gut",IF(I5>=Ampel_gelb,"mittel","kritisch"))) -> nicht bewertet
A8: Abteilung / Bereich | G8: offen | H8: =24-SUM(H4:H7) -> 24
G9: Erfüllungsgrad = (OK + Gewicht × bed. OK) ÷ (N.I.O + bed. OK + OK); Gewicht und Ampelgrenzen auf „Übersicht“.
A11: Nr. | B11: Kapitel | C11: Check-Punkt | D11: Normbezug | E11: Bewertung | F11: Maßnahmen / Bemerkung | G11: Verantwortlich | H11: Termin | I11: Erledigt | J11: Status | K11: Maßn.-Nr.
A12: A1 | B12: Anlage | C12: Allgemeiner Zustand der Maschine (Sauberkeit, Umgebung) | J12: =IF(OR(E12="N.I.O",E12="bed. OK"),IF(I12="ja","erledigt",IF(AND(H12<>"",H12<TODAY()),"überfällig","offen")),"") | K12: =IF(OR(E12="N.I.O",E12="bed. OK"),Offset_kompakt+COUNTIF($E$12:E12,"N.I.O")+COUNTIF($E$12:E12,"bed. OK"),"")
A13: A2 | B13: Anlage | C13: Existiert eine vorbeugende Instandhaltung (aktuell / wird sie gelebt)? | J13: =IF(OR(E13="N.I.O",E13="bed. OK"),IF(I13="ja","erledigt",IF(AND(H13<>"",H13<TODAY()),"überfällig","offen")),"") | K13: =IF(OR(E13="N.I.O",E13="bed. OK"),Offset_kompakt+COUNTIF($E$12:E13,"N.I.O")+COUNTIF($E$12:E13,"bed. OK"),"")
A14: A3 | B14: Anlage | C14: Gibt es Schmierpläne in der Nähe der Maschinen? | J14: =IF(OR(E14="N.I.O",E14="bed. OK"),IF(I14="ja","erledigt",IF(AND(H14<>"",H14<TODAY()),"überfällig","offen")),"") | K14: =IF(OR(E14="N.I.O",E14="bed. OK"),Offset_kompakt+COUNTIF($E$12:E14,"N.I.O")+COUNTIF($E$12:E14,"bed. OK"),"")
A15: A4 | B15: Anlage | C15: Gibt es Nachweise über die wöchentlich, monatlich, … durchgeführten Wartungs- und Inspektionsarbeiten? | J15: =IF(OR(E15="N.I.O",E15="bed. OK"),IF(I15="ja","erledigt",IF(AND(H15<>"",H15<TODAY()),"überfällig","offen")),"") | K15: =IF(OR(E15="N.I.O",E15="bed. OK"),Offset_kompakt+COUNTIF($E$12:E15,"N.I.O")+COUNTIF($E$12:E15,"bed. OK"),"")
A16: A5 | B16: Anlage | C16: Sind die Schmierarbeiten gemäß den vorgegebenen Schmierintervallen durchgeführt? | J16: =IF(OR(E16="N.I.O",E16="bed. OK"),IF(I16="ja","erledigt",IF(AND(H16<>"",H16<TODAY()),"überfällig","offen")),"") | K16: =IF(OR(E16="N.I.O",E16="bed. OK"),Offset_kompakt+COUNTIF($E$12:E16,"N.I.O")+COUNTIF($E$12:E16,"bed. OK"),"")
A17: A6 | B17: Anlage | C17: Wie werden ungeplante Reparaturen durchgeführt? Werden Betriebsmittel dafür bereitgestellt? | J17: =IF(OR(E17="N.I.O",E17="bed. OK"),IF(I17="ja","erledigt",IF(AND(H17<>"",H17<TODAY()),"überfällig","offen")),"") | K17: =IF(OR(E17="N.I.O",E17="bed. OK"),Offset_kompakt+COUNTIF($E$12:E17,"N.I.O")+COUNTIF($E$12:E17,"bed. OK"),"")
A18: A7 | B18: Anlage | C18: Sicherheitseinrichtungen an der Anlage? | J18: =IF(OR(E18="N.I.O",E18="bed. OK"),IF(I18="ja","erledigt",IF(AND(H18<>"",H18<TODAY()),"überfällig","offen")),"") | K18: =IF(OR(E18="N.I.O",E18="bed. OK"),Offset_kompakt+COUNTIF($E$12:E18,"N.I.O")+COUNTIF($E$12:E18,"bed. OK"),"")
A19: A8 | B19: Anlage | C19: Werden die Instandhalter geschult? | J19: =IF(OR(E19="N.I.O",E19="bed. OK"),IF(I19="ja","erledigt",IF(AND(H19<>"",H19<TODAY()),"überfällig","offen")),"") | K19: =IF(OR(E19="N.I.O",E19="bed. OK"),Offset_kompakt+COUNTIF($E$12:E19,"N.I.O")+COUNTIF($E$12:E19,"bed. OK"),"")
A20: A9 | B20: Anlage | C20: Technische Dokumente (System, Stücklisten, technische Zeichnungen) | J20: =IF(OR(E20="N.I.O",E20="bed. OK"),IF(I20="ja","erledigt",IF(AND(H20<>"",H20<TODAY()),"überfällig","offen")),"") | K20: =IF(OR(E20="N.I.O",E20="bed. OK"),Offset_kompakt+COUNTIF($E$12:E20,"N.I.O")+COUNTIF($E$12:E20,"bed. OK"),"")
A21: A10 | B21: Anlage | C21: Werden die Anlagen bereitgestellt? | J21: =IF(OR(E21="N.I.O",E21="bed. OK"),IF(I21="ja","erledigt",IF(AND(H21<>"",H21<TODAY()),"überfällig","offen")),"") | K21: =IF(OR(E21="N.I.O",E21="bed. OK"),Offset_kompakt+COUNTIF($E$12:E21,"N.I.O")+COUNTIF($E$12:E21,"bed. OK"),"")
A22: A11 | B22: Anlage | C22: Betreuung | J22: =IF(OR(E22="N.I.O",E22="bed. OK"),IF(I22="ja","erledigt",IF(AND(H22<>"",H22<TODAY()),"überfällig","offen")),"") | K22: =IF(OR(E22="N.I.O",E22="bed. OK"),Offset_kompakt+COUNTIF($E$12:E22,"N.I.O")+COUNTIF($E$12:E22,"bed. OK"),"")
A23: N1 | B23: Normanforderungen (ISO/TS 16949) | C23: Ermittelt die Organisation die für Schlüsselprozesse notwendigen Anlagen, stellt sie Ressourcen für die Instandhaltung der Maschinen und Betriebsmittel bereit und baut sie ein wirksames, geplantes, vorbeugendes Instandhaltungssystem auf? | D23: ISO/TS 16949:2009, 7.5.1.4 | J23: =IF(OR(E23="N.I.O",E23="bed. OK"),IF(I23="ja","erledigt",IF(AND(H23<>"",H23<TODAY()),"überfällig","offen")),"") | K23: =IF(OR(E23="N.I.O",E23="bed. OK"),Offset_kompakt+COUNTIF($E$12:E23,"N.I.O")+COUNTIF($E$12:E23,"bed. OK"),"")
A24: N2a | B24: Normanforderungen (ISO/TS 16949) | C24: Umfasst das vorbeugende Instandhaltungssystem geplante Instandhaltungstätigkeiten? | D24: ISO/TS 16949:2009, 7.5.1.4 | J24: =IF(OR(E24="N.I.O",E24="bed. OK"),IF(I24="ja","erledigt",IF(AND(H24<>"",H24<TODAY()),"überfällig","offen")),"") | K24: =IF(OR(E24="N.I.O",E24="bed. OK"),Offset_kompakt+COUNTIF($E$12:E24,"N.I.O")+COUNTIF($E$12:E24,"bed. OK"),"")
A25: N2b | B25: Normanforderungen (ISO/TS 16949) | C25: … Verpackung und Konservierung von Betriebsmitteln, Werkzeugen und Prüfmitteln? | D25: ISO/TS 16949:2009, 7.5.1.4 | J25: =IF(OR(E25="N.I.O",E25="bed. OK"),IF(I25="ja","erledigt",IF(AND(H25<>"",H25<TODAY()),"überfällig","offen")),"") | K25: =IF(OR(E25="N.I.O",E25="bed. OK"),Offset_kompakt+COUNTIF($E$12:E25,"N.I.O")+COUNTIF($E$12:E25,"bed. OK"),"")
A26: N2c | B26: Normanforderungen (ISO/TS 16949) | C26: … Verfügbarkeit von Ersatzteilen für Produktionseinrichtungen von Schlüsselprozessen? | D26: ISO/TS 16949:2009, 7.5.1.4 | J26: =IF(OR(E26="N.I.O",E26="bed. OK"),IF(I26="ja","erledigt",IF(AND(H26<>"",H26<TODAY()),"überfällig","offen")),"") | K26: =IF(OR(E26="N.I.O",E26="bed. OK"),Offset_kompakt+COUNTIF($E$12:E26,"N.I.O")+COUNTIF($E$12:E26,"bed. OK"),"")
A27: N2d | B27: Normanforderungen (ISO/TS 16949) | C27: … Dokumentation, Bewertung und Weiterentwicklung der Instandhaltungsziele? | D27: ISO/TS 16949:2009, 7.5.1.4 | J27: =IF(OR(E27="N.I.O",E27="bed. OK"),IF(I27="ja","erledigt",IF(AND(H27<>"",H27<TODAY()),"überfällig","offen")),"") | K27: =IF(OR(E27="N.I.O",E27="bed. OK"),Offset_kompakt+COUNTIF($E$12:E27,"N.I.O")+COUNTIF($E$12:E27,"bed. OK"),"")
A28: N3 | B28: Normanforderungen (ISO/TS 16949) | C28: Hält die Organisation ihre Betriebsstätten in einem ordentlichen, sauberen Zustand und sorgt sie für deren Instandhaltung im Einklang mit den Erfordernissen des Produkts? | D28: ISO/TS 16949:2009, 6.4.2 | J28: =IF(OR(E28="N.I.O",E28="bed. OK"),IF(I28="ja","erledigt",IF(AND(H28<>"",H28<TODAY()),"überfällig","offen")),"") | K28: =IF(OR(E28="N.I.O",E28="bed. OK"),Offset_kompakt+COUNTIF($E$12:E28,"N.I.O")+COUNTIF($E$12:E28,"bed. OK"),"")
A29: W1 | B29: Werkzeuge & Ersatzteile | C29: Allgemeiner Zustand der Werkzeuge (Sauberkeit, Umgebung) | J29: =IF(OR(E29="N.I.O",E29="bed. OK"),IF(I29="ja","erledigt",IF(AND(H29<>"",H29<TODAY()),"überfällig","offen")),"") | K29: =IF(OR(E29="N.I.O",E29="bed. OK"),Offset_kompakt+COUNTIF($E$12:E29,"N.I.O")+COUNTIF($E$12:E29,"bed. OK"),"")
A30: W2 | B30: Werkzeuge & Ersatzteile | C30: Technische Dokumente Werkzeuge (System, Stücklisten, technische Zeichnungen) | J30: =IF(OR(E30="N.I.O",E30="bed. OK"),IF(I30="ja","erledigt",IF(AND(H30<>"",H30<TODAY()),"überfällig","offen")),"") | K30: =IF(OR(E30="N.I.O",E30="bed. OK"),Offset_kompakt+COUNTIF($E$12:E30,"N.I.O")+COUNTIF($E$12:E30,"bed. OK"),"")
A31: W3 | B31: Werkzeuge & Ersatzteile | C31: Nach welchen Kriterien entscheidet Instandhalter/Meister, dass ein Werkzeug verschleißbedingt überholt werden muss? | J31: =IF(OR(E31="N.I.O",E31="bed. OK"),IF(I31="ja","erledigt",IF(AND(H31<>"",H31<TODAY()),"überfällig","offen")),"") | K31: =IF(OR(E31="N.I.O",E31="bed. OK"),Offset_kompakt+COUNTIF($E$12:E31,"N.I.O")+COUNTIF($E$12:E31,"bed. OK"),"")
A32: W4 | B32: Werkzeuge & Ersatzteile | C32: Gibt es ein Werkzeugmanagement? Werkzeugmappen? | J32: =IF(OR(E32="N.I.O",E32="bed. OK"),IF(I32="ja","erledigt",IF(AND(H32<>"",H32<TODAY()),"überfällig","offen")),"") | K32: =IF(OR(E32="N.I.O",E32="bed. OK"),Offset_kompakt+COUNTIF($E$12:E32,"N.I.O")+COUNTIF($E$12:E32,"bed. OK"),"")
A33: E1 | B33: Werkzeuge & Ersatzteile | C33: Allgemeiner Zustand der Ersatzteile (Sauberkeit, Umgebung) | J33: =IF(OR(E33="N.I.O",E33="bed. OK"),IF(I33="ja","erledigt",IF(AND(H33<>"",H33<TODAY()),"überfällig","offen")),"") | K33: =IF(OR(E33="N.I.O",E33="bed. OK"),Offset_kompakt+COUNTIF($E$12:E33,"N.I.O")+COUNTIF($E$12:E33,"bed. OK"),"")
A34: E2 | B34: Werkzeuge & Ersatzteile | C34: Existieren flächendeckend Ersatzteillisten für eigen- und fremdgefertigte Maschinen? | J34: =IF(OR(E34="N.I.O",E34="bed. OK"),IF(I34="ja","erledigt",IF(AND(H34<>"",H34<TODAY()),"überfällig","offen")),"") | K34: =IF(OR(E34="N.I.O",E34="bed. OK"),Offset_kompakt+COUNTIF($E$12:E34,"N.I.O")+COUNTIF($E$12:E34,"bed. OK"),"")
A35: E3 | B35: Werkzeuge & Ersatzteile | C35: Technische Dokumente Ersatzteile (System, Stücklisten, technische Zeichnungen) | J35: =IF(OR(E35="N.I.O",E35="bed. OK"),IF(I35="ja","erledigt",IF(AND(H35<>"",H35<TODAY()),"überfällig","offen")),"") | K35: =IF(OR(E35="N.I.O",E35="bed. OK"),Offset_kompakt+COUNTIF($E$12:E35,"N.I.O")+COUNTIF($E$12:E35,"bed. OK"),"")
A37: Auswertung je Kapitel
B38: Kapitel | C38: Punkte | D38: N.I.O | E38: bed. OK | F38: OK | G38: n. b. | H38: offen | I38: Erfüllungsgrad
B39: Anlage | C39: =COUNTIF($B$12:$B$35,B39) -> 11 | D39: =COUNTIFS($B$12:$B$35,$B39,$E$12:$E$35,"N.I.O") -> 0 | E39: =COUNTIFS($B$12:$B$35,$B39,$E$12:$E$35,"bed. OK") -> 0 | F39: =COUNTIFS($B$12:$B$35,$B39,$E$12:$E$35,"OK") -> 0 | G39: =COUNTIFS($B$12:$B$35,$B39,$E$12:$E$35,"n. b.") -> 0 | H39: =C39-SUM(D39:G39) -> 11 | I39: =IFERROR((F39+Gewicht_bedOK*E39)/(D39+E39+F39),"")
B40: Normanforderungen (ISO/TS 16949) | C40: =COUNTIF($B$12:$B$35,B40) -> 6 | D40: =COUNTIFS($B$12:$B$35,$B40,$E$12:$E$35,"N.I.O") -> 0 | E40: =COUNTIFS($B$12:$B$35,$B40,$E$12:$E$35,"bed. OK") -> 0 | F40: =COUNTIFS($B$12:$B$35,$B40,$E$12:$E$35,"OK") -> 0 | G40: =COUNTIFS($B$12:$B$35,$B40,$E$12:$E$35,"n. b.") -> 0 | H40: =C40-SUM(D40:G40) -> 6 | I40: =IFERROR((F40+Gewicht_bedOK*E40)/(D40+E40+F40),"")
B41: Werkzeuge & Ersatzteile | C41: =COUNTIF($B$12:$B$35,B41) -> 7 | D41: =COUNTIFS($B$12:$B$35,$B41,$E$12:$E$35,"N.I.O") -> 0 | E41: =COUNTIFS($B$12:$B$35,$B41,$E$12:$E$35,"bed. OK") -> 0 | F41: =COUNTIFS($B$12:$B$35,$B41,$E$12:$E$35,"OK") -> 0 | G41: =COUNTIFS($B$12:$B$35,$B41,$E$12:$E$35,"n. b.") -> 0 | H41: =C41-SUM(D41:G41) -> 7 | I41: =IFERROR((F41+Gewicht_bedOK*E41)/(D41+E41+F41),"")

Sheet Maßnahmen
A1: Maßnahmenplan
A2: Füllt sich automatisch aus allen Prüfpunkten mit N.I.O oder bed. OK. Eingaben bitte in den Audit-Blättern machen.
A4: Nr. | B4: Checkliste | C4: Objekt | D4: Punkt | E4: Check-Punkt | F4: Bewertung | G4: Befund / Maßnahme | H4: Verantwortlich | I4: Termin | J4: Status
A5: =IF(1<=Übersicht!$M$17,1,"") | B5: =IFERROR(IF($A5="","",IF($A5<=Übersicht!$P$13,"Allgemein",IF($A5<=Übersicht!$P$14,"Maschine",IF($A5<=Übersicht!$P$15,"Werkzeug","Kompakt")))),"") | C5: =IFERROR(IF($A5="","",IF($A5<=Übersicht!$P$13,IF(Audit_Allgemein!$C$4="","–",Audit_Allgemein!$C$4),IF($A5<=Übersicht!$P$14,IF(Audit_Maschine!$C$4="","–",Audit_Maschine!$C$4),IF($A5<=Übersicht!$P$15,IF(Audit_Werkzeuge!$C$4="","–",Audit_Werkzeuge!$C$4),IF(Audit_Kompakt!$C$4="","–",Audit_Kompakt!$C$4))))),"") | D5: =IFERROR(IF($A5="","",IF($A5<=Übersicht!$P$13,IF(INDEX(Audit_Allgemein!$A$12:$A$50,MATCH($A5,Audit_Allgemein!$K$12:$K$50,0))="","",INDEX(Audit_Allgemein!$A$12:$A$50,MATCH($A5,Audit_Allgemein!$K$12:$K$50,0))),IF($A5<=Übersicht!$P$14,IF(INDEX(Audit_Maschine!$A$12:$A$24,MATCH($A5,Audit_Maschine!$K$12:$K$24,0))="","",INDEX(Audit_Maschine!$A$12:$A$24,MATCH($A5,Audit_Maschine!$K$12:$K$24,0))),IF($A5<=Übersicht!$P$15,IF(INDEX(Audit_Werkzeuge!$A$12:$A$21,MATCH($A5,Audit_Werkzeuge!$K$12:$K$21,0))="","",INDEX(Audit_Werkzeuge!$A$12:$A$21,MATCH($A5,Audit_Werkzeuge!$K$12:$K$21,0))),IF(INDEX(Audit_Kompakt!$A$12:$A$35,MATCH($A5,Audit_Kompakt!$K$12:$K$35,0))="","",INDEX(Audit_Kompakt!$A$12:$A$35,MATCH($A5,Audit_Kompakt!$K$12:$K$35,0))))))),"") | E5: =IFERROR(IF($A5="","",IF($A5<=Übersicht!$P$13,IF(INDEX(Audit_Allgemein!$C$12:$C$50,MATCH($A5,Audit_Allgemein!$K$12:$K$50,0))="","",INDEX(Audit_Allgemein!$C$12:$C$50,MATCH($A5,Audit_Allgemein!$K$12:$K$50,0))),IF($A5<=Übersicht!$P$14,IF(INDEX(Audit_Maschine!$C$12:$C$24,MATCH($A5,Audit_Maschine!$K$12:$K$24,0))="","",INDEX(Audit_Maschine!$C$12:$C$24,MATCH($A5,Audit_Maschine!$K$12:$K$24,0))),IF($A5<=Übersicht!$P$15,IF(INDEX(Audit_Werkzeuge!$C$12:$C$21,MATCH($A5,Audit_Werkzeuge!$K$12:$K$21,0))="","",INDEX(Audit_Werkzeuge!$C$12:$C$21,MATCH($A5,Audit_Werkzeuge!$K$12:$K$21,0))),IF(INDEX(Audit_Kompakt!$C$12:$C$35,MATCH($A5,Audit_Kompakt!$K$12:$K$35,0))="","",INDEX(Audit_Kompakt!$C$12:$C$35,MATCH($A5,Audit_Kompakt!$K$12:$K$35,0))))))),"") | F5: =IFERROR(IF($A5="","",IF($A5<=Übersicht!$P$13,IF(INDEX(Audit_Allgemein!$E$12:$E$50,MATCH($A5,Audit_Allgemein!$K$12:$K$50,0))="","",INDEX(Audit_Allgemein!$E$12:$E$50,MATCH($A5,Audit_Allgemein!$K$12:$K$50,0))),IF($A5<=Übersicht!$P$14,IF(INDEX(Audit_Maschine!$E$12:$E$24,MATCH($A5,Audit_Maschine!$K$12:$K$24,0))="","",INDEX(Audit_Maschine!$E$12:$E$24,MATCH($A5,Audit_Maschine!$K$12:$K$24,0))),IF($A5<=Übersicht!$P$15,IF(INDEX(Audit_Werkzeuge!$E$12:$E$21,MATCH($A5,Audit_Werkzeuge!$K$12:$K$21,0))="","",INDEX(Audit_Werkzeuge!$E$12:$E$21,MATCH($A5,Audit_Werkzeuge!$K$12:$K$21,0))),IF(INDEX(Audit_Kompakt!$E$12:$E$35,MATCH($A5,Audit_Kompakt!$K$12:$K$35,0))="","",INDEX(Audit_Kompakt!$E$12:$E$35,MATCH($A5,Audit_Kompakt!$K$12:$K$35,0))))))),"") | G5: =IFERROR(IF($A5="","",IF($A5<=Übersicht!$P$13,IF(INDEX(Audit_Allgemein!$F$12:$F$50,MATCH($A5,Audit_Allgemein!$K$12:$K$50,0))="","",INDEX(Audit_Allgemein!$F$12:$F$50,MATCH($A5,Audit_Allgemein!$K$12:$K$50,0))),IF($A5<=Übersicht!$P$14,IF(INDEX(Audit_Maschine!$F$12:$F$24,MATCH($A5,Audit_Maschine!$K$12:$K$24,0))="","",INDEX(Audit_Maschine!$F$12:$F$24,MATCH($A5,Audit_Maschine!$K$12:$K$24,0))),IF($A5<=Übersicht!$P$15,IF(INDEX(Audit_Werkzeuge!$F$12:$F$21,MATCH($A5,Audit_Werkzeuge!$K$12:$K$21,0))="","",INDEX(Audit_Werkzeuge!$F$12:$F$21,MATCH($A5,Audit_Werkzeuge!$K$12:$K$21,0))),IF(INDEX(Audit_Kompakt!$F$12:$F$35,MATCH($A5,Audit_Kompakt!$K$12:$K$35,0))="","",INDEX(Audit_Kompakt!$F$12:$F$35,MATCH($A5,Audit_Kompakt!$K$12:$K$35,0))))))),"") | H5: =IFERROR(IF($A5="","",IF($A5<=Übersicht!$P$13,IF(INDEX(Audit_Allgemein!$G$12:$G$50,MATCH($A5,Audit_Allgemein!$K$12:$K$50,0))="","",INDEX(Audit_Allgemein!$G$12:$G$50,MATCH($A5,Audit_Allgemein!$K$12:$K$50,0))),IF($A5<=Übersicht!$P$14,IF(INDEX(Audit_Maschine!$G$12:$G$24,MATCH($A5,Audit_Maschine!$K$12:$K$24,0))="","",INDEX(Audit_Maschine!$G$12:$G$24,MATCH($A5,Audit_Maschine!$K$12:$K$24,0))),IF($A5<=Übersicht!$P$15,IF(INDEX(Audit_Werkzeuge!$G$12:$G$21,MATCH($A5,Audit_Werkzeuge!$K$12:$K$21,0))="","",INDEX(Audit_Werkzeuge!$G$12:$G$21,MATCH($A5,Audit_Werkzeuge!$K$12:$K$21,0))),IF(INDEX(Audit_Kompakt!$G$12:$G$35,MATCH($A5,Audit_Kompakt!$K$12:$K$35,0))="","",INDEX(Audit_Kompakt!$G$12:$G$35,MATCH($A5,Audit_Kompakt!$K$12:$K$35,0))))))),"") | I5: =IFERROR(IF($A5="","",IF($A5<=Übersicht!$P$13,IF(INDEX(Audit_Allgemein!$H$12:$H$50,MATCH($A5,Audit_Allgemein!$K$12:$K$50,0))="","",INDEX(Audit_Allgemein!$H$12:$H$50,MATCH($A5,Audit_Allgemein!$K$12:$K$50,0))),IF($A5<=Übersicht!$P$14,IF(INDEX(Audit_Maschine!$H$12:$H$24,MATCH($A5,Audit_Maschine!$K$12:$K$24,0))="","",INDEX(Audit_Maschine!$H$12:$H$24,MATCH($A5,Audit_Maschine!$K$12:$K$24,0))),IF($A5<=Übersicht!$P$15,IF(INDEX(Audit_Werkzeuge!$H$12:$H$21,MATCH($A5,Audit_Werkzeuge!$K$12:$K$21,0))="","",INDEX(Audit_Werkzeuge!$H$12:$H$21,MATCH($A5,Audit_Werkzeuge!$K$12:$K$21,0))),IF(INDEX(Audit_Kompakt!$H$12:$H$35,MATCH($A5,Audit_Kompakt!$K$12:$K$35,0))="","",INDEX(Audit_Kompakt!$H$12:$H$35,MATCH($A5,Audit_Kompakt!$K$12:$K$35,0))))))),"") | J5: =IFERROR(IF($A5="","",IF($A5<=Übersicht!$P$13,IF(INDEX(Audit_Allgemein!$J$12:$J$50,MATCH($A5,Audit_Allgemein!$K$12:$K$50,0))="","",INDEX(Audit_Allgemein!$J$12:$J$50,MATCH($A5,Audit_Allgemein!$K$12:$K$50,0))),IF($A5<=Übersicht!$P$14,IF(INDEX(Audit_Maschine!$J$12:$J$24,MATCH($A5,Audit_Maschine!$K$12:$K$24,0))="","",INDEX(Audit_Maschine!$J$12:$J$24,MATCH($A5,Audit_Maschine!$K$12:$K$24,0))),IF($A5<=Übersicht!$P$15,IF(INDEX(Audit_Werkzeuge!$J$12:$J$21,MATCH($A5,Audit_Werkzeuge!$K$12:$K$21,0))="","",INDEX(Audit_Werkzeuge!$J$12:$J$21,MATCH($A5,Audit_Werkzeuge!$K$12:$K$21,0))),IF(INDEX(Audit_Kompakt!$J$12:$J$35,MATCH($A5,Audit_Kompakt!$K$12:$K$35,0))="","",INDEX(Audit_Kompakt!$J$12:$J$35,MATCH($A5,Audit_Kompakt!$K$12:$K$35,0))))))),"")
A6: =IF(2<=Übersicht!$M$17,2,"") | B6: =IFERROR(IF($A6="","",IF($A6<=Übersicht!$P$13,"Allgemein",IF($A6<=Übersicht!$P$14,"Maschine",IF($A6<=Übersicht!$P$15,"Werkzeug","Kompakt")))),"") | C6: =IFERROR(IF($A6="","",IF($A6<=Übersicht!$P$13,IF(Audit_Allgemein!$C$4="","–",Audit_Allgemein!$C$4),IF($A6<=Übersicht!$P$14,IF(Audit_Maschine!$C$4="","–",Audit_Maschine!$C$4),IF($A6<=Übersicht!$P$15,IF(Audit_Werkzeuge!$C$4="","–",Audit_Werkzeuge!$C$4),IF(Audit_Kompakt!$C$4="","–",Audit_Kompakt!$C$4))))),"") | D6: =IFERROR(IF($A6="","",IF($A6<=Übersicht!$P$13,IF(INDEX(Audit_Allgemein!$A$12:$A$50,MATCH($A6,Audit_Allgemein!$K$12:$K$50,0))="","",INDEX(Audit_Allgemein!$A$12:$A$50,MATCH($A6,Audit_Allgemein!$K$12:$K$50,0))),IF($A6<=Übersicht!$P$14,IF(INDEX(Audit_Maschine!$A$12:$A$24,MATCH($A6,Audit_Maschine!$K$12:$K$24,0))="","",INDEX(Audit_Maschine!$A$12:$A$24,MATCH($A6,Audit_Maschine!$K$12:$K$24,0))),IF($A6<=Übersicht!$P$15,IF(INDEX(Audit_Werkzeuge!$A$12:$A$21,MATCH($A6,Audit_Werkzeuge!$K$12:$K$21,0))="","",INDEX(Audit_Werkzeuge!$A$12:$A$21,MATCH($A6,Audit_Werkzeuge!$K$12:$K$21,0))),IF(INDEX(Audit_Kompakt!$A$12:$A$35,MATCH($A6,Audit_Kompakt!$K$12:$K$35,0))="","",INDEX(Audit_Kompakt!$A$12:$A$35,MATCH($A6,Audit_Kompakt!$K$12:$K$35,0))))))),"") | E6: =IFERROR(IF($A6="","",IF($A6<=Übersicht!$P$13,IF(INDEX(Audit_Allgemein!$C$12:$C$50,MATCH($A6,Audit_Allgemein!$K$12:$K$50,0))="","",INDEX(Audit_Allgemein!$C$12:$C$50,MATCH($A6,Audit_Allgemein!$K$12:$K$50,0))),IF($A6<=Übersicht!$P$14,IF(INDEX(Audit_Maschine!$C$12:$C$24,MATCH($A6,Audit_Maschine!$K$12:$K$24,0))="","",INDEX(Audit_Maschine!$C$12:$C$24,MATCH($A6,Audit_Maschine!$K$12:$K$24,0))),IF($A6<=Übersicht!$P$15,IF(INDEX(Audit_Werkzeuge!$C$12:$C$21,MATCH($A6,Audit_Werkzeuge!$K$12:$K$21,0))="","",INDEX(Audit_Werkzeuge!$C$12:$C$21,MATCH($A6,Audit_Werkzeuge!$K$12:$K$21,0))),IF(INDEX(Audit_Kompakt!$C$12:$C$35,MATCH($A6,Audit_Kompakt!$K$12:$K$35,0))="","",INDEX(Audit_Kompakt!$C$12:$C$35,MATCH($A6,Audit_Kompakt!$K$12:$K$35,0))))))),"") | F6: =IFERROR(IF($A6="","",IF($A6<=Übersicht!$P$13,IF(INDEX(Audit_Allgemein!$E$12:$E$50,MATCH($A6,Audit_Allgemein!$K$12:$K$50,0))="","",INDEX(Audit_Allgemein!$E$12:$E$50,MATCH($A6,Audit_Allgemein!$K$12:$K$50,0))),IF($A6<=Übersicht!$P$14,IF(INDEX(Audit_Maschine!$E$12:$E$24,MATCH($A6,Audit_Maschine!$K$12:$K$24,0))="","",INDEX(Audit_Maschine!$E$12:$E$24,MATCH($A6,Audit_Maschine!$K$12:$K$24,0))),IF($A6<=Übersicht!$P$15,IF(INDEX(Audit_Werkzeuge!$E$12:$E$21,MATCH($A6,Audit_Werkzeuge!$K$12:$K$21,0))="","",INDEX(Audit_Werkzeuge!$E$12:$E$21,MATCH($A6,Audit_Werkzeuge!$K$12:$K$21,0))),IF(INDEX(Audit_Kompakt!$E$12:$E$35,MATCH($A6,Audit_Kompakt!$K$12:$K$35,0))="","",INDEX(Audit_Kompakt!$E$12:$E$35,MATCH($A6,Audit_Kompakt!$K$12:$K$35,0))))))),"") | G6: =IFERROR(IF($A6="","",IF($A6<=Übersicht!$P$13,IF(INDEX(Audit_Allgemein!$F$12:$F$50,MATCH($A6,Audit_Allgemein!$K$12:$K$50,0))="","",INDEX(Audit_Allgemein!$F$12:$F$50,MATCH($A6,Audit_Allgemein!$K$12:$K$50,0))),IF($A6<=Übersicht!$P$14,IF(INDEX(Audit_Maschine!$F$12:$F$24,MATCH($A6,Audit_Maschine!$K$12:$K$24,0))="","",INDEX(Audit_Maschine!$F$12:$F$24,MATCH($A6,Audit_Maschine!$K$12:$K$24,0))),IF($A6<=Übersicht!$P$15,IF(INDEX(Audit_Werkzeuge!$F$12:$F$21,MATCH($A6,Audit_Werkzeuge!$K$12:$K$21,0))="","",INDEX(Audit_Werkzeuge!$F$12:$F$21,MATCH($A6,Audit_Werkzeuge!$K$12:$K$21,0))),IF(INDEX(Audit_Kompakt!$F$12:$F$35,MATCH($A6,Audit_Kompakt!$K$12:$K$35,0))="","",INDEX(Audit_Kompakt!$F$12:$F$35,MATCH($A6,Audit_Kompakt!$K$12:$K$35,0))))))),"") | H6: =IFERROR(IF($A6="","",IF($A6<=Übersicht!$P$13,IF(INDEX(Audit_Allgemein!$G$12:$G$50,MATCH($A6,Audit_Allgemein!$K$12:$K$50,0))="","",INDEX(Audit_Allgemein!$G$12:$G$50,MATCH($A6,Audit_Allgemein!$K$12:$K$50,0))),IF($A6<=Übersicht!$P$14,IF(INDEX(Audit_Maschine!$G$12:$G$24,MATCH($A6,Audit_Maschine!$K$12:$K$24,0))="","",INDEX(Audit_Maschine!$G$12:$G$24,MATCH($A6,Audit_Maschine!$K$12:$K$24,0))),IF($A6<=Übersicht!$P$15,IF(INDEX(Audit_Werkzeuge!$G$12:$G$21,MATCH($A6,Audit_Werkzeuge!$K$12:$K$21,0))="","",INDEX(Audit_Werkzeuge!$G$12:$G$21,MATCH($A6,Audit_Werkzeuge!$K$12:$K$21,0))),IF(INDEX(Audit_Kompakt!$G$12:$G$35,MATCH($A6,Audit_Kompakt!$K$12:$K$35,0))="","",INDEX(Audit_Kompakt!$G$12:$G$35,MATCH($A6,Audit_Kompakt!$K$12:$K$35,0))))))),"") | I6: =IFERROR(IF($A6="","",IF($A6<=Übersicht!$P$13,IF(INDEX(Audit_Allgemein!$H$12:$H$50,MATCH($A6,Audit_Allgemein!$K$12:$K$50,0))="","",INDEX(Audit_Allgemein!$H$12:$H$50,MATCH($A6,Audit_Allgemein!$K$12:$K$50,0))),IF($A6<=Übersicht!$P$14,IF(INDEX(Audit_Maschine!$H$12:$H$24,MATCH($A6,Audit_Maschine!$K$12:$K$24,0))="","",INDEX(Audit_Maschine!$H$12:$H$24,MATCH($A6,Audit_Maschine!$K$12:$K$24,0))),IF($A6<=Übersicht!$P$15,IF(INDEX(Audit_Werkzeuge!$H$12:$H$21,MATCH($A6,Audit_Werkzeuge!$K$12:$K$21,0))="","",INDEX(Audit_Werkzeuge!$H$12:$H$21,MATCH($A6,Audit_Werkzeuge!$K$12:$K$21,0))),IF(INDEX(Audit_Kompakt!$H$12:$H$35,MATCH($A6,Audit_Kompakt!$K$12:$K$35,0))="","",INDEX(Audit_Kompakt!$H$12:$H$35,MATCH($A6,Audit_Kompakt!$K$12:$K$35,0))))))),"") | J6: =IFERROR(IF($A6="","",IF($A6<=Übersicht!$P$13,IF(INDEX(Audit_Allgemein!$J$12:$J$50,MATCH($A6,Audit_Allgemein!$K$12:$K$50,0))="","",INDEX(Audit_Allgemein!$J$12:$J$50,MATCH($A6,Audit_Allgemein!$K$12:$K$50,0))),IF($A6<=Übersicht!$P$14,IF(INDEX(Audit_Maschine!$J$12:$J$24,MATCH($A6,Audit_Maschine!$K$12:$K$24,0))="","",INDEX(Audit_Maschine!$J$12:$J$24,MATCH($A6,Audit_Maschine!$K$12:$K$24,0))),IF($A6<=Übersicht!$P$15,IF(INDEX(Audit_Werkzeuge!$J$12:$J$21,MATCH($A6,Audit_Werkzeuge!$K$12:$K$21,0))="","",INDEX(Audit_Werkzeuge!$J$12:$J$21,MATCH($A6,Audit_Werkzeuge!$K$12:$K$21,0))),IF(INDEX(Audit_Kompakt!$J$12:$J$35,MATCH($A6,Audit_Kompakt!$K$12:$K$35,0))="","",INDEX(Audit_Kompakt!$J$12:$J$35,MATCH($A6,Audit_Kompakt!$K$12:$K$35,0))))))),"")
