Workbook
Name P_Grenze_mittel: Parameter!$C$7
Name P_Grenze_hoch: Parameter!$C$8
Name P_Grenze_kritisch: Parameter!$C$9
Name Kl_Name: Parameter!$B$13:$B$16
Name Kl_Intervall: Parameter!$E$13:$E$16
Name Iv_Name: Parameter!$B$20:$B$26
Name Iv_Wochen: Parameter!$C$20:$C$26
Name SF_Modell: Parameter!$B$30:$B$32
Name SF_Wert: Parameter!$C$30:$C$32
Name IH_Text: Parameter!$C$36:$C$40
Name P_Krit: Parameter!$C$44
Name P_Vorwarn: Parameter!$C$45
Name L_Art: Parameter!$B$49:$B$55
Name L_Ausfuehrung: Parameter!$D$49:$D$53
Name L_Befund: Parameter!$F$49:$F$51
Name L_Status: Parameter!$G$49:$G$52
Name P_SF: Deckblatt!$C$12
Name M_Name: Deckblatt!$C$7
Name M_Equipment: Deckblatt!$C$8

Sheet Deckblatt
B2: Wartungsintervallberechnung – große Wartung
B3: Horizontale hydraulische Simultanbalgmaschine (HSIM) · risikobasierte Festlegung der Wartungsintervalle (RPZ)
B6: Stammdaten der Anlage
B7: Maschinenbezeichnung | C7: Horizontale hydraulische Simultanbalgmaschine (HSIM)
B8: Equipmentnummer (SAP)
B9: Standort / Kostenstelle
B10: Hersteller / Baujahr
B11: Schichtmodell | C11: 3-Schicht
B12: Schichtfaktor SF (automatisch) | C12: =IFERROR(INDEX(SF_Wert,MATCH(C11,SF_Modell,0)),1)
B13: Ablage | C13: =CELL("filename")
B15: Dokumentenlenkung
B16: Verantwortlich für Änderungen | C16: fz-pA / H. Mrugalla
B17: Stand / Version | C17: 02 (Entwurf – Freigabe ausstehend)
B18: Datum Stand | C18: =DATE(2026,10,17)
B19: Überarbeitet von
B20: Nächste Überprüfung der Bewertung | C20: =EDATE(C18,12)
B22: Freigabe (interdisziplinäres Team)
B23: Funktion | C23: Name | D23: Datum | E23: Unterschrift
B24: Instandhaltung (Ersteller)
B25: Produktion / Fertigung
B26: Qualitätsmanagement
B27: Arbeitssicherheit / Umwelt
B29: Änderungshistorie
B30: Stand | C30: Datum | D30: Änderung | G30: Bearbeiter
B31: 01 | C31: 03.02.2009 | D31: Ersterstellung Wartungsintervallberechnung | G31: fz-pA / H. Mrugalla
B32: 02 (Entwurf) | C32: 17.10.2026 | D32: Strukturelle Überarbeitung: einheitliche Nummerierung und Formulierungen, Ampellogik, Dashboard, Durchführungsnachweis, konsolidierter Bewertungskatalog, Parameterblatt, offene Punkte. Alle Bewertungen unverändert übernommen (Details: Blatt „Änderungsprotokoll“).
B35: Aufbau der Datei
B36: Blatt | C36: Inhalt / Zweck | G36: Zielgruppe
B37: Dashboard | C37: Kennzahlen, Risikoverteilung, Top-10-Risiken, Risikomatrix, Auswertung je Baugruppe, Durchführungsstatus | G37: Management, QM, IH-Leitung
B38: Wartungsplan | C38: Alle Wartungsmaßnahmen mit Bewertung (F, IH, Q, AS, US, S, A, E, SF), RPZ, Risikoklasse (Ampel) und Intervall | G38: Instandhaltung, Produktion
B39: Durchführungsnachweis | C39: Letzte Durchführung je Maßnahme, nächste Fälligkeit, Status (überfällig / bald fällig / i.O.), Befund | G39: Instandhaltung, QM (Audit)
B40: Anlagenübersicht | C40: Übersichtszeichnung mit Positionsnummern und Zuordnung zu den Abschnitten des Wartungsplans | G40: alle
B41: Bewertungskatalog | C41: Bewertungsskalen 1–5 aller Kriterien auf einem Blatt (ersetzt 8 Einzelblätter der Vorversion) | G41: Bewertungsteam
B42: RPZ-Methodik | C42: Berechnungslogik der RPZ, Wertebereiche, Rechenbeispiel | G42: Bewertungsteam, QM, Management
B43: Parameter | C43: Grenzwerte, Intervalle, Schichtfaktor, Auswahllisten – zentrale Stellschrauben | G43: IH-Leitung
B44: Offene Punkte | C44: Bei der Überarbeitung festgestellte Lücken/Unstimmigkeiten mit Maßnahmenverfolgung | G44: Bewertungsteam
B45: Weiterentwicklung | C45: Vorschläge für zusätzliche Kriterien und Kennzahlen (IATF 16949, TPM) | G45: Management, QM
B46: Änderungsprotokoll | C46: Alle wesentlichen Änderungen gegenüber der Vorversion mit Begründung | G46: QM, Dokumentenlenkung
B48: Anwendung in 5 Schritten
B49: 1. Stammdaten und Schichtmodell oben eintragen (gelbe Felder). Der Schichtfaktor wird automatisch für alle Maßnahmen übernommen.
...

Sheet Dashboard
B1: Dashboard – Wartungsplan & Risikobewertung
B2: =M_Name&" · Equipment-Nr.: "&IF(M_Equipment="","–",M_Equipment)&" · Stand der Auswertung: "&TEXT(TODAY(),"DD.MM.YYYY")
B5: Risiko & Bewertung | J5: Durchführung & Aufwand
B6: Kennzahl | C6: Wert | D6: Erläuterung | J6: Kennzahl | L6: Wert | M6: Erläuterung
B7: Wartungsmaßnahmen gesamt | C7: =COUNTIF(Wartungsplan!$AE$6:$AE$323,"Maßnahme") | D7: Anzahl Maßnahmenzeilen im Wartungsplan | J7: Überfällige Maßnahmen | L7: =COUNTIF('Durchführungsnachweis'!$J$6:$J$293,"überfällig") | M7: Fälligkeit überschritten
B8: davon vollständig bewertet | C8: =COUNT(Wartungsplan!$R$6:$R$323) | D8: Maßnahmen mit berechneter RPZ | J8: Bald fällig | L8: =COUNTIF('Durchführungsnachweis'!$J$6:$J$293,"bald fällig") | M8: innerhalb Vorwarnzeit
B9: Bewertung unvollständig | C9: =COUNTIFS(Wartungsplan!$AE$6:$AE$323,"Maßnahme",Wartungsplan!$S$6:$S$323,"unvollständig") | D9: Kein Intervall ermittelbar → siehe Offene Punkte | J9: In Ordnung | L9: =COUNTIF('Durchführungsnachweis'!$J$6:$J$293,"in Ordnung") | M9: fristgerecht durchgeführt
B10: Ø RPZ | C10: =IFERROR(AVERAGE(Wartungsplan!$R$6:$R$323),0) | D10: Mittelwert aller bewerteten Maßnahmen | J10: Noch nicht erfasst | L10: =COUNTIF('Durchführungsnachweis'!$J$6:$J$293,"nicht erfasst") | M10: ohne Durchführungsdatum
B11: Maximale RPZ | C11: =IFERROR(MAX(Wartungsplan!$R$6:$R$323),0) | D11: Höchstes Einzelrisiko (Grenze „kritisch“ > 125) | J11: Termintreue (PM-Compliance) | L11: =IFERROR((L9+L8)/(L7+L8+L9),"–") | M11: nicht überfällige / erfasste Maßnahmen (IATF 8.5.1.5)
B12: Hohes oder kritisches Risiko | C12: =COUNTIF(Wartungsplan!$S$6:$S$323,"hoch")+COUNTIF(Wartungsplan!$S$6:$S$323,"kritisch") | D12: Maßnahmen mit Intervall ≤ 8 Wochen | J12: Befunde n.i.O. | L12: =COUNTIF('Durchführungsnachweis'!$K$6:$K$293,"n.i.O.*") | M12: Abweichungen bei letzter Durchführung
B13: Arbeitssicherheitsrelevant (AS ≥ Schwelle) | C13: =COUNTIFS(Wartungsplan!$AE$6:$AE$323,"Maßnahme",Wartungsplan!$K$6:$K$323,">="&P_Krit) | D13: Bewertung AS ≥ Relevanzschwelle (Parameter) | J13: Durchführungen pro Jahr (Soll) | L13: =SUMPRODUCT((Wartungsplan!$AE$6:$AE$323="Maßnahme")*IFERROR(52/Wartungsplan!$V$6:$V$323,0)) | M13: Summe aus festgelegten Intervallen
B14: Qualitätsrelevant (Q ≥ Schwelle) | C14: =COUNTIFS(Wartungsplan!$AE$6:$AE$323,"Maßnahme",Wartungsplan!$J$6:$J$323,">="&P_Krit) | D14: Bewertung Q ≥ Relevanzschwelle – Bezug zu Control Plan / FMEA prüfen | J14: Geplanter Aufwand [h/Jahr] | L14: =SUM(Wartungsplan!$AB$6:$AB$323) | M14: aus Plan-Zeiten; Basis Kapazitätsplanung
B15: Umweltrelevant (US ≥ Schwelle) | C15: =COUNTIFS(Wartungsplan!$AE$6:$AE$323,"Maßnahme",Wartungsplan!$L$6:$L$323,">="&P_Krit) | D15: Bewertung US ≥ Relevanzschwelle | J15: Plan-Zeiten erfasst | L15: =COUNT(Wartungsplan!$AA$6:$AA$323)&" von "&C7 | M15: Aufwand ist erst bei vollständigen Plan-Zeiten aussagekräftig
B16: Abweichend festgelegte Intervalle | C16: =SUMPRODUCT((Wartungsplan!$AE$6:$AE$323="Maßnahme")*(Wartungsplan!$U$6:$U$323<>Wartungsplan!$T$6:$T$323)) | D16: Festgelegt ≠ berechnet (Begründung erforderlich) | J16: Maßnahmen mit Ausführungszuordnung | L16: =COUNTIFS(Wartungsplan!$AE$6:$AE$323,"Maßnahme",Wartungsplan!$Z$6:$Z$323,"?*")&" von "&C7 | M16: Spalte „Ausführung durch“ im Wartungsplan
B18: Risikoverteilung
B19: Risikoklasse | C19: Anzahl | D19: Anteil | E19: Intervall
B20: gering | C20: =COUNTIFS(Wartungsplan!$AE$6:$AE$323,"Maßnahme",Wartungsplan!$S$6:$S$323,B20) | D20: =IFERROR(C20/$C$25,0) | E20: =IFERROR(INDEX(Kl_Intervall,MATCH(B20,Kl_Name,0)),"–")
B21: mittel | C21: =COUNTIFS(Wartungsplan!$AE$6:$AE$323,"Maßnahme",Wartungsplan!$S$6:$S$323,B21) | D21: =IFERROR(C21/$C$25,0) | E21: =IFERROR(INDEX(Kl_Intervall,MATCH(B21,Kl_Name,0)),"–")
B22: hoch | C22: =COUNTIFS(Wartungsplan!$AE$6:$AE$323,"Maßnahme",Wartungsplan!$S$6:$S$323,B22) | D22: =IFERROR(C22/$C$25,0) | E22: =IFERROR(INDEX(Kl_Intervall,MATCH(B22,Kl_Name,0)),"–")
B23: kritisch | C23: =COUNTIFS(Wartungsplan!$AE$6:$AE$323,"Maßnahme",Wartungsplan!$S$6:$S$323,B23) | D23: =IFERROR(C23/$C$25,0) | E23: =IFERROR(INDEX(Kl_Intervall,MATCH(B23,Kl_Name,0)),"–")
B24: unvollständig | C24: =COUNTIFS(Wartungsplan!$AE$6:$AE$323,"Maßnahme",Wartungsplan!$S$6:$S$323,B24) | D24: =IFERROR(C24/$C$25,0) | E24: =IFERROR(INDEX(Kl_Intervall,MATCH(B24,Kl_Name,0)),"–")
B25: Summe | C25: =SUM(C20:C24) | D25: =SUM(D20:D24)
B27: Maßnahmen je festgelegtem Intervall
B28: Intervall | C28: Anzahl | D28: Durchf./Jahr | E28: Aufwand h/Jahr
B29: täglich | C29: =COUNTIFS(Wartungsplan!$AE$6:$AE$323,"Maßnahme",Wartungsplan!$U$6:$U$323,B29) | D29: =IFERROR(C29*52/INDEX(Iv_Wochen,MATCH(B29,Iv_Name,0)),0) | E29: =SUMIFS(Wartungsplan!$AB$6:$AB$323,Wartungsplan!$U$6:$U$323,B29)
B30: wöchentlich | C30: =COUNTIFS(Wartungsplan!$AE$6:$AE$323,"Maßnahme",Wartungsplan!$U$6:$U$323,B30) | D30: =IFERROR(C30*52/INDEX(Iv_Wochen,MATCH(B30,Iv_Name,0)),0) | E30: =SUMIFS(Wartungsplan!$AB$6:$AB$323,Wartungsplan!$U$6:$U$323,B30)
B31: 4 Wochen | C31: =COUNTIFS(Wartungsplan!$AE$6:$AE$323,"Maßnahme",Wartungsplan!$U$6:$U$323,B31) | D31: =IFERROR(C31*52/INDEX(Iv_Wochen,MATCH(B31,Iv_Name,0)),0) | E31: =SUMIFS(Wartungsplan!$AB$6:$AB$323,Wartungsplan!$U$6:$U$323,B31)
B32: 8 Wochen | C32: =COUNTIFS(Wartungsplan!$AE$6:$AE$323,"Maßnahme",Wartungsplan!$U$6:$U$323,B32) | D32: =IFERROR(C32*52/INDEX(Iv_Wochen,MATCH(B32,Iv_Name,0)),0) | E32: =SUMIFS(Wartungsplan!$AB$6:$AB$323,Wartungsplan!$U$6:$U$323,B32) | J32: Kriterienprofil (Ø Bewertung aller Maßnahmen)
B33: 16 Wochen | C33: =COUNTIFS(Wartungsplan!$AE$6:$AE$323,"Maßnahme",Wartungsplan!$U$6:$U$323,B33) | D33: =IFERROR(C33*52/INDEX(Iv_Wochen,MATCH(B33,Iv_Name,0)),0) | E33: =SUMIFS(Wartungsplan!$AB$6:$AB$323,Wartungsplan!$U$6:$U$323,B33) | J33: Kriterium | K33: Kürzel | L33: Ø Bewertung | M33: Anzahl ≥ 4
B34: halbjährlich | C34: =COUNTIFS(Wartungsplan!$AE$6:$AE$323,"Maßnahme",Wartungsplan!$U$6:$U$323,B34) | D34: =IFERROR(C34*52/INDEX(Iv_Wochen,MATCH(B34,Iv_Name,0)),0) | E34: =SUMIFS(Wartungsplan!$AB$6:$AB$323,Wartungsplan!$U$6:$U$323,B34) | J34: Funktionalität der Anlage | K34: F | L34: =IFERROR(AVERAGE(Wartungsplan!$H$6:$H$323),0) | M34: =COUNTIF(Wartungsplan!$H$6:$H$323,">=4")
B35: jährlich | C35: =COUNTIFS(Wartungsplan!$AE$6:$AE$323,"Maßnahme",Wartungsplan!$U$6:$U$323,B35) | D35: =IFERROR(C35*52/INDEX(Iv_Wochen,MATCH(B35,Iv_Name,0)),0) | E35: =SUMIFS(Wartungsplan!$AB$6:$AB$323,Wartungsplan!$U$6:$U$323,B35) | J35: Instandsetzungsaufwand | K35: IH | L35: =IFERROR(AVERAGE(Wartungsplan!$I$6:$I$323),0) | M35: =COUNTIF(Wartungsplan!$I$6:$I$323,">=4")
B36: Bewertung fehlt | C36: =COUNTIFS(Wartungsplan!$AE$6:$AE$323,"Maßnahme",Wartungsplan!$U$6:$U$323,B36) | D36: =IFERROR(C36*52/INDEX(Iv_Wochen,MATCH(B36,Iv_Name,0)),0) | E36: =SUMIFS(Wartungsplan!$AB$6:$AB$323,Wartungsplan!$U$6:$U$323,B36) | J36: Qualität / Kunde | K36: Q | L36: =IFERROR(AVERAGE(Wartungsplan!$J$6:$J$323),0) | M36: =COUNTIF(Wartungsplan!$J$6:$J$323,">=4")
J37: Arbeitssicherheit | K37: AS | L37: =IFERROR(AVERAGE(Wartungsplan!$K$6:$K$323),0) | M37: =COUNTIF(Wartungsplan!$K$6:$K$323,">=4")
J38: Umweltschutz | K38: US | L38: =IFERROR(AVERAGE(Wartungsplan!$L$6:$L$323),0) | M38: =COUNTIF(Wartungsplan!$L$6:$L$323,">=4")
B39: Risikomatrix: Ausfall- (A) × Entdeckungswahrscheinlichkeit (E) | J39: Schadenshöhe | K39: S | L39: =IFERROR(AVERAGE(Wartungsplan!$M$6:$M$323),0) | M39: =COUNTIF(Wartungsplan!$M$6:$M$323,">=4")
B40: A ↓ / E → | C40: 1 | D40: 2 | E40: 3 | F40: 4 | G40: 5 | J40: Ausfallwahrscheinlichkeit | K40: A | L40: =IFERROR(AVERAGE(Wartungsplan!$O$6:$O$323),0) | M40: =COUNTIF(Wartungsplan!$O$6:$O$323,">=4")
B41: A = 5 | C41: =COUNTIFS(Wartungsplan!$O$6:$O$323,5,Wartungsplan!$P$6:$P$323,1) | D41: =COUNTIFS(Wartungsplan!$O$6:$O$323,5,Wartungsplan!$P$6:$P$323,2) | E41: =COUNTIFS(Wartungsplan!$O$6:$O$323,5,Wartungsplan!$P$6:$P$323,3) | F41: =COUNTIFS(Wartungsplan!$O$6:$O$323,5,Wartungsplan!$P$6:$P$323,4) | G41: =COUNTIFS(Wartungsplan!$O$6:$O$323,5,Wartungsplan!$P$6:$P$323,5) | J41: Entdeckungswahrscheinlichkeit | K41: E | L41: =IFERROR(AVERAGE(Wartungsplan!$P$6:$P$323),0) | M41: =COUNTIF(Wartungsplan!$P$6:$P$323,">=4")
B42: A = 4 | C42: =COUNTIFS(Wartungsplan!$O$6:$O$323,4,Wartungsplan!$P$6:$P$323,1) | D42: =COUNTIFS(Wartungsplan!$O$6:$O$323,4,Wartungsplan!$P$6:$P$323,2) | E42: =COUNTIFS(Wartungsplan!$O$6:$O$323,4,Wartungsplan!$P$6:$P$323,3) | F42: =COUNTIFS(Wartungsplan!$O$6:$O$323,4,Wartungsplan!$P$6:$P$323,4) | G42: =COUNTIFS(Wartungsplan!$O$6:$O$323,4,Wartungsplan!$P$6:$P$323,5)
B43: A = 3 | C43: =COUNTIFS(Wartungsplan!$O$6:$O$323,3,Wartungsplan!$P$6:$P$323,1) | D43: =COUNTIFS(Wartungsplan!$O$6:$O$323,3,Wartungsplan!$P$6:$P$323,2) | E43: =COUNTIFS(Wartungsplan!$O$6:$O$323,3,Wartungsplan!$P$6:$P$323,3) | F43: =COUNTIFS(Wartungsplan!$O$6:$O$323,3,Wartungsplan!$P$6:$P$323,4) | G43: =COUNTIFS(Wartungsplan!$O$6:$O$323,3,Wartungsplan!$P$6:$P$323,5) | J43: Top-10-Risiken (höchste RPZ)
B44: A = 2 | C44: =COUNTIFS(Wartungsplan!$O$6:$O$323,2,Wartungsplan!$P$6:$P$323,1) | D44: =COUNTIFS(Wartungsplan!$O$6:$O$323,2,Wartungsplan!$P$6:$P$323,2) | E44: =COUNTIFS(Wartungsplan!$O$6:$O$323,2,Wartungsplan!$P$6:$P$323,3) | F44: =COUNTIFS(Wartungsplan!$O$6:$O$323,2,Wartungsplan!$P$6:$P$323,4) | G44: =COUNTIFS(Wartungsplan!$O$6:$O$323,2,Wartungsplan!$P$6:$P$323,5) | I44: Nr. | J44: Maßnahme | K44: Baugruppe | L44: RPZ | M44: Klasse | N44: Intervall
...

Sheet Wartungsplan
A1: Wartungsplan – risikobasierte Wartungsintervallberechnung (große Wartung)
A2: ="Maschine: "&M_Name&" · Equipment-Nr.: "&IF(M_Equipment="","(bitte auf Deckblatt eintragen)",M_Equipment)&" · Schichtfaktor SF: "&TEXT(P_SF,"0.00")
A3: Legende: gelb = Eingabe · weiß = Formel · grau kursiv = Vorschlag (freizugeben) · Bewertung 1 = gering … 5 = sehr hoch · B = √(F²+IH²+Q²+AS²+US²+S²)/2 · RPZ = B × A × E × SF
A4: Maßnahme | H4: Bedeutung B – Folgen bei Ausfall (1–5) | N4: Risikobewertung | S4: Ergebnis & Festlegung | X4: Planungsdaten | AC4: Gliederung & Rückverfolgbarkeit
A5: Nr. | B5: Auszuführende Maßnahme | C5: Art der Maßnahme | D5: Hinweis | E5: Objekt / Bild | F5: Hilfs-/Betriebsmittel, Einstellwerte | G5: Sollzustand / Prüfkriterium | H5: F | I5: IH | J5: Q | K5: AS | L5: US | M5: S | N5: B | O5: A | P5: E | Q5: SF | R5: RPZ | S5: Risikoklasse | T5: Intervall berechnet | U5: Intervall festgelegt | V5: Intervall [Wochen] | W5: Begründung Abweichung / Bemerkung | X5: Relevanz AS/Q/US | Y5: Instandsetzung bei Ausfall (lt. IH) | Z5: Ausführung durch | AA5: Plan-Zeit [min] | AB5: Aufwand [h/Jahr] | AC5: Baugruppe | AD5: Pos. Übersicht | AE5: Zeilentyp | AF5: Bewertung übernommen von | AG5: Nr. Vorversion | AH5: Originaltext Vorversion | AI5: Reihenfolge | AJ5: Rangschlüssel
A6: 1 | B6: Not-Aus | AC6: Not-Aus | AD6: – | AE6: Baugruppe | AG6: 1 | AH6: Not-Aus | AI6: 1
A7: 1.1 | B7: Funktion prüfen (Rasterung, Schaltwirkung) | C7: Funktionsprüfung | D7: ⚠ Gefahrenstelle | G7: Not-Aus sowie sicherheitsrelevante Einrichtungen werden täglich vor Arbeitsbeginn geprüft (Sichtkontrolle). | H7: 3 | I7: 3 | J7: 1 | K7: 5 | L7: 1 | M7: 2 | N7: =IF(COUNT(H7:M7)=6,SQRT(SUMSQ(H7:M7))/2,"") | O7: 2 | P7: 1 | Q7: =P_SF | R7: =IF(COUNT(N7:Q7)=4,N7*O7*P7*Q7,"") | S7: =IF(R7="","unvollständig",IF(R7>P_Grenze_kritisch,"kritisch",IF(R7>=P_Grenze_hoch,"hoch",IF(R7>=P_Grenze_mittel,"mittel","gering")))) | T7: =IF(S7="unvollständig","Bewertung fehlt",INDEX(Kl_Intervall,MATCH(S7,Kl_Name,0))) | U7: =T7 | V7: =IFERROR(INDEX(Iv_Wochen,MATCH(U7,Iv_Name,0)),"") | X7: =TRIM(IF(N(K7)>=P_Krit,"AS ","")&IF(N(J7)>=P_Krit,"Q ","")&IF(N(L7)>=P_Krit,"US","")) | Y7: =IF(ISNUMBER(I7),INDEX(IH_Text,I7),"") | AB7: =IF(AND(ISNUMBER(V7),ISNUMBER(AA7)),52/V7*AA7/60,"") | AC7: Not-Aus | AD7: – | AE7: Maßnahme | AG7: 1.1 | AH7: Prüfe die Funktion (Rasterung, Schaltwirkung) | AI7: 2 | AJ7: =IF(ISNUMBER(R7),R7-AI7/100000,"")
A8: 2 | B8: Bedienpult | AC8: Bedienpult | AD8: 1 | AE8: Baugruppe | AG8: 2 | AH8: 1.) Bedienpult | AI8: 3
A9: 2.1 | B9: Funktion aller Bedienelemente prüfen | C9: Funktionsprüfung | G9: Alle Bedienelemente schalten einwandfrei; keine Beschädigung | H9: 3 | I9: 2 | J9: 1 | K9: 3 | L9: 1 | M9: 3 | N9: =IF(COUNT(H9:M9)=6,SQRT(SUMSQ(H9:M9))/2,"") | O9: 2 | P9: 1 | Q9: =P_SF | R9: =IF(COUNT(N9:Q9)=4,N9*O9*P9*Q9,"") | S9: =IF(R9="","unvollständig",IF(R9>P_Grenze_kritisch,"kritisch",IF(R9>=P_Grenze_hoch,"hoch",IF(R9>=P_Grenze_mittel,"mittel","gering")))) | T9: =IF(S9="unvollständig","Bewertung fehlt",INDEX(Kl_Intervall,MATCH(S9,Kl_Name,0))) | U9: =T9 | V9: =IFERROR(INDEX(Iv_Wochen,MATCH(U9,Iv_Name,0)),"") | X9: =TRIM(IF(N(K9)>=P_Krit,"AS ","")&IF(N(J9)>=P_Krit,"Q ","")&IF(N(L9)>=P_Krit,"US","")) | Y9: =IF(ISNUMBER(I9),INDEX(IH_Text,I9),"") | AB9: =IF(AND(ISNUMBER(V9),ISNUMBER(AA9)),52/V9*AA9/60,"") | AC9: Bedienpult | AD9: 1 | AE9: Maßnahme | AG9: 2.1 | AH9: Prüfe die Funktion aller Bedienelemente | AI9: 4 | AJ9: =IF(ISNUMBER(R9),R9-AI9/100000,"")
A10: 2.2 | B10: Bedienpult reinigen | C10: Reinigung | G10: Bedienpult sauber; Anzeigen und Beschriftungen lesbar | H10: 1 | I10: 2 | J10: 1 | K10: 2 | L10: 1 | M10: 2 | N10: =IF(COUNT(H10:M10)=6,SQRT(SUMSQ(H10:M10))/2,"") | O10: 2 | P10: 1 | Q10: =P_SF | R10: =IF(COUNT(N10:Q10)=4,N10*O10*P10*Q10,"") | S10: =IF(R10="","unvollständig",IF(R10>P_Grenze_kritisch,"kritisch",IF(R10>=P_Grenze_hoch,"hoch",IF(R10>=P_Grenze_mittel,"mittel","gering")))) | T10: =IF(S10="unvollständig","Bewertung fehlt",INDEX(Kl_Intervall,MATCH(S10,Kl_Name,0))) | U10: =T10 | V10: =IFERROR(INDEX(Iv_Wochen,MATCH(U10,Iv_Name,0)),"") | X10: =TRIM(IF(N(K10)>=P_Krit,"AS ","")&IF(N(J10)>=P_Krit,"Q ","")&IF(N(L10)>=P_Krit,"US","")) | Y10: =IF(ISNUMBER(I10),INDEX(IH_Text,I10),"") | AB10: =IF(AND(ISNUMBER(V10),ISNUMBER(AA10)),52/V10*AA10/60,"") | AC10: Bedienpult | AD10: 1 | AE10: Maßnahme | AG10: 2.2 | AH10: Bedienpult reinigen | AI10: 5 | AJ10: =IF(ISNUMBER(R10),R10-AI10/100000,"")
A11: 2.3 | B11: 24-V-Glühbirnen (Meldeleuchten) prüfen, ggf. austauschen | C11: Inspektion | G11: Alle Meldeleuchten funktionsfähig | H11: 3 | I11: 2 | J11: 1 | K11: 3 | L11: 1 | M11: 3 | N11: =IF(COUNT(H11:M11)=6,SQRT(SUMSQ(H11:M11))/2,"") | O11: 2 | P11: 1 | Q11: =P_SF | R11: =IF(COUNT(N11:Q11)=4,N11*O11*P11*Q11,"") | S11: =IF(R11="","unvollständig",IF(R11>P_Grenze_kritisch,"kritisch",IF(R11>=P_Grenze_hoch,"hoch",IF(R11>=P_Grenze_mittel,"mittel","gering")))) | T11: =IF(S11="unvollständig","Bewertung fehlt",INDEX(Kl_Intervall,MATCH(S11,Kl_Name,0))) | U11: =T11 | V11: =IFERROR(INDEX(Iv_Wochen,MATCH(U11,Iv_Name,0)),"") | X11: =TRIM(IF(N(K11)>=P_Krit,"AS ","")&IF(N(J11)>=P_Krit,"Q ","")&IF(N(L11)>=P_Krit,"US","")) | Y11: =IF(ISNUMBER(I11),INDEX(IH_Text,I11),"") | AB11: =IF(AND(ISNUMBER(V11),ISNUMBER(AA11)),52/V11*AA11/60,"") | AC11: Bedienpult | AD11: 1 | AE11: Maßnahme | AG11: 2.3 | AH11: Prüfe 24V Glühbirnen; ggf. austauschen | AI11: 6 | AJ11: =IF(ISNUMBER(R11),R11-AI11/100000,"")
A12: 3 | B12: Staucheinheit (Stauchdorn, Stauchspindel, Elemente für Abdichthub von rechts); Pos. 29 Stauchspindel (Kugelgewindespindel) | AC12: Staucheinheit (Stauchdorn, Stauchspindel, Elemente für Abdichthub von rechts); Pos. 29 Stauchspindel (Kugelgewindespindel) | AD12: 2 / 29 | AE12: Baugruppe | AG12: 3 | AH12: 2.) Staucheinheit (bestehend aus Stauchdorn, Stauchspindel und Elementen für Abdichthub von rechts) Pos. 29 Stauchspindel (Kugelgewindespindel) | AI12: 7
A13: 3.1 | B13: Stauchspindel nach folgenden Kriterien inspizieren: | AC13: Staucheinheit (Stauchdorn, Stauchspindel, Elemente für Abdichthub von rechts); Pos. 29 Stauchspindel (Kugelgewindespindel) | AD13: 2 / 29 | AE13: Prüfgruppe | AG13: 3.1 | AH13: Inspiziere Stauchspindel nach folgenden Kriterien: | AI13: 8
A14: 3.1.1 | B14: Stauchspindel auf Beschädigungen prüfen: Oberfläche (Riefen, Kratzer), Geräusche, Laufruhe | C14: Inspektion | G14: Keine Riefen/Kratzer; ruhiger, geräuscharmer Lauf | H14: 4 | I14: 4 | J14: 4 | K14: 2 | L14: 1 | M14: 1 | N14: =IF(COUNT(H14:M14)=6,SQRT(SUMSQ(H14:M14))/2,"") | O14: 2 | P14: 3 | Q14: =P_SF | R14: =IF(COUNT(N14:Q14)=4,N14*O14*P14*Q14,"") | S14: =IF(R14="","unvollständig",IF(R14>P_Grenze_kritisch,"kritisch",IF(R14>=P_Grenze_hoch,"hoch",IF(R14>=P_Grenze_mittel,"mittel","gering")))) | T14: =IF(S14="unvollständig","Bewertung fehlt",INDEX(Kl_Intervall,MATCH(S14,Kl_Name,0))) | U14: =T14 | V14: =IFERROR(INDEX(Iv_Wochen,MATCH(U14,Iv_Name,0)),"") | X14: =TRIM(IF(N(K14)>=P_Krit,"AS ","")&IF(N(J14)>=P_Krit,"Q ","")&IF(N(L14)>=P_Krit,"US","")) | Y14: =IF(ISNUMBER(I14),INDEX(IH_Text,I14),"") | AB14: =IF(AND(ISNUMBER(V14),ISNUMBER(AA14)),52/V14*AA14/60,"") | AC14: Staucheinheit (Stauchdorn, Stauchspindel, Elemente für Abdichthub von rechts); Pos. 29 Stauchspindel (Kugelgewindespindel) | AD14: 2 / 29 | AE14: Maßnahme | AG14: 3.1.1 | AH14: Stauchspindel auf Beschädigungen prüfen (Oberfläche (Riffen, Kratzer) d. Stauchspindel prüfen; Stauchspindel auf Geräusche, Laufruhe prüfen | AI14: 9 | AJ14: =IF(ISNUMBER(R14),R14-AI14/100000,"")
A15: 3.1.2 | B15: Stauchspindel auf Verschmutzung prüfen, ggf. reinigen | C15: Inspektion | G15: Spindel sauber, frei von Ablagerungen | H15: 4 | I15: 4 | J15: 4 | K15: 2 | L15: 1 | M15: 1 | N15: =IF(COUNT(H15:M15)=6,SQRT(SUMSQ(H15:M15))/2,"") | O15: 2 | P15: 3 | Q15: =P_SF | R15: =IF(COUNT(N15:Q15)=4,N15*O15*P15*Q15,"") | S15: =IF(R15="","unvollständig",IF(R15>P_Grenze_kritisch,"kritisch",IF(R15>=P_Grenze_hoch,"hoch",IF(R15>=P_Grenze_mittel,"mittel","gering")))) | T15: =IF(S15="unvollständig","Bewertung fehlt",INDEX(Kl_Intervall,MATCH(S15,Kl_Name,0))) | U15: =T15 | V15: =IFERROR(INDEX(Iv_Wochen,MATCH(U15,Iv_Name,0)),"") | X15: =TRIM(IF(N(K15)>=P_Krit,"AS ","")&IF(N(J15)>=P_Krit,"Q ","")&IF(N(L15)>=P_Krit,"US","")) | Y15: =IF(ISNUMBER(I15),INDEX(IH_Text,I15),"") | AB15: =IF(AND(ISNUMBER(V15),ISNUMBER(AA15)),52/V15*AA15/60,"") | AC15: Staucheinheit (Stauchdorn, Stauchspindel, Elemente für Abdichthub von rechts); Pos. 29 Stauchspindel (Kugelgewindespindel) | AD15: 2 / 29 | AE15: Maßnahme | AG15: 3.1.2 | AH15: Stauchspindel auf Verschmutzung prüfen ggf. reinigen | AI15: 10 | AJ15: =IF(ISNUMBER(R15),R15-AI15/100000,"")
A16: 3.1.3 | B16: Stauchspindel abschmieren (siehe Schmierplan) | C16: Schmierung | G16: Gleichmäßiger Schmierfilm vorhanden | H16: 5 | I16: 5 | J16: 3 | K16: 3 | L16: 2 | M16: 3 | N16: =IF(COUNT(H16:M16)=6,SQRT(SUMSQ(H16:M16))/2,"") | O16: 5 | P16: 4 | Q16: =P_SF | R16: =IF(COUNT(N16:Q16)=4,N16*O16*P16*Q16,"") | S16: =IF(R16="","unvollständig",IF(R16>P_Grenze_kritisch,"kritisch",IF(R16>=P_Grenze_hoch,"hoch",IF(R16>=P_Grenze_mittel,"mittel","gering")))) | T16: =IF(S16="unvollständig","Bewertung fehlt",INDEX(Kl_Intervall,MATCH(S16,Kl_Name,0))) | U16: =T16 | V16: =IFERROR(INDEX(Iv_Wochen,MATCH(U16,Iv_Name,0)),"") | X16: =TRIM(IF(N(K16)>=P_Krit,"AS ","")&IF(N(J16)>=P_Krit,"Q ","")&IF(N(L16)>=P_Krit,"US","")) | Y16: =IF(ISNUMBER(I16),INDEX(IH_Text,I16),"") | AB16: =IF(AND(ISNUMBER(V16),ISNUMBER(AA16)),52/V16*AA16/60,"") | AC16: Staucheinheit (Stauchdorn, Stauchspindel, Elemente für Abdichthub von rechts); Pos. 29 Stauchspindel (Kugelgewindespindel) | AD16: 2 / 29 | AE16: Maßnahme | AG16: 3.1.3 | AH16: Stauchspindel abschmieren (siehe Schmierplan) | AI16: 11 | AJ16: =IF(ISNUMBER(R16),R16-AI16/100000,"")
A17: 3.1.4 | B17: Zustand der Stauchspindel auf Schmierfilm und Verschleiß prüfen; bei ausreichendem Schmierfilm ist keine Schmierung notwendig | C17: Inspektion | G17: Ausreichender Schmierfilm; kein sichtbarer Verschleiß | H17: 5 | I17: 5 | J17: 3 | K17: 3 | L17: 2 | M17: 3 | N17: =IF(COUNT(H17:M17)=6,SQRT(SUMSQ(H17:M17))/2,"") | O17: 5 | P17: 4 | Q17: =P_SF | R17: =IF(COUNT(N17:Q17)=4,N17*O17*P17*Q17,"") | S17: =IF(R17="","unvollständig",IF(R17>P_Grenze_kritisch,"kritisch",IF(R17>=P_Grenze_hoch,"hoch",IF(R17>=P_Grenze_mittel,"mittel","gering")))) | T17: =IF(S17="unvollständig","Bewertung fehlt",INDEX(Kl_Intervall,MATCH(S17,Kl_Name,0))) | U17: =T17 | V17: =IFERROR(INDEX(Iv_Wochen,MATCH(U17,Iv_Name,0)),"") | X17: =TRIM(IF(N(K17)>=P_Krit,"AS ","")&IF(N(J17)>=P_Krit,"Q ","")&IF(N(L17)>=P_Krit,"US","")) | Y17: =IF(ISNUMBER(I17),INDEX(IH_Text,I17),"") | AB17: =IF(AND(ISNUMBER(V17),ISNUMBER(AA17)),52/V17*AA17/60,"") | AC17: Staucheinheit (Stauchdorn, Stauchspindel, Elemente für Abdichthub von rechts); Pos. 29 Stauchspindel (Kugelgewindespindel) | AD17: 2 / 29 | AE17: Maßnahme | AG17: 3.1.4 | AH17: überprüfe den Zustand der Stauch-Spindel auf Schmierfilm und Verschleiß. Bei ausreichendem Schmierfilm; --> Schmierung nicht notwendig | AI17: 12 | AJ17: =IF(ISNUMBER(R17),R17-AI17/100000,"")
A18: 3.1.5 | B18: Abdeckung abschrauben; Schmierung über Bohrung Pos. 33 in der Spindel. ACHTUNG: Spindel dazu unbedingt auf Maximalhub ausfahren. 6–10 Hübe je Schmiernippel; Spindel mit sauberem Pinsel abschmieren (Teflon-Fett) | C18: Schmierung | D18: ⚠ Gefahrenstelle | F18: Profi Spezial Grease (Profi Star) | G18: Spindel vollständig abgeschmiert; Abdeckung wieder montiert | H18: 5 | I18: 5 | J18: 3 | K18: 3 | L18: 2 | M18: 3 | N18: =IF(COUNT(H18:M18)=6,SQRT(SUMSQ(H18:M18))/2,"") | O18: 5 | P18: 4 | Q18: =P_SF | R18: =IF(COUNT(N18:Q18)=4,N18*O18*P18*Q18,"") | S18: =IF(R18="","unvollständig",IF(R18>P_Grenze_kritisch,"kritisch",IF(R18>=P_Grenze_hoch,"hoch",IF(R18>=P_Grenze_mittel,"mittel","gering")))) | T18: =IF(S18="unvollständig","Bewertung fehlt",INDEX(Kl_Intervall,MATCH(S18,Kl_Name,0))) | U18: =T18 | V18: =IFERROR(INDEX(Iv_Wochen,MATCH(U18,Iv_Name,0)),"") | X18: =TRIM(IF(N(K18)>=P_Krit,"AS ","")&IF(N(J18)>=P_Krit,"Q ","")&IF(N(L18)>=P_Krit,"US","")) | Y18: =IF(ISNUMBER(I18),INDEX(IH_Text,I18),"") | AB18: =IF(AND(ISNUMBER(V18),ISNUMBER(AA18)),52/V18*AA18/60,"") | AC18: Staucheinheit (Stauchdorn, Stauchspindel, Elemente für Abdichthub von rechts); Pos. 29 Stauchspindel (Kugelgewindespindel) | AD18: 2 / 29 | AE18: Maßnahme | AG18: 3.1.5 | AH18: Abdeckung abschrauben --> Schmierung erfolgt über Bohrung Pos. 33 in der Spindel Achtung: Spindel dazu unbedingt auf Maximalhub ausfahren --> Schmieren 6-10 Hübe/Schmiernippel + Spindel mit sauberen Pinsel abschmieren (Teflon-Fett) | AI18: 13 | AJ18: =IF(ISNUMBER(R18),R18-AI18/100000,"")
A19: 3.1.6 | B19: Getriebe kontrollieren (Sichtkontrolle auf Öl-Leckage) | C19: Inspektion | G19: Keine Öl-Leckage | H19: 4 | I19: 4 | J19: 4 | K19: 2 | L19: 1 | M19: 1 | N19: =IF(COUNT(H19:M19)=6,SQRT(SUMSQ(H19:M19))/2,"") | O19: 2 | P19: 4 | Q19: =P_SF | R19: =IF(COUNT(N19:Q19)=4,N19*O19*P19*Q19,"") | S19: =IF(R19="","unvollständig",IF(R19>P_Grenze_kritisch,"kritisch",IF(R19>=P_Grenze_hoch,"hoch",IF(R19>=P_Grenze_mittel,"mittel","gering")))) | T19: =IF(S19="unvollständig","Bewertung fehlt",INDEX(Kl_Intervall,MATCH(S19,Kl_Name,0))) | U19: =T19 | V19: =IFERROR(INDEX(Iv_Wochen,MATCH(U19,Iv_Name,0)),"") | X19: =TRIM(IF(N(K19)>=P_Krit,"AS ","")&IF(N(J19)>=P_Krit,"Q ","")&IF(N(L19)>=P_Krit,"US","")) | Y19: =IF(ISNUMBER(I19),INDEX(IH_Text,I19),"") | AB19: =IF(AND(ISNUMBER(V19),ISNUMBER(AA19)),52/V19*AA19/60,"") | AC19: Staucheinheit (Stauchdorn, Stauchspindel, Elemente für Abdichthub von rechts); Pos. 29 Stauchspindel (Kugelgewindespindel) | AD19: 2 / 29 | AE19: Maßnahme | AG19: 3.1.6 | AH19: kontrolliere Getriebe (Sichtkontrolle auf Öl-Leckage ) | AI19: 14 | AJ19: =IF(ISNUMBER(R19),R19-AI19/100000,"")
A20: 3.1.7 | B20: Elektromotor kontrollieren (Funktion, Verschmutzung, Laufruhe, Kabel) | C20: Inspektion | G20: Motor sauber, ruhiger Lauf; Kabel unbeschädigt | H20: 4 | I20: 4 | J20: 4 | K20: 2 | L20: 1 | M20: 1 | N20: =IF(COUNT(H20:M20)=6,SQRT(SUMSQ(H20:M20))/2,"") | O20: 2 | P20: 4 | Q20: =P_SF | R20: =IF(COUNT(N20:Q20)=4,N20*O20*P20*Q20,"") | S20: =IF(R20="","unvollständig",IF(R20>P_Grenze_kritisch,"kritisch",IF(R20>=P_Grenze_hoch,"hoch",IF(R20>=P_Grenze_mittel,"mittel","gering")))) | T20: =IF(S20="unvollständig","Bewertung fehlt",INDEX(Kl_Intervall,MATCH(S20,Kl_Name,0))) | U20: =T20 | V20: =IFERROR(INDEX(Iv_Wochen,MATCH(U20,Iv_Name,0)),"") | X20: =TRIM(IF(N(K20)>=P_Krit,"AS ","")&IF(N(J20)>=P_Krit,"Q ","")&IF(N(L20)>=P_Krit,"US","")) | Y20: =IF(ISNUMBER(I20),INDEX(IH_Text,I20),"") | AB20: =IF(AND(ISNUMBER(V20),ISNUMBER(AA20)),52/V20*AA20/60,"") | AC20: Staucheinheit (Stauchdorn, Stauchspindel, Elemente für Abdichthub von rechts); Pos. 29 Stauchspindel (Kugelgewindespindel) | AD20: 2 / 29 | AE20: Maßnahme | AG20: 3.1.7 | AH20: Kontrolliere Elektromotor (Funktion/Verschmutzung/Laufruhe/Kabeln) | AI20: 15 | AJ20: =IF(ISNUMBER(R20),R20-AI20/100000,"")
A21: 4 | B21: Oberer und unterer Werkzeugträger | AC21: Oberer und unterer Werkzeugträger | AD21: 3 / 6 | AE21: Baugruppe | AG21: 4 | AH21: 3.) u. 6.) Oberer Werkzeugträger/Unterer Werkzeugträger | AI21: 16
A22: 4.1 | B22: Alle Werkzeugträger nach folgenden Kriterien inspizieren: | AC22: Oberer und unterer Werkzeugträger | AD22: 3 / 6 | AE22: Prüfgruppe | AG22: 4.1 | AH22: Inspiziere alle Werkzeugträger nach folgenden Kriterien: | AI22: 17
A23: 4.1.1 | B23: Spindel auf Beschädigungen prüfen: Oberfläche (Riefen, Kratzer), Geräusche, Laufruhe | C23: Inspektion | G23: Keine Riefen/Kratzer; ruhiger, geräuscharmer Lauf | H23: 5 | I23: 5 | J23: 3 | K23: 3 | L23: 2 | M23: 3 | N23: =IF(COUNT(H23:M23)=6,SQRT(SUMSQ(H23:M23))/2,"") | O23: 5 | P23: 4 | Q23: =P_SF | R23: =IF(COUNT(N23:Q23)=4,N23*O23*P23*Q23,"") | S23: =IF(R23="","unvollständig",IF(R23>P_Grenze_kritisch,"kritisch",IF(R23>=P_Grenze_hoch,"hoch",IF(R23>=P_Grenze_mittel,"mittel","gering")))) | T23: =IF(S23="unvollständig","Bewertung fehlt",INDEX(Kl_Intervall,MATCH(S23,Kl_Name,0))) | U23: =T23 | V23: =IFERROR(INDEX(Iv_Wochen,MATCH(U23,Iv_Name,0)),"") | X23: =TRIM(IF(N(K23)>=P_Krit,"AS ","")&IF(N(J23)>=P_Krit,"Q ","")&IF(N(L23)>=P_Krit,"US","")) | Y23: =IF(ISNUMBER(I23),INDEX(IH_Text,I23),"") | AB23: =IF(AND(ISNUMBER(V23),ISNUMBER(AA23)),52/V23*AA23/60,"") | AC23: Oberer und unterer Werkzeugträger | AD23: 3 / 6 | AE23: Maßnahme | AG23: 4.1.1 | AH23: Spindel auf Beschädigungen prüfen (Oberfläche (Riffen, Kratzer) d. Spindel prüfen; Stauchspindel auf Geräusche, Laufruhe prüfen | AI23: 18 | AJ23: =IF(ISNUMBER(R23),R23-AI23/100000,"")
A24: 4.1.2 | B24: Spindel auf Verschmutzung prüfen, ggf. reinigen | C24: Inspektion | G24: Spindel sauber, frei von Ablagerungen | H24: 2 | I24: 2 | J24: 1 | K24: 1 | L24: 3 | M24: 1 | N24: =IF(COUNT(H24:M24)=6,SQRT(SUMSQ(H24:M24))/2,"") | O24: 5 | P24: 2 | Q24: =P_SF | R24: =IF(COUNT(N24:Q24)=4,N24*O24*P24*Q24,"") | S24: =IF(R24="","unvollständig",IF(R24>P_Grenze_kritisch,"kritisch",IF(R24>=P_Grenze_hoch,"hoch",IF(R24>=P_Grenze_mittel,"mittel","gering")))) | T24: =IF(S24="unvollständig","Bewertung fehlt",INDEX(Kl_Intervall,MATCH(S24,Kl_Name,0))) | U24: =T24 | V24: =IFERROR(INDEX(Iv_Wochen,MATCH(U24,Iv_Name,0)),"") | X24: =TRIM(IF(N(K24)>=P_Krit,"AS ","")&IF(N(J24)>=P_Krit,"Q ","")&IF(N(L24)>=P_Krit,"US","")) | Y24: =IF(ISNUMBER(I24),INDEX(IH_Text,I24),"") | AB24: =IF(AND(ISNUMBER(V24),ISNUMBER(AA24)),52/V24*AA24/60,"") | AC24: Oberer und unterer Werkzeugträger | AD24: 3 / 6 | AE24: Maßnahme | AG24: 4.1.2 | AH24: Spindel auf Verschmutzung prüfen ggf. reinigen | AI24: 19 | AJ24: =IF(ISNUMBER(R24),R24-AI24/100000,"")
A25: 4.1.3 | B25: Spindel abschmieren (siehe Schmierplan): Spindelmutter Y-Schlitten, 6 Hübe je Schmiernippel. Werkzeugträger zusammenfahren und prüfen, ob genügend Schmierfilm auf der Spindel vorhanden ist; ggf. nochmals abschmieren | C25: Schmierung | D25: ⚠ Gefahrenstelle / ℹ Hinweis beachten | F25: Profi Spezial Grease (Profi Star) | G25: Ausreichender Schmierfilm auf der Spindel | H25: 5 | I25: 5 | J25: 3 | K25: 3 | L25: 2 | M25: 3 | N25: =IF(COUNT(H25:M25)=6,SQRT(SUMSQ(H25:M25))/2,"") | O25: 5 | P25: 2 | Q25: =P_SF | R25: =IF(COUNT(N25:Q25)=4,N25*O25*P25*Q25,"") | S25: =IF(R25="","unvollständig",IF(R25>P_Grenze_kritisch,"kritisch",IF(R25>=P_Grenze_hoch,"hoch",IF(R25>=P_Grenze_mittel,"mittel","gering")))) | T25: =IF(S25="unvollständig","Bewertung fehlt",INDEX(Kl_Intervall,MATCH(S25,Kl_Name,0))) | U25: =T25 | V25: =IFERROR(INDEX(Iv_Wochen,MATCH(U25,Iv_Name,0)),"") | X25: =TRIM(IF(N(K25)>=P_Krit,"AS ","")&IF(N(J25)>=P_Krit,"Q ","")&IF(N(L25)>=P_Krit,"US","")) | Y25: =IF(ISNUMBER(I25),INDEX(IH_Text,I25),"") | AB25: =IF(AND(ISNUMBER(V25),ISNUMBER(AA25)),52/V25*AA25/60,"") | AC25: Oberer und unterer Werkzeugträger | AD25: 3 / 6 | AE25: Maßnahme | AG25: 4.1.3 | AH25: Spindel abschmieren (siehe Schmierplan) Spindelmutter Y-Schlitten --> Schmieren (6) Hübe/Schmiernippel. Werkzuegträger zusammenfahren und überprüfen ob genügend Schmierfilm auf Spindel vorhanden ggf. nochmal abschmieren | AI25: 20 | AJ25: =IF(ISNUMBER(R25),R25-AI25/100000,"")
A26: 4.1.4 | B26: Hauptführung Y-Schlitten kontrollieren (!) – Schmierplan Pos. 1–5: Führungen abschmieren, 6 Hübe je Schmiernippel | C26: Schmierung | D26: ⚠ Gefahrenstelle / ℹ Hinweis beachten | F26: Profi Spezial Grease (Profi Star) | G26: abgeschmiert | H26: 5 | I26: 5 | J26: 3 | K26: 3 | L26: 2 | M26: 3 | N26: =IF(COUNT(H26:M26)=6,SQRT(SUMSQ(H26:M26))/2,"") | Q26: =P_SF | R26: =IF(COUNT(N26:Q26)=4,N26*O26*P26*Q26,"") | S26: =IF(R26="","unvollständig",IF(R26>P_Grenze_kritisch,"kritisch",IF(R26>=P_Grenze_hoch,"hoch",IF(R26>=P_Grenze_mittel,"mittel","gering")))) | T26: =IF(S26="unvollständig","Bewertung fehlt",INDEX(Kl_Intervall,MATCH(S26,Kl_Name,0))) | U26: =T26 | V26: =IFERROR(INDEX(Iv_Wochen,MATCH(U26,Iv_Name,0)),"") | X26: =TRIM(IF(N(K26)>=P_Krit,"AS ","")&IF(N(J26)>=P_Krit,"Q ","")&IF(N(L26)>=P_Krit,"US","")) | Y26: =IF(ISNUMBER(I26),INDEX(IH_Text,I26),"") | AB26: =IF(AND(ISNUMBER(V26),ISNUMBER(AA26)),52/V26*AA26/60,"") | AC26: Oberer und unterer Werkzeugträger | AD26: 3 / 6 | AE26: Maßnahme | AG26: 4.1.4 | AH26: Hauptführung Y-Schlitten kontrollieren !!! Schmierplan Pos. 1-5 Führungen abschmiern (6) Hübe/Schmiernippel | AI26: 21 | AJ26: =IF(ISNUMBER(R26),R26-AI26/100000,"")
A27: 4.1.5 | B27: Elektromotor kontrollieren (Funktion, Verschmutzung, Laufruhe, Kabel) | C27: Inspektion | G27: Motor sauber, ruhiger Lauf; Kabel unbeschädigt | H27: 3 | I27: 3 | J27: 2 | K27: 2 | L27: 2 | M27: 3 | N27: =IF(COUNT(H27:M27)=6,SQRT(SUMSQ(H27:M27))/2,"") | O27: 2 | P27: 3 | Q27: =P_SF | R27: =IF(COUNT(N27:Q27)=4,N27*O27*P27*Q27,"") | S27: =IF(R27="","unvollständig",IF(R27>P_Grenze_kritisch,"kritisch",IF(R27>=P_Grenze_hoch,"hoch",IF(R27>=P_Grenze_mittel,"mittel","gering")))) | T27: =IF(S27="unvollständig","Bewertung fehlt",INDEX(Kl_Intervall,MATCH(S27,Kl_Name,0))) | U27: =T27 | V27: =IFERROR(INDEX(Iv_Wochen,MATCH(U27,Iv_Name,0)),"") | X27: =TRIM(IF(N(K27)>=P_Krit,"AS ","")&IF(N(J27)>=P_Krit,"Q ","")&IF(N(L27)>=P_Krit,"US","")) | Y27: =IF(ISNUMBER(I27),INDEX(IH_Text,I27),"") | AB27: =IF(AND(ISNUMBER(V27),ISNUMBER(AA27)),52/V27*AA27/60,"") | AC27: Oberer und unterer Werkzeugträger | AD27: 3 / 6 | AE27: Maßnahme | AG27: 4.1.5 | AH27: Kontrolliere Elektromotor (Funktion/Verschmutzung/Laufruhe/Kabeln) | AI27: 22 | AJ27: =IF(ISNUMBER(R27),R27-AI27/100000,"")
A28: 5 | B28: Verschlussbalken | AC28: Verschlussbalken | AD28: 5 | AE28: Baugruppe | AG28: 5 | AH28: 5.) Verschlussbalken | AI28: 23
A29: 5.1 | B29: Verschlussbalken abschmieren, 6 Hübe je Schmiernippel | C29: Schmierung | D29: ℹ Hinweis beachten | F29: Profi Spezial Grease (Profi Star) | G29: Alle Schmierstellen abgeschmiert | H29: 5 | I29: 5 | J29: 3 | K29: 3 | L29: 2 | M29: 3 | N29: =IF(COUNT(H29:M29)=6,SQRT(SUMSQ(H29:M29))/2,"") | O29: 4 | P29: 4 | Q29: =P_SF | R29: =IF(COUNT(N29:Q29)=4,N29*O29*P29*Q29,"") | S29: =IF(R29="","unvollständig",IF(R29>P_Grenze_kritisch,"kritisch",IF(R29>=P_Grenze_hoch,"hoch",IF(R29>=P_Grenze_mittel,"mittel","gering")))) | T29: =IF(S29="unvollständig","Bewertung fehlt",INDEX(Kl_Intervall,MATCH(S29,Kl_Name,0))) | U29: =T29 | V29: =IFERROR(INDEX(Iv_Wochen,MATCH(U29,Iv_Name,0)),"") | X29: =TRIM(IF(N(K29)>=P_Krit,"AS ","")&IF(N(J29)>=P_Krit,"Q ","")&IF(N(L29)>=P_Krit,"US","")) | Y29: =IF(ISNUMBER(I29),INDEX(IH_Text,I29),"") | AB29: =IF(AND(ISNUMBER(V29),ISNUMBER(AA29)),52/V29*AA29/60,"") | AC29: Verschlussbalken | AD29: 5 | AE29: Maßnahme | AG29: 5.1.2 | AH29: Verschlußbalcken abschmieren (6) Hübe/Schmiernippel | AI29: 24 | AJ29: =IF(ISNUMBER(R29),R29-AI29/100000,"")
A30: 5.2 | B30: Alle Hydraulikzylinder nach folgenden Kriterien inspizieren: | AC30: Verschlussbalken | AD30: 5 | AE30: Prüfgruppe | AG30: 5.1.1 | AH30: Inspiziere alle Hydraulikzylinder nach folgenden Kriterien: | AI30: 25
A31: 5.2.1 | B31: Kolbenspiel kontrollieren | C31: Inspektion | G31: Kein unzulässiges Kolbenspiel | H31: 3 | I31: 4 | J31: 2 | K31: 2 | L31: 3 | M31: 3 | N31: =IF(COUNT(H31:M31)=6,SQRT(SUMSQ(H31:M31))/2,"") | O31: 3 | P31: 5 | Q31: =P_SF | R31: =IF(COUNT(N31:Q31)=4,N31*O31*P31*Q31,"") | S31: =IF(R31="","unvollständig",IF(R31>P_Grenze_kritisch,"kritisch",IF(R31>=P_Grenze_hoch,"hoch",IF(R31>=P_Grenze_mittel,"mittel","gering")))) | T31: =IF(S31="unvollständig","Bewertung fehlt",INDEX(Kl_Intervall,MATCH(S31,Kl_Name,0))) | U31: =T31 | V31: =IFERROR(INDEX(Iv_Wochen,MATCH(U31,Iv_Name,0)),"") | X31: =TRIM(IF(N(K31)>=P_Krit,"AS ","")&IF(N(J31)>=P_Krit,"Q ","")&IF(N(L31)>=P_Krit,"US","")) | Y31: =IF(ISNUMBER(I31),INDEX(IH_Text,I31),"") | AB31: =IF(AND(ISNUMBER(V31),ISNUMBER(AA31)),52/V31*AA31/60,"") | AC31: Verschlussbalken | AD31: 5 | AE31: Maßnahme | AG31: 5.1.3 | AH31: kontrolliere Kolbenspiel | AI31: 26 | AJ31: =IF(ISNUMBER(R31),R31-AI31/100000,"")
A32: 5.2.2 | B32: Dichtungen kontrollieren (Sichtkontrolle auf Öl-Leckage) | C32: Inspektion | G32: Keine Öl-Leckage | H32: 3 | I32: 4 | J32: 2 | K32: 3 | L32: 5 | M32: 3 | N32: =IF(COUNT(H32:M32)=6,SQRT(SUMSQ(H32:M32))/2,"") | O32: 3 | P32: 4 | Q32: =P_SF | R32: =IF(COUNT(N32:Q32)=4,N32*O32*P32*Q32,"") | S32: =IF(R32="","unvollständig",IF(R32>P_Grenze_kritisch,"kritisch",IF(R32>=P_Grenze_hoch,"hoch",IF(R32>=P_Grenze_mittel,"mittel","gering")))) | T32: =IF(S32="unvollständig","Bewertung fehlt",INDEX(Kl_Intervall,MATCH(S32,Kl_Name,0))) | U32: =T32 | V32: =IFERROR(INDEX(Iv_Wochen,MATCH(U32,Iv_Name,0)),"") | X32: =TRIM(IF(N(K32)>=P_Krit,"AS ","")&IF(N(J32)>=P_Krit,"Q ","")&IF(N(L32)>=P_Krit,"US","")) | Y32: =IF(ISNUMBER(I32),INDEX(IH_Text,I32),"") | AB32: =IF(AND(ISNUMBER(V32),ISNUMBER(AA32)),52/V32*AA32/60,"") | AC32: Verschlussbalken | AD32: 5 | AE32: Maßnahme | AG32: 5.1.4 | AH32: kontrolliere Dichtungen (Sichtkontrolle auf Öl-Leckage ) | AI32: 27 | AJ32: =IF(ISNUMBER(R32),R32-AI32/100000,"")
A33: 5.2.3 | B33: Anschlüsse auf Dichtheit und Beschädigungen prüfen | C33: Inspektion | G33: Dicht, unbeschädigt | H33: 3 | I33: 3 | J33: 2 | K33: 3 | L33: 5 | M33: 3 | N33: =IF(COUNT(H33:M33)=6,SQRT(SUMSQ(H33:M33))/2,"") | O33: 1 | P33: 5 | Q33: =P_SF | R33: =IF(COUNT(N33:Q33)=4,N33*O33*P33*Q33,"") | S33: =IF(R33="","unvollständig",IF(R33>P_Grenze_kritisch,"kritisch",IF(R33>=P_Grenze_hoch,"hoch",IF(R33>=P_Grenze_mittel,"mittel","gering")))) | T33: =IF(S33="unvollständig","Bewertung fehlt",INDEX(Kl_Intervall,MATCH(S33,Kl_Name,0))) | U33: =T33 | V33: =IFERROR(INDEX(Iv_Wochen,MATCH(U33,Iv_Name,0)),"") | X33: =TRIM(IF(N(K33)>=P_Krit,"AS ","")&IF(N(J33)>=P_Krit,"Q ","")&IF(N(L33)>=P_Krit,"US","")) | Y33: =IF(ISNUMBER(I33),INDEX(IH_Text,I33),"") | AB33: =IF(AND(ISNUMBER(V33),ISNUMBER(AA33)),52/V33*AA33/60,"") | AC33: Verschlussbalken | AD33: 5 | AE33: Maßnahme | AG33: 5.1.5 | AH33: Anschlüsse auf Dichtheit und Beschädigungen prüfen | AI33: 28 | AJ33: =IF(ISNUMBER(R33),R33-AI33/100000,"")
A34: 5.2.4 | B34: Befestigung des Zylinders prüfen (wenn möglich) | C34: Inspektion | G34: Fest, kein Spiel | H34: 3 | I34: 3 | J34: 2 | K34: 2 | L34: 3 | M34: 3 | N34: =IF(COUNT(H34:M34)=6,SQRT(SUMSQ(H34:M34))/2,"") | O34: 2 | P34: 4 | Q34: =P_SF | R34: =IF(COUNT(N34:Q34)=4,N34*O34*P34*Q34,"") | S34: =IF(R34="","unvollständig",IF(R34>P_Grenze_kritisch,"kritisch",IF(R34>=P_Grenze_hoch,"hoch",IF(R34>=P_Grenze_mittel,"mittel","gering")))) | T34: =IF(S34="unvollständig","Bewertung fehlt",INDEX(Kl_Intervall,MATCH(S34,Kl_Name,0))) | U34: =T34 | V34: =IFERROR(INDEX(Iv_Wochen,MATCH(U34,Iv_Name,0)),"") | X34: =TRIM(IF(N(K34)>=P_Krit,"AS ","")&IF(N(J34)>=P_Krit,"Q ","")&IF(N(L34)>=P_Krit,"US","")) | Y34: =IF(ISNUMBER(I34),INDEX(IH_Text,I34),"") | AB34: =IF(AND(ISNUMBER(V34),ISNUMBER(AA34)),52/V34*AA34/60,"") | AC34: Verschlussbalken | AD34: 5 | AE34: Maßnahme | AG34: 5.1.6 | AH34: überprüfe die Befestigung des Zylinders (wenn möglich) | AI34: 29 | AJ34: =IF(ISNUMBER(R34),R34-AI34/100000,"")
A35: 5.2.5 | B35: Funktion des Zylinders testen | C35: Funktionsprüfung | G35: Gleichmäßige Bewegung über den gesamten Hub | H35: 3 | I35: 3 | J35: 2 | K35: 1 | L35: 1 | M35: 3 | N35: =IF(COUNT(H35:M35)=6,SQRT(SUMSQ(H35:M35))/2,"") | O35: 2 | P35: 4 | Q35: =P_SF | R35: =IF(COUNT(N35:Q35)=4,N35*O35*P35*Q35,"") | S35: =IF(R35="","unvollständig",IF(R35>P_Grenze_kritisch,"kritisch",IF(R35>=P_Grenze_hoch,"hoch",IF(R35>=P_Grenze_mittel,"mittel","gering")))) | T35: =IF(S35="unvollständig","Bewertung fehlt",INDEX(Kl_Intervall,MATCH(S35,Kl_Name,0))) | U35: =T35 | V35: =IFERROR(INDEX(Iv_Wochen,MATCH(U35,Iv_Name,0)),"") | X35: =TRIM(IF(N(K35)>=P_Krit,"AS ","")&IF(N(J35)>=P_Krit,"Q ","")&IF(N(L35)>=P_Krit,"US","")) | Y35: =IF(ISNUMBER(I35),INDEX(IH_Text,I35),"") | AB35: =IF(AND(ISNUMBER(V35),ISNUMBER(AA35)),52/V35*AA35/60,"") | AC35: Verschlussbalken | AD35: 5 | AE35: Maßnahme | AG35: 5.1.7 | AH35: Funktion des Zylinders testen | AI35: 30 | AJ35: =IF(ISNUMBER(R35),R35-AI35/100000,"")
A36: 5.2.6 | B36: Hydraulikverschraubungen kontrollieren, ggf. nachziehen | C36: Inspektion | G36: Verschraubungen fest und dicht | H36: 3 | I36: 3 | J36: 2 | K36: 3 | L36: 4 | M36: 3 | N36: =IF(COUNT(H36:M36)=6,SQRT(SUMSQ(H36:M36))/2,"") | O36: 3 | P36: 4 | Q36: =P_SF | R36: =IF(COUNT(N36:Q36)=4,N36*O36*P36*Q36,"") | S36: =IF(R36="","unvollständig",IF(R36>P_Grenze_kritisch,"kritisch",IF(R36>=P_Grenze_hoch,"hoch",IF(R36>=P_Grenze_mittel,"mittel","gering")))) | T36: =IF(S36="unvollständig","Bewertung fehlt",INDEX(Kl_Intervall,MATCH(S36,Kl_Name,0))) | U36: =T36 | V36: =IFERROR(INDEX(Iv_Wochen,MATCH(U36,Iv_Name,0)),"") | X36: =TRIM(IF(N(K36)>=P_Krit,"AS ","")&IF(N(J36)>=P_Krit,"Q ","")&IF(N(L36)>=P_Krit,"US","")) | Y36: =IF(ISNUMBER(I36),INDEX(IH_Text,I36),"") | AB36: =IF(AND(ISNUMBER(V36),ISNUMBER(AA36)),52/V36*AA36/60,"") | AC36: Verschlussbalken | AD36: 5 | AE36: Maßnahme | AG36: 5.1.8 | AH36: kontrolliere Hydraulikverschraubungen ggf. nachziehen | AI36: 31 | AJ36: =IF(ISNUMBER(R36),R36-AI36/100000,"")
A37: 5.2.7 | B37: Hydraulikschläuche/-leitungen auf Dichtheit und Beschädigungen prüfen, ggf. nachziehen | C37: Inspektion | G37: Dicht; keine Scheuerstellen, Risse oder Knicke | H37: 3 | I37: 3 | J37: 2 | K37: 3 | L37: 5 | M37: 3 | N37: =IF(COUNT(H37:M37)=6,SQRT(SUMSQ(H37:M37))/2,"") | O37: 4 | P37: 4 | Q37: =P_SF | R37: =IF(COUNT(N37:Q37)=4,N37*O37*P37*Q37,"") | S37: =IF(R37="","unvollständig",IF(R37>P_Grenze_kritisch,"kritisch",IF(R37>=P_Grenze_hoch,"hoch",IF(R37>=P_Grenze_mittel,"mittel","gering")))) | T37: =IF(S37="unvollständig","Bewertung fehlt",INDEX(Kl_Intervall,MATCH(S37,Kl_Name,0))) | U37: =T37 | V37: =IFERROR(INDEX(Iv_Wochen,MATCH(U37,Iv_Name,0)),"") | X37: =TRIM(IF(N(K37)>=P_Krit,"AS ","")&IF(N(J37)>=P_Krit,"Q ","")&IF(N(L37)>=P_Krit,"US","")) | Y37: =IF(ISNUMBER(I37),INDEX(IH_Text,I37),"") | AB37: =IF(AND(ISNUMBER(V37),ISNUMBER(AA37)),52/V37*AA37/60,"") | AC37: Verschlussbalken | AD37: 5 | AE37: Maßnahme | AG37: 5.1.9 | AH37: Hydraulikschläuche/Hydraulikleitungen auf Dichtheit und Beschädigungen prüfen ggf. Nachziehen | AI37: 32 | AJ37: =IF(ISNUMBER(R37),R37-AI37/100000,"")
A38: 5.3 | B38: Alle Sensoren/Endschalter nach folgenden Kriterien inspizieren: | AC38: Verschlussbalken | AD38: 5 | AE38: Prüfgruppe | AG38: 5.2 | AH38: Inspiziere alle Sensoren/Endschalter nach folgenden Kriterien: | AI38: 33
A39: 5.3.1 | B39: Funktion testen | C39: Funktionsprüfung | G39: Schaltsignal kommt sicher | H39: 3 | I39: 1 | J39: 2 | K39: 4 | L39: 1 | M39: 3 | N39: =IF(COUNT(H39:M39)=6,SQRT(SUMSQ(H39:M39))/2,"") | O39: 3 | P39: 2 | Q39: =P_SF | R39: =IF(COUNT(N39:Q39)=4,N39*O39*P39*Q39,"") | S39: =IF(R39="","unvollständig",IF(R39>P_Grenze_kritisch,"kritisch",IF(R39>=P_Grenze_hoch,"hoch",IF(R39>=P_Grenze_mittel,"mittel","gering")))) | T39: =IF(S39="unvollständig","Bewertung fehlt",INDEX(Kl_Intervall,MATCH(S39,Kl_Name,0))) | U39: =T39 | V39: =IFERROR(INDEX(Iv_Wochen,MATCH(U39,Iv_Name,0)),"") | X39: =TRIM(IF(N(K39)>=P_Krit,"AS ","")&IF(N(J39)>=P_Krit,"Q ","")&IF(N(L39)>=P_Krit,"US","")) | Y39: =IF(ISNUMBER(I39),INDEX(IH_Text,I39),"") | AB39: =IF(AND(ISNUMBER(V39),ISNUMBER(AA39)),52/V39*AA39/60,"") | AC39: Verschlussbalken | AD39: 5 | AE39: Maßnahme | AG39: 5.2.1 | AH39: Funktion testen | AI39: 34 | AJ39: =IF(ISNUMBER(R39),R39-AI39/100000,"")
A40: 5.3.2 | B40: Anschlüsse kontrollieren | C40: Inspektion | G40: Stecker fest, unbeschädigt | H40: 3 | I40: 2 | J40: 2 | K40: 4 | L40: 1 | M40: 3 | N40: =IF(COUNT(H40:M40)=6,SQRT(SUMSQ(H40:M40))/2,"") | O40: 3 | P40: 5 | Q40: =P_SF | R40: =IF(COUNT(N40:Q40)=4,N40*O40*P40*Q40,"") | S40: =IF(R40="","unvollständig",IF(R40>P_Grenze_kritisch,"kritisch",IF(R40>=P_Grenze_hoch,"hoch",IF(R40>=P_Grenze_mittel,"mittel","gering")))) | T40: =IF(S40="unvollständig","Bewertung fehlt",INDEX(Kl_Intervall,MATCH(S40,Kl_Name,0))) | U40: =T40 | V40: =IFERROR(INDEX(Iv_Wochen,MATCH(U40,Iv_Name,0)),"") | X40: =TRIM(IF(N(K40)>=P_Krit,"AS ","")&IF(N(J40)>=P_Krit,"Q ","")&IF(N(L40)>=P_Krit,"US","")) | Y40: =IF(ISNUMBER(I40),INDEX(IH_Text,I40),"") | AB40: =IF(AND(ISNUMBER(V40),ISNUMBER(AA40)),52/V40*AA40/60,"") | AC40: Verschlussbalken | AD40: 5 | AE40: Maßnahme | AG40: 5.2.2 | AH40: Anschlüsse kontrollieren | AI40: 35 | AJ40: =IF(ISNUMBER(R40),R40-AI40/100000,"")
...

Sheet Durchführungsnachweis
A1: Durchführungsnachweis – Status der Wartungsmaßnahmen
A2: ="Maschine: "&M_Name&" · Stichtag: "&TEXT(TODAY(),"DD.MM.YYYY")&" · Vorwarnzeit: "&P_Vorwarn&" Tage"
A3: Nach jeder Durchführung Datum, Befund und Namen eintragen (gelbe Felder). Fälligkeit und Status werden automatisch berechnet. Für eine lückenlose Historie die Zeile vor dem Überschreiben z. B. in SAP-PM rückmelden oder als PDF archivieren.
A5: Nr. | B5: Baugruppe | C5: Maßnahme | D5: Intervall festgelegt | E5: Intervall [Wochen] | F5: Ausführung durch | G5: Letzte Durchführung | H5: Nächste Fälligkeit | I5: Tage bis Fälligkeit | J5: Status | K5: Befund | L5: Durchgeführt von | M5: Bemerkung / Folgeauftrag (SAP-Nr.)
A6: 1.1 | B6: =IFERROR(INDEX(Wartungsplan!$AC$6:$AC$323,MATCH($A6,Wartungsplan!$A$6:$A$323,0)),"") | C6: =IFERROR(INDEX(Wartungsplan!$B$6:$B$323,MATCH($A6,Wartungsplan!$A$6:$A$323,0)),"") | D6: =IFERROR(INDEX(Wartungsplan!$U$6:$U$323,MATCH($A6,Wartungsplan!$A$6:$A$323,0)),"") | E6: =IFERROR(INDEX(Wartungsplan!$V$6:$V$323,MATCH($A6,Wartungsplan!$A$6:$A$323,0)),"") | F6: =IFERROR(IF(INDEX(Wartungsplan!$Z$6:$Z$323,MATCH($A6,Wartungsplan!$A$6:$A$323,0))="","",INDEX(Wartungsplan!$Z$6:$Z$323,MATCH($A6,Wartungsplan!$A$6:$A$323,0))),"") | H6: =IF(OR(G6="",NOT(ISNUMBER(E6))),"",G6+E6*7) | I6: =IF(H6="","",H6-TODAY()) | J6: =IF(NOT(ISNUMBER(E6)),"Intervall fehlt",IF(G6="","nicht erfasst",IF(I6<0,"überfällig",IF(I6<=P_Vorwarn,"bald fällig","in Ordnung"))))
A7: 2.1 | B7: =IFERROR(INDEX(Wartungsplan!$AC$6:$AC$323,MATCH($A7,Wartungsplan!$A$6:$A$323,0)),"") | C7: =IFERROR(INDEX(Wartungsplan!$B$6:$B$323,MATCH($A7,Wartungsplan!$A$6:$A$323,0)),"") | D7: =IFERROR(INDEX(Wartungsplan!$U$6:$U$323,MATCH($A7,Wartungsplan!$A$6:$A$323,0)),"") | E7: =IFERROR(INDEX(Wartungsplan!$V$6:$V$323,MATCH($A7,Wartungsplan!$A$6:$A$323,0)),"") | F7: =IFERROR(IF(INDEX(Wartungsplan!$Z$6:$Z$323,MATCH($A7,Wartungsplan!$A$6:$A$323,0))="","",INDEX(Wartungsplan!$Z$6:$Z$323,MATCH($A7,Wartungsplan!$A$6:$A$323,0))),"") | H7: =IF(OR(G7="",NOT(ISNUMBER(E7))),"",G7+E7*7) | I7: =IF(H7="","",H7-TODAY()) | J7: =IF(NOT(ISNUMBER(E7)),"Intervall fehlt",IF(G7="","nicht erfasst",IF(I7<0,"überfällig",IF(I7<=P_Vorwarn,"bald fällig","in Ordnung"))))
A8: 2.2 | B8: =IFERROR(INDEX(Wartungsplan!$AC$6:$AC$323,MATCH($A8,Wartungsplan!$A$6:$A$323,0)),"") | C8: =IFERROR(INDEX(Wartungsplan!$B$6:$B$323,MATCH($A8,Wartungsplan!$A$6:$A$323,0)),"") | D8: =IFERROR(INDEX(Wartungsplan!$U$6:$U$323,MATCH($A8,Wartungsplan!$A$6:$A$323,0)),"") | E8: =IFERROR(INDEX(Wartungsplan!$V$6:$V$323,MATCH($A8,Wartungsplan!$A$6:$A$323,0)),"") | F8: =IFERROR(IF(INDEX(Wartungsplan!$Z$6:$Z$323,MATCH($A8,Wartungsplan!$A$6:$A$323,0))="","",INDEX(Wartungsplan!$Z$6:$Z$323,MATCH($A8,Wartungsplan!$A$6:$A$323,0))),"") | H8: =IF(OR(G8="",NOT(ISNUMBER(E8))),"",G8+E8*7) | I8: =IF(H8="","",H8-TODAY()) | J8: =IF(NOT(ISNUMBER(E8)),"Intervall fehlt",IF(G8="","nicht erfasst",IF(I8<0,"überfällig",IF(I8<=P_Vorwarn,"bald fällig","in Ordnung"))))
A9: 2.3 | B9: =IFERROR(INDEX(Wartungsplan!$AC$6:$AC$323,MATCH($A9,Wartungsplan!$A$6:$A$323,0)),"") | C9: =IFERROR(INDEX(Wartungsplan!$B$6:$B$323,MATCH($A9,Wartungsplan!$A$6:$A$323,0)),"") | D9: =IFERROR(INDEX(Wartungsplan!$U$6:$U$323,MATCH($A9,Wartungsplan!$A$6:$A$323,0)),"") | E9: =IFERROR(INDEX(Wartungsplan!$V$6:$V$323,MATCH($A9,Wartungsplan!$A$6:$A$323,0)),"") | F9: =IFERROR(IF(INDEX(Wartungsplan!$Z$6:$Z$323,MATCH($A9,Wartungsplan!$A$6:$A$323,0))="","",INDEX(Wartungsplan!$Z$6:$Z$323,MATCH($A9,Wartungsplan!$A$6:$A$323,0))),"") | H9: =IF(OR(G9="",NOT(ISNUMBER(E9))),"",G9+E9*7) | I9: =IF(H9="","",H9-TODAY()) | J9: =IF(NOT(ISNUMBER(E9)),"Intervall fehlt",IF(G9="","nicht erfasst",IF(I9<0,"überfällig",IF(I9<=P_Vorwarn,"bald fällig","in Ordnung"))))
A10: 3.1.1 | B10: =IFERROR(INDEX(Wartungsplan!$AC$6:$AC$323,MATCH($A10,Wartungsplan!$A$6:$A$323,0)),"") | C10: =IFERROR(INDEX(Wartungsplan!$B$6:$B$323,MATCH($A10,Wartungsplan!$A$6:$A$323,0)),"") | D10: =IFERROR(INDEX(Wartungsplan!$U$6:$U$323,MATCH($A10,Wartungsplan!$A$6:$A$323,0)),"") | E10: =IFERROR(INDEX(Wartungsplan!$V$6:$V$323,MATCH($A10,Wartungsplan!$A$6:$A$323,0)),"") | F10: =IFERROR(IF(INDEX(Wartungsplan!$Z$6:$Z$323,MATCH($A10,Wartungsplan!$A$6:$A$323,0))="","",INDEX(Wartungsplan!$Z$6:$Z$323,MATCH($A10,Wartungsplan!$A$6:$A$323,0))),"") | H10: =IF(OR(G10="",NOT(ISNUMBER(E10))),"",G10+E10*7) | I10: =IF(H10="","",H10-TODAY()) | J10: =IF(NOT(ISNUMBER(E10)),"Intervall fehlt",IF(G10="","nicht erfasst",IF(I10<0,"überfällig",IF(I10<=P_Vorwarn,"bald fällig","in Ordnung"))))
A11: 3.1.2 | B11: =IFERROR(INDEX(Wartungsplan!$AC$6:$AC$323,MATCH($A11,Wartungsplan!$A$6:$A$323,0)),"") | C11: =IFERROR(INDEX(Wartungsplan!$B$6:$B$323,MATCH($A11,Wartungsplan!$A$6:$A$323,0)),"") | D11: =IFERROR(INDEX(Wartungsplan!$U$6:$U$323,MATCH($A11,Wartungsplan!$A$6:$A$323,0)),"") | E11: =IFERROR(INDEX(Wartungsplan!$V$6:$V$323,MATCH($A11,Wartungsplan!$A$6:$A$323,0)),"") | F11: =IFERROR(IF(INDEX(Wartungsplan!$Z$6:$Z$323,MATCH($A11,Wartungsplan!$A$6:$A$323,0))="","",INDEX(Wartungsplan!$Z$6:$Z$323,MATCH($A11,Wartungsplan!$A$6:$A$323,0))),"") | H11: =IF(OR(G11="",NOT(ISNUMBER(E11))),"",G11+E11*7) | I11: =IF(H11="","",H11-TODAY()) | J11: =IF(NOT(ISNUMBER(E11)),"Intervall fehlt",IF(G11="","nicht erfasst",IF(I11<0,"überfällig",IF(I11<=P_Vorwarn,"bald fällig","in Ordnung"))))
A12: 3.1.3 | B12: =IFERROR(INDEX(Wartungsplan!$AC$6:$AC$323,MATCH($A12,Wartungsplan!$A$6:$A$323,0)),"") | C12: =IFERROR(INDEX(Wartungsplan!$B$6:$B$323,MATCH($A12,Wartungsplan!$A$6:$A$323,0)),"") | D12: =IFERROR(INDEX(Wartungsplan!$U$6:$U$323,MATCH($A12,Wartungsplan!$A$6:$A$323,0)),"") | E12: =IFERROR(INDEX(Wartungsplan!$V$6:$V$323,MATCH($A12,Wartungsplan!$A$6:$A$323,0)),"") | F12: =IFERROR(IF(INDEX(Wartungsplan!$Z$6:$Z$323,MATCH($A12,Wartungsplan!$A$6:$A$323,0))="","",INDEX(Wartungsplan!$Z$6:$Z$323,MATCH($A12,Wartungsplan!$A$6:$A$323,0))),"") | H12: =IF(OR(G12="",NOT(ISNUMBER(E12))),"",G12+E12*7) | I12: =IF(H12="","",H12-TODAY()) | J12: =IF(NOT(ISNUMBER(E12)),"Intervall fehlt",IF(G12="","nicht erfasst",IF(I12<0,"überfällig",IF(I12<=P_Vorwarn,"bald fällig","in Ordnung"))))
A13: 3.1.4 | B13: =IFERROR(INDEX(Wartungsplan!$AC$6:$AC$323,MATCH($A13,Wartungsplan!$A$6:$A$323,0)),"") | C13: =IFERROR(INDEX(Wartungsplan!$B$6:$B$323,MATCH($A13,Wartungsplan!$A$6:$A$323,0)),"") | D13: =IFERROR(INDEX(Wartungsplan!$U$6:$U$323,MATCH($A13,Wartungsplan!$A$6:$A$323,0)),"") | E13: =IFERROR(INDEX(Wartungsplan!$V$6:$V$323,MATCH($A13,Wartungsplan!$A$6:$A$323,0)),"") | F13: =IFERROR(IF(INDEX(Wartungsplan!$Z$6:$Z$323,MATCH($A13,Wartungsplan!$A$6:$A$323,0))="","",INDEX(Wartungsplan!$Z$6:$Z$323,MATCH($A13,Wartungsplan!$A$6:$A$323,0))),"") | H13: =IF(OR(G13="",NOT(ISNUMBER(E13))),"",G13+E13*7) | I13: =IF(H13="","",H13-TODAY()) | J13: =IF(NOT(ISNUMBER(E13)),"Intervall fehlt",IF(G13="","nicht erfasst",IF(I13<0,"überfällig",IF(I13<=P_Vorwarn,"bald fällig","in Ordnung"))))
A14: 3.1.5 | B14: =IFERROR(INDEX(Wartungsplan!$AC$6:$AC$323,MATCH($A14,Wartungsplan!$A$6:$A$323,0)),"") | C14: =IFERROR(INDEX(Wartungsplan!$B$6:$B$323,MATCH($A14,Wartungsplan!$A$6:$A$323,0)),"") | D14: =IFERROR(INDEX(Wartungsplan!$U$6:$U$323,MATCH($A14,Wartungsplan!$A$6:$A$323,0)),"") | E14: =IFERROR(INDEX(Wartungsplan!$V$6:$V$323,MATCH($A14,Wartungsplan!$A$6:$A$323,0)),"") | F14: =IFERROR(IF(INDEX(Wartungsplan!$Z$6:$Z$323,MATCH($A14,Wartungsplan!$A$6:$A$323,0))="","",INDEX(Wartungsplan!$Z$6:$Z$323,MATCH($A14,Wartungsplan!$A$6:$A$323,0))),"") | H14: =IF(OR(G14="",NOT(ISNUMBER(E14))),"",G14+E14*7) | I14: =IF(H14="","",H14-TODAY()) | J14: =IF(NOT(ISNUMBER(E14)),"Intervall fehlt",IF(G14="","nicht erfasst",IF(I14<0,"überfällig",IF(I14<=P_Vorwarn,"bald fällig","in Ordnung"))))
A15: 3.1.6 | B15: =IFERROR(INDEX(Wartungsplan!$AC$6:$AC$323,MATCH($A15,Wartungsplan!$A$6:$A$323,0)),"") | C15: =IFERROR(INDEX(Wartungsplan!$B$6:$B$323,MATCH($A15,Wartungsplan!$A$6:$A$323,0)),"") | D15: =IFERROR(INDEX(Wartungsplan!$U$6:$U$323,MATCH($A15,Wartungsplan!$A$6:$A$323,0)),"") | E15: =IFERROR(INDEX(Wartungsplan!$V$6:$V$323,MATCH($A15,Wartungsplan!$A$6:$A$323,0)),"") | F15: =IFERROR(IF(INDEX(Wartungsplan!$Z$6:$Z$323,MATCH($A15,Wartungsplan!$A$6:$A$323,0))="","",INDEX(Wartungsplan!$Z$6:$Z$323,MATCH($A15,Wartungsplan!$A$6:$A$323,0))),"") | H15: =IF(OR(G15="",NOT(ISNUMBER(E15))),"",G15+E15*7) | I15: =IF(H15="","",H15-TODAY()) | J15: =IF(NOT(ISNUMBER(E15)),"Intervall fehlt",IF(G15="","nicht erfasst",IF(I15<0,"überfällig",IF(I15<=P_Vorwarn,"bald fällig","in Ordnung"))))
A16: 3.1.7 | B16: =IFERROR(INDEX(Wartungsplan!$AC$6:$AC$323,MATCH($A16,Wartungsplan!$A$6:$A$323,0)),"") | C16: =IFERROR(INDEX(Wartungsplan!$B$6:$B$323,MATCH($A16,Wartungsplan!$A$6:$A$323,0)),"") | D16: =IFERROR(INDEX(Wartungsplan!$U$6:$U$323,MATCH($A16,Wartungsplan!$A$6:$A$323,0)),"") | E16: =IFERROR(INDEX(Wartungsplan!$V$6:$V$323,MATCH($A16,Wartungsplan!$A$6:$A$323,0)),"") | F16: =IFERROR(IF(INDEX(Wartungsplan!$Z$6:$Z$323,MATCH($A16,Wartungsplan!$A$6:$A$323,0))="","",INDEX(Wartungsplan!$Z$6:$Z$323,MATCH($A16,Wartungsplan!$A$6:$A$323,0))),"") | H16: =IF(OR(G16="",NOT(ISNUMBER(E16))),"",G16+E16*7) | I16: =IF(H16="","",H16-TODAY()) | J16: =IF(NOT(ISNUMBER(E16)),"Intervall fehlt",IF(G16="","nicht erfasst",IF(I16<0,"überfällig",IF(I16<=P_Vorwarn,"bald fällig","in Ordnung"))))
A17: 4.1.1 | B17: =IFERROR(INDEX(Wartungsplan!$AC$6:$AC$323,MATCH($A17,Wartungsplan!$A$6:$A$323,0)),"") | C17: =IFERROR(INDEX(Wartungsplan!$B$6:$B$323,MATCH($A17,Wartungsplan!$A$6:$A$323,0)),"") | D17: =IFERROR(INDEX(Wartungsplan!$U$6:$U$323,MATCH($A17,Wartungsplan!$A$6:$A$323,0)),"") | E17: =IFERROR(INDEX(Wartungsplan!$V$6:$V$323,MATCH($A17,Wartungsplan!$A$6:$A$323,0)),"") | F17: =IFERROR(IF(INDEX(Wartungsplan!$Z$6:$Z$323,MATCH($A17,Wartungsplan!$A$6:$A$323,0))="","",INDEX(Wartungsplan!$Z$6:$Z$323,MATCH($A17,Wartungsplan!$A$6:$A$323,0))),"") | H17: =IF(OR(G17="",NOT(ISNUMBER(E17))),"",G17+E17*7) | I17: =IF(H17="","",H17-TODAY()) | J17: =IF(NOT(ISNUMBER(E17)),"Intervall fehlt",IF(G17="","nicht erfasst",IF(I17<0,"überfällig",IF(I17<=P_Vorwarn,"bald fällig","in Ordnung"))))
... A93: 21.3 | B93: =IFERROR(INDEX(Wartungsplan!$AC$6:$AC$323,MATCH($A93,Wartungsplan!$A$6:$A$323,0)),"") | C93: =IFERROR(INDEX(Wartungsplan!$B$6:$B$323,MATCH($A93,Wartungsplan!$A$6:$A$323,0)),"") | D93: =IFERROR(INDEX(Wartungsplan!$U$6:$U$323,MATCH($A93,Wartungsplan!$A$6:$A$323,0)),"") | E93: =IFERROR(INDEX(Wartungsplan!$V$6:$V$323,MATCH($A93,Wartungsplan!$A$6:$A$323,0)),"") | F93: =IFERROR(IF(INDEX(Wartungsplan!$Z$6:$Z$323,MATCH($A93,Wartungsplan!$A$6:$A$323,0))="","",INDEX(Wartungsplan!$Z$6:$Z$323,MATCH($A93,Wartungsplan!$A$6:$A$323,0))),"") | H93: =IF(OR(G93="",NOT(ISNUMBER(E93))),"",G93+E93*7) | I93: =IF(H93="","",H93-TODAY()) | J93: =IF(NOT(ISNUMBER(E93)),"Intervall fehlt",IF(G93="","nicht erfasst",IF(I93<0,"überfällig",IF(I93<=P_Vorwarn,"bald fällig","in Ordnung"))))

Sheet Anlagenübersicht
B1: Anlagenübersicht – Positionen der Übersichtszeichnung
B2: Zuordnung der Positionsnummern zu den Abschnitten des Wartungsplans (Zeichnung aus der Vorversion)
K5: Pos. | L5: Baugruppe | M5: Abschnitt im Plan | N5: Status
K6: 1 | L6: Bedienpult | M6: 2 | N6: im Wartungsplan enthalten
K7: 2 | L7: Staucheinheit | M7: 3 | N7: im Wartungsplan enthalten
K8: 3 | L8: Oberer Werkzeugträger | M8: 4 | N8: im Wartungsplan enthalten
K9: 4 | L9: (Bezeichnung in der Vorversion nicht angegeben) | M9: – | N9: nicht im Wartungsplan – prüfen
K10: 5 | L10: Verschlussbalken | M10: 5 | N10: im Wartungsplan enthalten
K11: 6 | L11: Unterer Werkzeugträger | M11: 4 | N11: im Wartungsplan enthalten
K12: 7 | L12: (Bezeichnung in der Vorversion nicht angegeben) | M12: – | N12: nicht im Wartungsplan – prüfen
K13: 8 | L13: Entnahmehandling (Handling Balggreifer) | M13: 9 | N13: im Wartungsplan enthalten
K14: 9 | L14: (Bezeichnung in der Vorversion nicht angegeben) | M14: – | N14: nicht im Wartungsplan – prüfen
K15: 10 | L15: (Bezeichnung in der Vorversion nicht angegeben) | M15: – | N15: nicht im Wartungsplan – prüfen
K16: 11 | L16: Wasserbehälter für Umformmedium | M16: 7 | N16: im Wartungsplan enthalten
K17: 12 | L17: (Bezeichnung in der Vorversion nicht angegeben) | M17: – | N17: nicht im Wartungsplan – prüfen
... K31: 26 | L31: Hydraulik-Druckfilter (mit Filtereinsatz) | M31: 17 | N31: im Wartungsplan enthalten
B32: Hinweis: Die Positionen 4, 7, 9, 10, 12, 18, 21, 23, 27 und 28 sind in der Zeichnung nummeriert, aber im Wartungsplan nicht berücksichtigt. Bitte im Team klären, ob dort Wartungsbedarf besteht (siehe Blatt „Offene Punkte“). | K32: 27 | L32: (Bezeichnung in der Vorversion nicht angegeben) | M32: – | N32: nicht im Wartungsplan – prüfen
K33: 28 | L33: (Bezeichnung in der Vorversion nicht angegeben) | M33: – | N33: nicht im Wartungsplan – prüfen
K34: 29 | L34: Stauchspindel (Kugelgewindespindel) | M34: 3 | N34: im Wartungsplan enthalten
K35: 30 | L35: Druckübersetzer | M35: 18 | N35: im Wartungsplan enthalten
K37: Ergänzend: Pos. 33 = Schmierbohrung in der Stauchspindel (Detailbild bei Maßnahme 3.1.5). Abschnitte 1 (Not-Aus), 6 (Zylinder), 19 (Schmierung allgemein), 20 (Schutzeinrichtungen) und 21 (Kühlaggregat) sind keiner Position zugeordnet.

Sheet Bewertungskatalog
B1: Bewertungskatalog – Skalen 1 bis 5
B2: Konsolidiert aus den 8 Einzelblättern der Vorversion (Bedeutung F, IH, Q, AS, US, S · Ausfallwahrscheinlichkeit A · Entdeckungswahrscheinlichkeit E)
B5: Kürzel | C5: Kriterium | D5: Leitfrage | E5: 1 | F5: 2 | G5: 3 | H5: 4 | I5: 5
D6: Ausprägung des Risikos | E6: sehr gering | F6: gering | G6: mittel | H6: hoch | I6: sehr hoch
D7: Einstufung (Bezeichnung der Vorversion) | E7: sehr gut | F7: gut | G7: mittel | H7: schlecht | I7: sehr schlecht
B8: Bedeutung B – Folgen eines Ausfalls (fließen über B = √(F²+IH²+Q²+AS²+US²+S²)/2 in die RPZ ein)
B9: F | C9: Funktionalität der Anlage | D9: Welche Auswirkung hat der Ausfall auf die Funktion der Anlage? | E9: kaum wahrnehmbare Auswirkungen | F9: geringe Auswirkungen auf die Funktionalität der Anlage | G9: mäßige Auswirkungen auf die Funktionalität der Anlage | H9: hohe Auswirkungen auf die Funktionalität der Anlage | I9: Anlage wird zerstört; Verschleiß ist enorm hoch
B10: IH | C10: Instandsetzungsaufwand bei Ausfall (Dauer / Personal) | D10: Wie lange dauert die Instandsetzung und wer kann sie durchführen? | E10: Zeit < 10 min; kann durch geschulten Anlagenbediener durchgeführt werden | F10: Zeit 10–30 min; kann vom Instandhalter allein durchgeführt werden | G10: Zeit 30–60 min; kann von Instandhalter und Anlagenbediener durchgeführt werden | H10: Zeit 1–3 h; mindestens 2 Mitarbeiter erforderlich | I10: Zeit > 3 h; mindestens 2 Mitarbeiter / Spezialisten erforderlich
B11: Q | C11: Qualität (Auswirkung auf den Kunden) | D11: Welche Auswirkung hat der Ausfall auf die Produktqualität beim Kunden? | E11: kaum wahrnehmbare Auswirkungen | F11: geringe Auswirkungen auf den Kunden | G11: mäßige Auswirkungen auf den Kunden | H11: Verärgerung des Kunden | I11: Verlust des Kunden
