Workbook
Name Iv_Name: Einstellungen!$B$7:$B$26
Name Iv_Anzahl: Einstellungen!$C$7:$C$26
Name Iv_Einheit: Einstellungen!$D$7:$D$26
Name Iv_Liste: OFFSET(Einstellungen!$B$7,0,0,MAX(1,COUNTA(Einstellungen!$B$7:$B$26)),1)
Name P_Grenze_mittel: Einstellungen!$C$32
Name P_Grenze_hoch: Einstellungen!$C$33
Name P_Grenze_kritisch: Einstellungen!$C$34
Name Kl_Name: Einstellungen!$B$37:$B$40
Name Kl_Intervall: Einstellungen!$E$37:$E$40
Name P_Vorwarn: Einstellungen!$C$46
Name P_Krit: Einstellungen!$C$47
Name SF_Modell: Einstellungen!$B$51:$B$53
Name SF_Wert: Einstellungen!$C$51:$C$53
Name IH_Text: Einstellungen!$C$57:$C$61
Name L_Art: Einstellungen!$B$65:$B$71
Name L_Ausfuehrung: Einstellungen!$D$65:$D$69
Name L_Befund: Einstellungen!$F$65:$F$67
Name P_SF: Start!$C$28
Name M_Name: Start!$C$23
Name M_Equipment: Start!$C$24

Sheet Start
B2: Wartungsplan – große Wartung
B3: Horizontale hydraulische Simultanbalgmaschine (HSIM) · Intervalle, Termine und risikobasierte Bewertung (RPZ)
B6: So funktioniert der Plan – 3 Schritte im Alltag
B7: 1 Intervall wählen | C7: Im Blatt „Wartungsplan“ in der Spalte Intervall aus der Liste wählen (wöchentlich … jährlich) oder frei eintippen, z. B. „2 Jahre“. Vorbelegt ist das empfohlene Intervall aus der Risikobewertung.
B8: 2 Datum eintragen | C8: Nach jeder Durchführung das Datum in „Zuletzt durchgeführt“ eintragen – dazu Befund und Namen.
B9: 3 Ampel beachten | C9: Nächster Termin und Status werden automatisch berechnet: rot = überfällig, gelb = fällig, grün = in Ordnung. Das Dashboard zeigt alle fälligen Maßnahmen auf einen Blick.
B11: Legende
B12: Eingabe | C12: gelb = hier eintragen oder auswählen
B13: Formel | C13: weiß = wird automatisch berechnet
B14: Vorschlag | C14: grau kursiv = Vorschlag, durch Instandhaltung freizugeben
B15: überfällig | C15: Fälligkeitstermin überschritten – sofort durchführen
B16: fällig | C16: wird innerhalb der Vorwarnzeit fällig – einplanen
B17: in Ordnung | C17: fristgerecht durchgeführt
B18: nicht erfasst | C18: noch kein Datum der letzten Durchführung eingetragen
B19: Intervall prüfen | C19: Intervall-Eingabe nicht erkannt (Schreibweise: Zahl + Einheit, z. B. „2 Jahre“)
B20: Intervall fehlt | C20: kein Intervall festgelegt (z. B. weil die Risikobewertung unvollständig ist)
B22: Stammdaten der Anlage
B23: Maschinenbezeichnung | C23: Horizontale hydraulische Simultanbalgmaschine (HSIM)
B24: Equipmentnummer (SAP)
B25: Standort / Kostenstelle
B26: Hersteller / Baujahr
B27: Schichtmodell | C27: 3-Schicht
B28: Schichtfaktor SF (automatisch) | C28: =IFERROR(INDEX(SF_Wert,MATCH(C27,SF_Modell,0)),1)
B30: Dokumentenlenkung & Freigabe
B31: Verantwortlich für Änderungen | C31: fz-pA / H. Mrugalla
B32: Stand / Version | C32: 03 (Entwurf – Freigabe ausstehend)
B33: Datum Stand | C33: =DATE(2026,10,17)
B34: Überarbeitet von
B35: Nächste Überprüfung der Bewertung | C35: =EDATE(C33,12)
B37: Freigabe durch | C37: Name | D37: Datum | E37: Unterschrift
B38: Instandhaltung (Ersteller)
B39: Produktion / Fertigung
B40: Qualitätsmanagement
B41: Arbeitssicherheit / Umwelt
B43: Änderungshistorie
B44: Stand | C44: Datum | D44: Änderung | G44: Bearbeiter
B45: 01 | C45: 03.02.2009 | D45: Ersterstellung Wartungsintervallberechnung | G45: fz-pA / H. Mrugalla
B46: 02 | C46: 17.10.2026 | D46: Strukturelle Überarbeitung, Ampellogik, Dashboard, Bewertungskatalog, offene Punkte (Entwurf)
B47: 03 (Entwurf) | C47: 17.10.2026 | D47: Vereinfachung: 7 statt 11 Blätter; Plan und Durchführungsnachweis zusammengeführt; flexible Intervalle (Standardliste + freie Eingabe, kalendergenaue Termine); Status-Ampel; Dashboard mit Fälligkeitsliste und Erfüllungsgrad.
B49: Blätter dieser Datei
...

Sheet Dashboard
B1: Dashboard – Wartungsplan HSIM
B2: =M_Name&" · Equipment-Nr.: "&IF(M_Equipment="","–",M_Equipment)&" · Stand: "&TEXT(TODAY(),"DD.MM.YYYY")
B5: Status heute
B6: ÜBERFÄLLIG | E6: FÄLLIG | H6: IN ORDNUNG | K6: ERFÜLLUNGSGRAD
B7: =COUNTIF(Wartungsplan!$L$6:$L$323,"überfällig") | E7: =COUNTIF(Wartungsplan!$L$6:$L$323,"fällig") | H7: =COUNTIF(Wartungsplan!$L$6:$L$323,"in Ordnung") | K7: =IFERROR((COUNTIF(Wartungsplan!$L$6:$L$323,"in Ordnung")+COUNTIF(Wartungsplan!$L$6:$L$323,"fällig"))/(COUNTIF(Wartungsplan!$L$6:$L$323,"in Ordnung")+COUNTIF(Wartungsplan!$L$6:$L$323,"fällig")+COUNTIF(Wartungsplan!$L$6:$L$323,"überfällig")),"–")
B9: Termin überschritten | E9: ="in den nächsten "&P_Vorwarn&" Tagen" | H9: fristgerecht erledigt | K9: nicht überfällig / erfasste Maßnahmen
B11: MASSNAHMEN GESAMT | E11: NOCH NICHT ERFASST | H11: INTERVALL FEHLT / PRÜFEN | K11: ERFASSUNGSGRAD
B12: =COUNTIF(Wartungsplan!$AH$6:$AH$323,"Maßnahme") | E12: =COUNTIF(Wartungsplan!$L$6:$L$323,"nicht erfasst") | H12: =COUNTIF(Wartungsplan!$L$6:$L$323,"Intervall fehlt")+COUNTIF(Wartungsplan!$L$6:$L$323,"Intervall prüfen") | K12: =IFERROR(1-COUNTIF(Wartungsplan!$L$6:$L$323,"nicht erfasst")/COUNTIF(Wartungsplan!$AH$6:$AH$323,"Maßnahme"),0)
B14: im Wartungsplan | E14: ohne Datum der letzten Durchführung | H14: siehe Spalte Status | K14: Maßnahmen mit Durchführungsdatum
B16: ="Soll-Durchführungen pro Jahr: "&TEXT(SUM(Wartungsplan!$AL$6:$AL$323),"0")&" · Geplanter Aufwand: "&TEXT(SUM(Wartungsplan!$AM$6:$AM$323),"0.0")&" h/Jahr (Plan-Zeit bei "&COUNT(Wartungsplan!$AE$6:$AE$323)&" von "&COUNTIF(Wartungsplan!$AH$6:$AH$323,"Maßnahme")&" Maßnahmen erfasst) · Abweichend von RPZ-Empfehlung festgelegt: "&SUMPRODUCT((Wartungsplan!$AH$6:$AH$323="Maßnahme")*(Wartungsplan!$H$6:$H$323<>"")*(Wartungsplan!$H$6:$H$323<>Wartungsplan!$G$6:$G$323))
B18: Zu erledigen: überfällige und fällige Maßnahmen (nach Termin sortiert)
B19: Nr. | C19: Maßnahme | H19: Baugruppe | J19: Termin | K19: Tage | L19: Status | M19: Ausführung
B20: =IFERROR(INDEX(Wartungsplan!$A$6:$A$323,MATCH(SMALL(Wartungsplan!$AO$6:$AO$323,1),Wartungsplan!$AO$6:$AO$323,0)),"") | C20: =IFERROR(INDEX(Wartungsplan!$B$6:$B$323,MATCH(SMALL(Wartungsplan!$AO$6:$AO$323,1),Wartungsplan!$AO$6:$AO$323,0)),"") | H20: =IFERROR(INDEX(Wartungsplan!$AG$6:$AG$323,MATCH(SMALL(Wartungsplan!$AO$6:$AO$323,1),Wartungsplan!$AO$6:$AO$323,0)),"") | J20: =IFERROR(INDEX(Wartungsplan!$J$6:$J$323,MATCH(SMALL(Wartungsplan!$AO$6:$AO$323,1),Wartungsplan!$AO$6:$AO$323,0)),"") | K20: =IFERROR(INDEX(Wartungsplan!$K$6:$K$323,MATCH(SMALL(Wartungsplan!$AO$6:$AO$323,1),Wartungsplan!$AO$6:$AO$323,0)),"") | L20: =IFERROR(INDEX(Wartungsplan!$L$6:$L$323,MATCH(SMALL(Wartungsplan!$AO$6:$AO$323,1),Wartungsplan!$AO$6:$AO$323,0)),"") | M20: =IFERROR(INDEX(Wartungsplan!$M$6:$M$323,MATCH(SMALL(Wartungsplan!$AO$6:$AO$323,1),Wartungsplan!$AO$6:$AO$323,0)),"")
B21: =IFERROR(INDEX(Wartungsplan!$A$6:$A$323,MATCH(SMALL(Wartungsplan!$AO$6:$AO$323,2),Wartungsplan!$AO$6:$AO$323,0)),"") | C21: =IFERROR(INDEX(Wartungsplan!$B$6:$B$323,MATCH(SMALL(Wartungsplan!$AO$6:$AO$323,2),Wartungsplan!$AO$6:$AO$323,0)),"") | H21: =IFERROR(INDEX(Wartungsplan!$AG$6:$AG$323,MATCH(SMALL(Wartungsplan!$AO$6:$AO$323,2),Wartungsplan!$AO$6:$AO$323,0)),"") | J21: =IFERROR(INDEX(Wartungsplan!$J$6:$J$323,MATCH(SMALL(Wartungsplan!$AO$6:$AO$323,2),Wartungsplan!$AO$6:$AO$323,0)),"") | K21: =IFERROR(INDEX(Wartungsplan!$K$6:$K$323,MATCH(SMALL(Wartungsplan!$AO$6:$AO$323,2),Wartungsplan!$AO$6:$AO$323,0)),"") | L21: =IFERROR(INDEX(Wartungsplan!$L$6:$L$323,MATCH(SMALL(Wartungsplan!$AO$6:$AO$323,2),Wartungsplan!$AO$6:$AO$323,0)),"") | M21: =IFERROR(INDEX(Wartungsplan!$M$6:$M$323,MATCH(SMALL(Wartungsplan!$AO$6:$AO$323,2),Wartungsplan!$AO$6:$AO$323,0)),"")
B22: =IFERROR(INDEX(Wartungsplan!$A$6:$A$323,MATCH(SMALL(Wartungsplan!$AO$6:$AO$323,3),Wartungsplan!$AO$6:$AO$323,0)),"") | C22: =IFERROR(INDEX(Wartungsplan!$B$6:$B$323,MATCH(SMALL(Wartungsplan!$AO$6:$AO$323,3),Wartungsplan!$AO$6:$AO$323,0)),"") | H22: =IFERROR(INDEX(Wartungsplan!$AG$6:$AG$323,MATCH(SMALL(Wartungsplan!$AO$6:$AO$323,3),Wartungsplan!$AO$6:$AO$323,0)),"") | J22: =IFERROR(INDEX(Wartungsplan!$J$6:$J$323,MATCH(SMALL(Wartungsplan!$AO$6:$AO$323,3),Wartungsplan!$AO$6:$AO$323,0)),"") | K22: =IFERROR(INDEX(Wartungsplan!$K$6:$K$323,MATCH(SMALL(Wartungsplan!$AO$6:$AO$323,3),Wartungsplan!$AO$6:$AO$323,0)),"") | L22: =IFERROR(INDEX(Wartungsplan!$L$6:$L$323,MATCH(SMALL(Wartungsplan!$AO$6:$AO$323,3),Wartungsplan!$AO$6:$AO$323,0)),"") | M22: =IFERROR(INDEX(Wartungsplan!$M$6:$M$323,MATCH(SMALL(Wartungsplan!$AO$6:$AO$323,3),Wartungsplan!$AO$6:$AO$323,0)),"")
B23: =IFERROR(INDEX(Wartungsplan!$A$6:$A$323,MATCH(SMALL(Wartungsplan!$AO$6:$AO$323,4),Wartungsplan!$AO$6:$AO$323,0)),"") | C23: =IFERROR(INDEX(Wartungsplan!$B$6:$B$323,MATCH(SMALL(Wartungsplan!$AO$6:$AO$323,4),Wartungsplan!$AO$6:$AO$323,0)),"") | H23: =IFERROR(INDEX(Wartungsplan!$AG$6:$AG$323,MATCH(SMALL(Wartungsplan!$AO$6:$AO$323,4),Wartungsplan!$AO$6:$AO$323,0)),"") | J23: =IFERROR(INDEX(Wartungsplan!$J$6:$J$323,MATCH(SMALL(Wartungsplan!$AO$6:$AO$323,4),Wartungsplan!$AO$6:$AO$323,0)),"") | K23: =IFERROR(INDEX(Wartungsplan!$K$6:$K$323,MATCH(SMALL(Wartungsplan!$AO$6:$AO$323,4),Wartungsplan!$AO$6:$AO$323,0)),"") | L23: =IFERROR(INDEX(Wartungsplan!$L$6:$L$323,MATCH(SMALL(Wartungsplan!$AO$6:$AO$323,4),Wartungsplan!$AO$6:$AO$323,0)),"") | M23: =IFERROR(INDEX(Wartungsplan!$M$6:$M$323,MATCH(SMALL(Wartungsplan!$AO$6:$AO$323,4),Wartungsplan!$AO$6:$AO$323,0)),"")
B24: =IFERROR(INDEX(Wartungsplan!$A$6:$A$323,MATCH(SMALL(Wartungsplan!$AO$6:$AO$323,5),Wartungsplan!$AO$6:$AO$323,0)),"") | C24: =IFERROR(INDEX(Wartungsplan!$B$6:$B$323,MATCH(SMALL(Wartungsplan!$AO$6:$AO$323,5),Wartungsplan!$AO$6:$AO$323,0)),"") | H24: =IFERROR(INDEX(Wartungsplan!$AG$6:$AG$323,MATCH(SMALL(Wartungsplan!$AO$6:$AO$323,5),Wartungsplan!$AO$6:$AO$323,0)),"") | J24: =IFERROR(INDEX(Wartungsplan!$J$6:$J$323,MATCH(SMALL(Wartungsplan!$AO$6:$AO$323,5),Wartungsplan!$AO$6:$AO$323,0)),"") | K24: =IFERROR(INDEX(Wartungsplan!$K$6:$K$323,MATCH(SMALL(Wartungsplan!$AO$6:$AO$323,5),Wartungsplan!$AO$6:$AO$323,0)),"") | L24: =IFERROR(INDEX(Wartungsplan!$L$6:$L$323,MATCH(SMALL(Wartungsplan!$AO$6:$AO$323,5),Wartungsplan!$AO$6:$AO$323,0)),"") | M24: =IFERROR(INDEX(Wartungsplan!$M$6:$M$323,MATCH(SMALL(Wartungsplan!$AO$6:$AO$323,5),Wartungsplan!$AO$6:$AO$323,0)),"")
B25: =IFERROR(INDEX(Wartungsplan!$A$6:$A$323,MATCH(SMALL(Wartungsplan!$AO$6:$AO$323,6),Wartungsplan!$AO$6:$AO$323,0)),"") | C25: =IFERROR(INDEX(Wartungsplan!$B$6:$B$323,MATCH(SMALL(Wartungsplan!$AO$6:$AO$323,6),Wartungsplan!$AO$6:$AO$323,0)),"") | H25: =IFERROR(INDEX(Wartungsplan!$AG$6:$AG$323,MATCH(SMALL(Wartungsplan!$AO$6:$AO$323,6),Wartungsplan!$AO$6:$AO$323,0)),"") | J25: =IFERROR(INDEX(Wartungsplan!$J$6:$J$323,MATCH(SMALL(Wartungsplan!$AO$6:$AO$323,6),Wartungsplan!$AO$6:$AO$323,0)),"") | K25: =IFERROR(INDEX(Wartungsplan!$K$6:$K$323,MATCH(SMALL(Wartungsplan!$AO$6:$AO$323,6),Wartungsplan!$AO$6:$AO$323,0)),"") | L25: =IFERROR(INDEX(Wartungsplan!$L$6:$L$323,MATCH(SMALL(Wartungsplan!$AO$6:$AO$323,6),Wartungsplan!$AO$6:$AO$323,0)),"") | M25: =IFERROR(INDEX(Wartungsplan!$M$6:$M$323,MATCH(SMALL(Wartungsplan!$AO$6:$AO$323,6),Wartungsplan!$AO$6:$AO$323,0)),"")
B26: =IFERROR(INDEX(Wartungsplan!$A$6:$A$323,MATCH(SMALL(Wartungsplan!$AO$6:$AO$323,7),Wartungsplan!$AO$6:$AO$323,0)),"") | C26: =IFERROR(INDEX(Wartungsplan!$B$6:$B$323,MATCH(SMALL(Wartungsplan!$AO$6:$AO$323,7),Wartungsplan!$AO$6:$AO$323,0)),"") | H26: =IFERROR(INDEX(Wartungsplan!$AG$6:$AG$323,MATCH(SMALL(Wartungsplan!$AO$6:$AO$323,7),Wartungsplan!$AO$6:$AO$323,0)),"") | J26: =IFERROR(INDEX(Wartungsplan!$J$6:$J$323,MATCH(SMALL(Wartungsplan!$AO$6:$AO$323,7),Wartungsplan!$AO$6:$AO$323,0)),"") | K26: =IFERROR(INDEX(Wartungsplan!$K$6:$K$323,MATCH(SMALL(Wartungsplan!$AO$6:$AO$323,7),Wartungsplan!$AO$6:$AO$323,0)),"") | L26: =IFERROR(INDEX(Wartungsplan!$L$6:$L$323,MATCH(SMALL(Wartungsplan!$AO$6:$AO$323,7),Wartungsplan!$AO$6:$AO$323,0)),"") | M26: =IFERROR(INDEX(Wartungsplan!$M$6:$M$323,MATCH(SMALL(Wartungsplan!$AO$6:$AO$323,7),Wartungsplan!$AO$6:$AO$323,0)),"")
B27: =IFERROR(INDEX(Wartungsplan!$A$6:$A$323,MATCH(SMALL(Wartungsplan!$AO$6:$AO$323,8),Wartungsplan!$AO$6:$AO$323,0)),"") | C27: =IFERROR(INDEX(Wartungsplan!$B$6:$B$323,MATCH(SMALL(Wartungsplan!$AO$6:$AO$323,8),Wartungsplan!$AO$6:$AO$323,0)),"") | H27: =IFERROR(INDEX(Wartungsplan!$AG$6:$AG$323,MATCH(SMALL(Wartungsplan!$AO$6:$AO$323,8),Wartungsplan!$AO$6:$AO$323,0)),"") | J27: =IFERROR(INDEX(Wartungsplan!$J$6:$J$323,MATCH(SMALL(Wartungsplan!$AO$6:$AO$323,8),Wartungsplan!$AO$6:$AO$323,0)),"") | K27: =IFERROR(INDEX(Wartungsplan!$K$6:$K$323,MATCH(SMALL(Wartungsplan!$AO$6:$AO$323,8),Wartungsplan!$AO$6:$AO$323,0)),"") | L27: =IFERROR(INDEX(Wartungsplan!$L$6:$L$323,MATCH(SMALL(Wartungsplan!$AO$6:$AO$323,8),Wartungsplan!$AO$6:$AO$323,0)),"") | M27: =IFERROR(INDEX(Wartungsplan!$M$6:$M$323,MATCH(SMALL(Wartungsplan!$AO$6:$AO$323,8),Wartungsplan!$AO$6:$AO$323,0)),"")
B28: =IFERROR(INDEX(Wartungsplan!$A$6:$A$323,MATCH(SMALL(Wartungsplan!$AO$6:$AO$323,9),Wartungsplan!$AO$6:$AO$323,0)),"") | C28: =IFERROR(INDEX(Wartungsplan!$B$6:$B$323,MATCH(SMALL(Wartungsplan!$AO$6:$AO$323,9),Wartungsplan!$AO$6:$AO$323,0)),"") | H28: =IFERROR(INDEX(Wartungsplan!$AG$6:$AG$323,MATCH(SMALL(Wartungsplan!$AO$6:$AO$323,9),Wartungsplan!$AO$6:$AO$323,0)),"") | J28: =IFERROR(INDEX(Wartungsplan!$J$6:$J$323,MATCH(SMALL(Wartungsplan!$AO$6:$AO$323,9),Wartungsplan!$AO$6:$AO$323,0)),"") | K28: =IFERROR(INDEX(Wartungsplan!$K$6:$K$323,MATCH(SMALL(Wartungsplan!$AO$6:$AO$323,9),Wartungsplan!$AO$6:$AO$323,0)),"") | L28: =IFERROR(INDEX(Wartungsplan!$L$6:$L$323,MATCH(SMALL(Wartungsplan!$AO$6:$AO$323,9),Wartungsplan!$AO$6:$AO$323,0)),"") | M28: =IFERROR(INDEX(Wartungsplan!$M$6:$M$323,MATCH(SMALL(Wartungsplan!$AO$6:$AO$323,9),Wartungsplan!$AO$6:$AO$323,0)),"")
B29: =IFERROR(INDEX(Wartungsplan!$A$6:$A$323,MATCH(SMALL(Wartungsplan!$AO$6:$AO$323,10),Wartungsplan!$AO$6:$AO$323,0)),"") | C29: =IFERROR(INDEX(Wartungsplan!$B$6:$B$323,MATCH(SMALL(Wartungsplan!$AO$6:$AO$323,10),Wartungsplan!$AO$6:$AO$323,0)),"") | H29: =IFERROR(INDEX(Wartungsplan!$AG$6:$AG$323,MATCH(SMALL(Wartungsplan!$AO$6:$AO$323,10),Wartungsplan!$AO$6:$AO$323,0)),"") | J29: =IFERROR(INDEX(Wartungsplan!$J$6:$J$323,MATCH(SMALL(Wartungsplan!$AO$6:$AO$323,10),Wartungsplan!$AO$6:$AO$323,0)),"") | K29: =IFERROR(INDEX(Wartungsplan!$K$6:$K$323,MATCH(SMALL(Wartungsplan!$AO$6:$AO$323,10),Wartungsplan!$AO$6:$AO$323,0)),"") | L29: =IFERROR(INDEX(Wartungsplan!$L$6:$L$323,MATCH(SMALL(Wartungsplan!$AO$6:$AO$323,10),Wartungsplan!$AO$6:$AO$323,0)),"") | M29: =IFERROR(INDEX(Wartungsplan!$M$6:$M$323,MATCH(SMALL(Wartungsplan!$AO$6:$AO$323,10),Wartungsplan!$AO$6:$AO$323,0)),"")
B30: =IFERROR(INDEX(Wartungsplan!$A$6:$A$323,MATCH(SMALL(Wartungsplan!$AO$6:$AO$323,11),Wartungsplan!$AO$6:$AO$323,0)),"") | C30: =IFERROR(INDEX(Wartungsplan!$B$6:$B$323,MATCH(SMALL(Wartungsplan!$AO$6:$AO$323,11),Wartungsplan!$AO$6:$AO$323,0)),"") | H30: =IFERROR(INDEX(Wartungsplan!$AG$6:$AG$323,MATCH(SMALL(Wartungsplan!$AO$6:$AO$323,11),Wartungsplan!$AO$6:$AO$323,0)),"") | J30: =IFERROR(INDEX(Wartungsplan!$J$6:$J$323,MATCH(SMALL(Wartungsplan!$AO$6:$AO$323,11),Wartungsplan!$AO$6:$AO$323,0)),"") | K30: =IFERROR(INDEX(Wartungsplan!$K$6:$K$323,MATCH(SMALL(Wartungsplan!$AO$6:$AO$323,11),Wartungsplan!$AO$6:$AO$323,0)),"") | L30: =IFERROR(INDEX(Wartungsplan!$L$6:$L$323,MATCH(SMALL(Wartungsplan!$AO$6:$AO$323,11),Wartungsplan!$AO$6:$AO$323,0)),"") | M30: =IFERROR(INDEX(Wartungsplan!$M$6:$M$323,MATCH(SMALL(Wartungsplan!$AO$6:$AO$323,11),Wartungsplan!$AO$6:$AO$323,0)),"")
B31: =IFERROR(INDEX(Wartungsplan!$A$6:$A$323,MATCH(SMALL(Wartungsplan!$AO$6:$AO$323,12),Wartungsplan!$AO$6:$AO$323,0)),"") | C31: =IFERROR(INDEX(Wartungsplan!$B$6:$B$323,MATCH(SMALL(Wartungsplan!$AO$6:$AO$323,12),Wartungsplan!$AO$6:$AO$323,0)),"") | H31: =IFERROR(INDEX(Wartungsplan!$AG$6:$AG$323,MATCH(SMALL(Wartungsplan!$AO$6:$AO$323,12),Wartungsplan!$AO$6:$AO$323,0)),"") | J31: =IFERROR(INDEX(Wartungsplan!$J$6:$J$323,MATCH(SMALL(Wartungsplan!$AO$6:$AO$323,12),Wartungsplan!$AO$6:$AO$323,0)),"") | K31: =IFERROR(INDEX(Wartungsplan!$K$6:$K$323,MATCH(SMALL(Wartungsplan!$AO$6:$AO$323,12),Wartungsplan!$AO$6:$AO$323,0)),"") | L31: =IFERROR(INDEX(Wartungsplan!$L$6:$L$323,MATCH(SMALL(Wartungsplan!$AO$6:$AO$323,12),Wartungsplan!$AO$6:$AO$323,0)),"") | M31: =IFERROR(INDEX(Wartungsplan!$M$6:$M$323,MATCH(SMALL(Wartungsplan!$AO$6:$AO$323,12),Wartungsplan!$AO$6:$AO$323,0)),"")
B32: =IFERROR(INDEX(Wartungsplan!$A$6:$A$323,MATCH(SMALL(Wartungsplan!$AO$6:$AO$323,13),Wartungsplan!$AO$6:$AO$323,0)),"") | C32: =IFERROR(INDEX(Wartungsplan!$B$6:$B$323,MATCH(SMALL(Wartungsplan!$AO$6:$AO$323,13),Wartungsplan!$AO$6:$AO$323,0)),"") | H32: =IFERROR(INDEX(Wartungsplan!$AG$6:$AG$323,MATCH(SMALL(Wartungsplan!$AO$6:$AO$323,13),Wartungsplan!$AO$6:$AO$323,0)),"") | J32: =IFERROR(INDEX(Wartungsplan!$J$6:$J$323,MATCH(SMALL(Wartungsplan!$AO$6:$AO$323,13),Wartungsplan!$AO$6:$AO$323,0)),"") | K32: =IFERROR(INDEX(Wartungsplan!$K$6:$K$323,MATCH(SMALL(Wartungsplan!$AO$6:$AO$323,13),Wartungsplan!$AO$6:$AO$323,0)),"") | L32: =IFERROR(INDEX(Wartungsplan!$L$6:$L$323,MATCH(SMALL(Wartungsplan!$AO$6:$AO$323,13),Wartungsplan!$AO$6:$AO$323,0)),"") | M32: =IFERROR(INDEX(Wartungsplan!$M$6:$M$323,MATCH(SMALL(Wartungsplan!$AO$6:$AO$323,13),Wartungsplan!$AO$6:$AO$323,0)),"")
B33: =IFERROR(INDEX(Wartungsplan!$A$6:$A$323,MATCH(SMALL(Wartungsplan!$AO$6:$AO$323,14),Wartungsplan!$AO$6:$AO$323,0)),"") | C33: =IFERROR(INDEX(Wartungsplan!$B$6:$B$323,MATCH(SMALL(Wartungsplan!$AO$6:$AO$323,14),Wartungsplan!$AO$6:$AO$323,0)),"") | H33: =IFERROR(INDEX(Wartungsplan!$AG$6:$AG$323,MATCH(SMALL(Wartungsplan!$AO$6:$AO$323,14),Wartungsplan!$AO$6:$AO$323,0)),"") | J33: =IFERROR(INDEX(Wartungsplan!$J$6:$J$323,MATCH(SMALL(Wartungsplan!$AO$6:$AO$323,14),Wartungsplan!$AO$6:$AO$323,0)),"") | K33: =IFERROR(INDEX(Wartungsplan!$K$6:$K$323,MATCH(SMALL(Wartungsplan!$AO$6:$AO$323,14),Wartungsplan!$AO$6:$AO$323,0)),"") | L33: =IFERROR(INDEX(Wartungsplan!$L$6:$L$323,MATCH(SMALL(Wartungsplan!$AO$6:$AO$323,14),Wartungsplan!$AO$6:$AO$323,0)),"") | M33: =IFERROR(INDEX(Wartungsplan!$M$6:$M$323,MATCH(SMALL(Wartungsplan!$AO$6:$AO$323,14),Wartungsplan!$AO$6:$AO$323,0)),"")
B34: =IFERROR(INDEX(Wartungsplan!$A$6:$A$323,MATCH(SMALL(Wartungsplan!$AO$6:$AO$323,15),Wartungsplan!$AO$6:$AO$323,0)),"") | C34: =IFERROR(INDEX(Wartungsplan!$B$6:$B$323,MATCH(SMALL(Wartungsplan!$AO$6:$AO$323,15),Wartungsplan!$AO$6:$AO$323,0)),"") | H34: =IFERROR(INDEX(Wartungsplan!$AG$6:$AG$323,MATCH(SMALL(Wartungsplan!$AO$6:$AO$323,15),Wartungsplan!$AO$6:$AO$323,0)),"") | J34: =IFERROR(INDEX(Wartungsplan!$J$6:$J$323,MATCH(SMALL(Wartungsplan!$AO$6:$AO$323,15),Wartungsplan!$AO$6:$AO$323,0)),"") | K34: =IFERROR(INDEX(Wartungsplan!$K$6:$K$323,MATCH(SMALL(Wartungsplan!$AO$6:$AO$323,15),Wartungsplan!$AO$6:$AO$323,0)),"") | L34: =IFERROR(INDEX(Wartungsplan!$L$6:$L$323,MATCH(SMALL(Wartungsplan!$AO$6:$AO$323,15),Wartungsplan!$AO$6:$AO$323,0)),"") | M34: =IFERROR(INDEX(Wartungsplan!$M$6:$M$323,MATCH(SMALL(Wartungsplan!$AO$6:$AO$323,15),Wartungsplan!$AO$6:$AO$323,0)),"")
B35: =IF(COUNT(Wartungsplan!$AO$6:$AO$323)>15,"… weitere "&(COUNT(Wartungsplan!$AO$6:$AO$323)-15)&" Maßnahmen – im Wartungsplan nach Status filtern",IF(COUNT(Wartungsplan!$AO$6:$AO$323)=0,"Aktuell keine fälligen oder überfälligen Maßnahmen.",""))
B37: Maßnahmen pro Intervall
B38: Intervall | D38: Gruppe | E38: Anzahl | F38: Anteil
B39: =IF(Einstellungen!B7="","",Einstellungen!B7) | D39: =IF(Einstellungen!B7="","",Einstellungen!E7) | E39: =IF(B39="","",COUNTIFS(Wartungsplan!$AH$6:$AH$323,"Maßnahme",Wartungsplan!$H$6:$H$323,B39)) | F39: =IF(B39="","",IFERROR(E39/$E$53,0))
B40: =IF(Einstellungen!B8="","",Einstellungen!B8) | D40: =IF(Einstellungen!B8="","",Einstellungen!E8) | E40: =IF(B40="","",COUNTIFS(Wartungsplan!$AH$6:$AH$323,"Maßnahme",Wartungsplan!$H$6:$H$323,B40)) | F40: =IF(B40="","",IFERROR(E40/$E$53,0))
B41: =IF(Einstellungen!B9="","",Einstellungen!B9) | D41: =IF(Einstellungen!B9="","",Einstellungen!E9) | E41: =IF(B41="","",COUNTIFS(Wartungsplan!$AH$6:$AH$323,"Maßnahme",Wartungsplan!$H$6:$H$323,B41)) | F41: =IF(B41="","",IFERROR(E41/$E$53,0))
B42: =IF(Einstellungen!B10="","",Einstellungen!B10) | D42: =IF(Einstellungen!B10="","",Einstellungen!E10) | E42: =IF(B42="","",COUNTIFS(Wartungsplan!$AH$6:$AH$323,"Maßnahme",Wartungsplan!$H$6:$H$323,B42)) | F42: =IF(B42="","",IFERROR(E42/$E$53,0))
B43: =IF(Einstellungen!B11="","",Einstellungen!B11) | D43: =IF(Einstellungen!B11="","",Einstellungen!E11) | E43: =IF(B43="","",COUNTIFS(Wartungsplan!$AH$6:$AH$323,"Maßnahme",Wartungsplan!$H$6:$H$323,B43)) | F43: =IF(B43="","",IFERROR(E43/$E$53,0))
B44: =IF(Einstellungen!B12="","",Einstellungen!B12) | D44: =IF(Einstellungen!B12="","",Einstellungen!E12) | E44: =IF(B44="","",COUNTIFS(Wartungsplan!$AH$6:$AH$323,"Maßnahme",Wartungsplan!$H$6:$H$323,B44)) | F44: =IF(B44="","",IFERROR(E44/$E$53,0))
B45: =IF(Einstellungen!B13="","",Einstellungen!B13) | D45: =IF(Einstellungen!B13="","",Einstellungen!E13) | E45: =IF(B45="","",COUNTIFS(Wartungsplan!$AH$6:$AH$323,"Maßnahme",Wartungsplan!$H$6:$H$323,B45)) | F45: =IF(B45="","",IFERROR(E45/$E$53,0))
B46: =IF(Einstellungen!B14="","",Einstellungen!B14) | D46: =IF(Einstellungen!B14="","",Einstellungen!E14) | E46: =IF(B46="","",COUNTIFS(Wartungsplan!$AH$6:$AH$323,"Maßnahme",Wartungsplan!$H$6:$H$323,B46)) | F46: =IF(B46="","",IFERROR(E46/$E$53,0))
B47: =IF(Einstellungen!B15="","",Einstellungen!B15) | D47: =IF(Einstellungen!B15="","",Einstellungen!E15) | E47: =IF(B47="","",COUNTIFS(Wartungsplan!$AH$6:$AH$323,"Maßnahme",Wartungsplan!$H$6:$H$323,B47)) | F47: =IF(B47="","",IFERROR(E47/$E$53,0))
B48: =IF(Einstellungen!B16="","",Einstellungen!B16) | D48: =IF(Einstellungen!B16="","",Einstellungen!E16) | E48: =IF(B48="","",COUNTIFS(Wartungsplan!$AH$6:$AH$323,"Maßnahme",Wartungsplan!$H$6:$H$323,B48)) | F48: =IF(B48="","",IFERROR(E48/$E$53,0))
...

Sheet Wartungsplan
A1: Wartungsplan – große Wartung
A2: ="Maschine: "&M_Name&" · Equipment-Nr.: "&IF(M_Equipment="","(auf Blatt Start eintragen)",M_Equipment)&" · Stichtag: "&TEXT(TODAY(),"DD.MM.YYYY")
A3: Gelb = Eingabe. Intervall: aus Liste wählen oder frei eintippen (z. B. „2 Jahre“). Nach Durchführung Datum eintragen → Termin und Ampel rechnen sich selbst. Risikobewertung: [+] über Spalte Q aufklappen.
A4: Maßnahme | G4: Intervall & Termine | M4: Durchführung & Nachweis | Q4: Risikobewertung & Planung (aufklappbar) | AG4: Hilfsspalten (ausgeblendet) | AP4: Vorversion (aufklappbar)
A5: Nr. | B5: Maßnahme | C5: Art | D5: Hilfsmittel & Hinweise | E5: Sollzustand / Prüfkriterium | F5: Bild | G5: Empfehlung (RPZ) | H5: Intervall | I5: Zuletzt durchgeführt | J5: Nächster Termin | K5: Tage | L5: Status | M5: Ausführung durch | N5: Durchgeführt von | O5: Befund | P5: Bemerkung / Begründung | Q5: F | R5: IH | S5: Q | T5: AS | U5: US | V5: S | W5: A | X5: E | Y5: SF | Z5: B | AA5: RPZ | AB5: Risikoklasse | AC5: Relevanz AS/Q/US | AD5: Instandsetzung bei Ausfall | AE5: Plan-Zeit [min] | AF5: Bewertung übernommen von | AG5: Baugruppe | AH5: Zeilentyp | AI5: Int. Anzahl | AJ5: Int. Einheit | AK5: Int. Tage | AL5: Durchf. pro Jahr | AM5: Aufwand [h/Jahr] | AN5: Rang RPZ | AO5: Rang Termin | AP5: Nr. Vorversion | AQ5: Originaltext Vorversion
A6: 1 | B6: Not-Aus | AG6: Not-Aus | AH6: Baugruppe | AP6: 1 | AQ6: Not-Aus
A7: 1.1 | B7: Funktion prüfen (Rasterung, Schaltwirkung) | C7: Funktionsprüfung | D7: ⚠ Gefahrenstelle | E7: Not-Aus sowie sicherheitsrelevante Einrichtungen werden täglich vor Arbeitsbeginn geprüft (Sichtkontrolle). | G7: =IF(AB7="unvollständig","Bewertung fehlt",INDEX(Kl_Intervall,MATCH(AB7,Kl_Name,0))) | H7: =IF(G7="Bewertung fehlt","",G7) | J7: =IF(OR(I7="",NOT(ISNUMBER(AK7))),"",IF(AJ7="Tage",I7+AI7,IF(AJ7="Wochen",I7+7*AI7,EDATE(I7,ROUND(AI7*IF(AJ7="Jahre",12,1),0))))) | K7: =IF(J7="","",J7-TODAY()) | L7: =IF(H7="","Intervall fehlt",IF(NOT(ISNUMBER(AK7)),"Intervall prüfen",IF(I7="","nicht erfasst",IF(K7<0,"überfällig",IF(K7<=MIN(P_Vorwarn,ROUND(AK7/4,0)),"fällig","in Ordnung"))))) | Q7: 3 | R7: 3 | S7: 1 | T7: 5 | U7: 1 | V7: 2 | W7: 2 | X7: 1 | Y7: =P_SF | Z7: =IF(COUNT(Q7:V7)=6,SQRT(SUMSQ(Q7:V7))/2,"") | AA7: =IF(COUNT(W7:Z7)=4,Z7*W7*X7*Y7,"") | AB7: =IF(AA7="","unvollständig",IF(AA7>P_Grenze_kritisch,"kritisch",IF(AA7>=P_Grenze_hoch,"hoch",IF(AA7>=P_Grenze_mittel,"mittel","gering")))) | AC7: =TRIM(IF(N(T7)>=P_Krit,"AS ","")&IF(N(S7)>=P_Krit,"Q ","")&IF(N(U7)>=P_Krit,"US","")) | AD7: =IF(ISNUMBER(R7),INDEX(IH_Text,R7),"") | AG7: Not-Aus | AH7: Maßnahme | AI7: =IF(H7="","",IFERROR(INDEX(Iv_Anzahl,MATCH(H7,Iv_Name,0)),IFERROR(VALUE(LEFT(TRIM(SUBSTITUTE(LOWER(H7),"alle ","")),FIND(" ",TRIM(SUBSTITUTE(LOWER(H7),"alle ",""))&" ")-1)),""))) | AJ7: =IF(H7="","",IFERROR(INDEX(Iv_Einheit,MATCH(H7,Iv_Name,0)),IF(ISNUMBER(SEARCH("jahr",H7)),"Jahre",IF(ISNUMBER(SEARCH("monat",H7)),"Monate",IF(ISNUMBER(SEARCH("woche",H7)),"Wochen",IF(ISNUMBER(SEARCH("tag",H7)),"Tage","")))))) | AK7: =IF(AND(ISNUMBER(AI7),AJ7<>""),IF(AI7>0,AI7*IF(AJ7="Tage",1,IF(AJ7="Wochen",7,IF(AJ7="Monate",365/12,365))),""),"") | AL7: =IF(ISNUMBER(AK7),365/AK7,"") | AM7: =IF(AND(ISNUMBER(AL7),ISNUMBER(AE7)),AL7*AE7/60,"") | AN7: =IF(ISNUMBER(AA7),AA7-ROW()/100000,"") | AO7: =IF(OR(L7="überfällig",L7="fällig"),J7+ROW()/100000,"") | AP7: 1.1 | AQ7: Prüfe die Funktion (Rasterung, Schaltwirkung)
A8: 2 | B8: Bedienpult (Pos. 1) | AG8: Bedienpult | AH8: Baugruppe | AP8: 2 | AQ8: 1.) Bedienpult
A9: 2.1 | B9: Funktion aller Bedienelemente prüfen | C9: Funktionsprüfung | E9: Alle Bedienelemente schalten einwandfrei; keine Beschädigung | G9: =IF(AB9="unvollständig","Bewertung fehlt",INDEX(Kl_Intervall,MATCH(AB9,Kl_Name,0))) | H9: =IF(G9="Bewertung fehlt","",G9) | J9: =IF(OR(I9="",NOT(ISNUMBER(AK9))),"",IF(AJ9="Tage",I9+AI9,IF(AJ9="Wochen",I9+7*AI9,EDATE(I9,ROUND(AI9*IF(AJ9="Jahre",12,1),0))))) | K9: =IF(J9="","",J9-TODAY()) | L9: =IF(H9="","Intervall fehlt",IF(NOT(ISNUMBER(AK9)),"Intervall prüfen",IF(I9="","nicht erfasst",IF(K9<0,"überfällig",IF(K9<=MIN(P_Vorwarn,ROUND(AK9/4,0)),"fällig","in Ordnung"))))) | Q9: 3 | R9: 2 | S9: 1 | T9: 3 | U9: 1 | V9: 3 | W9: 2 | X9: 1 | Y9: =P_SF | Z9: =IF(COUNT(Q9:V9)=6,SQRT(SUMSQ(Q9:V9))/2,"") | AA9: =IF(COUNT(W9:Z9)=4,Z9*W9*X9*Y9,"") | AB9: =IF(AA9="","unvollständig",IF(AA9>P_Grenze_kritisch,"kritisch",IF(AA9>=P_Grenze_hoch,"hoch",IF(AA9>=P_Grenze_mittel,"mittel","gering")))) | AC9: =TRIM(IF(N(T9)>=P_Krit,"AS ","")&IF(N(S9)>=P_Krit,"Q ","")&IF(N(U9)>=P_Krit,"US","")) | AD9: =IF(ISNUMBER(R9),INDEX(IH_Text,R9),"") | AG9: Bedienpult | AH9: Maßnahme | AI9: =IF(H9="","",IFERROR(INDEX(Iv_Anzahl,MATCH(H9,Iv_Name,0)),IFERROR(VALUE(LEFT(TRIM(SUBSTITUTE(LOWER(H9),"alle ","")),FIND(" ",TRIM(SUBSTITUTE(LOWER(H9),"alle ",""))&" ")-1)),""))) | AJ9: =IF(H9="","",IFERROR(INDEX(Iv_Einheit,MATCH(H9,Iv_Name,0)),IF(ISNUMBER(SEARCH("jahr",H9)),"Jahre",IF(ISNUMBER(SEARCH("monat",H9)),"Monate",IF(ISNUMBER(SEARCH("woche",H9)),"Wochen",IF(ISNUMBER(SEARCH("tag",H9)),"Tage","")))))) | AK9: =IF(AND(ISNUMBER(AI9),AJ9<>""),IF(AI9>0,AI9*IF(AJ9="Tage",1,IF(AJ9="Wochen",7,IF(AJ9="Monate",365/12,365))),""),"") | AL9: =IF(ISNUMBER(AK9),365/AK9,"") | AM9: =IF(AND(ISNUMBER(AL9),ISNUMBER(AE9)),AL9*AE9/60,"") | AN9: =IF(ISNUMBER(AA9),AA9-ROW()/100000,"") | AO9: =IF(OR(L9="überfällig",L9="fällig"),J9+ROW()/100000,"") | AP9: 2.1 | AQ9: Prüfe die Funktion aller Bedienelemente
A10: 2.2 | B10: Bedienpult reinigen | C10: Reinigung | E10: Bedienpult sauber; Anzeigen und Beschriftungen lesbar | G10: =IF(AB10="unvollständig","Bewertung fehlt",INDEX(Kl_Intervall,MATCH(AB10,Kl_Name,0))) | H10: =IF(G10="Bewertung fehlt","",G10) | J10: =IF(OR(I10="",NOT(ISNUMBER(AK10))),"",IF(AJ10="Tage",I10+AI10,IF(AJ10="Wochen",I10+7*AI10,EDATE(I10,ROUND(AI10*IF(AJ10="Jahre",12,1),0))))) | K10: =IF(J10="","",J10-TODAY()) | L10: =IF(H10="","Intervall fehlt",IF(NOT(ISNUMBER(AK10)),"Intervall prüfen",IF(I10="","nicht erfasst",IF(K10<0,"überfällig",IF(K10<=MIN(P_Vorwarn,ROUND(AK10/4,0)),"fällig","in Ordnung"))))) | Q10: 1 | R10: 2 | S10: 1 | T10: 2 | U10: 1 | V10: 2 | W10: 2 | X10: 1 | Y10: =P_SF | Z10: =IF(COUNT(Q10:V10)=6,SQRT(SUMSQ(Q10:V10))/2,"") | AA10: =IF(COUNT(W10:Z10)=4,Z10*W10*X10*Y10,"") | AB10: =IF(AA10="","unvollständig",IF(AA10>P_Grenze_kritisch,"kritisch",IF(AA10>=P_Grenze_hoch,"hoch",IF(AA10>=P_Grenze_mittel,"mittel","gering")))) | AC10: =TRIM(IF(N(T10)>=P_Krit,"AS ","")&IF(N(S10)>=P_Krit,"Q ","")&IF(N(U10)>=P_Krit,"US","")) | AD10: =IF(ISNUMBER(R10),INDEX(IH_Text,R10),"") | AG10: Bedienpult | AH10: Maßnahme | AI10: =IF(H10="","",IFERROR(INDEX(Iv_Anzahl,MATCH(H10,Iv_Name,0)),IFERROR(VALUE(LEFT(TRIM(SUBSTITUTE(LOWER(H10),"alle ","")),FIND(" ",TRIM(SUBSTITUTE(LOWER(H10),"alle ",""))&" ")-1)),""))) | AJ10: =IF(H10="","",IFERROR(INDEX(Iv_Einheit,MATCH(H10,Iv_Name,0)),IF(ISNUMBER(SEARCH("jahr",H10)),"Jahre",IF(ISNUMBER(SEARCH("monat",H10)),"Monate",IF(ISNUMBER(SEARCH("woche",H10)),"Wochen",IF(ISNUMBER(SEARCH("tag",H10)),"Tage","")))))) | AK10: =IF(AND(ISNUMBER(AI10),AJ10<>""),IF(AI10>0,AI10*IF(AJ10="Tage",1,IF(AJ10="Wochen",7,IF(AJ10="Monate",365/12,365))),""),"") | AL10: =IF(ISNUMBER(AK10),365/AK10,"") | AM10: =IF(AND(ISNUMBER(AL10),ISNUMBER(AE10)),AL10*AE10/60,"") | AN10: =IF(ISNUMBER(AA10),AA10-ROW()/100000,"") | AO10: =IF(OR(L10="überfällig",L10="fällig"),J10+ROW()/100000,"") | AP10: 2.2 | AQ10: Bedienpult reinigen
A11: 2.3 | B11: 24-V-Glühbirnen (Meldeleuchten) prüfen, ggf. austauschen | C11: Inspektion | E11: Alle Meldeleuchten funktionsfähig | G11: =IF(AB11="unvollständig","Bewertung fehlt",INDEX(Kl_Intervall,MATCH(AB11,Kl_Name,0))) | H11: =IF(G11="Bewertung fehlt","",G11) | J11: =IF(OR(I11="",NOT(ISNUMBER(AK11))),"",IF(AJ11="Tage",I11+AI11,IF(AJ11="Wochen",I11+7*AI11,EDATE(I11,ROUND(AI11*IF(AJ11="Jahre",12,1),0))))) | K11: =IF(J11="","",J11-TODAY()) | L11: =IF(H11="","Intervall fehlt",IF(NOT(ISNUMBER(AK11)),"Intervall prüfen",IF(I11="","nicht erfasst",IF(K11<0,"überfällig",IF(K11<=MIN(P_Vorwarn,ROUND(AK11/4,0)),"fällig","in Ordnung"))))) | Q11: 3 | R11: 2 | S11: 1 | T11: 3 | U11: 1 | V11: 3 | W11: 2 | X11: 1 | Y11: =P_SF | Z11: =IF(COUNT(Q11:V11)=6,SQRT(SUMSQ(Q11:V11))/2,"") | AA11: =IF(COUNT(W11:Z11)=4,Z11*W11*X11*Y11,"") | AB11: =IF(AA11="","unvollständig",IF(AA11>P_Grenze_kritisch,"kritisch",IF(AA11>=P_Grenze_hoch,"hoch",IF(AA11>=P_Grenze_mittel,"mittel","gering")))) | AC11: =TRIM(IF(N(T11)>=P_Krit,"AS ","")&IF(N(S11)>=P_Krit,"Q ","")&IF(N(U11)>=P_Krit,"US","")) | AD11: =IF(ISNUMBER(R11),INDEX(IH_Text,R11),"") | AG11: Bedienpult | AH11: Maßnahme | AI11: =IF(H11="","",IFERROR(INDEX(Iv_Anzahl,MATCH(H11,Iv_Name,0)),IFERROR(VALUE(LEFT(TRIM(SUBSTITUTE(LOWER(H11),"alle ","")),FIND(" ",TRIM(SUBSTITUTE(LOWER(H11),"alle ",""))&" ")-1)),""))) | AJ11: =IF(H11="","",IFERROR(INDEX(Iv_Einheit,MATCH(H11,Iv_Name,0)),IF(ISNUMBER(SEARCH("jahr",H11)),"Jahre",IF(ISNUMBER(SEARCH("monat",H11)),"Monate",IF(ISNUMBER(SEARCH("woche",H11)),"Wochen",IF(ISNUMBER(SEARCH("tag",H11)),"Tage","")))))) | AK11: =IF(AND(ISNUMBER(AI11),AJ11<>""),IF(AI11>0,AI11*IF(AJ11="Tage",1,IF(AJ11="Wochen",7,IF(AJ11="Monate",365/12,365))),""),"") | AL11: =IF(ISNUMBER(AK11),365/AK11,"") | AM11: =IF(AND(ISNUMBER(AL11),ISNUMBER(AE11)),AL11*AE11/60,"") | AN11: =IF(ISNUMBER(AA11),AA11-ROW()/100000,"") | AO11: =IF(OR(L11="überfällig",L11="fällig"),J11+ROW()/100000,"") | AP11: 2.3 | AQ11: Prüfe 24V Glühbirnen; ggf. austauschen
A12: 3 | B12: Staucheinheit (Stauchdorn, Stauchspindel, Elemente für Abdichthub von rechts); Pos. 29 Stauchspindel (Kugelgewindespindel) (Pos. 2 / 29) | AG12: Staucheinheit (Stauchdorn, Stauchspindel, Elemente für Abdichthub von rechts); Pos. 29 Stauchspindel (Kugelgewindespindel) | AH12: Baugruppe | AP12: 3 | AQ12: 2.) Staucheinheit (bestehend aus Stauchdorn, Stauchspindel und Elementen für Abdichthub von rechts) Pos. 29 Stauchspindel (Kugelgewindespindel)
A13: 3.1 | B13: Stauchspindel nach folgenden Kriterien inspizieren: | AG13: Staucheinheit (Stauchdorn, Stauchspindel, Elemente für Abdichthub von rechts); Pos. 29 Stauchspindel (Kugelgewindespindel) | AH13: Prüfgruppe | AP13: 3.1 | AQ13: Inspiziere Stauchspindel nach folgenden Kriterien:
A14: 3.1.1 | B14: Stauchspindel auf Beschädigungen prüfen: Oberfläche (Riefen, Kratzer), Geräusche, Laufruhe | C14: Inspektion | E14: Keine Riefen/Kratzer; ruhiger, geräuscharmer Lauf | G14: =IF(AB14="unvollständig","Bewertung fehlt",INDEX(Kl_Intervall,MATCH(AB14,Kl_Name,0))) | H14: =IF(G14="Bewertung fehlt","",G14) | J14: =IF(OR(I14="",NOT(ISNUMBER(AK14))),"",IF(AJ14="Tage",I14+AI14,IF(AJ14="Wochen",I14+7*AI14,EDATE(I14,ROUND(AI14*IF(AJ14="Jahre",12,1),0))))) | K14: =IF(J14="","",J14-TODAY()) | L14: =IF(H14="","Intervall fehlt",IF(NOT(ISNUMBER(AK14)),"Intervall prüfen",IF(I14="","nicht erfasst",IF(K14<0,"überfällig",IF(K14<=MIN(P_Vorwarn,ROUND(AK14/4,0)),"fällig","in Ordnung"))))) | Q14: 4 | R14: 4 | S14: 4 | T14: 2 | U14: 1 | V14: 1 | W14: 2 | X14: 3 | Y14: =P_SF | Z14: =IF(COUNT(Q14:V14)=6,SQRT(SUMSQ(Q14:V14))/2,"") | AA14: =IF(COUNT(W14:Z14)=4,Z14*W14*X14*Y14,"") | AB14: =IF(AA14="","unvollständig",IF(AA14>P_Grenze_kritisch,"kritisch",IF(AA14>=P_Grenze_hoch,"hoch",IF(AA14>=P_Grenze_mittel,"mittel","gering")))) | AC14: =TRIM(IF(N(T14)>=P_Krit,"AS ","")&IF(N(S14)>=P_Krit,"Q ","")&IF(N(U14)>=P_Krit,"US","")) | AD14: =IF(ISNUMBER(R14),INDEX(IH_Text,R14),"") | AG14: Staucheinheit (Stauchdorn, Stauchspindel, Elemente für Abdichthub von rechts); Pos. 29 Stauchspindel (Kugelgewindespindel) | AH14: Maßnahme | AI14: =IF(H14="","",IFERROR(INDEX(Iv_Anzahl,MATCH(H14,Iv_Name,0)),IFERROR(VALUE(LEFT(TRIM(SUBSTITUTE(LOWER(H14),"alle ","")),FIND(" ",TRIM(SUBSTITUTE(LOWER(H14),"alle ",""))&" ")-1)),""))) | AJ14: =IF(H14="","",IFERROR(INDEX(Iv_Einheit,MATCH(H14,Iv_Name,0)),IF(ISNUMBER(SEARCH("jahr",H14)),"Jahre",IF(ISNUMBER(SEARCH("monat",H14)),"Monate",IF(ISNUMBER(SEARCH("woche",H14)),"Wochen",IF(ISNUMBER(SEARCH("tag",H14)),"Tage","")))))) | AK14: =IF(AND(ISNUMBER(AI14),AJ14<>""),IF(AI14>0,AI14*IF(AJ14="Tage",1,IF(AJ14="Wochen",7,IF(AJ14="Monate",365/12,365))),""),"") | AL14: =IF(ISNUMBER(AK14),365/AK14,"") | AM14: =IF(AND(ISNUMBER(AL14),ISNUMBER(AE14)),AL14*AE14/60,"") | AN14: =IF(ISNUMBER(AA14),AA14-ROW()/100000,"") | AO14: =IF(OR(L14="überfällig",L14="fällig"),J14+ROW()/100000,"") | AP14: 3.1.1 | AQ14: Stauchspindel auf Beschädigungen prüfen (Oberfläche (Riffen, Kratzer) d. Stauchspindel prüfen; Stauchspindel auf Geräusche, Laufruhe prüfen
A15: 3.1.2 | B15: Stauchspindel auf Verschmutzung prüfen, ggf. reinigen | C15: Inspektion | E15: Spindel sauber, frei von Ablagerungen | G15: =IF(AB15="unvollständig","Bewertung fehlt",INDEX(Kl_Intervall,MATCH(AB15,Kl_Name,0))) | H15: =IF(G15="Bewertung fehlt","",G15) | J15: =IF(OR(I15="",NOT(ISNUMBER(AK15))),"",IF(AJ15="Tage",I15+AI15,IF(AJ15="Wochen",I15+7*AI15,EDATE(I15,ROUND(AI15*IF(AJ15="Jahre",12,1),0))))) | K15: =IF(J15="","",J15-TODAY()) | L15: =IF(H15="","Intervall fehlt",IF(NOT(ISNUMBER(AK15)),"Intervall prüfen",IF(I15="","nicht erfasst",IF(K15<0,"überfällig",IF(K15<=MIN(P_Vorwarn,ROUND(AK15/4,0)),"fällig","in Ordnung"))))) | Q15: 4 | R15: 4 | S15: 4 | T15: 2 | U15: 1 | V15: 1 | W15: 2 | X15: 3 | Y15: =P_SF | Z15: =IF(COUNT(Q15:V15)=6,SQRT(SUMSQ(Q15:V15))/2,"") | AA15: =IF(COUNT(W15:Z15)=4,Z15*W15*X15*Y15,"") | AB15: =IF(AA15="","unvollständig",IF(AA15>P_Grenze_kritisch,"kritisch",IF(AA15>=P_Grenze_hoch,"hoch",IF(AA15>=P_Grenze_mittel,"mittel","gering")))) | AC15: =TRIM(IF(N(T15)>=P_Krit,"AS ","")&IF(N(S15)>=P_Krit,"Q ","")&IF(N(U15)>=P_Krit,"US","")) | AD15: =IF(ISNUMBER(R15),INDEX(IH_Text,R15),"") | AG15: Staucheinheit (Stauchdorn, Stauchspindel, Elemente für Abdichthub von rechts); Pos. 29 Stauchspindel (Kugelgewindespindel) | AH15: Maßnahme | AI15: =IF(H15="","",IFERROR(INDEX(Iv_Anzahl,MATCH(H15,Iv_Name,0)),IFERROR(VALUE(LEFT(TRIM(SUBSTITUTE(LOWER(H15),"alle ","")),FIND(" ",TRIM(SUBSTITUTE(LOWER(H15),"alle ",""))&" ")-1)),""))) | AJ15: =IF(H15="","",IFERROR(INDEX(Iv_Einheit,MATCH(H15,Iv_Name,0)),IF(ISNUMBER(SEARCH("jahr",H15)),"Jahre",IF(ISNUMBER(SEARCH("monat",H15)),"Monate",IF(ISNUMBER(SEARCH("woche",H15)),"Wochen",IF(ISNUMBER(SEARCH("tag",H15)),"Tage","")))))) | AK15: =IF(AND(ISNUMBER(AI15),AJ15<>""),IF(AI15>0,AI15*IF(AJ15="Tage",1,IF(AJ15="Wochen",7,IF(AJ15="Monate",365/12,365))),""),"") | AL15: =IF(ISNUMBER(AK15),365/AK15,"") | AM15: =IF(AND(ISNUMBER(AL15),ISNUMBER(AE15)),AL15*AE15/60,"") | AN15: =IF(ISNUMBER(AA15),AA15-ROW()/100000,"") | AO15: =IF(OR(L15="überfällig",L15="fällig"),J15+ROW()/100000,"") | AP15: 3.1.2 | AQ15: Stauchspindel auf Verschmutzung prüfen ggf. reinigen
A16: 3.1.3 | B16: Stauchspindel abschmieren (siehe Schmierplan) | C16: Schmierung | E16: Gleichmäßiger Schmierfilm vorhanden | G16: =IF(AB16="unvollständig","Bewertung fehlt",INDEX(Kl_Intervall,MATCH(AB16,Kl_Name,0))) | H16: =IF(G16="Bewertung fehlt","",G16) | J16: =IF(OR(I16="",NOT(ISNUMBER(AK16))),"",IF(AJ16="Tage",I16+AI16,IF(AJ16="Wochen",I16+7*AI16,EDATE(I16,ROUND(AI16*IF(AJ16="Jahre",12,1),0))))) | K16: =IF(J16="","",J16-TODAY()) | L16: =IF(H16="","Intervall fehlt",IF(NOT(ISNUMBER(AK16)),"Intervall prüfen",IF(I16="","nicht erfasst",IF(K16<0,"überfällig",IF(K16<=MIN(P_Vorwarn,ROUND(AK16/4,0)),"fällig","in Ordnung"))))) | Q16: 5 | R16: 5 | S16: 3 | T16: 3 | U16: 2 | V16: 3 | W16: 5 | X16: 4 | Y16: =P_SF | Z16: =IF(COUNT(Q16:V16)=6,SQRT(SUMSQ(Q16:V16))/2,"") | AA16: =IF(COUNT(W16:Z16)=4,Z16*W16*X16*Y16,"") | AB16: =IF(AA16="","unvollständig",IF(AA16>P_Grenze_kritisch,"kritisch",IF(AA16>=P_Grenze_hoch,"hoch",IF(AA16>=P_Grenze_mittel,"mittel","gering")))) | AC16: =TRIM(IF(N(T16)>=P_Krit,"AS ","")&IF(N(S16)>=P_Krit,"Q ","")&IF(N(U16)>=P_Krit,"US","")) | AD16: =IF(ISNUMBER(R16),INDEX(IH_Text,R16),"") | AG16: Staucheinheit (Stauchdorn, Stauchspindel, Elemente für Abdichthub von rechts); Pos. 29 Stauchspindel (Kugelgewindespindel) | AH16: Maßnahme | AI16: =IF(H16="","",IFERROR(INDEX(Iv_Anzahl,MATCH(H16,Iv_Name,0)),IFERROR(VALUE(LEFT(TRIM(SUBSTITUTE(LOWER(H16),"alle ","")),FIND(" ",TRIM(SUBSTITUTE(LOWER(H16),"alle ",""))&" ")-1)),""))) | AJ16: =IF(H16="","",IFERROR(INDEX(Iv_Einheit,MATCH(H16,Iv_Name,0)),IF(ISNUMBER(SEARCH("jahr",H16)),"Jahre",IF(ISNUMBER(SEARCH("monat",H16)),"Monate",IF(ISNUMBER(SEARCH("woche",H16)),"Wochen",IF(ISNUMBER(SEARCH("tag",H16)),"Tage","")))))) | AK16: =IF(AND(ISNUMBER(AI16),AJ16<>""),IF(AI16>0,AI16*IF(AJ16="Tage",1,IF(AJ16="Wochen",7,IF(AJ16="Monate",365/12,365))),""),"") | AL16: =IF(ISNUMBER(AK16),365/AK16,"") | AM16: =IF(AND(ISNUMBER(AL16),ISNUMBER(AE16)),AL16*AE16/60,"") | AN16: =IF(ISNUMBER(AA16),AA16-ROW()/100000,"") | AO16: =IF(OR(L16="überfällig",L16="fällig"),J16+ROW()/100000,"") | AP16: 3.1.3 | AQ16: Stauchspindel abschmieren (siehe Schmierplan)
A17: 3.1.4 | B17: Zustand der Stauchspindel auf Schmierfilm und Verschleiß prüfen; bei ausreichendem Schmierfilm ist keine Schmierung notwendig | C17: Inspektion | E17: Ausreichender Schmierfilm; kein sichtbarer Verschleiß | G17: =IF(AB17="unvollständig","Bewertung fehlt",INDEX(Kl_Intervall,MATCH(AB17,Kl_Name,0))) | H17: =IF(G17="Bewertung fehlt","",G17) | J17: =IF(OR(I17="",NOT(ISNUMBER(AK17))),"",IF(AJ17="Tage",I17+AI17,IF(AJ17="Wochen",I17+7*AI17,EDATE(I17,ROUND(AI17*IF(AJ17="Jahre",12,1),0))))) | K17: =IF(J17="","",J17-TODAY()) | L17: =IF(H17="","Intervall fehlt",IF(NOT(ISNUMBER(AK17)),"Intervall prüfen",IF(I17="","nicht erfasst",IF(K17<0,"überfällig",IF(K17<=MIN(P_Vorwarn,ROUND(AK17/4,0)),"fällig","in Ordnung"))))) | Q17: 5 | R17: 5 | S17: 3 | T17: 3 | U17: 2 | V17: 3 | W17: 5 | X17: 4 | Y17: =P_SF | Z17: =IF(COUNT(Q17:V17)=6,SQRT(SUMSQ(Q17:V17))/2,"") | AA17: =IF(COUNT(W17:Z17)=4,Z17*W17*X17*Y17,"") | AB17: =IF(AA17="","unvollständig",IF(AA17>P_Grenze_kritisch,"kritisch",IF(AA17>=P_Grenze_hoch,"hoch",IF(AA17>=P_Grenze_mittel,"mittel","gering")))) | AC17: =TRIM(IF(N(T17)>=P_Krit,"AS ","")&IF(N(S17)>=P_Krit,"Q ","")&IF(N(U17)>=P_Krit,"US","")) | AD17: =IF(ISNUMBER(R17),INDEX(IH_Text,R17),"") | AG17: Staucheinheit (Stauchdorn, Stauchspindel, Elemente für Abdichthub von rechts); Pos. 29 Stauchspindel (Kugelgewindespindel) | AH17: Maßnahme | AI17: =IF(H17="","",IFERROR(INDEX(Iv_Anzahl,MATCH(H17,Iv_Name,0)),IFERROR(VALUE(LEFT(TRIM(SUBSTITUTE(LOWER(H17),"alle ","")),FIND(" ",TRIM(SUBSTITUTE(LOWER(H17),"alle ",""))&" ")-1)),""))) | AJ17: =IF(H17="","",IFERROR(INDEX(Iv_Einheit,MATCH(H17,Iv_Name,0)),IF(ISNUMBER(SEARCH("jahr",H17)),"Jahre",IF(ISNUMBER(SEARCH("monat",H17)),"Monate",IF(ISNUMBER(SEARCH("woche",H17)),"Wochen",IF(ISNUMBER(SEARCH("tag",H17)),"Tage","")))))) | AK17: =IF(AND(ISNUMBER(AI17),AJ17<>""),IF(AI17>0,AI17*IF(AJ17="Tage",1,IF(AJ17="Wochen",7,IF(AJ17="Monate",365/12,365))),""),"") | AL17: =IF(ISNUMBER(AK17),365/AK17,"") | AM17: =IF(AND(ISNUMBER(AL17),ISNUMBER(AE17)),AL17*AE17/60,"") | AN17: =IF(ISNUMBER(AA17),AA17-ROW()/100000,"") | AO17: =IF(OR(L17="überfällig",L17="fällig"),J17+ROW()/100000,"") | AP17: 3.1.4 | AQ17: überprüfe den Zustand der Stauch-Spindel auf Schmierfilm und Verschleiß. Bei ausreichendem Schmierfilm; --> Schmierung nicht notwendig
A18: 3.1.5 | B18: Abdeckung abschrauben; Schmierung über Bohrung Pos. 33 in der Spindel. ACHTUNG: Spindel dazu unbedingt auf Maximalhub ausfahren. 6–10 Hübe je Schmiernippel; Spindel mit sauberem Pinsel abschmieren (Teflon-Fett) | C18: Schmierung | D18: ⚠ Gefahrenstelle Profi Spezial Grease (Profi Star) | E18: Spindel vollständig abgeschmiert; Abdeckung wieder montiert | G18: =IF(AB18="unvollständig","Bewertung fehlt",INDEX(Kl_Intervall,MATCH(AB18,Kl_Name,0))) | H18: =IF(G18="Bewertung fehlt","",G18) | J18: =IF(OR(I18="",NOT(ISNUMBER(AK18))),"",IF(AJ18="Tage",I18+AI18,IF(AJ18="Wochen",I18+7*AI18,EDATE(I18,ROUND(AI18*IF(AJ18="Jahre",12,1),0))))) | K18: =IF(J18="","",J18-TODAY()) | L18: =IF(H18="","Intervall fehlt",IF(NOT(ISNUMBER(AK18)),"Intervall prüfen",IF(I18="","nicht erfasst",IF(K18<0,"überfällig",IF(K18<=MIN(P_Vorwarn,ROUND(AK18/4,0)),"fällig","in Ordnung"))))) | Q18: 5 | R18: 5 | S18: 3 | T18: 3 | U18: 2 | V18: 3 | W18: 5 | X18: 4 | Y18: =P_SF | Z18: =IF(COUNT(Q18:V18)=6,SQRT(SUMSQ(Q18:V18))/2,"") | AA18: =IF(COUNT(W18:Z18)=4,Z18*W18*X18*Y18,"") | AB18: =IF(AA18="","unvollständig",IF(AA18>P_Grenze_kritisch,"kritisch",IF(AA18>=P_Grenze_hoch,"hoch",IF(AA18>=P_Grenze_mittel,"mittel","gering")))) | AC18: =TRIM(IF(N(T18)>=P_Krit,"AS ","")&IF(N(S18)>=P_Krit,"Q ","")&IF(N(U18)>=P_Krit,"US","")) | AD18: =IF(ISNUMBER(R18),INDEX(IH_Text,R18),"") | AG18: Staucheinheit (Stauchdorn, Stauchspindel, Elemente für Abdichthub von rechts); Pos. 29 Stauchspindel (Kugelgewindespindel) | AH18: Maßnahme | AI18: =IF(H18="","",IFERROR(INDEX(Iv_Anzahl,MATCH(H18,Iv_Name,0)),IFERROR(VALUE(LEFT(TRIM(SUBSTITUTE(LOWER(H18),"alle ","")),FIND(" ",TRIM(SUBSTITUTE(LOWER(H18),"alle ",""))&" ")-1)),""))) | AJ18: =IF(H18="","",IFERROR(INDEX(Iv_Einheit,MATCH(H18,Iv_Name,0)),IF(ISNUMBER(SEARCH("jahr",H18)),"Jahre",IF(ISNUMBER(SEARCH("monat",H18)),"Monate",IF(ISNUMBER(SEARCH("woche",H18)),"Wochen",IF(ISNUMBER(SEARCH("tag",H18)),"Tage","")))))) | AK18: =IF(AND(ISNUMBER(AI18),AJ18<>""),IF(AI18>0,AI18*IF(AJ18="Tage",1,IF(AJ18="Wochen",7,IF(AJ18="Monate",365/12,365))),""),"") | AL18: =IF(ISNUMBER(AK18),365/AK18,"") | AM18: =IF(AND(ISNUMBER(AL18),ISNUMBER(AE18)),AL18*AE18/60,"") | AN18: =IF(ISNUMBER(AA18),AA18-ROW()/100000,"") | AO18: =IF(OR(L18="überfällig",L18="fällig"),J18+ROW()/100000,"") | AP18: 3.1.5 | AQ18: Abdeckung abschrauben --> Schmierung erfolgt über Bohrung Pos. 33 in der Spindel Achtung: Spindel dazu unbedingt auf Maximalhub ausfahren --> Schmieren 6-10 Hübe/Schmiernippel + Spindel mit sauberen Pinsel abschmieren (Teflon-Fett)
A19: 3.1.6 | B19: Getriebe kontrollieren (Sichtkontrolle auf Öl-Leckage) | C19: Inspektion | E19: Keine Öl-Leckage | G19: =IF(AB19="unvollständig","Bewertung fehlt",INDEX(Kl_Intervall,MATCH(AB19,Kl_Name,0))) | H19: =IF(G19="Bewertung fehlt","",G19) | J19: =IF(OR(I19="",NOT(ISNUMBER(AK19))),"",IF(AJ19="Tage",I19+AI19,IF(AJ19="Wochen",I19+7*AI19,EDATE(I19,ROUND(AI19*IF(AJ19="Jahre",12,1),0))))) | K19: =IF(J19="","",J19-TODAY()) | L19: =IF(H19="","Intervall fehlt",IF(NOT(ISNUMBER(AK19)),"Intervall prüfen",IF(I19="","nicht erfasst",IF(K19<0,"überfällig",IF(K19<=MIN(P_Vorwarn,ROUND(AK19/4,0)),"fällig","in Ordnung"))))) | Q19: 4 | R19: 4 | S19: 4 | T19: 2 | U19: 1 | V19: 1 | W19: 2 | X19: 4 | Y19: =P_SF | Z19: =IF(COUNT(Q19:V19)=6,SQRT(SUMSQ(Q19:V19))/2,"") | AA19: =IF(COUNT(W19:Z19)=4,Z19*W19*X19*Y19,"") | AB19: =IF(AA19="","unvollständig",IF(AA19>P_Grenze_kritisch,"kritisch",IF(AA19>=P_Grenze_hoch,"hoch",IF(AA19>=P_Grenze_mittel,"mittel","gering")))) | AC19: =TRIM(IF(N(T19)>=P_Krit,"AS ","")&IF(N(S19)>=P_Krit,"Q ","")&IF(N(U19)>=P_Krit,"US","")) | AD19: =IF(ISNUMBER(R19),INDEX(IH_Text,R19),"") | AG19: Staucheinheit (Stauchdorn, Stauchspindel, Elemente für Abdichthub von rechts); Pos. 29 Stauchspindel (Kugelgewindespindel) | AH19: Maßnahme | AI19: =IF(H19="","",IFERROR(INDEX(Iv_Anzahl,MATCH(H19,Iv_Name,0)),IFERROR(VALUE(LEFT(TRIM(SUBSTITUTE(LOWER(H19),"alle ","")),FIND(" ",TRIM(SUBSTITUTE(LOWER(H19),"alle ",""))&" ")-1)),""))) | AJ19: =IF(H19="","",IFERROR(INDEX(Iv_Einheit,MATCH(H19,Iv_Name,0)),IF(ISNUMBER(SEARCH("jahr",H19)),"Jahre",IF(ISNUMBER(SEARCH("monat",H19)),"Monate",IF(ISNUMBER(SEARCH("woche",H19)),"Wochen",IF(ISNUMBER(SEARCH("tag",H19)),"Tage","")))))) | AK19: =IF(AND(ISNUMBER(AI19),AJ19<>""),IF(AI19>0,AI19*IF(AJ19="Tage",1,IF(AJ19="Wochen",7,IF(AJ19="Monate",365/12,365))),""),"") | AL19: =IF(ISNUMBER(AK19),365/AK19,"") | AM19: =IF(AND(ISNUMBER(AL19),ISNUMBER(AE19)),AL19*AE19/60,"") | AN19: =IF(ISNUMBER(AA19),AA19-ROW()/100000,"") | AO19: =IF(OR(L19="überfällig",L19="fällig"),J19+ROW()/100000,"") | AP19: 3.1.6 | AQ19: kontrolliere Getriebe (Sichtkontrolle auf Öl-Leckage )
A20: 3.1.7 | B20: Elektromotor kontrollieren (Funktion, Verschmutzung, Laufruhe, Kabel) | C20: Inspektion | E20: Motor sauber, ruhiger Lauf; Kabel unbeschädigt | G20: =IF(AB20="unvollständig","Bewertung fehlt",INDEX(Kl_Intervall,MATCH(AB20,Kl_Name,0))) | H20: =IF(G20="Bewertung fehlt","",G20) | J20: =IF(OR(I20="",NOT(ISNUMBER(AK20))),"",IF(AJ20="Tage",I20+AI20,IF(AJ20="Wochen",I20+7*AI20,EDATE(I20,ROUND(AI20*IF(AJ20="Jahre",12,1),0))))) | K20: =IF(J20="","",J20-TODAY()) | L20: =IF(H20="","Intervall fehlt",IF(NOT(ISNUMBER(AK20)),"Intervall prüfen",IF(I20="","nicht erfasst",IF(K20<0,"überfällig",IF(K20<=MIN(P_Vorwarn,ROUND(AK20/4,0)),"fällig","in Ordnung"))))) | Q20: 4 | R20: 4 | S20: 4 | T20: 2 | U20: 1 | V20: 1 | W20: 2 | X20: 4 | Y20: =P_SF | Z20: =IF(COUNT(Q20:V20)=6,SQRT(SUMSQ(Q20:V20))/2,"") | AA20: =IF(COUNT(W20:Z20)=4,Z20*W20*X20*Y20,"") | AB20: =IF(AA20="","unvollständig",IF(AA20>P_Grenze_kritisch,"kritisch",IF(AA20>=P_Grenze_hoch,"hoch",IF(AA20>=P_Grenze_mittel,"mittel","gering")))) | AC20: =TRIM(IF(N(T20)>=P_Krit,"AS ","")&IF(N(S20)>=P_Krit,"Q ","")&IF(N(U20)>=P_Krit,"US","")) | AD20: =IF(ISNUMBER(R20),INDEX(IH_Text,R20),"") | AG20: Staucheinheit (Stauchdorn, Stauchspindel, Elemente für Abdichthub von rechts); Pos. 29 Stauchspindel (Kugelgewindespindel) | AH20: Maßnahme | AI20: =IF(H20="","",IFERROR(INDEX(Iv_Anzahl,MATCH(H20,Iv_Name,0)),IFERROR(VALUE(LEFT(TRIM(SUBSTITUTE(LOWER(H20),"alle ","")),FIND(" ",TRIM(SUBSTITUTE(LOWER(H20),"alle ",""))&" ")-1)),""))) | AJ20: =IF(H20="","",IFERROR(INDEX(Iv_Einheit,MATCH(H20,Iv_Name,0)),IF(ISNUMBER(SEARCH("jahr",H20)),"Jahre",IF(ISNUMBER(SEARCH("monat",H20)),"Monate",IF(ISNUMBER(SEARCH("woche",H20)),"Wochen",IF(ISNUMBER(SEARCH("tag",H20)),"Tage","")))))) | AK20: =IF(AND(ISNUMBER(AI20),AJ20<>""),IF(AI20>0,AI20*IF(AJ20="Tage",1,IF(AJ20="Wochen",7,IF(AJ20="Monate",365/12,365))),""),"") | AL20: =IF(ISNUMBER(AK20),365/AK20,"") | AM20: =IF(AND(ISNUMBER(AL20),ISNUMBER(AE20)),AL20*AE20/60,"") | AN20: =IF(ISNUMBER(AA20),AA20-ROW()/100000,"") | AO20: =IF(OR(L20="überfällig",L20="fällig"),J20+ROW()/100000,"") | AP20: 3.1.7 | AQ20: Kontrolliere Elektromotor (Funktion/Verschmutzung/Laufruhe/Kabeln)
A21: 4 | B21: Oberer und unterer Werkzeugträger (Pos. 3 / 6) | AG21: Oberer und unterer Werkzeugträger | AH21: Baugruppe | AP21: 4 | AQ21: 3.) u. 6.) Oberer Werkzeugträger/Unterer Werkzeugträger
A22: 4.1 | B22: Alle Werkzeugträger nach folgenden Kriterien inspizieren: | AG22: Oberer und unterer Werkzeugträger | AH22: Prüfgruppe | AP22: 4.1 | AQ22: Inspiziere alle Werkzeugträger nach folgenden Kriterien:
A23: 4.1.1 | B23: Spindel auf Beschädigungen prüfen: Oberfläche (Riefen, Kratzer), Geräusche, Laufruhe | C23: Inspektion | E23: Keine Riefen/Kratzer; ruhiger, geräuscharmer Lauf | G23: =IF(AB23="unvollständig","Bewertung fehlt",INDEX(Kl_Intervall,MATCH(AB23,Kl_Name,0))) | H23: =IF(G23="Bewertung fehlt","",G23) | J23: =IF(OR(I23="",NOT(ISNUMBER(AK23))),"",IF(AJ23="Tage",I23+AI23,IF(AJ23="Wochen",I23+7*AI23,EDATE(I23,ROUND(AI23*IF(AJ23="Jahre",12,1),0))))) | K23: =IF(J23="","",J23-TODAY()) | L23: =IF(H23="","Intervall fehlt",IF(NOT(ISNUMBER(AK23)),"Intervall prüfen",IF(I23="","nicht erfasst",IF(K23<0,"überfällig",IF(K23<=MIN(P_Vorwarn,ROUND(AK23/4,0)),"fällig","in Ordnung"))))) | Q23: 5 | R23: 5 | S23: 3 | T23: 3 | U23: 2 | V23: 3 | W23: 5 | X23: 4 | Y23: =P_SF | Z23: =IF(COUNT(Q23:V23)=6,SQRT(SUMSQ(Q23:V23))/2,"") | AA23: =IF(COUNT(W23:Z23)=4,Z23*W23*X23*Y23,"") | AB23: =IF(AA23="","unvollständig",IF(AA23>P_Grenze_kritisch,"kritisch",IF(AA23>=P_Grenze_hoch,"hoch",IF(AA23>=P_Grenze_mittel,"mittel","gering")))) | AC23: =TRIM(IF(N(T23)>=P_Krit,"AS ","")&IF(N(S23)>=P_Krit,"Q ","")&IF(N(U23)>=P_Krit,"US","")) | AD23: =IF(ISNUMBER(R23),INDEX(IH_Text,R23),"") | AG23: Oberer und unterer Werkzeugträger | AH23: Maßnahme | AI23: =IF(H23="","",IFERROR(INDEX(Iv_Anzahl,MATCH(H23,Iv_Name,0)),IFERROR(VALUE(LEFT(TRIM(SUBSTITUTE(LOWER(H23),"alle ","")),FIND(" ",TRIM(SUBSTITUTE(LOWER(H23),"alle ",""))&" ")-1)),""))) | AJ23: =IF(H23="","",IFERROR(INDEX(Iv_Einheit,MATCH(H23,Iv_Name,0)),IF(ISNUMBER(SEARCH("jahr",H23)),"Jahre",IF(ISNUMBER(SEARCH("monat",H23)),"Monate",IF(ISNUMBER(SEARCH("woche",H23)),"Wochen",IF(ISNUMBER(SEARCH("tag",H23)),"Tage","")))))) | AK23: =IF(AND(ISNUMBER(AI23),AJ23<>""),IF(AI23>0,AI23*IF(AJ23="Tage",1,IF(AJ23="Wochen",7,IF(AJ23="Monate",365/12,365))),""),"") | AL23: =IF(ISNUMBER(AK23),365/AK23,"") | AM23: =IF(AND(ISNUMBER(AL23),ISNUMBER(AE23)),AL23*AE23/60,"") | AN23: =IF(ISNUMBER(AA23),AA23-ROW()/100000,"") | AO23: =IF(OR(L23="überfällig",L23="fällig"),J23+ROW()/100000,"") | AP23: 4.1.1 | AQ23: Spindel auf Beschädigungen prüfen (Oberfläche (Riffen, Kratzer) d. Spindel prüfen; Stauchspindel auf Geräusche, Laufruhe prüfen
A24: 4.1.2 | B24: Spindel auf Verschmutzung prüfen, ggf. reinigen | C24: Inspektion | E24: Spindel sauber, frei von Ablagerungen | G24: =IF(AB24="unvollständig","Bewertung fehlt",INDEX(Kl_Intervall,MATCH(AB24,Kl_Name,0))) | H24: =IF(G24="Bewertung fehlt","",G24) | J24: =IF(OR(I24="",NOT(ISNUMBER(AK24))),"",IF(AJ24="Tage",I24+AI24,IF(AJ24="Wochen",I24+7*AI24,EDATE(I24,ROUND(AI24*IF(AJ24="Jahre",12,1),0))))) | K24: =IF(J24="","",J24-TODAY()) | L24: =IF(H24="","Intervall fehlt",IF(NOT(ISNUMBER(AK24)),"Intervall prüfen",IF(I24="","nicht erfasst",IF(K24<0,"überfällig",IF(K24<=MIN(P_Vorwarn,ROUND(AK24/4,0)),"fällig","in Ordnung"))))) | Q24: 2 | R24: 2 | S24: 1 | T24: 1 | U24: 3 | V24: 1 | W24: 5 | X24: 2 | Y24: =P_SF | Z24: =IF(COUNT(Q24:V24)=6,SQRT(SUMSQ(Q24:V24))/2,"") | AA24: =IF(COUNT(W24:Z24)=4,Z24*W24*X24*Y24,"") | AB24: =IF(AA24="","unvollständig",IF(AA24>P_Grenze_kritisch,"kritisch",IF(AA24>=P_Grenze_hoch,"hoch",IF(AA24>=P_Grenze_mittel,"mittel","gering")))) | AC24: =TRIM(IF(N(T24)>=P_Krit,"AS ","")&IF(N(S24)>=P_Krit,"Q ","")&IF(N(U24)>=P_Krit,"US","")) | AD24: =IF(ISNUMBER(R24),INDEX(IH_Text,R24),"") | AG24: Oberer und unterer Werkzeugträger | AH24: Maßnahme | AI24: =IF(H24="","",IFERROR(INDEX(Iv_Anzahl,MATCH(H24,Iv_Name,0)),IFERROR(VALUE(LEFT(TRIM(SUBSTITUTE(LOWER(H24),"alle ","")),FIND(" ",TRIM(SUBSTITUTE(LOWER(H24),"alle ",""))&" ")-1)),""))) | AJ24: =IF(H24="","",IFERROR(INDEX(Iv_Einheit,MATCH(H24,Iv_Name,0)),IF(ISNUMBER(SEARCH("jahr",H24)),"Jahre",IF(ISNUMBER(SEARCH("monat",H24)),"Monate",IF(ISNUMBER(SEARCH("woche",H24)),"Wochen",IF(ISNUMBER(SEARCH("tag",H24)),"Tage","")))))) | AK24: =IF(AND(ISNUMBER(AI24),AJ24<>""),IF(AI24>0,AI24*IF(AJ24="Tage",1,IF(AJ24="Wochen",7,IF(AJ24="Monate",365/12,365))),""),"") | AL24: =IF(ISNUMBER(AK24),365/AK24,"") | AM24: =IF(AND(ISNUMBER(AL24),ISNUMBER(AE24)),AL24*AE24/60,"") | AN24: =IF(ISNUMBER(AA24),AA24-ROW()/100000,"") | AO24: =IF(OR(L24="überfällig",L24="fällig"),J24+ROW()/100000,"") | AP24: 4.1.2 | AQ24: Spindel auf Verschmutzung prüfen ggf. reinigen
A25: 4.1.3 | B25: Spindel abschmieren (siehe Schmierplan): Spindelmutter Y-Schlitten, 6 Hübe je Schmiernippel. Werkzeugträger zusammenfahren und prüfen, ob genügend Schmierfilm auf der Spindel vorhanden ist; ggf. nochmals abschmieren | C25: Schmierung | D25: ⚠ Gefahrenstelle / ℹ Hinweis beachten Profi Spezial Grease (Profi Star) | E25: Ausreichender Schmierfilm auf der Spindel | G25: =IF(AB25="unvollständig","Bewertung fehlt",INDEX(Kl_Intervall,MATCH(AB25,Kl_Name,0))) | H25: =IF(G25="Bewertung fehlt","",G25) | J25: =IF(OR(I25="",NOT(ISNUMBER(AK25))),"",IF(AJ25="Tage",I25+AI25,IF(AJ25="Wochen",I25+7*AI25,EDATE(I25,ROUND(AI25*IF(AJ25="Jahre",12,1),0))))) | K25: =IF(J25="","",J25-TODAY()) | L25: =IF(H25="","Intervall fehlt",IF(NOT(ISNUMBER(AK25)),"Intervall prüfen",IF(I25="","nicht erfasst",IF(K25<0,"überfällig",IF(K25<=MIN(P_Vorwarn,ROUND(AK25/4,0)),"fällig","in Ordnung"))))) | Q25: 5 | R25: 5 | S25: 3 | T25: 3 | U25: 2 | V25: 3 | W25: 5 | X25: 2 | Y25: =P_SF | Z25: =IF(COUNT(Q25:V25)=6,SQRT(SUMSQ(Q25:V25))/2,"") | AA25: =IF(COUNT(W25:Z25)=4,Z25*W25*X25*Y25,"") | AB25: =IF(AA25="","unvollständig",IF(AA25>P_Grenze_kritisch,"kritisch",IF(AA25>=P_Grenze_hoch,"hoch",IF(AA25>=P_Grenze_mittel,"mittel","gering")))) | AC25: =TRIM(IF(N(T25)>=P_Krit,"AS ","")&IF(N(S25)>=P_Krit,"Q ","")&IF(N(U25)>=P_Krit,"US","")) | AD25: =IF(ISNUMBER(R25),INDEX(IH_Text,R25),"") | AG25: Oberer und unterer Werkzeugträger | AH25: Maßnahme | AI25: =IF(H25="","",IFERROR(INDEX(Iv_Anzahl,MATCH(H25,Iv_Name,0)),IFERROR(VALUE(LEFT(TRIM(SUBSTITUTE(LOWER(H25),"alle ","")),FIND(" ",TRIM(SUBSTITUTE(LOWER(H25),"alle ",""))&" ")-1)),""))) | AJ25: =IF(H25="","",IFERROR(INDEX(Iv_Einheit,MATCH(H25,Iv_Name,0)),IF(ISNUMBER(SEARCH("jahr",H25)),"Jahre",IF(ISNUMBER(SEARCH("monat",H25)),"Monate",IF(ISNUMBER(SEARCH("woche",H25)),"Wochen",IF(ISNUMBER(SEARCH("tag",H25)),"Tage","")))))) | AK25: =IF(AND(ISNUMBER(AI25),AJ25<>""),IF(AI25>0,AI25*IF(AJ25="Tage",1,IF(AJ25="Wochen",7,IF(AJ25="Monate",365/12,365))),""),"") | AL25: =IF(ISNUMBER(AK25),365/AK25,"") | AM25: =IF(AND(ISNUMBER(AL25),ISNUMBER(AE25)),AL25*AE25/60,"") | AN25: =IF(ISNUMBER(AA25),AA25-ROW()/100000,"") | AO25: =IF(OR(L25="überfällig",L25="fällig"),J25+ROW()/100000,"") | AP25: 4.1.3 | AQ25: Spindel abschmieren (siehe Schmierplan) Spindelmutter Y-Schlitten --> Schmieren (6) Hübe/Schmiernippel. Werkzuegträger zusammenfahren und überprüfen ob genügend Schmierfilm auf Spindel vorhanden ggf. nochmal abschmieren
A26: 4.1.4 | B26: Hauptführung Y-Schlitten kontrollieren (!) – Schmierplan Pos. 1–5: Führungen abschmieren, 6 Hübe je Schmiernippel | C26: Schmierung | D26: ⚠ Gefahrenstelle / ℹ Hinweis beachten Profi Spezial Grease (Profi Star) | E26: abgeschmiert | G26: =IF(AB26="unvollständig","Bewertung fehlt",INDEX(Kl_Intervall,MATCH(AB26,Kl_Name,0))) | H26: =IF(G26="Bewertung fehlt","",G26) | J26: =IF(OR(I26="",NOT(ISNUMBER(AK26))),"",IF(AJ26="Tage",I26+AI26,IF(AJ26="Wochen",I26+7*AI26,EDATE(I26,ROUND(AI26*IF(AJ26="Jahre",12,1),0))))) | K26: =IF(J26="","",J26-TODAY()) | L26: =IF(H26="","Intervall fehlt",IF(NOT(ISNUMBER(AK26)),"Intervall prüfen",IF(I26="","nicht erfasst",IF(K26<0,"überfällig",IF(K26<=MIN(P_Vorwarn,ROUND(AK26/4,0)),"fällig","in Ordnung"))))) | Q26: 5 | R26: 5 | S26: 3 | T26: 3 | U26: 2 | V26: 3 | Y26: =P_SF | Z26: =IF(COUNT(Q26:V26)=6,SQRT(SUMSQ(Q26:V26))/2,"") | AA26: =IF(COUNT(W26:Z26)=4,Z26*W26*X26*Y26,"") | AB26: =IF(AA26="","unvollständig",IF(AA26>P_Grenze_kritisch,"kritisch",IF(AA26>=P_Grenze_hoch,"hoch",IF(AA26>=P_Grenze_mittel,"mittel","gering")))) | AC26: =TRIM(IF(N(T26)>=P_Krit,"AS ","")&IF(N(S26)>=P_Krit,"Q ","")&IF(N(U26)>=P_Krit,"US","")) | AD26: =IF(ISNUMBER(R26),INDEX(IH_Text,R26),"") | AG26: Oberer und unterer Werkzeugträger | AH26: Maßnahme | AI26: =IF(H26="","",IFERROR(INDEX(Iv_Anzahl,MATCH(H26,Iv_Name,0)),IFERROR(VALUE(LEFT(TRIM(SUBSTITUTE(LOWER(H26),"alle ","")),FIND(" ",TRIM(SUBSTITUTE(LOWER(H26),"alle ",""))&" ")-1)),""))) | AJ26: =IF(H26="","",IFERROR(INDEX(Iv_Einheit,MATCH(H26,Iv_Name,0)),IF(ISNUMBER(SEARCH("jahr",H26)),"Jahre",IF(ISNUMBER(SEARCH("monat",H26)),"Monate",IF(ISNUMBER(SEARCH("woche",H26)),"Wochen",IF(ISNUMBER(SEARCH("tag",H26)),"Tage","")))))) | AK26: =IF(AND(ISNUMBER(AI26),AJ26<>""),IF(AI26>0,AI26*IF(AJ26="Tage",1,IF(AJ26="Wochen",7,IF(AJ26="Monate",365/12,365))),""),"") | AL26: =IF(ISNUMBER(AK26),365/AK26,"") | AM26: =IF(AND(ISNUMBER(AL26),ISNUMBER(AE26)),AL26*AE26/60,"") | AN26: =IF(ISNUMBER(AA26),AA26-ROW()/100000,"") | AO26: =IF(OR(L26="überfällig",L26="fällig"),J26+ROW()/100000,"") | AP26: 4.1.4 | AQ26: Hauptführung Y-Schlitten kontrollieren !!! Schmierplan Pos. 1-5 Führungen abschmiern (6) Hübe/Schmiernippel
A27: 4.1.5 | B27: Elektromotor kontrollieren (Funktion, Verschmutzung, Laufruhe, Kabel) | C27: Inspektion | E27: Motor sauber, ruhiger Lauf; Kabel unbeschädigt | G27: =IF(AB27="unvollständig","Bewertung fehlt",INDEX(Kl_Intervall,MATCH(AB27,Kl_Name,0))) | H27: =IF(G27="Bewertung fehlt","",G27) | J27: =IF(OR(I27="",NOT(ISNUMBER(AK27))),"",IF(AJ27="Tage",I27+AI27,IF(AJ27="Wochen",I27+7*AI27,EDATE(I27,ROUND(AI27*IF(AJ27="Jahre",12,1),0))))) | K27: =IF(J27="","",J27-TODAY()) | L27: =IF(H27="","Intervall fehlt",IF(NOT(ISNUMBER(AK27)),"Intervall prüfen",IF(I27="","nicht erfasst",IF(K27<0,"überfällig",IF(K27<=MIN(P_Vorwarn,ROUND(AK27/4,0)),"fällig","in Ordnung"))))) | Q27: 3 | R27: 3 | S27: 2 | T27: 2 | U27: 2 | V27: 3 | W27: 2 | X27: 3 | Y27: =P_SF | Z27: =IF(COUNT(Q27:V27)=6,SQRT(SUMSQ(Q27:V27))/2,"") | AA27: =IF(COUNT(W27:Z27)=4,Z27*W27*X27*Y27,"") | AB27: =IF(AA27="","unvollständig",IF(AA27>P_Grenze_kritisch,"kritisch",IF(AA27>=P_Grenze_hoch,"hoch",IF(AA27>=P_Grenze_mittel,"mittel","gering")))) | AC27: =TRIM(IF(N(T27)>=P_Krit,"AS ","")&IF(N(S27)>=P_Krit,"Q ","")&IF(N(U27)>=P_Krit,"US","")) | AD27: =IF(ISNUMBER(R27),INDEX(IH_Text,R27),"") | AG27: Oberer und unterer Werkzeugträger | AH27: Maßnahme | AI27: =IF(H27="","",IFERROR(INDEX(Iv_Anzahl,MATCH(H27,Iv_Name,0)),IFERROR(VALUE(LEFT(TRIM(SUBSTITUTE(LOWER(H27),"alle ","")),FIND(" ",TRIM(SUBSTITUTE(LOWER(H27),"alle ",""))&" ")-1)),""))) | AJ27: =IF(H27="","",IFERROR(INDEX(Iv_Einheit,MATCH(H27,Iv_Name,0)),IF(ISNUMBER(SEARCH("jahr",H27)),"Jahre",IF(ISNUMBER(SEARCH("monat",H27)),"Monate",IF(ISNUMBER(SEARCH("woche",H27)),"Wochen",IF(ISNUMBER(SEARCH("tag",H27)),"Tage","")))))) | AK27: =IF(AND(ISNUMBER(AI27),AJ27<>""),IF(AI27>0,AI27*IF(AJ27="Tage",1,IF(AJ27="Wochen",7,IF(AJ27="Monate",365/12,365))),""),"") | AL27: =IF(ISNUMBER(AK27),365/AK27,"") | AM27: =IF(AND(ISNUMBER(AL27),ISNUMBER(AE27)),AL27*AE27/60,"") | AN27: =IF(ISNUMBER(AA27),AA27-ROW()/100000,"") | AO27: =IF(OR(L27="überfällig",L27="fällig"),J27+ROW()/100000,"") | AP27: 4.1.5 | AQ27: Kontrolliere Elektromotor (Funktion/Verschmutzung/Laufruhe/Kabeln)
A28: 5 | B28: Verschlussbalken (Pos. 5) | AG28: Verschlussbalken | AH28: Baugruppe | AP28: 5 | AQ28: 5.) Verschlussbalken
